Workbook
Name \A: #REF!
Name \B: #REF!
Name \C: #REF!
Name \P: #REF!
Name \Q: #REF!
Name \R: #REF!
Name \S: #REF!
Name \T: #REF!
Name \X: #REF!
Name ___CON1: #REF!
Name ___CON2: #REF!
Name ___ddn400: #REF!
Name ___ddn600: #REF!
Name ___E99999: #REF!
Name ___gon4: #REF!
Name ___IV999999: #REF!
Name ___IZ53: #REF!
Name ___JZ123: #REF!
Name ___lap1: #REF!
Name ___lap2: #REF!
Name ___LI10: OFFSET(#REF!,4,0,COUNTA(#REF!)-1,1)
Name ___LI3: OFFSET(#REF!,4,0,COUNTA(#REF!)-1,1)
Name ___LI6: OFFSET(#REF!,4,0,COUNTA(#REF!)-1,1)
Name ___LI7: OFFSET(#REF!,4,0,COUNTA(#REF!)-1,1)
Name ___LZ123: #REF!
Name ___MAC12: #REF!
Name ___MAC46: #REF!
Name ___MZ53: #REF!
Name ___NCL100: #REF!
Name ___NCL200: #REF!
Name ___NCL250: #REF!
Name ___NET2: #REF!
Name ___nin190: #REF!
Name ___sc1: #REF!
Name ___SC2: #REF!
Name ___sc3: #REF!
Name ___SN3: #REF!
Name ___TB1: #REF!
Name ___TL1: #REF!
Name ___TL2: #REF!
Name ___TL3: #REF!
Name ___TLA120: #REF!
Name ___TLA35: #REF!
Name ___TLA50: #REF!
Name ___TLA70: #REF!
Name ___TLA95: #REF!
Name ___VL100: #REF!
Name ___VL200: #REF!
Name ___VL250: #REF!
Name ___XY123: #REF!
Name __1: #REF!
Name __2: #REF!
Name __CON1: #REF!
Name __CON2: #REF!
Name __ddn400: #REF!
Name __ddn600: #REF!
Name __E99999: #REF!
Name __gon4: #REF!
Name __IV17532: #REF!
Name __IV19999: #REF!

Sheet Instruction
B1: Actual Reporting
B2: 1. | C2: Please update copertura for the period / data entry - line 53 onwords
B3: 2. | C3: Please update the actual cost for the period / data entry - line 75 onwords
B4: 3. | C4: Update columns "Q" & "R" in the data entry and budget assumption tab
B6: 4. | C6: YTD and MTD variances, as well as the report is populated automatically
B7: 5. | C7: Please provide the rootcauses for the variances YTD and MTD Report (column J-P)
C8: Checkline in column "U" needs to be zero in each line
B9: 6. | C9: SAP extraction actual cost lines as separate sheet
B11: FCST Reporting
B13: 1. | C13: Please fill in the copertura and actuals for the upcoming months _ data entry tab - lines 53-94
B14: 2. | C14: FCST tab is populated automatically , please check the correctness
B15: 3. | C15: Provide root cause split for the upcoming periods variances
B16: 4. | C16: Paste values previous submitted FCST in "FCST25" sheet lines 47-87
B17: 5. | C17: Check variances vs last forecast in "FCST25" sheet lines 91-131
B18: 6. | C18: Update column AE & AF in "FCST CPU"
B19: 7. | C19: Update Material & Freight In part in "FCST CPU"

Sheet Root cause explanations
B2: Budget Cost | C2: Budgeted cost of the period @ Budget FX rate
B4: ACE | C4: Permanent saving, linked to ACE projects. This line needs to give us the deviation versus the budgeted ACE improvements
B6: MFG Efficiency | C6: Saving / Cost in relation with current year standard production process not linked to price , one off or ACE ; e.g delay of hiring , not spending the budget for a specific line or additional consumption due to breakdown etc
B8: S&OP | C8: Increase or decrease of cost due to volume fluctuations; Excess of Manpower, Additional / less vertical closure days impact, Incremental cost increase / decrease on the fixed cost due to volume change
B10: Price / Inflation | C10: Pure Price or Inflation impact
B12: fX translation | C12: fx impact act fx versus budget fx
B14: One off | C14: Extraordinary expense/income not linked to current year standard production process; previous years income/ loss, write off and sale of assets , one time expenses like restructuring program, cost related to opening ceremony, extra ordinary donations etc
B16: Oth Functions | C16: Cost related to claims , which in the past was recharged to R&D, Procurement , Logistics
B18: Actual Cost | C18: Actual cost of the period converted @ actual fx rate

Sheet HC 2026
A1: Headcount 2026 (ACT + FCST)
C3: Jan | D3: Feb | E3: March | F3: April | G3: May | H3: June | I3: July | J3: August | K3: Sept | L3: Oct | M3: Nov | N3: Dec | O3: Total
A4: Direct HC | B4: Production | C4: 236.73 | D4: 215 | E4: 132 | F4: 245 | G4: 253.01372 | H4: 245.10067 | I4: 242.74113 | J4: 238.75755 | K4: 242.0053 | L4: 244.84655 | M4: 243.1902 | N4: 245.46848 | O4: =AVERAGE(C4:N4) -> 231.9878
B5: Shared | O5: =AVERAGE(C5:N5) -> #DIV/0!
B6: Total | C6: =C4+C5 -> 236.73 | D6: =D4+D5 -> 215 | E6: =E4+E5 -> 132 | F6: =F4+F5 -> 245 | G6: =G4+G5 -> 253.01372 | H6: =H4+H5 -> 245.10067 | I6: =I4+I5 -> 242.74113 | J6: =J4+J5 -> 238.75755 | ... N6: =N4+N5 -> 245.46848 | O6: =AVERAGE(C6:N6) -> 231.9878
B8: Assigned hours | O8: =AVERAGE(C8:N8) -> #DIV/0!
C10: Jan | D10: Feb | E10: March | F10: April | G10: May | H10: June | I10: July | J10: August | K10: Sept | L10: Oct | M10: Nov | N10: Dec | O10: Total
A11: Indirect HC | B11: Production | C11: 85 | D11: 82 | E11: 69 | F11: 85 | G11: 85 | H11: 85 | I11: 85 | J11: 85 | K11: 85 | L11: 85 | M11: 85 | N11: 85 | O11: =AVERAGE(C11:N11) -> 83.416667
B12: Shared | O12: =AVERAGE(C12:N12) -> #DIV/0!
B13: Total | C13: =C11+C12 -> 85 | D13: =D11+D12 -> 82 | E13: =E11+E12 -> 69 | F13: =F11+F12 -> 85 | G13: =G11+G12 -> 85 | H13: =H11+H12 -> 85 | I13: =I11+I12 -> 85 | J13: =J11+J12 -> 85 | ... N13: =N11+N12 -> 85 | O13: =AVERAGE(C13:N13) -> 83.416667
C16: Jan | D16: Feb | E16: March | F16: April | G16: May | H16: June | I16: July | J16: August | K16: Sept | L16: Oct | M16: Nov | N16: Dec | O16: Total
A17: Fixed HC | B17: Production | C17: 22 | D17: 22 | E17: 22 | F17: 22 | G17: 22 | H17: 22 | I17: 22 | J17: 23 | K17: 23 | L17: 23 | M17: 23 | N17: 23 | O17: =AVERAGE(C17:N17) -> 22.416667
B18: Shared | C18: 3.5 | D18: 3.5 | E18: 3.5 | F18: 4.5 | G18: 4.5 | H18: 4.5 | I18: 4.5 | J18: 4.5 | K18: 4.5 | L18: 4.5 | M18: 4.5 | N18: 4.5 | O18: =AVERAGE(C18:N18) -> 4.25
B19: Lapro | O19: =AVERAGE(C19:N19) -> #DIV/0!
B20: Total | C20: =C17+C18+C19 -> 25.5 | D20: =D17+D18+D19 -> 25.5 | E20: =E17+E18+E19 -> 25.5 | F20: =F17+F18+F19 -> 26.5 | G20: =G17+G18+G19 -> 26.5 | H20: =H17+H18+H19 -> 26.5 | I20: =I17+I18+I19 -> 26.5 | J20: =J17+J18+J19 -> 27.5 | ... N20: =N17+N18+N19 -> 27.5 | O20: =AVERAGE(C20:N20) -> 26.666667
C24: Jan | D24: Feb | E24: March | F24: April | G24: May | H24: June | I24: July | J24: Aug | K24: Sep | L24: Oct | M24: Nov | N24: Dec | O24: Total
B25: Direct HC | C25: =+C6 -> 236.73 | D25: =+D6 -> 215 | E25: =+E6 -> 132 | F25: =+F6 -> 245 | G25: =+G6 -> 253.01372 | H25: =+H6 -> 245.10067 | I25: =+I6 -> 242.74113 | J25: =+J6 -> 238.75755 | ... N25: =+N6 -> 245.46848 | O25: =O6 -> 231.9878
B26: Indirect HC | C26: =+C13 -> 85 | D26: =+D13 -> 82 | E26: =+E13 -> 69 | F26: =+F13 -> 85 | G26: =+G13 -> 85 | H26: =+H13 -> 85 | I26: =+I13 -> 85 | J26: =+J13 -> 85 | ... N26: =+N13 -> 85 | O26: =O13 -> 83.416667
B27: Total HC | C27: =C25+C26 -> 321.73 | D27: =D25+D26 -> 297 | E27: =E25+E26 -> 201 | F27: =F25+F26 -> 330 | G27: =G25+G26 -> 338.01372 | H27: =H25+H26 -> 330.10067 | I27: =I25+I26 -> 327.74113 | J27: =J25+J26 -> 323.75755 | ... O27: =O25+O26 -> 315.40447
B29: Temporary ratio | C29: =+C26/C27 -> 0.26419669 | D29: =+D26/D27 -> 0.27609428 | E29: =+E26/E27 -> 0.34328358 | F29: =+F26/F27 -> 0.25757576 | G29: =+G26/G27 -> 0.25146908 | H29: =+H26/H27 -> 0.25749721 | I29: =+I26/I27 -> 0.25935103 | J29: =+J26/J27 -> 0.26254214 | ... N29: =+N26/N27 -> 0.25721061
A32: BUDGET | C32: Jan | D32: Feb | E32: March | F32: April | G32: May | H32: June | I32: July | J32: August | K32: Sept | L32: Oct | M32: Nov | N32: Dec | O32: Total
A33: Direct HC | B33: Production | C33: 244 | D33: 244 | E33: 244 | F33: 244 | G33: 247 | H33: 245 | I33: 245 | J33: 251 | K33: 252 | L33: 250 | M33: 251 | N33: 252 | O33: =AVERAGE(C33:N33) -> 247.41667
B34: Shared | O34: =AVERAGE(C34:N34) -> #DIV/0!
B35: Total | C35: =C33+C34 -> 244 | D35: =D33+D34 -> 244 | E35: =E33+E34 -> 244 | F35: =F33+F34 -> 244 | G35: =G33+G34 -> 247 | H35: =H33+H34 -> 245 | I35: =I33+I34 -> 245 | J35: =J33+J34 -> 251 | ... N35: =N33+N34 -> 252 | O35: =AVERAGE(C35:N35) -> 247.41667
B37: Assigned hours | O37: =AVERAGE(C37:N37) -> #DIV/0!
A39: BUDGET | C39: Jan | D39: Feb | E39: March | F39: April | G39: May | H39: June | I39: July | J39: August | K39: Sept | L39: Oct | M39: Nov | N39: Dec | O39: Total
A40: Indirect HC | B40: Production | C40: 85 | D40: 85 | E40: 85 | F40: 85 | G40: 85 | H40: 85 | I40: 85 | J40: 85 | K40: 85 | L40: 85 | M40: 85 | N40: 85 | O40: =AVERAGE(C40:N40) -> 85
B41: Shared | O41: =AVERAGE(C41:N41) -> #DIV/0!
B42: Total | C42: =C40+C41 -> 85 | D42: =D40+D41 -> 85 | E42: =E40+E41 -> 85 | F42: =F40+F41 -> 85 | G42: =G40+G41 -> 85 | H42: =H40+H41 -> 85 | I42: =I40+I41 -> 85 | J42: =J40+J41 -> 85 | ... N42: =N40+N41 -> 85 | O42: =AVERAGE(C42:N42) -> 85
A45: BUDGET | C45: Jan | D45: Feb | E45: March | F45: April | G45: May | H45: June | I45: July | J45: August | K45: Sept | L45: Oct | M45: Nov | N45: Dec | O45: Total
A46: Fixed HC | B46: Production | C46: 22 | D46: 22 | E46: 22 | F46: 22 | G46: 22 | H46: 22 | I46: 22 | J46: 23 | K46: 23 | L46: 23 | M46: 23 | N46: 23 | O46: =AVERAGE(C46:N46) -> 22.416667
B47: Shared | C47: 4.5 | D47: 4.5 | E47: 4.5 | F47: 4.5 | G47: 4.5 | H47: 4.5 | I47: 4.5 | J47: 4.5 | K47: 4.5 | L47: 4.5 | M47: 4.5 | N47: 4.5 | O47: =AVERAGE(C47:N47) -> 4.5 | P47: 1.5 hqd included
B48: Lapro | O48: =AVERAGE(C48:N48) -> #DIV/0!
B49: Total | C49: =C46+C47+C48 -> 26.5 | D49: =D46+D47+D48 -> 26.5 | E49: =E46+E47+E48 -> 26.5 | F49: =F46+F47+F48 -> 26.5 | G49: =G46+G47+G48 -> 26.5 | H49: =H46+H47+H48 -> 26.5 | I49: =I46+I47+I48 -> 26.5 | J49: =J46+J47+J48 -> 27.5 | ... N49: =N46+N47+N48 -> 27.5 | O49: =AVERAGE(C49:N49) -> 26.916667

Sheet G&A _Out of Per_
C2: RENTA | I2: EURASIA | K2: TOTAL
C3: TD | D3: DW | E3: CK | F3: INFRA | G3: TOTAL | I3: TOTAL | M3: Highlights;
B4: Association dues (MESS Payment) | G4: =SUM(C4:F4) -> 0 | K4: =G4+I4 -> 0
B5: G&A Recharge Eurosia - Renta | G5: =SUM(C5:F5) -> 0 | K5: =G5+I5 -> 0
B6: IT Recharge Group | G6: =SUM(C6:F6) -> 0 | K6: =G6+I6 -> 0
B7: Controlling Expenses | G7: =SUM(C7:F7) -> 0 | K7: =G7+I7 -> 0
B8: Enterprice Property Insurance | G8: =SUM(C8:F8) -> 0 | K8: =G8+I8 -> 0
B9: Profit on Asset Sale | G9: =SUM(C9:F9) -> 0 | K9: =G9+I9 -> 0
B10: Loss on Asset Sale | G10: =SUM(C10:F10) -> 0 | K10: =G10+I10 -> 0
B11: Litigation fee | G11: =SUM(C11:F11) -> 0 | K11: =G11+I11 -> 0
B12: INFRA | G12: =SUM(C12:F12) -> 0 | K12: =G12+I12 -> 0
B13: …...... | G13: =SUM(C13:F13) -> 0 | K13: =G13+I13 -> 0
B14: G&A _ Out of Perimeter | C14: =SUM(C4:C13) -> 0 | D14: =SUM(D4:D13) -> 0 | E14: =SUM(E4:E13) -> 0 | F14: =SUM(F4:F13) -> 0 | G14: =SUM(G4:G13) -> 0 | I14: =SUM(I4:I13) -> 0 | K14: =SUM(K4:K13) -> 0

Sheet CC
I2: MFG | J2: PTK4M00WAB
J3: PTK4M00WAC
J4: PTK4M00WAD
J5: PTK4M00WAE
J6: PTK4M00WAF
J7: PTK4M00WAG
J8: PTK4M00WAH
J9: PTK4M00WAI
J10: PTK4M00WAJ
J11: PTK4M00WAK
J12: PTK4M00WYD
I13: Overhead | J13: PTK4Y00WYE

Sheet ACE 2026
A1: YTD | B1: =IF($V$3>=B$2,1,0) -> 1 | C1: =IF($V$3>=C$2,1,0) -> 0 | D1: =IF($V$3>=D$2,1,0) -> 0 | E1: =IF($V$3>=E$2,1,0) -> 0 | F1: =IF($V$3>=F$2,1,0) -> 0 | G1: =IF($V$3>=G$2,1,0) -> 0 | H1: =IF($V$3>=H$2,1,0) -> 0 | I1: =IF($V$3>=I$2,1,0) -> 0 | ... M1: =IF($V$3>=M$2,1,0) -> 0
A2: MTD | B2: 1 | C2: 2 | D2: 3 | E2: 4 | F2: 5 | G2: 6 | H2: 7 | I2: 8 | J2: 9 | K2: 10 | L2: 11 | M2: 12
T3: Month | U3: Jan | V3: =VLOOKUP(U3,List!$C$2:$D$13,2,0) -> 1 | W3: =VLOOKUP(U3,List!$C$2:$E$13,3,0) -> 1
A4: ACE Budget | B4: Jan | C4: Feb | D4: March | E4: April | F4: May | G4: June | H4: July | I4: August | J4: Sept | K4: Oct | L4: Nov | M4: Dec | N4: Total | P4: MTD | Q4: YTD
A5: Direct Labour | B5: 4644.3971 | C5: 5010.6746 | D5: 5057.5234 | E5: 4872.7558 | F5: 15380.89 | G5: 49280.033 | H5: 49328.755 | I5: 49547.308 | J5: 58604.946 | K5: 54442.467 | L5: 52437.071 | M5: 52468.259 | N5: =SUM(B5:M5) -> 401075.08 | P5: =+SUMIFS(B5:M5,$B$2:$M$2,$V$3)/1000 -> 4.6443971 | Q5: =+SUMIFS(B5:M5,$B$1:$M$1,$W$3)/1000 -> 4.6443971
A6: Variable Utilities | B6: 0 | C6: 0 | D6: 0 | E6: 0 | F6: 0 | G6: 0 | H6: 0 | I6: 0 | J6: 0 | K6: 0 | L6: 0 | M6: 0 | N6: =SUM(B6:M6) -> 0 | P6: =+SUMIFS(B6:M6,$B$2:$M$2,$V$3)/1000 -> 0 | Q6: =+SUMIFS(B6:M6,$B$1:$M$1,$W$3)/1000 -> 0
A7: Scrap | B7: 0 | C7: 0 | D7: 0 | E7: 6811.5 | F7: 5019 | G7: 7528.5 | H7: 6094.5 | I7: 5557.5 | J7: 7780.5 | K7: 6669 | L7: 7410 | M7: 5570.25 | N7: =SUM(B7:M7) -> 58440.75 | P7: =+SUMIFS(B7:M7,$B$2:$M$2,$V$3)/1000 -> 0 | Q7: =+SUMIFS(B7:M7,$B$1:$M$1,$W$3)/1000 -> 0
A8: Scrap Reselling | B8: 0 | C8: 0 | D8: 0 | E8: 0 | F8: 0 | G8: 0 | H8: 0 | I8: 0 | J8: 0 | K8: 0 | L8: 0 | M8: 0 | N8: =SUM(B8:M8) -> 0 | P8: =+SUMIFS(B8:M8,$B$2:$M$2,$V$3)/1000 -> 0 | Q8: =+SUMIFS(B8:M8,$B$1:$M$1,$W$3)/1000 -> 0
A9: Variable Costs | B9: 1000 | C9: 1000 | D9: 1000 | E9: 1000 | F9: 1000 | G9: 1000 | H9: 1000 | I9: 1000 | J9: 1000 | K9: 1000 | L9: 1000 | M9: 1000 | N9: =SUM(B9:M9) -> 12000 | P9: =+SUMIFS(B9:M9,$B$2:$M$2,$V$3)/1000 -> 1 | Q9: =+SUMIFS(B9:M9,$B$1:$M$1,$W$3)/1000 -> 1
A10: VARIABLE CONVERSION | B10: =SUM(B5:B9) -> 5644.3971 | C10: =SUM(C5:C9) -> 6010.6746 | D10: =SUM(D5:D9) -> 6057.5234 | E10: =SUM(E5:E9) -> 12684.256 | F10: =SUM(F5:F9) -> 21399.89 | G10: =SUM(G5:G9) -> 57808.533 | H10: =SUM(H5:H9) -> 56423.255 | I10: =SUM(I5:I9) -> 56104.808 | ... M10: =SUM(M5:M9) -> 59038.509 | N10: =SUM(B10:M10) -> 471515.83 | P10: =SUM(P5:P9) -> 5.6443971 | Q10: =SUM(Q5:Q9) -> 5.6443971
A11: Indirect Labour | B11: 0 | C11: 0 | D11: 0 | E11: 0 | F11: 0 | G11: 0 | H11: 0 | I11: 0 | J11: 0 | K11: 0 | L11: 0 | M11: 0 | N11: =SUM(B11:M11) -> 0 | P11: =+SUMIFS(B11:M11,$B$2:$M$2,$V$3)/1000 -> 0 | Q11: =+SUMIFS(B11:M11,$B$1:$M$1,$W$3)/1000 -> 0
A12: Fixed Labour | B12: 0 | C12: 0 | D12: 0 | E12: 0 | F12: 0 | G12: 0 | H12: 0 | I12: 0 | J12: 0 | K12: 0 | L12: 0 | M12: 0 | N12: =SUM(B12:M12) -> 0 | P12: =+SUMIFS(B12:M12,$B$2:$M$2,$V$3)/1000 -> 0 | Q12: =+SUMIFS(B12:M12,$B$1:$M$1,$W$3)/1000 -> 0
A13: Semifixed | B13: 0 | C13: 0 | D13: 0 | E13: 0 | F13: 0 | G13: 0 | H13: 0 | I13: 0 | J13: 0 | K13: 0 | L13: 0 | M13: 0 | N13: =SUM(B13:M13) -> 0 | P13: =+SUMIFS(B13:M13,$B$2:$M$2,$V$3)/1000 -> 0 | Q13: =+SUMIFS(B13:M13,$B$1:$M$1,$W$3)/1000 -> 0
A14: Fixed utilities | B14: 1100 | C14: 1100 | D14: 1100 | E14: 1100 | F14: 1100 | G14: 1100 | H14: 1100 | I14: 1100 | J14: 1100 | K14: 1100 | L14: 1100 | M14: 1100 | N14: =SUM(B14:M14) -> 13200 | P14: =+SUMIFS(B14:M14,$B$2:$M$2,$V$3)/1000 -> 1.1 | Q14: =+SUMIFS(B14:M14,$B$1:$M$1,$W$3)/1000 -> 1.1
A15: Fixed Cost | B15: 0 | C15: 0 | D15: 0 | E15: 0 | F15: 0 | G15: 0 | H15: 0 | I15: 0 | J15: 0 | K15: 0 | L15: 0 | M15: 0 | N15: =SUM(B15:M15) -> 0 | P15: =+SUMIFS(B15:M15,$B$2:$M$2,$V$3)/1000 -> 0 | Q15: =+SUMIFS(B15:M15,$B$1:$M$1,$W$3)/1000 -> 0
A16: Obsolete | N16: =SUM(B16:M16) -> 0 | P16: =+SUMIFS(B16:M16,$B$2:$M$2,$V$3)/1000 -> 0 | Q16: =+SUMIFS(B16:M16,$B$1:$M$1,$W$3)/1000 -> 0
A17: Depreciation | N17: =SUM(B17:M17) -> 0 | P17: =+SUMIFS(B17:M17,$B$2:$M$2,$V$3)/1000 -> 0 | Q17: =+SUMIFS(B17:M17,$B$1:$M$1,$W$3)/1000 -> 0
A18: FIXED CONVERSION | B18: =SUM(B11:B17) -> 1100 | C18: =SUM(C11:C17) -> 1100 | D18: =SUM(D11:D17) -> 1100 | E18: =SUM(E11:E17) -> 1100 | F18: =SUM(F11:F17) -> 1100 | G18: =SUM(G11:G17) -> 1100 | H18: =SUM(H11:H17) -> 1100 | I18: =SUM(I11:I17) -> 1100 | ... M18: =SUM(M11:M17) -> 1100 | N18: =SUM(B18:M18) -> 13200 | P18: =SUM(P11:P17) -> 1.1 | Q18: =SUM(Q11:Q17) -> 1.1
A19: OVH AND OTHERS | B19: 0 | C19: 0 | D19: 0 | E19: 0 | F19: 0 | G19: 0 | H19: 0 | I19: 0 | J19: 0 | K19: 0 | L19: 0 | M19: 0 | N19: =SUM(B19:M19) -> 0 | P19: =+SUMIFS(B19:M19,$B$2:$M$2,$V$3)/1000 -> 0 | Q19: =+SUMIFS(B19:M19,$B$1:$M$1,$W$3)/1000 -> 0
A20: Grand Total | B20: =SUM(B10,B18,B19) -> 6744.3971 | C20: =SUM(C10,C18,C19) -> 7110.6746 | D20: =SUM(D10,D18,D19) -> 7157.5234 | E20: =SUM(E10,E18,E19) -> 13784.256 | F20: =SUM(F10,F18,F19) -> 22499.89 | G20: =SUM(G10,G18,G19) -> 58908.533 | H20: =SUM(H10,H18,H19) -> 57523.255 | I20: =SUM(I10,I18,I19) -> 57204.808 | ... M20: =SUM(M10,M18,M19) -> 60138.509 | N20: =SUM(B20:M20) -> 484715.83 | P20: =P18+P10+P19 -> 6.7443971 | Q20: =Q18+Q10+Q19 -> 6.7443971
A23: F-Matrix Actual | B23: Jan | C23: Feb | D23: March | E23: April | F23: May | G23: June | H23: July | I23: August | J23: Sept | K23: Oct | L23: Nov | M23: Dec | N23: Total | P23: MTD | Q23: YTD
A24: Direct Labour | B24: 40450.38 | C24: 48560.941 | D24: 24543.182 | E24: 26853.444 | F24: 26083.254 | G24: 29086.995 | H24: 27265.034 | I24: 27115.925 | J24: 29457.764 | K24: 28696.971 | L24: 29000.118 | M24: 27498.863 | N24: =SUM(B24:M24) -> 364612.87 | P24: =+SUMIFS(B24:M24,$B$2:$M$2,$V$3)/1000 -> 40.45038 | Q24: =+SUMIFS(B24:M24,$B$1:$M$1,$W$3)/1000 -> 40.45038
A25: Variable Utilities | N25: =SUM(B25:M25) -> 0 | P25: =+SUMIFS(B25:M25,$B$2:$M$2,$V$3)/1000 -> 0 | Q25: =+SUMIFS(B25:M25,$B$1:$M$1,$W$3)/1000 -> 0
A26: Scrap | B26: 0 | C26: 0 | D26: 0 | E26: 0 | F26: 5251.9342 | G26: 8355.3499 | H26: 6472.9293 | I26: 6318.8726 | J26: 8738.4228 | K26: 7952.3833 | L26: 8265.5896 | M26: 6714.5183 | N26: =SUM(B26:M26) -> 58070 | P26: =+SUMIFS(B26:M26,$B$2:$M$2,$V$3)/1000 -> 0 | Q26: =+SUMIFS(B26:M26,$B$1:$M$1,$W$3)/1000 -> 0
A27: Scrap Reselling | N27: =SUM(B27:M27) -> 0 | P27: =+SUMIFS(B27:M27,$B$2:$M$2,$V$3)/1000 -> 0 | Q27: =+SUMIFS(B27:M27,$B$1:$M$1,$W$3)/1000 -> 0
A28: Variable Costs | B28: 1000 | C28: 1000 | D28: 1000 | E28: 1000 | F28: 1000 | G28: 1000 | H28: 1000 | I28: 1000 | J28: 1000 | K28: 1000 | L28: 1000 | M28: 1000 | N28: =SUM(B28:M28) -> 12000 | P28: =+SUMIFS(B28:M28,$B$2:$M$2,$V$3)/1000 -> 1 | Q28: =+SUMIFS(B28:M28,$B$1:$M$1,$W$3)/1000 -> 1
A29: VARIABLE CONVERSION | B29: =SUM(B24:B28) -> 41450.38 | C29: =SUM(C24:C28) -> 49560.941 | D29: =SUM(D24:D28) -> 25543.182 | E29: =SUM(E24:E28) -> 27853.444 | F29: =SUM(F24:F28) -> 32335.188 | G29: =SUM(G24:G28) -> 38442.345 | H29: =SUM(H24:H28) -> 34737.963 | I29: =SUM(I24:I28) -> 34434.797 | ... M29: =SUM(M24:M28) -> 35213.382 | N29: =SUM(B29:M29) -> 434682.87 | P29: =SUM(P24:P28) -> 41.45038 | Q29: =SUM(Q24:Q28) -> 41.45038
A30: Indirect Labour | B30: 0 | C30: 2240.8813 | D30: 2240.8813 | E30: 2240.8813 | F30: 2240.8813 | G30: 2240.8813 | H30: 2240.8813 | I30: 2240.8813 | J30: 2240.8813 | K30: 2240.8813 | L30: 2240.8813 | M30: 2240.8813 | N30: =SUM(B30:M30) -> 24649.694 | P30: =+SUMIFS(B30:M30,$B$2:$M$2,$V$3)/1000 -> 0 | Q30: =+SUMIFS(B30:M30,$B$1:$M$1,$W$3)/1000 -> 0
A31: Fixed Labour | N31: =SUM(B31:M31) -> 0 | P31: =+SUMIFS(B31:M31,$B$2:$M$2,$V$3)/1000 -> 0 | Q31: =+SUMIFS(B31:M31,$B$1:$M$1,$W$3)/1000 -> 0
A32: Semifixed | B32: 0 | C32: 211.30421 | D32: 211.30421 | E32: 211.30421 | F32: 211.30421 | G32: 211.30421 | H32: 845.21684 | I32: 845.21684 | J32: 845.21684 | K32: 845.21684 | L32: 845.21684 | M32: 845.21684 | N32: =SUM(B32:M32) -> 6127.8221 | P32: =+SUMIFS(B32:M32,$B$2:$M$2,$V$3)/1000 -> 0 | Q32: =+SUMIFS(B32:M32,$B$1:$M$1,$W$3)/1000 -> 0
A33: Fixed utilities | B33: 0 | C33: 0 | D33: 922.8 | E33: 922.8 | F33: 922.8 | G33: 922.8 | H33: 922.8 | I33: 922.8 | J33: 922.8 | K33: 922.8 | L33: 922.8 | M33: 922.8 | N33: =SUM(B33:M33) -> 9228 | P33: =+SUMIFS(B33:M33,$B$2:$M$2,$V$3)/1000 -> 0 | Q33: =+SUMIFS(B33:M33,$B$1:$M$1,$W$3)/1000 -> 0
A34: Fixed Cost | N34: =SUM(B34:M34) -> 0 | P34: =+SUMIFS(B34:M34,$B$2:$M$2,$V$3)/1000 -> 0 | Q34: =+SUMIFS(B34:M34,$B$1:$M$1,$W$3)/1000 -> 0
A35: Obsolete | N35: =SUM(B35:M35) -> 0 | P35: =+SUMIFS(B35:M35,$B$2:$M$2,$V$3)/1000 -> 0 | Q35: =+SUMIFS(B35:M35,$B$1:$M$1,$W$3)/1000 -> 0
A36: Depreciation | N36: =SUM(B36:M36) -> 0 | P36: =+SUMIFS(B36:M36,$B$2:$M$2,$V$3)/1000 -> 0 | Q36: =+SUMIFS(B36:M36,$B$1:$M$1,$W$3)/1000 -> 0
A37: FIXED CONVERSION | B37: =SUM(B30:B36) -> 0 | C37: =SUM(C30:C36) -> 2452.1855 | D37: =SUM(D30:D36) -> 3374.9855 | E37: =SUM(E30:E36) -> 3374.9855 | F37: =SUM(F30:F36) -> 3374.9855 | G37: =SUM(G30:G36) -> 3374.9855 | H37: =SUM(H30:H36) -> 4008.8981 | I37: =SUM(I30:I36) -> 4008.8981 | ... M37: =SUM(M30:M36) -> 4008.8981 | N37: =SUM(B37:M37) -> 40005.516 | P37: =SUM(P30:P36) -> 0 | Q37: =SUM(Q30:Q36) -> 0
A38: OVH AND OTHERS | N38: =SUM(B38:M38) -> 0 | P38: =+SUMIFS(B38:M38,$B$2:$M$2,$V$3)/1000 -> 0 | Q38: =+SUMIFS(B38:M38,$B$1:$M$1,$W$3)/1000 -> 0
A39: Grand Total | B39: =B29+B37+B38 -> 41450.38 | C39: =C29+C37+C38 -> 52013.126 | D39: =D29+D37+D38 -> 28918.168 | E39: =E29+E37+E38 -> 31228.429 | F39: =F29+F37+F38 -> 35710.174 | G39: =G29+G37+G38 -> 41817.33 | H39: =H29+H37+H38 -> 38746.861 | I39: =I29+I37+I38 -> 38443.695 | ... M39: =M29+M37+M38 -> 39222.28 | N39: =SUM(B39:M39) -> 474688.39 | P39: =P37+P29+P38 -> 41.45038 | Q39: =Q37+Q29+Q38 -> 41.45038
N40: =+N39-'ACE Details_FULL'!P42 -> -131622.82
A42: Over /Underabsorption | B42: Jan | C42: Feb | D42: March | E42: April | F42: May | G42: June | H42: July | I42: August | J42: Sept | K42: Oct | L42: Nov | M42: Dec | N42: Total | P42: MTD | Q42: YTD
A43: Direct Labour | B43: =B24-B5 -> 35805.983 | C43: =C24-C5 -> 43550.266 | D43: =D24-D5 -> 19485.659 | E43: =E24-E5 -> 21980.688 | F43: =F24-F5 -> 10702.364 | G43: =G24-G5 -> -20193.038 | H43: =H24-H5 -> -22063.721 | I43: =I24-I5 -> -22431.383 | ... M43: =M24-M5 -> -24969.396 | N43: =SUM(B43:M43) -> -36462.209 | P43: =+SUMIFS(B43:M43,$B$2:$M$2,$V$3)/1000 -> 35.805983 | Q43: =+SUMIFS(B43:M43,$B$1:$M$1,$W$3)/1000 -> 35.805983
...

Sheet VOLUME
B2: MTD | C2: Jan | D2: Feb | E2: Mar | F2: Apr | G2: May | H2: Jun | I2: Jul | J2: Aug | K2: Sep | L2: Oct | M2: Nov | N2: Dec | O2: Total
B3: Budget Volume | C3: 50463 | D3: 50446 | E3: 50447 | F3: 48050 | G3: 36788 | H3: 53265 | I3: 42049 | J3: 39150 | K3: 53732 | L3: 48548 | M3: 51408 | N3: 40676 | O3: =SUM(C3:N3) -> 565022
B5: STD Volume | C5: 46000 | D5: 46000 | E5: 46000 | F5: 48300 | G5: 32200 | H5: 71500 | I5: 57750 | J5: 52250 | K5: 71500 | L5: 71500 | M5: 68750 | N5: 62561 | O5: =SUM(C5:N5) -> 674311
B7: Actual Volume | C7: =+C10 -> 47357 | D7: =+D10 -> 42593.001 | E7: =+E10 -> 23002.001 | F7: =+F10 -> 44096 | G7: 36000 | H7: 54500.001 | I7: 41500 | J7: 39000.001 | K7: 54085 | L7: 49968 | M7: 51936 | N7: 42190 | O7: =SUM(C7:N7) -> 526227
B10: DW 2 | C10: =SUM(C11:C13) -> 47357 | D10: =SUM(D11:D13) -> 42593.001 | E10: =SUM(E11:E13) -> 23002.001 | F10: =SUM(F11:F13) -> 44096 | G10: 36000 | H10: 54500.001 | I10: 41500 | J10: 39000.001 | K10: 54085 | L10: 49968 | M10: 51936 | N10: 42190 | O10: =SUM(C10:N10) -> 526227
B11: FS | C11: 19805 | D11: 18495 | E11: 10482 | F11: 21500 | O11: =SUM(C11:N11) -> 70282
B12: BI | C12: 27552 | D12: 24098 | E12: 12520 | F12: 21500 | O12: =SUM(C12:N12) -> 85670
B13: KIT | D13: 0.001 | E13: 0.001 | F13: 1096 | O13: =SUM(C13:N13) -> 1096.002

Sheet HQD
A1: PERIMETER | B1: HQD REPORTING -EXCLUDED COST ITEMS | C1: IN | D1: OUT
A3: PERIMETER | B3: Direct Labor | C3: X
A4: PERIMETER | B4: Variable Utilities | C4: X
A5: PERIMETER | B5: Scrap | D5: X
A6: PERIMETER | B6: Scrap Reselling | D6: X
A7: PERIMETER | B7: Other Variable (Production Consumable, Inventory ADJ)
A8: PERIMETER | B8: Inventory Adjustment | D8: X
A9: PERIMETER | B9: Production Consummables | C9: X
A10: PERIMETER | B10: Variable Conv.
A11: PERIMETER | B11: Indirect Labour | C11: X
A12: PERIMETER | B12: Fixed Labour | C12: X
A13: PERIMETER | B13: Semifixed | C13: X
A14: PERIMETER | B14: Fixed utilities | C14: X
A15: PERIMETER | B15: Fixed Cost | C15: X
A16: PERIMETER | B16: IT LOCAL | C16: Should be under shares
A17: PERIMETER | B17: Security | C17: Should be under shares
A18: PERIMETER | B18: Obsolete | D18: X
A19: PERIMETER | B19: Depreciation | C19: X
A20: PERIMETER | B20: Fixed Conv.
A21: PERIMETER | B21: TOTAL MFG COST w/o SHARES
A22: PERIMETER | B22: TOTAL SHARES
A23: PERIMETER | B23: Mess Union Fee | C23: X | E23: Target'tan çıkarılırken bütçe değerleri alınabilir.
A24: PERIMETER | B24: IT LOCAL | C24: X | E24: Target'tan çıkarılırken bütçe değerleri alınabilir.
A25: PERIMETER | B25: Security | C25: X | E25: Target'tan çıkarılırken bütçe değerleri alınabilir.
A26: PERIMETER | B26: IT GLOBAL | D26: X
A27: PERIMETER | B27: G&A(Insurance included) | D27: X
A28: PERIMETER | B28: TOTAL MFG COST w/ SHARES
A29: PERIMETER | B29: Functional Currency Impact | C29: X
A32: OTHERS | B32: Scrap
A33: OTHERS | B33: Scrap Reselling
A34: OTHERS | B34: Inventory Adjustment
A35: OTHERS | B35: Obsolete
A36: OTHERS | B36: Asset Sales
A38: OVERHEAD | B38: IT GLOBAL
A39: OVERHEAD | B39: G&A(Insurance included)

Sheet >>>

Sheet MTD Report  (HQD) (deneme)
B2: TD MTD Oct | C2: Actual Cost | I2: GP | M2: TC ALL | N2: TC WO GP | O2: GP TC
M3: 38.12 | N3: 37.43 | O3: 49.19 | P3: =O3/M3-1 -> 0.29039874 | T3: HC | U3: Unit price TRY
C4: ='data entry '!Q115 -> 44096 | I4: 6565 | T4: =(G7+G11+G12) -> 48.06191
B5: - Gain / +Loss | S5: Working meal | T5: =T4 -> 48.06191 | U5: 165.3 | V5: =T5*U5 -> 7944.6338
C6: EUR/000 | D6: €/pc | F6: HC | G6: GP | I6: EUR/000 | J6: €/pc | S6: Transport | T6: =T5 -> 48.06191 | U6: 185.43 | V6: =T6*U6*2 -> 17824.24
A7: MFG PERIMETER | B7: Direct Labor | C7: 961.83748 | D7: 8.5640541 | F7: 447 | G7: 34 | I7: =C7/F7*G7 -> 73.159898 | J7: =I7/$I$4*1000 -> 11.14393 | M7: =J7/D7-1 -> 0.30124465 | V7: =SUM(V4:V6) -> 25768.874
A8: MFG PERIMETER | B8: Variable Utilities | C8: 63.35664 | D8: 0.56411785 | I8: =D8*$I$4/1000 -> 3.7034337 | J8: =I8/$I$4*1000 -> 0.56411785
A9: MFG PERIMETER | B9: Other Variable (Production Consumable) | C9: 41.55311 | D9: 0.36998255 | I9: =D9*$I$4/1000 -> 2.4289354 | J9: =I9/$I$4*1000 -> 0.36998255
A10: MFG PERIMETER | B10: Variable Conv. | C10: 1066.7472 | D10: 9.4981545 | I10: =SUM(I7:I9) -> 79.292267 | J10: =SUM(J7:J9) -> 12.07803
A11: MFG PERIMETER | B11: Indirect Labour | C11: 409.57862 | D11: 3.6468255 | F11: 157 | G11: =9 -> 9 | I11: =C11/F11*G11 -> 23.479029 | J11: =I11/$I$4*1000 -> 3.5763944 | K11: 4 | M11: =C11/F11*K11 -> 10.435124 | N11: =M11*1000/I4 -> 1.5895086 | O11: CKD Impact
A12: MFG PERIMETER | B12: Fixed Labour | C12: 105.67001 | D12: 0.94086964 | F12: 34 | G12: =F12/C4*I4 -> 5.0619104 | I12: =D12*I4/1000 -> 6.1768092 | J12: =I12/$I$4*1000 -> 0.94086964
A13: MFG PERIMETER | B13: Semifixed | C13: 191.79625 | D13: 1.7077245 | I13: =D13*I4/1000 -> 11.211212 | J13: =I13/$I$4*1000 -> 1.7077245
A14: MFG PERIMETER | B14: Fixed utilities | C14: 4.03094 | D14: 0.035890874 | I14: =D14*$I$4/1000 -> 0.23562359 | J14: =I14/$I$4*1000 -> 0.035890874
A15: MFG PERIMETER | B15: Fixed Cost | C15: 52.07714 | D15: 0.46368691 | I15: =D15*$I$4/1000 -> 3.0441045 | J15: =I15/$I$4*1000 -> 0.46368691
A16: MFG PERIMETER | B16: Depreciation | C16: 78.79631 | D16: 0.70159032 | I16: =D16*$I$4/1000 -> 4.6059404 | J16: =I16/$I$4*1000 -> 0.70159032
A17: MFG PERIMETER | B17: Fixed Conv. | C17: 841.94927 | D17: 7.4965878 | I17: =SUM(I11:I16) -> 48.752718 | J17: =SUM(J11:J16) -> 7.4261567
A18: MFG PERIMETER | B18: TOTAL MFG COST w/o SHARES | C18: 1908.6965 | D18: 16.994742 | I18: =I17+I10 -> 128.04499 | J18: =I18/$I$4*1000 -> 19.504187
A19: MFG PERIMETER | B19: TOTAL SHARES | C19: 16.80699 | D19: 0.14964687 | I19: =D19*$I$4/1000 -> 0.98243172 | J19: =I19/$I$4*1000 -> 0.14964687
A20: MFG PERIMETER | B20: TOTAL MFG COST w/ SHARES | C20: 1925.5035 | D20: 17.144389 | I20: =I19+I18 -> 129.02742 | J20: =I20/$I$4*1000 -> 19.653834
A21: MFG PERIMETER | B21: Functional Currency Impact | C21: 263.21196 | D21: 2.3435991 | I21: =D21*$I$4/1000 -> 15.385728 | J21: =I21/$I$4*1000 -> 2.3435991
A22: MFG PERIMETER | B22: TOTAL Including FC | C22: 2188.7155 | D22: 19.487988 | I22: =I21+I20 -> 144.41315 | J22: =I22/$I$4*1000 -> 21.997433 | M22: =J22/D22-1 -> 0.12876878
J23: =I23/$I$4*1000 -> 0
A24: OTHERS | B24: Scrap | C24: 43.39548 | D24: 0.38638673 | J24: =I24/$I$4*1000 -> 0
A25: OTHERS | B25: Scrap Reselling | C25: -128.11905 | D25: -1.1407525 | J25: =I25/$I$4*1000 -> 0
A26: OTHERS | B26: Other Variable (Inventory Adj) | C26: 11.52424 | D26: 0.10261007 | J26: =I26/$I$4*1000 -> 0
A27: OTHERS | B27: Obsolete | C27: 25 | D27: 0.22259618 | J27: =I27/$I$4*1000 -> 0
A28: OTHERS | B28: Asset Sales | C28: 0 | D28: 0 | J28: =I28/$I$4*1000 -> 0
A29: OTHERS | B29: TOTAL OTHERS | C29: -48.19933 | D29: -0.42915948 | J29: =I29/$I$4*1000 -> 0
J30: =I30/$I$4*1000 -> 0
A31: OVERHEAD | B31: IT GLOBAL | C31: 213.47408 | D31: 1.9007406 | J31: =I31/$I$4*1000 -> 0
A32: OVERHEAD | B32: G&A(Insurance included) | C32: 93.09748 | D32: 0.82892575 | J32: =I32/$I$4*1000 -> 0
A33: OVERHEAD | B33: TOTAL OVERHEAD | C33: 306.57156 | D33: 2.7296664 | J33: =I33/$I$4*1000 -> 0
J34: =I34/$I$4*1000 -> 0
A35: ALL | B35: TOTAL ALL | C35: 2447.0877 | D35: 21.788495 | J35: =I35/$I$4*1000 -> 0
A37: Check | C37: 0 | D37: 0

Sheet MTD Report  (HQD)
B2: DW MTD JAN | C2: Budget25 | F2: Actual Cost | I2: 1+11 Forecast | L2: Delta FCST vs ACT
C4: =+'MTD Report(HQD)_variance'!B4 -> 48050 | F4: =+'MTD Report(HQD)_variance'!Q4 -> 44096
B5: - Gain / +Loss
C6: EUR/000 | D6: €/pc | F6: EUR/000 | G6: €/pc | I6: EUR/000 | J6: €/pc
A7: MFG PERIMETER | B7: Direct Labor | C7: =+'MTD Report(HQD)_variance'!B7 -> 509 | D7: =+C7*1000/$C$4 -> 10.593132 | F7: =+'MTD Report(HQD)_variance'!Q7 -> 363.73443 | G7: =+F7*1000/$F$4 -> 8.2486945
A8: MFG PERIMETER | B8: Variable Utilities | C8: =+'MTD Report(HQD)_variance'!B8 -> 35.733562 | D8: =+C8*1000/$C$4 -> 0.74367454 | F8: =+'MTD Report(HQD)_variance'!Q8 -> 28.06842 | G8: =+F8*1000/$F$4 -> 0.63652984
A9: MFG PERIMETER | B9: Other Variable (Production Consumable) | C9: =+'MTD Report(HQD)_variance'!B9 -> 15.8935 | D9: =+C9*1000/$C$4 -> 0.33077003 | F9: =+'MTD Report(HQD)_variance'!Q9 -> 38.19678 | G9: =+F9*1000/$F$4 -> 0.8662187
A10: MFG PERIMETER | B10: Variable Conv. | C10: =+'MTD Report(HQD)_variance'!B10 -> 560.62706 | D10: =+C10*1000/$C$4 -> 11.667577 | F10: =+'MTD Report(HQD)_variance'!Q10 -> 429.99963 | G10: =+F10*1000/$F$4 -> 9.751443
A11: MFG PERIMETER | B11: Indirect Labour | C11: =+'MTD Report(HQD)_variance'!B11 -> 204.69927 | D11: =+C11*1000/$C$4 -> 4.2601306 | F11: =+'MTD Report(HQD)_variance'!Q11 -> 211.92001 | G11: =+F11*1000/$F$4 -> 4.8058783
A12: MFG PERIMETER | B12: Fixed Labour | C12: =+'MTD Report(HQD)_variance'!B12 -> 104.32865 | D12: =+C12*1000/$C$4 -> 2.1712517 | F12: =+'MTD Report(HQD)_variance'!Q12 -> 86.26424 | G12: =+F12*1000/$F$4 -> 1.9562827
A13: MFG PERIMETER | B13: Semifixed | C13: =+'MTD Report(HQD)_variance'!B13 -> 177.19911 | D13: =+C13*1000/$C$4 -> 3.6878066 | F13: =+'MTD Report(HQD)_variance'!Q13 -> 86.23783 | G13: =+F13*1000/$F$4 -> 1.9556837
A14: MFG PERIMETER | B14: Fixed utilities | C14: =+'MTD Report(HQD)_variance'!B14 -> 5 | D14: =+C14*1000/$C$4 -> 0.10405827 | F14: =+'MTD Report(HQD)_variance'!Q14 -> 3.80533 | G14: =+F14*1000/$F$4 -> 0.086296489
A15: MFG PERIMETER | B15: Fixed Cost | C15: =+'MTD Report(HQD)_variance'!B15 -> 43.218668 | D15: =+C15*1000/$C$4 -> 0.899452 | F15: =+'MTD Report(HQD)_variance'!Q15 -> -2.69822 | G15: =+F15*1000/$F$4 -> -0.061189677
A16: MFG PERIMETER | B16: Depreciation | C16: =+'MTD Report(HQD)_variance'!B16 -> 155.0923 | D16: =+C16*1000/$C$4 -> 3.2277274 | F16: =+'MTD Report(HQD)_variance'!Q16 -> -7.09792 | G16: =+F16*1000/$F$4 -> -0.16096517
A17: MFG PERIMETER | B17: Fixed Conv. | C17: =+'MTD Report(HQD)_variance'!B17 -> 689.538 | D17: =+C17*1000/$C$4 -> 14.350427 | F17: =+'MTD Report(HQD)_variance'!Q17 -> 378.43127 | G17: =+F17*1000/$F$4 -> 8.5819863
A18: MFG PERIMETER | B18: TOTAL MFG COST w/o SHARES | C18: =+'MTD Report(HQD)_variance'!B18 -> 1250.1651 | D18: =+C18*1000/$C$4 -> 26.018003 | F18: =+'MTD Report(HQD)_variance'!Q18 -> 808.4309 | G18: =+F18*1000/$F$4 -> 18.333429
... A20: MFG PERIMETER | B20: TOTAL MFG COST w/ SHARES | C20: =+'MTD Report(HQD)_variance'!B20 -> 1270.7321 | D20: =+C20*1000/$C$4 -> 26.446038 | F20: =+'MTD Report(HQD)_variance'!Q20 -> 821.47837 | G20: =+F20*1000/$F$4 -> 18.629317
A21: MFG PERIMETER | B21: Functional Currency Impact | C21: =+'MTD Report(HQD)_variance'!B22 -> 413.13905 | D21: =+C21*1000/$C$4 -> 8.5981072 | F21: =+'YTD Report(HQD)_variance '!Q22 -> 3696.26 | G21: =+F21*1000/$F$4 -> 83.823022
A22: MFG PERIMETER | B22: TOTAL Including FC | C22: =+C21+C20 -> 1683.8712 | D22: =+C22*1000/$C$4 -> 35.044145 | F22: =+F21+F20 -> 4517.7383 | G22: =+F22*1000/$F$4 -> 102.45234
A24: OTHERS | B24: Scrap | C24: =+'MTD Report(HQD)_variance'!B25 -> 19 | D24: =+C24*1000/$C$4 -> 0.39542144 | F24: =+'MTD Report(HQD)_variance'!Q25 -> 50.45741 | G24: =+F24*1000/$F$4 -> 1.1442627
A25: OTHERS | B25: Scrap Reselling | C25: =+'MTD Report(HQD)_variance'!B26 -> -48 | D25: =+C25*1000/$C$4 -> -0.99895942 | F25: =+'MTD Report(HQD)_variance'!Q26 -> -53.89348 | G25: =+F25*1000/$F$4 -> -1.2221852
A26: OTHERS | B26: Other Variable (Inventory Adj) | C26: =+'MTD Report(HQD)_variance'!B27 -> 0 | D26: =+C26*1000/$C$4 -> 0 | F26: =+'MTD Report(HQD)_variance'!Q27 -> 65.57718 | G26: =+F26*1000/$F$4 -> 1.4871458
A27: OTHERS | B27: Obsolete | C27: =+'MTD Report(HQD)_variance'!B28 -> 9 | D27: =+C27*1000/$C$4 -> 0.18730489 | F27: =+'MTD Report(HQD)_variance'!Q28 -> -177.1679 | G27: =+F27*1000/$F$4 -> -4.0177771
A28: OTHERS | B28: Asset Sales | C28: =+'MTD Report(HQD)_variance'!B29 -> 0 | D28: =+C28*1000/$C$4 -> 0 | F28: =+'MTD Report(HQD)_variance'!Q29 -> 0 | G28: =+F28*1000/$F$4 -> 0
A29: OTHERS | B29: TOTAL OTHERS | C29: =+'MTD Report(HQD)_variance'!B30 -> -20 | D29: =+C29*1000/$C$4 -> -0.41623309 | F29: =+'MTD Report(HQD)_variance'!Q30 -> -115.02679 | G29: =+F29*1000/$F$4 -> -2.6085538
A31: OVERHEAD | B31: IT GLOBAL | C31: =+'MTD Report(HQD)_variance'!B32 -> 90.697223 | D31: =+C31*1000/$C$4 -> 1.8875593 | F31: =+'MTD Report(HQD)_variance'!Q32 -> 89.41512 | G31: =+F31*1000/$F$4 -> 2.0277377
A32: OVERHEAD | B32: G&A(Insurance included) | C32: =+'MTD Report(HQD)_variance'!B33 -> 94.532002 | D32: =+C32*1000/$C$4 -> 1.9673674 | F32: =+'MTD Report(HQD)_variance'!Q33 -> 68.80723 | G32: =+F32*1000/$F$4 -> 1.5603962
A33: OVERHEAD | B33: TOTAL OVERHEAD | C33: =SUM(C31:C32) -> 185.22922 | D33: =+C33*1000/$C$4 -> 3.8549266 | F33: =SUM(F31:F32) -> 158.22235 | G33: =+F33*1000/$F$4 -> 3.5881338
A35: ALL | B35: TOTAL ALL | C35: =+C33+C29+C22 -> 1849.1004 | D35: =+C35*1000/$C$4 -> 38.482838 | F35: =+F33+F29+F22 -> 4560.9339 | G35: =+F35*1000/$F$4 -> 103.43192
A37: Check
G40: =G35-G21 -> 19.608897
F42: ASP DEC | G42: 175.20902
F43: MFG RATE | G43: =G20/G42 -> 0.10632625
G44: =G22/G42 -> 0.58474352

Sheet MTD VAR 
A1: Volume | B1: =+'Budget assumption'!Q35 -> 46000 | C1: =H1-B1 -> 4463 | H1: ='Budget assumption'!Q66 -> 50463 | I1: ='Budget assumption'!Q321 -> 0 | K1: ='data entry '!Q82 -> 44096 | M1: ='data entry '!Q115 -> 44096 | AA1: EFF | AB1: variable cost | AC1: Actual minus Copertura
B2: EUR | C2: EUR | H2: EUR | I2: EUR | K2: EUR | M2: EUR | Q2: Variances vs Budget | V2: Variances vs STD | AB2: fixed cost | AC2: Actual minus Budget
A3: Cost Elements | B3: STD | C3: Delta Volume | D3: ACE | E3: HW / TW | F3: Price FX | G3: Seasonality | H3: Plan Costs | I3: Budget VAR | K3: Copertura | M3: Act. Costs | O3: Variance vs STD | Q3: EFF | R3: FCA | S3: Total Variance | V3: EFF | W3: FCA | X3: Total Variance
D4: ACE
I5: FCA
A6: Direct Labour | B6: ='Budget assumption'!Q37 -> 523.40092 | C6: ='Budget assumption'!Q70 -> 50.781268 | D6: ='Budget assumption'!Q118 -> -4.6443971 | E6: ='Budget assumption'!Q149 -> -36.708483 | F6: ='Budget assumption'!Q180 -> -13.073388 | G6: ='Budget assumption'!Q242+'Budget assumption'!Q273 -> -34.755923 | H6: ='Budget assumption'!Q211 -> 485 | J6: =H6-SUM(B6:G6) -> 0 | K6: ='data entry '!Q84 -> 465.28736 | M6: ='data entry '!Q117 -> 363.73443 | O6: =M6-K6 -> -101.55293 | Q6: =M6-K6-E6-F6-D6-G6 -> -12.370737 | S6: =Q6+R6 -> -12.370737 | V6: =M6-K6 -> -101.55293 | X6: =V6+W6 -> -101.55293
A7: Variable Utilities | B7: ='Budget assumption'!Q38 -> 35.473246 | C7: ='Budget assumption'!Q71 -> 3.441676 | D7: ='Budget assumption'!Q119 -> 0 | E7: ='Budget assumption'!Q150 -> 0 | F7: ='Budget assumption'!Q181 -> -1.9248994 | G7: ='Budget assumption'!Q243+'Budget assumption'!Q274 -> 1.526754 | H7: ='Budget assumption'!Q212 -> 38.516777 | J7: =H7-SUM(B7:G7) -> 0 | K7: ='data entry '!Q85 -> 30.915274 | M7: ='data entry '!Q118 -> 28.06842 | O7: =M7-K7 -> -2.8468537 | Q7: =M7-K7-E7-F7-D7-G7 -> -2.4487083 | S7: =Q7+R7 -> -2.4487083 | V7: =M7-K7 -> -2.8468537 | X7: =V7+W7 -> -2.8468537
A8: Variable Costs | B8: ='Budget assumption'!Q39 -> 16.169661 | C8: ='Budget assumption'!Q72 -> 1.5688086 | D8: ='Budget assumption'!Q120 -> -1 | E8: ='Budget assumption'!Q151 -> 0 | F8: ='Budget assumption'!Q182 -> -0.0088085913 | G8: ='Budget assumption'!Q244+'Budget assumption'!Q275 -> 0.00033941312 | H8: ='Budget assumption'!Q213 -> 16.73 | J8: =H8-SUM(B8:G8) -> 0 | K8: ='data entry '!Q86 -> 13.272976 | M8: ='data entry '!Q119 -> 38.19678 | O8: =M8-K8 -> 24.923804 | Q8: =M8-K8-E8-F8-D8-G8 -> 25.932273 | S8: =Q8+R8 -> 25.932273 | V8: =M8-K8 -> 24.923804 | X8: =V8+W8 -> 24.923804
A9: VARIABLE CONVERSION | B9: =SUM(B6:B8) -> 575.04383 | C9: =SUM(C6:C8) -> 55.791752 | D9: =SUM(D6:D8) -> -5.6443971 | E9: =SUM(E6:E8) -> -36.708483 | F9: =SUM(F6:F8) -> -15.007095 | G9: =SUM(G6:G8) -> -33.22883 | H9: =SUM(H6:H8) -> 540.24678 | I9: =SUM(I6:I8) -> 0 | J9: =H9-SUM(B9:G9) -> 0 | K9: =SUM(K6:K8) -> 509.47561 | M9: =SUM(M6:M8) -> 429.99963 | O9: =SUM(O6:O8) -> -79.475978 | Q9: =SUM(Q6:Q8) -> 11.112828 | R9: =SUM(R6:R8) -> 0 | S9: =SUM(S6:S8) -> 11.112828 | V9: =SUM(V6:V8) -> -79.475978 | W9: =SUM(W6:W8) -> 0 | X9: =SUM(X6:X8) -> -79.475978
A10: Indirect Labour | B10: ='Budget assumption'!Q41 -> 205.29186 | D10: ='Budget assumption'!Q122 -> 0 | E10: ='Budget assumption'!Q153 -> -42 | F10: ='Budget assumption'!Q184 -> 36.808953 | G10: ='Budget assumption'!Q246+'Budget assumption'!Q277 -> -5.3518609 | H10: ='Budget assumption'!Q215 -> 194.74895 | I10: ='Budget assumption'!Q323 -> -19.917773 | J10: =H10-SUM(B10:G10) -> 0 | K10: ='data entry '!Q88 -> 184.03658 | M10: ='data entry '!Q121 -> 211.92001 | O10: =M10-K10 -> 27.883431 | Q10: =M10-H10 -> 17.171054 | R10: =H10-K10-E10-I10-F10-G10-D10 -> 41.173058 | S10: =Q10+R10 -> 58.344112 | V10: =M10-B10 -> 6.6281465 | W10: =B10-K10 -> 21.255285 | X10: =V10+W10 -> 27.883431
A11: Fixed Labour | B11: ='Budget assumption'!Q42 -> 74.257783 | D11: ='Budget assumption'!Q123 -> 0 | E11: ='Budget assumption'!Q154 -> 7 | F11: ='Budget assumption'!Q185 -> 16.249995 | G11: ='Budget assumption'!Q247+'Budget assumption'!Q278 -> 9.0722169 | H11: ='Budget assumption'!Q216 -> 106.58 | I11: ='Budget assumption'!Q324 -> -7.2046193 | J11: =H11-SUM(B11:G11) -> 0 | K11: ='data entry '!Q89 -> 65.067655 | M11: ='data entry '!Q122 -> 86.26424 | O11: =M11-K11 -> 21.196585 | Q11: =M11-H11 -> -20.315755 | R11: =H11-K11-E11-I11-F11-G11-D11 -> 16.394747 | S11: =Q11+R11 -> -3.9210082 | V11: =M11-B11 -> 12.006457 | W11: =B11-K11 -> 9.1901279 | X11: =V11+W11 -> 21.196585
A12: Semifixed | B12: ='Budget assumption'!Q43 -> 143.36581 | D12: ='Budget assumption'!Q124 -> 0 | E12: ='Budget assumption'!Q155 -> -13.179534 | F12: ='Budget assumption'!Q186 -> 45.529224 | G12: ='Budget assumption'!Q248+'Budget assumption'!Q279 -> 7.314194 | H12: ='Budget assumption'!Q217 -> 183.02969 | I12: ='Budget assumption'!Q325 -> -13.9096 | J12: =H12-SUM(B12:G12) -> 0 | K12: ='data entry '!Q90 -> 126.16662 | M12: ='data entry '!Q123 -> 86.23783 | O12: =M12-K12 -> -39.928792 | Q12: =M12-H12 -> -96.791861 | R12: =H12-K12-E12-I12-F12-G12-D12 -> 31.108784 | S12: =Q12+R12 -> -65.683076 | V12: =M12-B12 -> -57.127976 | W12: =B12-K12 -> 17.199184 | X12: =V12+W12 -> -39.928792
A13: Fixed utilities | B13: ='Budget assumption'!Q44 -> 9.1207173 | D13: ='Budget assumption'!Q125 -> -1.1 | E13: ='Budget assumption'!Q156 -> -2 | F13: ='Budget assumption'!Q187 -> -0.6 | G13: ='Budget assumption'!Q249+'Budget assumption'!Q280 -> -0.4207173 | H13: ='Budget assumption'!Q218 -> 5 | I13: ='Budget assumption'!Q326 -> -0.88490785 | J13: =H13-SUM(B13:G13) -> 0 | K13: ='data entry '!Q91 -> 6.95061 | M13: ='data entry '!Q124 -> 3.80533 | O13: =M13-K13 -> -3.14528 | Q13: =M13-H13 -> -1.19467 | R13: =H13-K13-E13-I13-F13-G13-D13 -> 3.0550151 | S13: =Q13+R13 -> 1.8603451 | V13: =M13-B13 -> -5.3153873 | W13: =B13-K13 -> 2.1701073 | X13: =V13+W13 -> -3.14528
A14: Fixed Cost | B14: ='Budget assumption'!Q45 -> 32.000366 | D14: ='Budget assumption'!Q126 -> 0 | E14: ='Budget assumption'!Q157 -> 0 | F14: ='Budget assumption'!Q188 -> 5.7693193 | G14: ='Budget assumption'!Q250+'Budget assumption'!Q281 -> 7.0905739 | H14: ='Budget assumption'!Q219 -> 44.860259 | I14: ='Budget assumption'!Q327 -> -3.1047312 | J14: =H14-SUM(B14:G14) -> 0 | K14: ='data entry '!Q92 -> 32.152644 | M14: ='data entry '!Q125 -> -2.69822 | O14: =M14-K14 -> -34.850864 | Q14: =M14-H14 -> -47.558479 | R14: =H14-K14-E14-I14-F14-G14-D14 -> 2.9524536 | S14: =Q14+R14 -> -44.606026 | V14: =M14-B14 -> -34.698586 | W14: =B14-K14 -> -0.15227756 | X14: =V14+W14 -> -34.850864
A15: Depreciation | B15: ='Budget assumption'!Q46 -> 125.28658 | D15: ='Budget assumption'!Q127 -> 0 | E15: ='Budget assumption'!Q158 -> -5.7388242 | F15: ='Budget assumption'!Q189 -> -0.0008 | G15: ='Budget assumption'!Q251+'Budget assumption'!Q282 -> 42.244789 | H15: ='Budget assumption'!Q220 -> 161.79174 | I15: ='Budget assumption'!Q329 -> -12.155522 | J15: =H15-SUM(B15:G15) -> 0 | K15: ='data entry '!Q93 -> 424.54616 | M15: ='data entry '!Q126 -> -7.09792 | O15: =M15-K15 -> -431.64408 | Q15: =M15-H15 -> -168.88966 | R15: =H15-K15-E15-I15-F15-G15-D15 -> -287.10406 | S15: =Q15+R15 -> -455.99373 | V15: =M15-B15 -> -132.3845 | W15: =B15-K15 -> -299.25959 | X15: =V15+W15 -> -431.64408
A16: FIXED CONVERSION | B16: =SUM(B10:B15) -> 589.32311 | C16: =SUM(C10:C15) -> 0 | D16: =SUM(D10:D15) -> -1.1 | E16: =SUM(E10:E15) -> -55.918358 | F16: =SUM(F10:F15) -> 103.75669 | G16: =SUM(G10:G15) -> 59.949196 | H16: =SUM(H10:H15) -> 696.01064 | I16: =SUM(I10:I15) -> -57.177153 | J16: =H16-SUM(B16:G16) -> 0 | K16: =SUM(K10:K15) -> 838.92027 | M16: =SUM(M10:M15) -> 378.43127 | O16: =SUM(O10:O15) -> -460.489 | Q16: =SUM(Q10:Q15) -> -317.57937 | R16: =SUM(R10:R15) -> -192.42001 | S16: =Q16+R16 -> -509.99938 | V16: =SUM(V10:V15) -> -210.89184 | W16: =SUM(W10:W15) -> -249.59716 | X16: =SUM(X10:X15) -> -460.489
A17: TOTAL MFG COST w/o SHARES | B17: =B9+B16 -> 1164.3669 | C17: =C9+C16 -> 55.791752 | D17: =D9+D16 -> -6.7443971 | E17: =E9+E16 -> -92.626841 | F17: =F9+F16 -> 88.749597 | G17: =G9+G16 -> 26.720366 | H17: =H9+H16 -> 1236.2574 | I17: =I9+I16 -> -57.177153 | J17: =H17-SUM(B17:G17) -> 0 | K17: =K9+K16 -> 1348.3959 | M17: =M9+M16 -> 808.4309 | O17: =M17-K17 -> -539.96498 | Q17: =Q9+Q16 -> -306.46655 | R17: =R9+R16 -> -192.42001 | S17: =Q17+R17 -> -498.88655 | V17: =V9+V16 -> -290.36782 | W17: =W9+W16 -> -249.59716 | X17: =X9+X16 -> -539.96498
A18: TOTAL SHARES | B18: ='Budget assumption'!Q49 -> 8.2249305 | D18: ='Budget assumption'!Q130 -> 0 | E18: ='Budget assumption'!Q161 -> 0 | F18: ='Budget assumption'!Q192 -> 10.41394 | G18: ='Budget assumption'!Q254+'Budget assumption'!Q285 -> 2.4941295 | H18: ='Budget assumption'!Q223 -> 21.133 | I18: ='Budget assumption'!V49 -> 0 | J18: =H18-SUM(B18:G18) -> 0 | K18: ='data entry '!Q96 -> 0 | M18: ='data entry '!Q129 -> 13.04747 | O18: =M18-K18 -> 13.04747 | Q18: =M18-H18 -> -8.0855299 | R18: =H18-K18-E18-I18-F18-G18-D18 -> 8.2249305 | S18: =Q18+R18 -> 0.13940057 | V18: =M18-B18 -> 4.8225395 | W18: =B18-K18 -> 8.2249305 | X18: =V18+W18 -> 13.04747
A19: TOTAL MFG COST w/ SHARES | B19: =B17+B18 -> 1172.5919 | C19: =C17+C18 -> 55.791752 | D19: =D17+D18 -> -6.7443971 | E19: =E17+E18 -> -92.626841 | F19: =F17+F18 -> 99.163537 | G19: =G17+G18 -> 29.214495 | H19: =H17+H18 -> 1257.3904 | I19: =I17+I18 -> -57.177153 | J19: =H19-SUM(B19:G19) -> 0 | K19: =K17+K18 -> 1348.3959 | M19: =M17+M18 -> 821.47837 | O19: =O17+O18 -> -526.91751 | Q19: =Q17+Q18 -> -314.55208 | R19: =R17+R18 -> -184.19508 | S19: =Q19+R19 -> -498.74715 | V19: =V17+V18 -> -285.54528 | W19: =W17+W18 -> -241.37223 | X19: =X17+X18 -> -526.91751
A20: Functional Currency Impact | B20: ='Budget assumption'!Q51 -> 344.37647 | D20: ='Budget assumption'!Q132 -> 0 | E20: ='Budget assumption'!Q163 -> 0 | F20: ='Budget assumption'!Q194 -> 0 | G20: ='Budget assumption'!Q256+'Budget assumption'!Q287 -> 71.312162 | H20: ='Budget assumption'!Q225 -> 415.68863 | I20: ='Budget assumption'!V51 -> 0 | J20: =H20-SUM(B20:G20) -> 0 | K20: ='data entry '!Q98 -> 0 | M20: ='data entry '!Q131 -> 36.99522 | O20: =M20-K20 -> 36.99522 | Q20: =M20-H20 -> -378.69341 | R20: =H20-K20-E20-I20-F20-G20-D20 -> 344.37647 | S20: =Q20+R20 -> -34.316942 | V20: =M20-B20 -> -307.38125 | W20: =B20-K20 -> 344.37647 | X20: =V20+W20 -> 36.99522
A21: TOTAL Including FC | B21: =B19+B20 -> 1516.9683 | C21: =C19+C20 -> 55.791752 | D21: =D19+D20 -> -6.7443971 | E21: =E19+E20 -> -92.626841 | F21: =F19+F20 -> 99.163537 | G21: =G19+G20 -> 100.52666 | H21: =H19+H20 -> 1673.0791 | I21: =I19+I20 -> -57.177153 | J21: =H21-SUM(B21:G21) -> 0 | K21: =K19+K20 -> 1348.3959 | M21: =M19+M20 -> 858.47359 | O21: =M21-K21 -> -489.92229 | Q21: =Q19+Q20 -> -693.24549 | R21: =R19+R20 -> 160.1814 | S21: =Q21+R21 -> -533.06409 | V21: =V19+V20 -> -592.92653 | W21: =W19+W20 -> 103.00424 | X21: =X19+X20 -> -489.92229
A22: Scrap | B22: ='Budget assumption'!Q53 -> 23.02009 | C22: ='Budget assumption'!Q74 -> 2.2334492 | D22: ='Budget assumption'!Q134 -> 0 | E22: ='Budget assumption'!Q165 -> 0 | F22: ='Budget assumption'!Q196 -> 1.7464607 | G22: ='Budget assumption'!Q258+'Budget assumption'!Q289 -> 0 | H22: ='Budget assumption'!Q227 -> 27 | J22: =H22-SUM(B22:G22) -> 0 | K22: ='data entry '!Q100 -> 19.811558 | M22: ='data entry '!Q133 -> 50.45741 | O22: =M22-K22 -> 30.645852 | Q22: =M22-K22-E22-F22-D22-G22 -> 28.899391 | S22: =Q22+R22 -> 28.899391 | V22: =M22-K22 -> 30.645852 | X22: =V22+W22 -> 30.645852
A23: Scrap Reselling | B23: ='Budget assumption'!Q54 -> -56.58 | C23: ='Budget assumption'!Q75 -> -5.48949 | D23: ='Budget assumption'!Q135 -> 0 | E23: ='Budget assumption'!Q166 -> 0 | F23: ='Budget assumption'!Q197 -> 7.06949 | G23: ='Budget assumption'!Q259+'Budget assumption'!Q290 -> 0 | H23: ='Budget assumption'!Q228 -> -55 | J23: =H23-SUM(B23:G23) -> 0 | K23: ='data entry '!Q101 -> -48.888273 | M23: ='data entry '!Q134 -> -53.89348 | O23: =M23-K23 -> -5.0052074 | Q23: =M23-K23-E23-F23-D23-G23 -> -12.074697 | S23: =Q23+R23 -> -12.074697 | V23: =M23-K23 -> -5.0052074 | X23: =V23+W23 -> -5.0052074
A24: Other Variable (Inventory Adj) | B24: ='Budget assumption'!Q55 -> 0 | C24: ='Budget assumption'!Q76+'Budget assumption'!Q291 -> 0 | D24: ='Budget assumption'!Q136 -> 0 | E24: ='Budget assumption'!Q167 -> 0 | F24: ='Budget assumption'!Q198 -> 0 | G24: ='Budget assumption'!Q260+'Budget assumption'!Q291 -> 0 | H24: ='Budget assumption'!Q229 -> 0 | J24: =H24-SUM(B24:G24) -> 0 | K24: ='data entry '!Q102 -> 0 | M24: ='data entry '!Q135 -> 65.57718 | O24: =M24-K24 -> 65.57718 | Q24: =M24-K24-E24-F24-D24-G24 -> 65.57718 | S24: =Q24+R24 -> 65.57718 | V24: =M24-K24 -> 65.57718 | X24: =V24+W24 -> 65.57718
A25: Obsolete | B25: ='Budget assumption'!Q56 -> 0 | C25: ='Budget assumption'!Q77+'Budget assumption'!Q292 -> 0 | D25: ='Budget assumption'!Q137 -> 0 | E25: ='Budget assumption'!Q168 -> 8.3333333 | F25: ='Budget assumption'!Q199 -> 0.66666667 | G25: ='Budget assumption'!Q261+'Budget assumption'!Q292 -> 0 | H25: ='Budget assumption'!Q230 -> 9 | J25: =H25-SUM(B25:G25) -> 0 | K25: ='data entry '!Q103 -> 0 | M25: ='data entry '!Q136 -> -177.1679 | O25: =M25-K25 -> -177.1679 | Q25: =M25-H25 -> -186.1679 | R25: =H25-K25-E25-I25-F25-G25-D25 -> 0 | S25: =Q25+R25 -> -186.1679 | V25: =M25-B25 -> -177.1679 | W25: =B25-K25 -> 0 | X25: =V25+W25 -> -177.1679
A26: Asset Sales | B26: ='Budget assumption'!Q57 -> 0 | C26: ='Budget assumption'!Q78+'Budget assumption'!Q293 -> 0 | D26: ='Budget assumption'!Q138 -> 0 | E26: ='Budget assumption'!Q169 -> 0 | F26: ='Budget assumption'!Q200 -> 0 | G26: ='Budget assumption'!Q262+'Budget assumption'!Q293 -> 0 | H26: ='Budget assumption'!Q231 -> 0 | J26: =H26-SUM(B26:G26) -> 0 | K26: ='data entry '!Q104 -> 0 | M26: ='data entry '!Q137 -> 0 | O26: =M26-K26 -> 0 | Q26: =M26-H26 -> 0 | R26: =H26-K26-E26-I26-F26-G26-D26 -> 0 | S26: =Q26+R26 -> 0 | V26: =M26-B26 -> 0 | W26: =B26-K26 -> 0 | X26: =V26+W26 -> 0
A27: TOTAL OTHERS | B27: =SUM(B22:B26) -> -33.55991 | C27: =SUM(C22:C26) -> -3.2560408 | D27: =SUM(D22:D26) -> 0 | E27: =SUM(E22:E26) -> 8.3333333 | F27: =SUM(F22:F26) -> 9.4826174 | G27: =SUM(G22:G26) -> 0 | H27: =SUM(H22:H26) -> -19 | I27: =SUM(I22:I26) -> 0 | J27: =H27-SUM(B27:G27) -> 0 | K27: =SUM(K22:K26) -> -29.076715 | M27: =SUM(M22:M26) -> -115.02679 | O27: =M27-K27 -> -85.950075 | Q27: =SUM(Q22:Q26) -> -103.76603 | R27: =SUM(R22:R26) -> 0 | S27: =Q27+R27 -> -103.76603 | V27: =SUM(V22:V26) -> -85.950075 | W27: =SUM(W22:W26) -> 0 | X27: =SUM(X22:X26) -> -85.950075
A28: IT GLOBAL | B28: ='Budget assumption'!Q59 -> 79.533064 | D28: ='Budget assumption'!Q140 -> 0 | E28: ='Budget assumption'!Q171 -> 16.558794 | F28: ='Budget assumption'!Q202 -> -25.911571 | G28: ='Budget assumption'!Q264+'Budget assumption'!Q295 -> 20.516936 | H28: ='Budget assumption'!Q233 -> 90.697223 | I28: ='Budget assumption'!Q337 -> -14.234309 | J28: =H28-SUM(B28:G28) -> 0 | K28: ='data entry '!Q106 -> 64.814167 | M28: ='data entry '!Q139 -> 89.41512 | O28: =M28-K28 -> 24.600953 | Q28: =M28-H28 -> -1.2821025 | R28: =H28-K28-E28-I28-F28-G28-D28 -> 28.953206 | S28: =Q28+R28 -> 27.671104 | V28: =M28-B28 -> 9.8820559 | W28: =B28-K28 -> 14.718897 | X28: =V28+W28 -> 24.600953
A29: G&A(Insurance included) | B29: ='Budget assumption'!Q60 -> 67.179506 | D29: ='Budget assumption'!Q141 -> 0 | E29: ='Budget assumption'!Q172 -> 0 | F29: ='Budget assumption'!Q203 -> 24.722002 | G29: ='Budget assumption'!Q265+'Budget assumption'!Q296 -> 2.6304938 | H29: ='Budget assumption'!Q234 -> 94.532002 | J29: =H29-SUM(B29:G29) -> 0 | K29: ='data entry '!Q107 -> 67.554582 | M29: ='data entry '!Q140 -> 68.80723 | O29: =M29-K29 -> 1.252648 | Q29: =M29-H29 -> -25.724772 | R29: =H29-K29-E29-I29-F29-G29-D29 -> -0.37507579 | S29: =Q29+R29 -> -26.099848 | V29: =M29-B29 -> 1.6277238 | X29: =V29+W29 -> 1.6277238
A30: TOTAL OVERHEAD | B30: =B28+B29 -> 146.71257 | C30: =C28+C29 -> 0 | D30: =D28+D29 -> 0 | E30: =E28+E29 -> 16.558794 | F30: =F28+F29 -> -1.189569 | G30: =G28+G29 -> 23.14743 | H30: =H28+H29 -> 185.22922 | I30: =I28+I29 -> -14.234309 | J30: =H30-SUM(B30:G30) -> 0 | K30: =K28+K29 -> 132.36875 | M30: =M28+M29 -> 158.22235 | O30: =O28+O29 -> 25.853601 | Q30: =Q28+Q29 -> -27.006875 | R30: =R28+R29 -> 28.57813 | S30: =S28+S29 -> 1.5712556 | V30: =V28+V29 -> 11.50978 | W30: =W28+W29 -> 14.718897 | X30: =X28+X29 -> 26.228677
D31: ='Budget assumption'!Q143 -> 0 | G31: ='Budget assumption'!Q267 -> 0 | J31: =H31-SUM(B31:G31) -> 0 | K31: ='data entry '!Q109 -> 0 | M31: ='data entry '!Q142 -> 0 | O31: =M31-K31 -> 0 | Q31: =M31-K31-E31-F31-D31-G31 -> 0 | S31: =Q31+R31 -> 0
A32: TOTAL ALL | B32: =B21+B27+B30 -> 1630.121 | C32: =C21+C27+C30 -> 52.535712 | D32: =D21+D27+D30 -> -6.7443971 | E32: =E21+E27+E30 -> -67.734714 | F32: =F21+F27+F30 -> 107.45659 | G32: =G21+G27+G30 -> 123.67409 | H32: =H21+H27+H30 -> 1839.3083 | I32: =I21+I27+I30 -> -71.411462 | J32: =H32-SUM(B32:G32) -> 0 | K32: =K21+K27+K30 -> 1451.6879 | M32: =M21+M27+M30 -> 901.66915 | O32: =M32-K32 -> -550.01876 | Q32: =Q21+Q27+Q30 -> -824.01839 | R32: =R21+R27+R30 -> 188.75953 | S32: =Q32+R32 -> -635.25886 | V32: =V21+V27+V30 -> -667.36683 | W32: =W21+W27+W30 -> 117.72314 | X32: =X21+X27+X30 -> -549.64369

Sheet Budget assumption
A1: YTD | B1: =IF($X$3>=B$2,1,0) -> 1 | C1: =IF($X$3>=C$2,1,0) -> 1 | D1: =IF($X$3>=D$2,1,0) -> 1 | E1: =IF($X$3>=E$2,1,0) -> 1 | F1: =IF($X$3>=F$2,1,0) -> 1 | G1: =IF($X$3>=G$2,1,0) -> 1 | H1: =IF($X$3>=H$2,1,0) -> 1 | I1: =IF($X$3>=I$2,1,0) -> 1 | ... M1: =IF($X$3>=M$2,1,0) -> 1
A2: MTD | B2: 1 | C2: 0 | D2: 0 | E2: 0 | F2: 0 | G2: 0 | H2: 0 | I2: 0 | J2: 0 | K2: 0 | L2: 0 | M2: 0
A3: Total Units (incl. accessories) | B3: 46000 | C3: 46000 | D3: 46000 | E3: 48300 | F3: 32200 | G3: 71500 | H3: 57750 | I3: 52250 | J3: 71500 | K3: 71500 | L3: 68750 | M3: 62561 | N3: =SUM(B3:M3) -> 674311 | V3: Month | W3: Jan | X3: 12 | Y3: 1
A4: STD 2026 _1st round | B4: STD | C4: STD | D4: STD | E4: STD | F4: STD | G4: STD | H4: STD | I4: STD | J4: STD | K4: STD | L4: STD | M4: STD | N4: STD
A5: Direct Labour | B5: 488.645 | C5: 521.785 | D5: 488.645 | E5: 488.645 | F5: 531.6 | G5: 732.38 | H5: 732.38 | I5: 732.38 | J5: 758.9 | K5: 732.38 | L5: 732.38 | M5: 732.38 | N5: =SUM(B5:M5) -> 7672.5 | O5: =N5/$N$3*1000 -> 11.378281
A6: Variable Utilities | B6: 37 | C6: 37 | D6: 37 | E6: 38 | F6: 23 | G6: 54 | H6: 44 | I6: 46 | J6: 45 | K6: 49 | L6: 57 | M6: 53 | N6: =SUM(B6:M6) -> 520 | O6: =N6/$N$3*1000 -> 0.77115752
A7: Variable Costs | B7: 16.17 | C7: 16.17 | D7: 16.17 | E7: 16.98 | F7: 11.32 | G7: 25.13 | H7: 20.3 | I7: 18.37 | J7: 25.13 | K7: 25.13 | L7: 24.17 | M7: 21.99 | N7: =SUM(B7:M7) -> 237.03 | O7: =N7/$N$3*1000 -> 0.35151436
A8: VARIABLE CONVERSION | B8: =SUM(B5:B7) -> 541.815 | C8: =SUM(C5:C7) -> 574.955 | D8: =SUM(D5:D7) -> 541.815 | E8: =SUM(E5:E7) -> 543.625 | F8: =SUM(F5:F7) -> 565.92 | G8: =SUM(G5:G7) -> 811.51 | H8: =SUM(H5:H7) -> 796.68 | I8: =SUM(I5:I7) -> 796.75 | ... N8: =SUM(N5:N7) -> 8429.53 | O8: =N8/$N$3*1000 -> 12.500953
A9: Indirect Labour | B9: 199.94 | C9: 212.35 | D9: 199.94 | E9: 199.94 | F9: 216.03 | G9: 278.18 | H9: 306.13 | I9: 278.18 | J9: 287.4 | K9: 278.18 | L9: 278.18 | M9: 274.91 | N9: =SUM(B9:M9) -> 3009.36 | O9: =N9/$N$3*1000 -> 4.4628665
A10: Fixed Labour | B10: 83.33 | C10: 92.97 | D10: 88.32 | E10: 88.32 | F10: 94.14 | G10: 88.33 | H10: 88.33 | I10: 91.82 | J10: 94.14 | K10: 92.92 | L10: 92.92 | M10: 93 | N10: =SUM(B10:M10) -> 1088.54 | O10: =N10/$N$3*1000 -> 1.6142996
A11: Semifixed | B11: 150.68 | C11: 150.68 | D11: 150.68 | E11: 154.21 | F11: 129.48 | G11: 206.14 | H11: 181.95 | I11: 172.45 | J11: 206.37 | K11: 206.37 | L11: 201.52 | M11: 191.06 | N11: =SUM(B11:M11) -> 2101.59 | O11: =N11/$N$3*1000 -> 3.116648
A12: Fixed utilities | B12: 8.7 | C12: 8.7 | D12: 8.7 | E12: 9.13 | F12: 6 | G12: 14.27 | H12: 11.55 | I12: 10.46 | J12: 14.27 | K12: 14.78 | L12: 14.2 | M12: 12.94 | N12: =SUM(B12:M12) -> 133.7 | O12: =N12/$N$3*1000 -> 0.19827646
A13: Fixed Cost | B13: 39.09094 | C13: 39.09094 | D13: 39.09094 | E13: 39.09094 | F13: 39.09094 | G13: 39.09094 | H13: 39.09094 | I13: 39.09094 | J13: 39.09094 | K13: 39.09094 | L13: 39.09094 | M13: 39.09094 | N13: =SUM(B13:M13) -> 469.09128 | O13: =N13/$N$3*1000 -> 0.69566013
A14: Depreciation | B14: 167.53137 | C14: 156.90109 | D14: 161.53885 | E14: 156.82095 | F14: 156.55436 | G14: 151.73734 | H14: 152.7794 | I14: 151.49565 | J14: 148.06127 | K14: 147.53007 | L14: 142.92661 | M14: 142.69082 | N14: =SUM(B14:M14) -> 1836.5678 | O14: =N14/$N$3*1000 -> 2.7236212
A15: FIXED CONVERSION | B15: =SUM(B9:B14) -> 649.27231 | C15: =SUM(C9:C14) -> 660.69203 | D15: =SUM(D9:D14) -> 648.26979 | E15: =SUM(E9:E14) -> 647.51189 | F15: =SUM(F9:F14) -> 641.2953 | G15: =SUM(G9:G14) -> 777.74828 | H15: =SUM(H9:H14) -> 779.83034 | I15: =SUM(I9:I14) -> 743.49659 | ... N15: =SUM(N9:N14) -> 8638.849 | O15: =N15/$N$3*1000 -> 12.811372
A16: TOTAL MFG COST w/o SHARES | B16: =B8+B15 -> 1191.0873 | C16: =C8+C15 -> 1235.647 | D16: =D8+D15 -> 1190.0848 | E16: =E8+E15 -> 1191.1369 | F16: =F8+F15 -> 1207.2153 | G16: =G8+G15 -> 1589.2583 | H16: =H8+H15 -> 1576.5103 | I16: =I8+I15 -> 1540.2466 | ... N16: =N8+N15 -> 17068.379 | O16: =N16/$N$3*1000 -> 25.312325
A17: TOTAL SHARES | B17: 10.71906 | C17: 10.67906 | D17: 10.69906 | E17: 10.69906 | F17: 10.64906 | G17: 9.75906 | H17: 9.06906 | I17: 9.06906 | J17: 10.02906 | K17: 9.77906 | L17: 9.61906 | M17: 9.79906 | N17: =SUM(B17:M17) -> 120.56872 | O17: =N17/$N$3*1000 -> 0.17880284 | Q17: Mess, Local IT, Security
A18: TOTAL MFG COST w/ SHARES | B18: =B16+B17 -> 1201.8064 | C18: =C16+C17 -> 1246.3261 | D18: =D16+D17 -> 1200.7838 | E18: =E16+E17 -> 1201.8359 | F18: =F16+F17 -> 1217.8644 | G18: =G16+G17 -> 1599.0173 | H18: =H16+H17 -> 1585.5794 | I18: =I16+I17 -> 1549.3156 | ... N18: =N16+N17 -> 17188.948 | O18: =N18/$N$3*1000 -> 25.491128
A19: Functional Currency Impact | B19: 415.68863 | C19: 386.88891 | D19: 421.50115 | E19: 413.13905 | F19: 424.61564 | G19: 416.35266 | H19: 428.1206 | I19: 429.39435 | J19: 419.28873 | K19: 432.68993 | L19: 423.80339 | M19: 436.70918 | N19: =SUM(B19:M19) -> 5048.1922 | O19: =N19/$N$3*1000 -> 7.486445
A20: TOTAL Including FC | B20: =B18+B19 -> 1617.495 | C20: =C18+C19 -> 1633.215 | D20: =D18+D19 -> 1622.285 | E20: =E18+E19 -> 1614.975 | F20: =F18+F19 -> 1642.48 | G20: =G18+G19 -> 2015.37 | H20: =H18+H19 -> 2013.7 | I20: =I18+I19 -> 1978.71 | ... N20: =N18+N19 -> 22237.14 | O20: =N20/$N$3*1000 -> 32.977573
A21: Scrap | B21: 23.02 | C21: 23.02 | D21: 23.02 | E21: 24.17 | F21: 16.11 | G21: 35.78 | H21: 28.9 | I21: 26.15 | J21: 35.78 | K21: 35.78 | L21: 34.41 | M21: 31.31 | N21: =SUM(B21:M21) -> 337.45 | O21: =N21/$N$3*1000 -> 0.50043674
A22: Scrap Reselling | B22: -56.58 | C22: -56.58 | D22: -56.58 | E22: -59.409 | F22: -39.606 | G22: -87.945 | H22: -71.0325 | I22: -64.2675 | J22: -87.945 | K22: -87.945 | L22: -84.5625 | M22: -76.95003 | N22: =SUM(B22:M22) -> -829.40253 | O22: =N22/$N$3*1000 -> -1.23
A23: Other Variable (Inventory Adj) | O23: =N23/$N$3*1000 -> 0
A24: Obsolete | O24: =N24/$N$3*1000 -> 0
A25: Asset Sales | O25: =N25/$N$3*1000 -> 0
A26: TOTAL OTHERS | B26: =SUM(B21:B25) -> -33.56 | C26: =SUM(C21:C25) -> -33.56 | D26: =SUM(D21:D25) -> -33.56 | E26: =SUM(E21:E25) -> -35.239 | F26: =SUM(F21:F25) -> -23.496 | G26: =SUM(G21:G25) -> -52.165 | H26: =SUM(H21:H25) -> -42.1325 | I26: =SUM(I21:I25) -> -38.1175 | ... N26: =SUM(N21:N25) -> -491.95253 | O26: =N26/$N$3*1000 -> -0.72956326
A27: IT GLOBAL | B27: 100.05 | C27: 100.69 | D27: 100.03 | E27: 100.04 | F27: 110.02 | G27: 100.04 | H27: 100.05 | I27: 100.05 | J27: 100.05 | K27: 100.05 | L27: 100.05 | M27: 54.75 | N27: =SUM(B27:M27) -> 1165.87 | O27: =N27/$N$3*1000 -> 1.7289797
A28: G&A(Insurance included) | B28: 69.81 | C28: 138.12 | D28: 114.27 | E28: 56.21 | F28: 81.91 | G28: 79.92 | H28: 74.09 | I28: 74.09 | J28: 74.09 | K28: 74.09 | L28: 74.09 | M28: 74.09 | N28: =SUM(B28:M28) -> 984.78 | O28: =N28/$N$3*1000 -> 1.460424
A29: TOTAL OVERHEAD | B29: =B27 -> 100.05 | C29: =C27 -> 100.69 | D29: =D27 -> 100.03 | E29: =E27 -> 100.04 | F29: =F27 -> 110.02 | G29: =G27 -> 100.04 | H29: =H27 -> 100.05 | I29: =I27 -> 100.05 | ... M29: =M27 -> 54.75 | N29: =N27+N28 -> 2150.65 | O29: =N29/$N$3*1000 -> 3.1894037
O30: =N30/$N$3*1000 -> 0
A31: TOTAL ALL | B31: =B20+B26+B29 -> 1683.985 | C31: =C20+C26+C29 -> 1700.345 | D31: =D20+D26+D29 -> 1688.755 | E31: =E20+E26+E29 -> 1679.776 | F31: =F20+F26+F29 -> 1729.004 | G31: =G20+G26+G29 -> 2063.245 | H31: =H20+H26+H29 -> 2071.6175 | I31: =I20+I26+I29 -> 2040.6425 | ... N31: =N20+N26+N29 -> 23895.837 | O31: =N31/$N$3*1000 -> 35.437413
B32: =B31/B3*1000 -> 36.60837 | C32: =C31/C3*1000 -> 36.964022 | D32: =D31/D3*1000 -> 36.712065 | E32: =E31/E3*1000 -> 34.777971 | F32: =F31/F3*1000 -> 53.695776 | G32: =G31/G3*1000 -> 28.856573 | H32: =H31/H3*1000 -> 35.872165 | I32: =I31/I3*1000 -> 39.055359 | ... N32: =N31/N3*1000 -> 35.437413
A34: Assigned hours
A35: Total Units (incl. accessories) | B35: =B3 -> 46000 | C35: =C3 -> 46000 | D35: =D3 -> 46000 | E35: =E3 -> 48300 | F35: =F3 -> 32200 | G35: =G3 -> 71500 | H35: =H3 -> 57750 | I35: =I3 -> 52250 | ... N35: =N3 -> 674311 | Q35: =SUMPRODUCT(B35:M35,B$2:M$2) -> 46000 | R35: =SUMIFS(B35:M35,$B$1:$M$1,$Y$3) -> 674311
A36: STD 2026 _flex | B36: STD | C36: STD | D36: STD | E36: STD | F36: STD | G36: STD | H36: STD | I36: STD | J36: STD | K36: STD | L36: STD | M36: STD | N36: STD | Q36: MTD | R36: YTD | AB36: FCA
A37: Direct Labour | B37: =$O5*B$35/1000 -> 523.40092 | C37: =$O5*C$35/1000 -> 523.40092 | D37: =$O5*D$35/1000 -> 523.40092 | E37: =$O5*E$35/1000 -> 549.57097 | F37: =$O5*F$35/1000 -> 366.38065 | G37: =$O5*G$35/1000 -> 813.54709 | H37: =$O5*H$35/1000 -> 657.09572 | I37: =$O5*I$35/1000 -> 594.51518 | ... M37: =$O5*M$35/1000 -> 711.83663 | N37: =SUM(B37:M37) -> 7672.5 | Q37: =SUMPRODUCT(B37:M37,B$2:M$2) -> 523.40092 | R37: =SUMIFS(B37:M37,$B$1:$M$1,$Y$3) -> 7672.5
