Workbook
Name \0: #REF!
Name \0: #REF!
Name \0: #REF!
Name \0: #REF!
Name \0: #REF!
Name \0: #REF!
Name \0: #REF!
Name \0: #REF!
Name \0: #REF!
Name \0: #REF!
Name \2: #REF!
Name \2: #REF!
Name \2: #REF!
Name \2: #REF!
Name \2: #REF!
Name \2: #REF!
Name \2: #REF!
Name \2: #REF!
Name \2: #REF!
Name \2: #REF!
Name \a: '[1]FA-LISTING'!#REF!
Name \a: '[1]FA-LISTING'!#REF!
Name \a: '[1]FA-LISTING'!#REF!
Name \a: #REF!
Name \a: #REF!
Name \a: #REF!
Name \a: #REF!
Name \a: #REF!
Name \a: #REF!
Name \a: #REF!
Name \B: '[1]FA-LISTING'!#REF!
Name \B: '[1]FA-LISTING'!#REF!
Name \B: '[1]FA-LISTING'!#REF!
Name \b: #REF!
Name \b: #REF!
Name \b: #REF!
Name \b: #REF!
Name \b: #REF!
Name \b: #REF!
Name \b: #REF!
Name \b1: #REF!
Name \b1: #REF!
Name \b1: #REF!
Name \b1: #REF!
Name \b1: #REF!
Name \b1: #REF!
Name \b1: #REF!
Name \b1: #REF!
Name \b1: #REF!
Name \b1: #REF!
Name \m: #REF!
Name \m: #REF!
Name \m: #REF!
Name \m: #REF!
Name \m: #REF!
Name \m: #REF!
Name \m: #REF!
Name \m: #REF!
Name \m: #REF!
Name \m: #REF!

Sheet DW  2026
A1: 1月费用总结： ①单：1月同期35欧元/台，订单量4.86万台，预测单台费用36.4欧元/台，较同期↑3.9%；实际37.48欧元/台，较同期↑6% 共梳理出8个问题
A2: KPI | B2: ACT 2025 | C2: Budget | D2: Budget-ACT VARIANCE | E2: Act | F2: CPU-Y0Y | G2: Analysis
A4: QTY | B4: 478100 | C4: 565020 | D4: =C4-B4 -> 86920
A5: Work days | B5: 237 | C5: 220 | D5: =C5-B5 -> -17
A6: Direct Labour | B6: 2372 | C6: 2969 | D6: =C6-B6 -> 597
A7: Direct Labour avrerage salary | B7: =0.114397955970597*1000 -> 114.39796 | C7: =0.113723208386452*1000 -> 113.72321 | D7: =C7-B7 -> -0.67474758 | G7: Direct Labour crease，Why decrease？ 人数上涨，工资下降
A8: indirect Labour | B8: 1000 | C8: 1020 | D8: =C8-B8 -> 20
A9: indirect Labour avrerage salary | B9: =2575/B8*1000 -> 2575 | C9: =2701/C8*1000 -> 2648.0392 | D9: =C9-B9 -> 73.039216
A10: Fixed Labour | B10: 293 | C10: 323 | D10: =C10-B10 -> 30
A11: Fixed avrerage salary | B11: =1047/B10*1000 -> 3573.3788 | C11: =1249/C10*1000 -> 3866.8731 | D11: =C11-B11 -> 293.49423 | G11: Why crease 上涨293万
A12: UPH | B12: 10.3048 | C12: 10.400748 | D12: =C12-B12 -> 0.095948021
A13: CPU | B13: =SUM(B14:B26) -> 42.496033 | C13: =SUM(C14:C26) -> 39.975046 | D13: =C13-B13 -> -2.5209874
A14: CS_Depreciation | B14: 13.955205 | C14: 12.395924 | D14: =C14-B14 -> -1.5592803
A15: CS_Fix Cost | B15: 1.0082632 | C15: 1.1921554 | D15: =C15-B15 -> 0.18389221 | G15: Why crease？ 固定人工预测上涨0.18
A16: CS_Obsolescence | B16: 0.50954071 | C16: 0.17698546 | D16: =C16-B16 -> -0.33255524
A17: CS_Fix Utilities | B17: 0.15380524 | C17: 0.11597097 | D17: =C17-B17 -> -0.037834271
A18: Indirect Labour | B18: 5.5151107 | C18: 4.7809268 | D18: =C18-B18 -> -0.73418393
A19: Fixed Labour | B19: 2.2433178 | C19: 2.2112842 | D19: =C19-B19 -> -0.0320336
A20: CS_Semifix | B20: 3.325059 | C20: 3.8154444 | D20: =C20-B20 -> 0.49038533 | G20: Why crease？ 半固定单台上涨0.49
A21: CS_Direct Labour | B21: 11.095745 | C21: 10.755978 | D21: =C21-B21 -> -0.3397671
A22: CS_SCRAP_VARIABLE | B22: 0.58196637 | C22: 0.44001178 | D22: =C22-B22 -> -0.14195459
A23: CS_Variable Cost | B23: 0.2931156 | C23: 0.32747707 | D23: =C23-B23 -> 0.034361472
A24: CS_Reselling | B24: -1.3629003 | C24: -1.0365156 | D24: =C24-B24 -> 0.32638466
A25: CS_Variable Utilities | B25: 0.64202061 | C25: 0.71735626 | D25: =C25-B25 -> 0.075335649
A26: GMA | B26: 4.535785 | C26: 4.0820473 | D26: =C26-B26 -> -0.45373768
A27: IT Expense-Internal Charge Out | B27: 2.0598917 | C27: 1.7973014 | D27: -0.1274777 | F27: =(E27/B27)-1 -> -1
A28: Association dues | B28: 0.10364806 | C28: 0.12931195 | D28: 0.24760611 | F28: =(E28/B28)-1 -> -1
A29: G&A | B29: 1.4372934 | C29: 1.8673518 | D29: 0.299214 | F29: =(E29/B29)-1 -> -1
A30: 类型 | B30: CODE | C30: Description | D30: Description(CN) | E30: K€ | F30: QTY-2025 | G30: 478100 | H30: Budget-QTY | I30: 565020 | J30: ACT-QTY
E31: MFG-2025 | F31: CPU-2025 | G31: Budget-2026 | H31: Budget-CPU-2026 | I31: ACT-2026 | J31: ACT-CPU-2026 | K31: CPU-Y0Y | L31: Budget-ACT VARIANCE | M31: CPU-Y0Y Analysis | N31: Budget-ACT VARIANCE Analysis
A32: 折旧 | B32: 6666110101 | C32: 6666110101 Depreciation of buildings | D32: 建筑物折旧 | E32: 364.2985 | F32: 0.76197134 | G32: 383.10318 | H32: 0.67803473 | L32: =H32-F32 -> -0.083936614
B33: 6666110106 | C33: 6666110106 Depreciation of R&D facilities | D33: 研发设施折旧 | E33: 0 | F33: 0 | G33: 0 | H33: 0 | L33: =H33-F33 -> 0
B34: 6666110107 | C34: 6666110107 Depreciation of mold | D34: 模具折旧 | E34: 2576.6794 | F34: 5.3894151 | G34: 2795.0328 | H34: 4.9467857 | L34: =H34-F34 -> -0.44262943
B35: 6666110110 | C35: 6666110110 Depreciation-Plant & Machinery | D35: 厂房及机械折旧 | E35: 3385.4586 | F35: 7.081068 | G35: 3606.3598 | H35: 6.3827118 | L35: =H35-F35 -> -0.69835619
B36: 6666110112 | C36: 6666110112 Depreciation of Furniture & Fixture | D36: 家具及装置折旧 | E36: 116.10877 | F36: 0.24285457 | G36: 175.22479 | H36: 0.31012139 | L36: =H36-F36 -> 0.067266822
B37: 6666110204 | C37: 6666110204 Amortization of license, trademarks and | D37: 许可证、商标及摊销 | E37: 2.8363716 | F37: 0.0059325907 | G37: 3.0302 | H37: 0.005362996 | L37: =H37-F37 -> -0.00056959475
B38: 6666110207 | C38: 6666110207 Amortization of Software | D38: 软件摊销 | E38: 60.971559 | F38: 0.12752888 | G38: 41.219178 | H38: 0.072951715 | L38: =H38-F38 -> -0.054577168
B39: 6666110506 | C39: 6666110506 Amortization-Leasehold Improvement | D39: 租赁改良摊销 | E39: 7.5633708 | F39: 0.015819642 | G39: 0 | H39: 0 | L39: =H39-F39 -> -0.015819642
B40: 6666110206 | C40: 6666110206 Amortization of Patents | D40: 专利摊销 | F40: 0 | G40: 0 | H40: 0 | L40: =H40-F40 -> 0
B41: FIX | C41: * CS_Depreciation | D41: * CS_折旧 | E41: 6513.9165 | F41: 13.62459 | G41: 7003.97 | H41: 12.395968 | L41: =H41-F41 -> -1.2286218
...

Sheet 厨电成本数据
A1: 分类 | B1: 指标 | C1: / | D1: 1月份 | E1: 2月份 | F1: 3月份 | G1: 4月份 | H1: 5月份 | I1: 6月份 | J1: 7月份 | K1: 8月份 | L1: 9月份 | M1: 10月份 | N1: 11月份 | O1: 12月份 | P1: 年度
A2: 厨电定单量 | B2: 厨电定单量 | C2: 同期 | D2: 79712 | E2: 82105 | F2: 92657 | G2: 98687 | H2: 93353 | I2: 75092 | J2: 77799 | K2: 58812 | L2: 90826 | M2: 111572 | N2: 111625 | O2: 75554 | P2: 1047794
B3: 厨电定单量 | C3: 目标 | D3: 116704 | E3: 116204 | F3: 106704 | G3: 104704 | H3: 71805 | I3: 110105 | J3: 86206 | K3: 81605 | L3: 117305 | M3: 121005 | N3: 130155 | O3: 91305 | P3: 1253807
B4: 厨电定单量 | C4: 26年 | D4: 97611 | E4: 106294 | F4: =厨电3月!L28 -> 107376 | G4: ='26年厨电费用指标到月测算汇总表 '!G50 -> 110370 | H4: ='厨电5月 '!L27 -> 67531 | I4: 111312 | J4: 86967 | K4: 81560.001 | L4: 117158 | M4: 117404 | N4: 113634 | O4: 76893 | P4: =SUM(D4:O4) -> 1194110
A5: 厨电定单量（累计） | B5: 厨电定单量（累计） | C5: 同期 | D5: =D2 -> 79712 | E5: =D5+E2 -> 161817 | F5: =E5+F2 -> 254474 | G5: =F5+G2 -> 353161 | H5: =G5+H2 -> 446514 | I5: =H5+I2 -> 521606 | J5: =I5+J2 -> 599405 | K5: =J5+K2 -> 658217 | L5: =K5+L2 -> 749043 | ... O5: =N5+O2 -> 1047794 | P5: =O5 -> 1047794
B6: 厨电定单量（累计） | C6: 目标 | D6: =D3 -> 116704 | E6: =D6+E3 -> 232908 | F6: =E6+F3 -> 339612 | G6: =F6+G3 -> 444316 | H6: =G6+H3 -> 516121 | I6: =H6+I3 -> 626226 | J6: =I6+J3 -> 712432 | K6: =J6+K3 -> 794037 | L6: =K6+L3 -> 911342 | ... O6: =N6+O3 -> 1253807 | P6: =O6 -> 1253807
B7: 厨电定单量（累计） | C7: 26年 | D7: =D4 -> 97611 | E7: =D7+E4 -> 203905 | F7: =E7+F4 -> 311281 | G7: =F7+G4 -> 421651 | H7: =G7+H4 -> 489182 | I7: =H7+I4 -> 600494 | J7: =I7+J4 -> 687461 | K7: =J7+K4 -> 769021 | L7: =K7+L4 -> 886179 | ... O7: =N7+O4 -> 1194110 | P7: =O7 -> 1194110
A8: 厨电费用金额 | B8: 厨电费用金额 | C8: 同期 | D8: 2786.3724 | E8: 2692.3078 | F8: 2979.4464 | G8: 2556.6921 | H8: 2816.0883 | I8: 2742.9449 | J8: 2368.5937 | K8: 2153.779 | L8: 1237.7853 | M8: 2317.4637 | N8: 2618.4649 | O8: 1590.4388 | P8: 28860.377
B9: 厨电费用金额 | C9: 目标 | D9: 2628.6417 | E9: 2650.3787 | F9: 2640.9033 | G9: 2463.9881 | H9: 2562.0587 | I9: 2548.9769 | J9: 2516.4942 | K9: 2516.238 | L9: 2799.5329 | M9: 2751.3699 | N9: 2807.1181 | O9: 2894.1929 | P9: 31779.893
B10: 厨电费用金额 | C10: 26年 | D10: 2493.4106 | E10: 2350.455 | F10: =厨电3月!J238 -> 2592.0249 | G10: ='26年厨电费用指标到月测算汇总表 '!G39 -> 2091.3038 | H10: ='厨电5月 '!J245 -> 2105.3224 | I10: 2408.2532 | J10: 2322.2299 | K10: 2326.7122 | L10: 2612.4902 | M10: 2584.0024 | N10: 2628.5695 | O10: 2703.5436 | P10: =SUM(D10:O10) -> 29218.318
A11: 厨电费用金额（累计） | B11: 厨电费用金额（累计） | C11: 同期 | D11: =D8 -> 2786.3724 | E11: =D11+E8 -> 5478.6802 | F11: =E11+F8 -> 8458.1266 | G11: =F11+G8 -> 11014.819 | H11: =G11+H8 -> 13830.907 | I11: =H11+I8 -> 16573.852 | J11: =I11+J8 -> 18942.446 | K11: =J11+K8 -> 21096.225 | L11: =K11+L8 -> 22334.01 | ... O11: =N11+O8 -> 28860.377 | P11: =O11 -> 28860.377
B12: 厨电费用金额（累计） | C12: 目标 | D12: =D9 -> 2628.6417 | E12: =D12+E9 -> 5279.0204 | F12: =E12+F9 -> 7919.9237 | G12: =F12+G9 -> 10383.912 | H12: =G12+H9 -> 12945.97 | I12: =H12+I9 -> 15494.947 | J12: =I12+J9 -> 18011.442 | K12: =J12+K9 -> 20527.679 | L12: =K12+L9 -> 23327.212 | ... O12: =N12+O9 -> 31779.893 | P12: =O12 -> 31779.893
B13: 厨电费用金额（累计） | C13: 26年 | D13: =D10 -> 2493.4106 | E13: =D13+E10 -> 4843.8656 | F13: =E13+F10 -> 7435.8905 | G13: =F13+G10 -> 9527.1943 | H13: =G13+H10 -> 11632.517 | I13: =H13+I10 -> 14040.77 | J13: =I13+J10 -> 16363 | K13: =J13+K10 -> 18689.712 | L13: =K13+L10 -> 21302.202 | ... O13: =N13+O10 -> 29218.318 | P13: =O13 -> 29218.318
A14: 厨电单台 | B14: 厨电单台 | C14: 同期 | D14: 34.955495 | E14: 32.791034 | F14: 32.155654 | G14: 25.907081 | H14: 30.166018 | I14: 36.527791 | J14: 30.44504 | K14: 36.62142 | L14: 13.628094 | M14: 20.771015 | N14: 23.468835 | O14: 14.25482 | P14: 27.543942
B15: 厨电单台 | C15: 目标 | D15: 22.524007 | E15: 22.807982 | F15: 24.749806 | G15: 23.532894 | H15: 35.680784 | I15: 23.150419 | J15: 29.191636 | K15: 30.83436 | L15: 23.865418 | M15: 22.737655 | N15: 21.567501 | O15: 31.698077 | P15: 25.346719
B16: 厨电单台 | C16: 26年 | D16: 25.548148 | E16: 22.115933 | F16: =F10/F4*1000 -> 24.139704 | G16: =G10/G4*1000 -> 18.948118 | H16: =H10/H4*1000 -> 31.175643 | I16: =I10/I4*1000 -> 21.635163 | J16: =J10/J4*1000 -> 26.702427 | K16: =K10/K4*1000 -> 28.527613 | L16: =L10/L4*1000 -> 22.298863 | M16: =M10/M4*1000 -> 22.009492 | ... P16: =P10/P4*1000 -> 24.468699
B17: 厨电单台 | C17: 同期差额 | D17: =(D16-D14)*D4 -> -918260.59 | E17: =(E16-E14)*E4 -> -1134699.1 | F17: =(F16-F14)*F4 -> -860720.59 | G17: =(G16-G14)*G4 -> -768060.73 | H17: =(H16-H14)*H4 -> 68181.024 | I17: =(I16-I14)*I4 -> -1657728.2 | J17: =(J16-J14)*J4 -> -325483.89 | K17: =(K16-K14)*K4 -> -660130.93 | ... P17: =(P16-P14)*P4 -> -3672178.8
B18: 厨电单台 | C18: 当月单台目标完成率 | D18: =2-D16/D15 -> 0.86573699 | E18: =2-E16/E15 -> 1.0303424 | F18: =2-F16/F15 -> 1.0246508 | G18: =2-G16/G15 -> 1.1948241 | H18: =2-H16/H15 -> 1.1262624 | I18: =2-I16/I15 -> 1.0654526 | J18: =2-J16/J15 -> 1.0852713 | K18: =2-K16/K15 -> 1.0748109 | ... P18: =2-P16/P15 -> 1.0346404
B19: 厨电单台 | C19: 单台同期优化 | D19: =(D14-D16)/D14 -> 0.26912356 | E19: =(E14-E16)/E14 -> 0.32554938 | F19: =(F14-F16)/F14 -> 0.24928585 | G19: =(G14-G16)/G14 -> 0.26861238 | H19: =(H14-H16)/H14 -> -0.033468971 | I19: =(I14-I16)/I14 -> 0.40770678 | J19: =(J14-J16)/J14 -> 0.12293016 | K19: =(K14-K16)/K14 -> 0.22101293 | ... P19: =(P14-P16)/P14 -> 0.11164863
A20: 厨电单台（累计） | B20: 厨电单台（累计） | C20: 同期 | D20: =D11/D5*1000 -> 34.955495 | E20: =E11/E5*1000 -> 33.85726 | F20: =F11/F5*1000 -> 33.237685 | G20: =G11/G5*1000 -> 31.189227 | H20: =H11/H5*1000 -> 30.975304 | I20: =I11/I5*1000 -> 31.774657 | J20: =J11/J5*1000 -> 31.602081 | K20: =K11/K5*1000 -> 32.050562 | ... P20: =P11/P5*1000 -> 27.543942
B21: 厨电单台（累计） | C21: 目标 | D21: =D12/D6*1000 -> 22.524007 | E21: =E12/E6*1000 -> 22.665689 | F21: =F12/F6*1000 -> 23.320506 | G21: =G12/G6*1000 -> 23.370556 | H21: =H12/H6*1000 -> 25.083208 | I21: =I12/I6*1000 -> 24.743379 | J21: =J12/J6*1000 -> 25.281629 | K21: =K12/K6*1000 -> 25.852296 | ... P21: =P12/P6*1000 -> 25.346719
B22: 厨电单台（累计） | C22: 26年 | D22: =D13/D7*1000 -> 25.544361 | E22: =E13/E7*1000 -> 23.755502 | F22: =F13/F7*1000 -> 23.888032 | G22: =G13/G7*1000 -> 22.594976 | H22: =H13/H7*1000 -> 23.779527 | I22: =I13/I7*1000 -> 23.382032 | J22: =J13/J7*1000 -> 23.802077 | K22: =K13/K7*1000 -> 24.303253 | ... P22: =P13/P7*1000 -> 24.468699
B23: 厨电单台（累计） | C23: 同期差额 | D23: =(D22-D20)*D7 -> -918630.23 | E23: =(E22-E20)*E7 -> -2059799 | F23: =(F22-F20)*F7 -> -2910369.3 | G23: =(G22-G20)*G7 -> -3623774.6 | H23: =(H22-H20)*H7 -> -3520044.6 | I23: =(I22-I20)*I7 -> -5039721.1 | J23: =(J22-J20)*J7 -> -5362198.6 | K23: =(K22-K20)*K7 -> -5957843 | ... P23: =(P22-P20)*P7 -> -3672178.8
B24: 厨电单台（累计） | C24: 当月单台目标完成率 | D24: =2-D22/D21 -> 0.86590512 | E24: =2-E22/E21 -> 0.95191797 | F24: =2-F22/F21 -> 0.97566408 | G24: =2-G22/G21 -> 1.0331862 | H24: =2-H22/H21 -> 1.0519743 | I24: =2-I22/I21 -> 1.0550186 | J24: =2-J22/J21 -> 1.0585228 | K24: =2-K22/K21 -> 1.059919 | ... P24: =2-P22/P21 -> 1.0346404
B25: 厨电单台（累计） | C25: 累计单台同期优化 | D25: =(D20-D22)/D20 -> 0.2692319 | E25: =(E20-E22)/E20 -> 0.29836313 | F25: =(F20-F22)/F20 -> 0.28129676 | G25: =(G20-G22)/G20 -> 0.27555191 | H25: =(H20-H22)/H20 -> 0.23230691 | I25: =(I20-I22)/I20 -> 0.26412953 | J25: =(J20-J22)/J20 -> 0.24681931 | K25: =(K20-K22)/K20 -> 0.24172146 | ... P25: =(P20-P22)/P20 -> 0.11164863
A26: 厨电折旧费用 | B26: 厨电折旧费用 | C26: 同期 | D26: 770 | E26: 741 | F26: 764 | G26: 766 | H26: 832 | I26: 824 | J26: 839 | K26: 583 | L26: 793 | M26: 590 | N26: 801 | O26: 816 | P26: =SUM(D26:O26) -> 9119
B27: 厨电折旧费用 | C27: 目标 | D27: 816 | E27: 780 | F27: 827 | G27: 816 | H27: 828 | I27: 822 | J27: 884 | K27: 894 | L27: 882 | M27: 898 | N27: 886 | O27: 897 | P27: =SUM(D27:O27) -> 10230
B28: 厨电折旧费用 | C28: 26年 | D28: 818 | E28: =363+250 -> 613 | F28: =厨电3月!J39 -> 798.62406 | G28: =厨电4月!I37 -> 466.69395 | H28: ='厨电5月 '!J38 -> 254.33901 | I28: 597.36367 | J28: 657.3779 | K28: 667.43613 | L28: 659.22372 | M28: 671.7118 | N28: 662.56808 | O28: 669.68611 | P28: =SUM(D28:O28) -> 7536.0244
A29: 厨电折旧费用累计 | B29: 厨电折旧费用累计 | C29: 同期 | D29: =D26 -> 770 | E29: =D29+E26 -> 1511 | F29: =E29+F26 -> 2275 | G29: =F29+G26 -> 3041 | H29: =G29+H26 -> 3873 | I29: =H29+I26 -> 4697 | J29: =I29+J26 -> 5536 | K29: =J29+K26 -> 6119 | L29: =K29+L26 -> 6912 | ... O29: =N29+O26 -> 9119 | P29: =O29 -> 9119
B30: 厨电折旧费用累计 | C30: 目标 | D30: =D27 -> 816 | E30: =D30+E27 -> 1596 | F30: =E30+F27 -> 2423 | G30: =F30+G27 -> 3239 | H30: =G30+H27 -> 4067 | I30: =H30+I27 -> 4889 | J30: =I30+J27 -> 5773 | K30: =J30+K27 -> 6667 | L30: =K30+L27 -> 7549 | ... O30: =N30+O27 -> 10230 | P30: =O30 -> 10230
B31: 厨电折旧费用累计 | C31: 26年 | D31: =D28 -> 818 | E31: =D31+E28 -> 1431 | F31: =E31+F28 -> 2229.6241 | G31: =F31+G28 -> 2696.318 | H31: =G31+H28 -> 2950.657 | I31: =H31+I28 -> 3548.0207 | J31: =I31+J28 -> 4205.3986 | K31: =J31+K28 -> 4872.8347 | L31: =K31+L28 -> 5532.0584 | ... O31: =N31+O28 -> 7536.0244 | P31: =O31 -> 7536.0244
A32: 厨电折旧单台 | B32: 厨电折旧单台 | C32: 同期 | D32: =D26/D2*1000 -> 9.6597752 | E32: =E26/E2*1000 -> 9.0250289 | F32: =F26/F2*1000 -> 8.2454645 | G32: =G26/G2*1000 -> 7.7619139 | H32: =H26/H2*1000 -> 8.9124077 | I32: =I26/I2*1000 -> 10.973206 | J32: =J26/J2*1000 -> 10.7842 | K32: =K26/K2*1000 -> 9.9129429 | ... O32: =O26/O2*1000 -> 10.800222 | P32: =P29/P2*1000 -> 8.7030466
B33: 厨电折旧单台 | C33: 目标 | D33: =D27/D3*1000 -> 6.9920483 | E33: =E27/E3*1000 -> 6.7123335 | F33: =F27/F3*1000 -> 7.7504124 | G33: =G27/G3*1000 -> 7.7933985 | H33: =H27/H3*1000 -> 11.53123 | I33: =I27/I3*1000 -> 7.465601 | J33: =J27/J3*1000 -> 10.254507 | K33: =K27/K3*1000 -> 10.955211 | ... O33: =O27/O3*1000 -> 9.8242155 | P33: =P30/P3*1000 -> 8.1591505
B34: 厨电折旧单台 | C34: 26年 | D34: =D28/D4*1000 -> 8.3802031 | E34: =E28/E4*1000 -> 5.7670235 | F34: =F28/F4*1000 -> 7.4376403 | G34: =G28/G4*1000 -> 4.2284493 | H34: =H28/H4*1000 -> 3.7662556 | I34: =I28/I4*1000 -> 5.3665703 | J34: =J28/J4*1000 -> 7.558935 | K34: =K28/K4*1000 -> 8.1833757 | ... O34: =O28/O4*1000 -> 8.7093248 | P34: =P31/P4*1000 -> 6.3109968
B35: 厨电折旧单台 | C35: 同期差额 | D35: =(D34-D32)*D4 -> -124900.32 | E35: =(E34-E32)*E4 -> -346306.42 | F35: =(F34-F32)*F4 -> -86740.931 | G35: =(G34-G32)*G4 -> -389988.49 | H35: =(H34-H32)*H4 -> -347524.8 | I35: =(I34-I32)*I4 -> -624085.86 | J35: =(J34-J32)*J4 -> -280491.65 | K35: =(K34-K32)*K4 -> -141063.5 | ... P35: =(P34-P32)*P4 -> -2856370.5
A36: 厨电变动费用 | B36: 厨电变动费用 | C36: 同期 | D36: =D8-D26 -> 2016.3724 | E36: =E8-E26 -> 1951.3078 | F36: =F8-F26 -> 2215.4464 | G36: =G8-G26 -> 1790.6921 | H36: =H8-H26 -> 1984.0883 | I36: =I8-I26 -> 1918.9449 | J36: =J8-J26 -> 1529.5937 | K36: =K8-K26 -> 1570.779 | ... P36: =P8-P26 -> 19741.377
B37: 厨电变动费用 | C37: 目标 | D37: =D9-D27 -> 1812.6417 | E37: =E9-E27 -> 1870.3787 | F37: =F9-F27 -> 1813.9033 | G37: =G9-G27 -> 1647.9881 | H37: =H9-H27 -> 1734.0587 | I37: =I9-I27 -> 1726.9769 | J37: =J9-J27 -> 1632.4942 | K37: =K9-K27 -> 1622.238 | ... P37: =P9-P27 -> 21549.893
B38: 厨电变动费用 | C38: 26年 | D38: =D10-D28 -> 1675.4106 | E38: =E10-E28 -> 1737.455 | F38: =F10-F28 -> 1793.4008 | G38: =G10-G28 -> 1624.6099 | H38: =H10-H28 -> 1850.9834 | I38: =I10-I28 -> 1810.8896 | J38: =J10-J28 -> 1664.852 | K38: =K10-K28 -> 1659.276 | ... P38: =P10-P28 -> 21682.293
A39: 厨电变动费用累计 | B39: 厨电变动费用累计 | C39: 同期 | D39: =D36 -> 2016.3724 | E39: =D39+E36 -> 3967.6802 | F39: =E39+F36 -> 6183.1266 | G39: =F39+G36 -> 7973.8188 | H39: =G39+H36 -> 9957.907 | I39: =H39+I36 -> 11876.852 | J39: =I39+J36 -> 13406.446 | K39: =J39+K36 -> 14977.225 | L39: =K39+L36 -> 15422.01 | ... O39: =N39+O36 -> 19741.377 | P39: =O39 -> 19741.377
B40: 厨电变动费用累计 | C40: 目标 | D40: =D37 -> 1812.6417 | E40: =D40+E37 -> 3683.0204 | F40: =E40+F37 -> 5496.9237 | G40: =F40+G37 -> 7144.9118 | H40: =G40+H37 -> 8878.9705 | I40: =H40+I37 -> 10605.947 | J40: =I40+J37 -> 12238.442 | K40: =J40+K37 -> 13860.679 | L40: =K40+L37 -> 15778.212 | ... O40: =N40+O37 -> 21549.893 | P40: =O40 -> 21549.893
...

Sheet 26年厨电费用指标到月测算汇总表 
B1: 土耳其厨电费用指标统计
B2: 一、年度预测： 产量预测：年度预算125.4万台↑20%，实际5月累计48.91万台 ↑19% 单台预测：25年单台达成27.54欧，26年目标25.35欧，预测达成24.47欧，同比↓12%；额收益397万 三、5月达成实际： 单台实际：5月同期30.17欧，实际单台费用31.2欧，较同期↑3.3%； 5月累计单台：5月同期31.19欧，4月实际23.78欧，累计单台↓7.41欧，额收益352万欧
A3: 费 | B3: 序号 | C3: / | D3: 1月份 | E3: 2月份 | F3: 3月份 | G3: 4月份 | H3: 5月份 | I3: 6月份 | J3: 7月份 | K3: 8月份 | L3: 9月份 | M3: 10月份 | N3: 11月份 | O3: 12月份 | P3: 年度
B4: 费率 | C4: 销售收入（26年预测） | D4: 11387.793 | E4: 11383.957 | F4: 11384.182 | G4: 10843.261 | H4: 8301.8079 | I4: 12020.11 | J4: 9489.0377 | K4: 8834.8314 | L4: 12125.496 | M4: 10955.642 | N4: 11601.048 | O4: 9179.1981 | P4: 127506.36
C5: 销售收入（25年实际） | D5: 11599.19 | E5: 10318.459 | F5: 10279.816 | G5: 10804.991 | H5: 11868.184 | I5: 6637.8974 | J5: 9550.8211 | K5: 7188.5794 | L5: 5817.7726 | M5: 5854.6235 | N5: 7485.28 | O5: 8923.716 | P5: 106138.64
C6: 单价（同期） | D6: 238.80897 | E6: 224.15352 | F6: 221.84897 | G6: 218.88846 | H6: 220.99255 | I6: 223.76947 | J6: 228.17739 | K6: 224.80468 | L6: 205.80772 | M6: 223.36513 | N6: 220 | O6: 212 | P6: 222
C7: 单价（实际） | D7: 225.66619 | E7: 225.66619 | F7: 225.66619 | G7: 225.66619 | H7: 225.66619 | I7: 225.66619 | J7: 225.66619 | K7: 225.66619 | L7: 225.66619 | M7: 225.66619 | N7: 225.66619 | O7: 225.66619 | P7: 225.66619
C8: 制造费用（26年预测） | D8: 1838.2556 | E8: 1852.3924 | F8: 1893.0365 | G8: 1849.6673 | H8: 1928.8688 | I8: 1870.4326 | J8: 1859.2351 | K8: 1842.1673 | L8: 1948.6868 | M8: 1894.9246 | N8: 1861.9628 | O8: 1947.1505 | P8: 22586.78
C9: 制造费用（25年实际） | D9: 1702.2213 | E9: 1632.2334 | F9: 1827.8999 | G9: 1591.5968 | H9: 1866.987 | I9: 1737.9 | J9: 1637.4123 | K9: 1533.5455 | L9: 1597.8553 | M9: 1443.0898 | N9: 1758.5061 | O9: 1502.3028 | P9: 19831.55
C10: 同期 | D10: 0.14675346 | E10: 0.15818577 | F10: 0.17781446 | G10: 0.147302 | H10: 0.15731025 | I10: 0.26181483 | J10: 0.17144205 | K10: 0.21333082 | L10: 0.2746507 | M10: 0.24648721 | N10: 0.23492856 | O10: 0.16834947 | P10: 0.18684571
C11: 目标 | D11: 0.16142334 | E11: 0.16271955 | F11: 0.16628656 | G11: 0.17058221 | H11: 0.23234323 | I11: 0.15560861 | J11: 0.19593505 | K11: 0.20851188 | L11: 0.16070986 | M11: 0.17296335 | N11: 0.16049954 | O11: 0.21212643 | P11: 0.17714238
C12: 26年 | D12: =D8/D4 -> 0.16142334 | E12: =E8/E4 -> 0.16271955 | F12: =F8/F4 -> 0.16628656 | G12: =G8/G4 -> 0.17058221 | H12: =H8/H4 -> 0.23234323 | I12: =I8/I4 -> 0.15560861 | J12: =J8/J4 -> 0.19593505 | K12: =K8/K4 -> 0.20851188 | ... P12: =P8/P4 -> 0.17714238
B13: 降幅 | D13: =(D10-D12)/D10 -> -0.09996281 | E13: =(E10-E12)/E10 -> -0.028661121 | F13: =(F10-F12)/F10 -> 0.064831052 | G13: =(G10-G12)/G10 -> -0.15804409 | H13: =(H10-H12)/H10 -> -0.47697446 | I13: =(I10-I12)/I10 -> 0.40565396 | J13: =(J10-J12)/J10 -> -0.14286464 | K13: =(K10-K12)/K10 -> 0.022589029 | ... P13: =(P10-P12)/P10 -> 0.051932324
B14: 完成率 | D14: =2-D12/D11 -> 1 | E14: =2-E12/E11 -> 1 | F14: =2-F12/F11 -> 1 | G14: =2-G12/G11 -> 1 | H14: =2-H12/H11 -> 1 | I14: =2-I12/I11 -> 1 | J14: =2-J12/J11 -> 1 | K14: =2-K12/K11 -> 1 | ... O14: =2-O12/O11 -> 1
B15: 费率（累计） | C15: 累计销售收入（26年预测） | D15: =D4 -> 11387.793 | E15: =D15+E4 -> 22771.75 | F15: =E15+F4 -> 34155.932 | G15: =F15+G4 -> 44999.193 | H15: =G15+H4 -> 53301.001 | I15: =H15+I4 -> 65321.11 | J15: =I15+J4 -> 74810.148 | K15: =J15+K4 -> 83644.98 | L15: =K15+L4 -> 95770.476 | ... O15: =N15+O4 -> 127506.36 | P15: =O15 -> 127506.36
C16: 累计销售收入（25年实际） | D16: =D5 -> 11599.19 | E16: =D16+E5 -> 21917.65 | F16: =E16+F5 -> 32197.465 | G16: =F16+G5 -> 43002.456 | H16: =G16+H5 -> 54870.64 | I16: =H16+I5 -> 61508.538 | J16: =I16+J5 -> 71059.359 | K16: =J16+K5 -> 78247.938 | L16: =K16+L5 -> 84065.711 | ... O16: =N16+O5 -> 106329.33 | P16: =O16 -> 106329.33
C17: 累计制造费用（26年预测） | D17: =D8 -> 1838.2556 | E17: =D17+E8 -> 3690.648 | F17: =E17+F8 -> 5583.6845 | G17: =F17+G8 -> 7433.3518 | H17: =G17+H8 -> 9362.2206 | I17: =H17+I8 -> 11232.653 | J17: =I17+J8 -> 13091.888 | K17: =J17+K8 -> 14934.056 | L17: =K17+L8 -> 16882.742 | ... O17: =N17+O8 -> 22586.78 | P17: =O17 -> 22586.78
C18: 累计制造费用（25年实际） | D18: =D9 -> 1702.2213 | E18: =D18+E9 -> 3334.4547 | F18: =E18+F9 -> 5162.3545 | G18: =F18+G9 -> 6753.9513 | H18: =G18+H9 -> 8620.9383 | I18: =H18+I9 -> 10358.838 | J18: =I18+J9 -> 11996.251 | K18: =J18+K9 -> 13529.796 | L18: =K18+L9 -> 15127.651 | ... O18: =N18+O9 -> 19831.55 | P18: =O18 -> 19831.55
C19: 同期 | D19: =D18/D16 -> 0.14675346 | E19: =E18/E16 -> 0.1521356 | F19: =F18/F16 -> 0.16033419 | G19: =G18/G16 -> 0.15705966 | H19: =H18/H16 -> 0.15711386 | I19: =I18/I16 -> 0.16841302 | J19: =J18/J16 -> 0.16882014 | K19: =K18/K16 -> 0.1729093 | ... P19: =P18/P16 -> 0.18651063
C20: 目标 | D20: 0.16142334 | E20: 0.16207134 | F20: 0.16347627 | G20: 0.16518856 | H20: 0.17564812 | I20: 0.17196054 | J20: 0.1750015 | K20: 0.17854097 | L20: 0.17628337 | M20: 0.17594257 | N20: 0.1744285 | O20: 0.17714238 | P20: 0.17714238
C21: 26年 | D21: =D17/D15 -> 0.16142334 | E21: =E17/E15 -> 0.16207134 | F21: =F17/F15 -> 0.16347627 | G21: =G17/G15 -> 0.16518856 | H21: =H17/H15 -> 0.17564812 | I21: =I17/I15 -> 0.17196054 | J21: =J17/J15 -> 0.1750015 | K21: =K17/K15 -> 0.17854097 | ... P21: =P17/P15 -> 0.17714238
B22: 降幅 | D22: =(D19-D21)/D19 -> -0.09996281 | E22: =(E19-E21)/E19 -> -0.065308465 | F22: =(F19-F21)/F19 -> -0.019597081 | G22: =(G19-G21)/G19 -> -0.05175674 | H22: =(H19-H21)/H19 -> -0.11796704 | I22: =(I19-I21)/I19 -> -0.021064411 | J22: =(J19-J21)/J19 -> -0.036615098 | K22: =(K19-K21)/K19 -> -0.032570075 | ... O22: =(O19-O21)/O19 -> 0.050229047
B23: 完成率 | D23: =2-D21/D20 -> 1 | E23: =2-E21/E20 -> 1 | F23: =2-F21/F20 -> 1 | G23: =2-G21/G20 -> 1 | H23: =2-H21/H20 -> 1 | I23: =2-I21/I20 -> 1 | J23: =2-J21/J20 -> 1 | K23: 0.06 | L23: =2-L21/L20 -> 1 | M23: =2-M21/M20 -> 1 | N23: =2-N21/N20 -> 1 | O23: =2-O21/O20 -> 1 | P23: =2-P21/P20 -> 1
B24: 单台 | C24: 同期 | D24: 34.955495 | E24: 32.791034 | F24: 32.155654 | G24: 25.907081 | H24: 30.166018 | I24: 36.527791 | J24: 30.44504 | K24: 36.62142 | L24: 13.628094 | M24: 20.771015 | N24: 23.468835 | O24: 14.25482 | P24: 27.543942
C25: 目标 | D25: 22.524007 | E25: 22.807982 | F25: 24.749806 | G25: 23.532894 | H25: 35.680784 | I25: 23.150419 | J25: 29.191636 | K25: 30.83436 | L25: 23.865418 | M25: 22.737655 | N25: 21.567501 | O25: 31.698077 | P25: 25.346719
C26: 26年 | D26: ='厨电1月 '!E11 -> 25.548148 | E26: ='厨电2月 '!E12 -> 22.115933 | F26: =厨电3月!F11 -> 24.139704 | G26: =厨电4月!E12 -> 18.948118 | H26: ='厨电5月 '!K245 -> 31.175643 | I26: 21.635163 | J26: 26.702427 | K26: 28.527613 | L26: 22.298863 | M26: 22.009492 | N26: 23.131893 | O26: 35.159814 | P26: 24.23174
B27: 当月单台完成率 | D27: =2-D26/D25 -> 0.86573699 | E27: =2-E26/E25 -> 1.0303424 | F27: =2-F26/F25 -> 1.0246508 | G27: =2-G26/G25 -> 1.1948241 | H27: =2-H26/H25 -> 1.1262624 | I27: =2-I26/I25 -> 1.0654526 | J27: =2-J26/J25 -> 1.0852713 | K27: =2-K26/K25 -> 1.0748109 | ... P27: =2-P26/P25 -> 1.0439891
B28: 目标同期优化率 | D28: =D25/D24-1 -> -0.3556376 | E28: =E25/E24-1 -> -0.30444456 | F28: =F25/F24-1 -> -0.23031246 | G28: =G25/G24-1 -> -0.091642405 | H28: =H25/H24-1 -> 0.18281385 | I28: =I25/I24-1 -> -0.3662245 | J28: =J25/J24-1 -> -0.041169416 | K28: =K25/K24-1 -> -0.15802392 | ... O28: =O25/O24-1 -> 1.2236742
B29: 当月单台同期优化率 | D29: =(D24-D26)/D24 -> 0.26912356 | E29: =(E24-E26)/E24 -> 0.32554938 | F29: =(F24-F26)/F24 -> 0.24928585 | G29: =(G24-G26)/G24 -> 0.26861238 | H29: =(H24-H26)/H24 -> -0.033468971 | I29: =(I24-I26)/I24 -> 0.40770678 | J29: =(J24-J26)/J24 -> 0.12293016 | K29: =(K24-K26)/K24 -> 0.22101293 | ... P29: =(P24-P26)/P24 -> 0.12025157
B30: 当月费用额
B31: 单台（累计） | C31: 同期 | D31: =D40/D60*1000 -> 34.955495 | E31: =E40/E60*1000 -> 33.85726 | F31: =F40/F60*1000 -> 33.237685 | G31: =G40/G60*1000 -> 31.189227 | H31: =H40/H60*1000 -> 30.975304 | I31: =I40/I60*1000 -> 31.774657 | J31: =J40/J60*1000 -> 31.602081 | K31: =K40/K60*1000 -> 32.050562 | ... P31: =P40/P60*1000 -> 27.543942
C32: 目标 | D32: =D41/D61*1000 -> 22.524007 | E32: =E41/E61*1000 -> 22.665689 | F32: =F41/F61*1000 -> 23.320506 | G32: =G41/G61*1000 -> 23.370556 | H32: =H41/H61*1000 -> 25.083208 | I32: =I41/I61*1000 -> 24.743379 | J32: =J41/J61*1000 -> 25.281629 | K32: =K41/K61*1000 -> 25.852296 | ... P32: =P41/P61*1000 -> 25.346719 | R32: =31.19-23.78 -> 7.41
C33: 26年 | D33: =D42/D62*1000 -> 25.544361 | E33: =E42/E62*1000 -> 23.755502 | F33: =F42/F62*1000 -> 23.888032 | G33: =G42/G62*1000 -> 22.594976 | H33: =H42/H62*1000 -> 23.779527 | I33: =I42/I62*1000 -> 23.382032 | J33: =J42/J62*1000 -> 23.802077 | K33: =K42/K62*1000 -> 24.303253 | ... P33: =P42/P62*1000 -> 24.468699
B34: 累计单台完成率 | D34: =2-D33/D32 -> 0.86590512 | E34: =2-E33/E32 -> 0.95191797 | F34: =2-F33/F32 -> 0.97566408 | G34: =2-G33/G32 -> 1.0331862 | H34: =2-H33/H32 -> 1.0519743 | I34: =2-I33/I32 -> 1.0550186 | J34: =2-J33/J32 -> 1.0585228 | K34: =2-K33/K32 -> 1.059919 | ... O34: =2-O33/O32 -> 1.0346404 | P34: =O34 -> 1.0346404
B35: 累计单台同期优化率 | D35: =(D31-D33)/D31 -> 0.2692319 | E35: =(E31-E33)/E31 -> 0.29836313 | F35: =(F31-F33)/F31 -> 0.28129676 | G35: =(G31-G33)/G31 -> 0.27555191 | H35: =(H31-H33)/H31 -> 0.23230691 | I35: =(I31-I33)/I31 -> 0.26412953 | J35: =(J31-J33)/J31 -> 0.24681931 | K35: =(K31-K33)/K31 -> 0.24172146 | ... O35: =(O31-O33)/O31 -> 0.11164863 | P35: =O35 -> 0.11164863
B36: 累计费用额 | D36: =D42 -> 2493.4106 | E36: =E42 -> 4843.8656 | F36: =F42 -> 7435.8905 | G36: =G42 -> 9527.1943 | H36: =H42 -> 11632.517 | I36: =I42 -> 14040.77 | J36: =J42 -> 16363 | K36: =K42 -> 18689.712 | ... O36: =O42 -> 29218.318
B37: 费用金额 | C37: 同期 | D37: 2786.3724 | E37: 2692.3078 | F37: 2979.4464 | G37: 2556.6921 | H37: 2816.0883 | I37: 2742.9449 | J37: 2368.5937 | K37: 2153.779 | L37: 1237.7853 | M37: 2317.4637 | N37: 2618.4649 | O37: 1590.4388 | P37: 28860.377
C38: 目标 | D38: 2628.6417 | E38: 2650.3787 | F38: 2640.9033 | G38: 2463.9881 | H38: 2562.0587 | I38: 2548.9769 | J38: 2516.4942 | K38: 2516.238 | L38: 2799.5329 | M38: 2751.3699 | N38: 2807.1181 | O38: 2894.1929 | P38: 31779.893
C39: 26年 | D39: 2493.4106 | E39: 2350.455 | F39: =厨电3月!J238 -> 2592.0249 | G39: =厨电4月!I235 -> 2091.3038 | H39: ='厨电5月 '!J245 -> 2105.3224 | I39: 2408.2532 | J39: 2322.2299 | K39: 2326.7122 | L39: 2612.4902 | M39: 2584.0024 | N39: 2628.5695 | O39: 2703.5436 | P39: 29058.509
B40: 费用金额（累计） | C40: 同期 | D40: =D37 -> 2786.3724 | E40: =D40+E37 -> 5478.6802 | F40: =E40+F37 -> 8458.1266 | G40: =F40+G37 -> 11014.819 | H40: =G40+H37 -> 13830.907 | I40: =H40+I37 -> 16573.852 | J40: =I40+J37 -> 18942.446 | K40: =J40+K37 -> 21096.225 | L40: =K40+L37 -> 22334.01 | ... O40: =N40+O37 -> 28860.377 | P40: =O40 -> 28860.377
...

Sheet 25年厨电费用指标到月测算汇总表  (2)
B1: 土耳其厨电费用指标统计
B2: 一、年度预测： 产量预测：年度预算125.4万台↑20%，实际Q1 30.9万台 ↑22% 单台预测：25年单台达成31.88欧，26年目标25.3欧，预测达成25.6欧，同比↓19.7%； 二、Q1达成预测： 单台预测：Q1单台预测:23.89欧，同期单台33.24欧，同比28.1%； 三、3月达成实际： 单台预测：3月同期32.16欧，实际单台费用24.1欧，较同期↓24.9%； 四、4月达成预测： 单台预测：4月同期25.91欧，预测单台费用23.5欧，较同期↓9.2%；
A3: 费 | B3: 序号 | C3: / | D3: 1月份 | E3: 2月份 | F3: 3月份 | G3: 4月份 | H3: 5月份 | I3: 6月份 | J3: 7月份 | K3: 8月份 | L3: 9月份 | M3: 10月份 | N3: 11月份 | O3: 12月份 | P3: 年度
B4: 费率 | C4: 销售收入（25年预测） | D4: 11387.793 | E4: 11383.957 | F4: 11384.182 | G4: 10843.261 | H4: 8301.8079 | I4: 12020.11 | J4: 9489.0377 | K4: 8834.8314 | L4: 12125.496 | M4: 10955.642 | N4: 11601.048 | O4: 9179.1981 | P4: 127506.36
C5: 销售收入（25年实际） | D5: 11599.19 | E5: 10318.459 | F5: 10279.816 | G5: 10804.991 | H5: 11868.184 | I5: 6637.8974 | J5: 9550.8211 | K5: 7188.5794 | L5: 5817.7726 | M5: 5854.6235 | N5: 7485.28 | O5: 8923.716 | P5: 106138.64
C6: 单价（同期） | D6: 238.80897 | E6: 224.15352 | F6: 221.84897 | G6: 218.88846 | H6: 220.99255 | I6: 223.76947 | J6: 228.17739 | K6: 224.80468 | L6: 205.80772 | M6: 223.36513 | N6: 220 | O6: 212 | P6: 222
C7: 单价（实际） | D7: 225.66619 | E7: 225.66619 | F7: 225.66619 | G7: 225.66619 | H7: 225.66619 | I7: 225.66619 | J7: 225.66619 | K7: 225.66619 | L7: 225.66619 | M7: 225.66619 | N7: 225.66619 | O7: 225.66619 | P7: 225.66619
C8: 制造费用（25年预测） | D8: 1838.2556 | E8: 1852.3924 | F8: 1893.0365 | G8: 1849.6673 | H8: 1928.8688 | I8: 1870.4326 | J8: 1859.2351 | K8: 1842.1673 | L8: 1948.6868 | M8: 1894.9246 | N8: 1861.9628 | O8: 1947.1505 | P8: 22586.78
C9: 制造费用（25年实际） | D9: 1702.2213 | E9: 1632.2334 | F9: 1827.8999 | G9: 1591.5968 | H9: 1866.987 | I9: 1737.9 | J9: 1637.4123 | K9: 1533.5455 | L9: 1597.8553 | M9: 1443.0898 | N9: 1758.5061 | O9: 1502.3028 | P9: 19831.55
C10: 同期 | D10: 0.14675346 | E10: 0.15818577 | F10: 0.17781446 | G10: 0.147302 | H10: 0.15731025 | I10: 0.26181483 | J10: 0.17144205 | K10: 0.21333082 | L10: 0.2746507 | M10: 0.24648721 | N10: 0.23492856 | O10: 0.16834947 | P10: 0.18684571
C11: 目标 | D11: 0.16142334 | E11: 0.16271955 | F11: 0.16628656 | G11: 0.17058221 | H11: 0.23234323 | I11: 0.15560861 | J11: 0.19593505 | K11: 0.20851188 | L11: 0.16070986 | M11: 0.17296335 | N11: 0.16049954 | O11: 0.21212643 | P11: 0.17714238
C12: 25年 | D12: =D8/D4 -> 0.16142334 | E12: =E8/E4 -> 0.16271955 | F12: =F8/F4 -> 0.16628656 | G12: =G8/G4 -> 0.17058221 | H12: =H8/H4 -> 0.23234323 | I12: =I8/I4 -> 0.15560861 | J12: =J8/J4 -> 0.19593505 | K12: =K8/K4 -> 0.20851188 | ... P12: =P8/P4 -> 0.17714238
B13: 降幅 | D13: =(D10-D12)/D10 -> -0.09996281 | E13: =(E10-E12)/E10 -> -0.028661121 | F13: =(F10-F12)/F10 -> 0.064831052 | G13: =(G10-G12)/G10 -> -0.15804409 | H13: =(H10-H12)/H10 -> -0.47697446 | I13: =(I10-I12)/I10 -> 0.40565396 | J13: =(J10-J12)/J10 -> -0.14286464 | K13: =(K10-K12)/K10 -> 0.022589029 | ... P13: =(P10-P12)/P10 -> 0.051932324
B14: 完成率 | D14: =2-D12/D11 -> 1 | E14: =2-E12/E11 -> 1 | F14: =2-F12/F11 -> 1 | G14: =2-G12/G11 -> 1 | H14: =2-H12/H11 -> 1 | I14: =2-I12/I11 -> 1 | J14: =2-J12/J11 -> 1 | K14: =2-K12/K11 -> 1 | ... O14: =2-O12/O11 -> 1
B15: 费率（累计） | C15: 累计销售收入（25年预测） | D15: =D4 -> 11387.793 | E15: =D15+E4 -> 22771.75 | F15: =E15+F4 -> 34155.932 | G15: =F15+G4 -> 44999.193 | H15: =G15+H4 -> 53301.001 | I15: =H15+I4 -> 65321.11 | J15: =I15+J4 -> 74810.148 | K15: =J15+K4 -> 83644.98 | L15: =K15+L4 -> 95770.476 | ... O15: =N15+O4 -> 127506.36 | P15: =O15 -> 127506.36
C16: 累计销售收入（25年实际） | D16: =D5 -> 11599.19 | E16: =D16+E5 -> 21917.65 | F16: =E16+F5 -> 32197.465 | G16: =F16+G5 -> 43002.456 | H16: =G16+H5 -> 54870.64 | I16: =H16+I5 -> 61508.538 | J16: =I16+J5 -> 71059.359 | K16: =J16+K5 -> 78247.938 | L16: =K16+L5 -> 84065.711 | ... O16: =N16+O5 -> 106329.33 | P16: =O16 -> 106329.33
C17: 累计制造费用（25年预测） | D17: =D8 -> 1838.2556 | E17: =D17+E8 -> 3690.648 | F17: =E17+F8 -> 5583.6845 | G17: =F17+G8 -> 7433.3518 | H17: =G17+H8 -> 9362.2206 | I17: =H17+I8 -> 11232.653 | J17: =I17+J8 -> 13091.888 | K17: =J17+K8 -> 14934.056 | L17: =K17+L8 -> 16882.742 | ... O17: =N17+O8 -> 22586.78 | P17: =O17 -> 22586.78
C18: 累计制造费用（25年实际） | D18: =D9 -> 1702.2213 | E18: =D18+E9 -> 3334.4547 | F18: =E18+F9 -> 5162.3545 | G18: =F18+G9 -> 6753.9513 | H18: =G18+H9 -> 8620.9383 | I18: =H18+I9 -> 10358.838 | J18: =I18+J9 -> 11996.251 | K18: =J18+K9 -> 13529.796 | L18: =K18+L9 -> 15127.651 | ... O18: =N18+O9 -> 19831.55 | P18: =O18 -> 19831.55
C19: 同期 | D19: =D18/D16 -> 0.14675346 | E19: =E18/E16 -> 0.1521356 | F19: =F18/F16 -> 0.16033419 | G19: =G18/G16 -> 0.15705966 | H19: =H18/H16 -> 0.15711386 | I19: =I18/I16 -> 0.16841302 | J19: =J18/J16 -> 0.16882014 | K19: =K18/K16 -> 0.1729093 | ... P19: =P18/P16 -> 0.18651063
C20: 目标 | D20: 0.16142334 | E20: 0.16207134 | F20: 0.16347627 | G20: 0.16518856 | H20: 0.17564812 | I20: 0.17196054 | J20: 0.1750015 | K20: 0.17854097 | L20: 0.17628337 | M20: 0.17594257 | N20: 0.1744285 | O20: 0.17714238 | P20: 0.17714238
C21: 25年 | D21: =D17/D15 -> 0.16142334 | E21: =E17/E15 -> 0.16207134 | F21: =F17/F15 -> 0.16347627 | G21: =G17/G15 -> 0.16518856 | H21: =H17/H15 -> 0.17564812 | I21: =I17/I15 -> 0.17196054 | J21: =J17/J15 -> 0.1750015 | K21: =K17/K15 -> 0.17854097 | ... P21: =P17/P15 -> 0.17714238
B22: 降幅 | D22: =(D19-D21)/D19 -> -0.09996281 | E22: =(E19-E21)/E19 -> -0.065308465 | F22: =(F19-F21)/F19 -> -0.019597081 | G22: =(G19-G21)/G19 -> -0.05175674 | H22: =(H19-H21)/H19 -> -0.11796704 | I22: =(I19-I21)/I19 -> -0.021064411 | J22: =(J19-J21)/J19 -> -0.036615098 | K22: =(K19-K21)/K19 -> -0.032570075 | ... O22: =(O19-O21)/O19 -> 0.050229047
B23: 完成率 | D23: =2-D21/D20 -> 1 | E23: =2-E21/E20 -> 1 | F23: =2-F21/F20 -> 1 | G23: =2-G21/G20 -> 1 | H23: =2-H21/H20 -> 1 | I23: =2-I21/I20 -> 1 | J23: =2-J21/J20 -> 1 | K23: 0.06 | L23: =2-L21/L20 -> 1 | M23: =2-M21/M20 -> 1 | N23: =2-N21/N20 -> 1 | O23: =2-O21/O20 -> 1 | P23: =2-P21/P20 -> 1
B24: 单台 | C24: 同期 | D24: 29.694717 | E24: 27.682021 | F24: 29.102664 | G24: 31.122967 | H24: 23.033408 | I24: 30.245796 | J24: 31.123389 | K24: 66.79137 | L24: 34.287464 | M24: 34.79144 | N24: 37.649627 | O24: 48.840682 | P24: 33.260307
C25: 目标 | D25: 40.044992 | E25: 37.996493 | F25: 32.697817 | G25: 28.580161 | H25: 32.622575 | I25: 27.648112 | J25: 26.507382 | K25: 34.668329 | L25: 22.833595 | M25: 28.518712 | N25: 30.947958 | O25: 33.592314 | P25: 30.719784
C26: 25年 | D26: 34.955495 | E26: 32.791031 | F26: 32.155654 | G26: 25.907081 | H26: 30.165326 | I26: 36.527791 | J26: 30.44504 | K26: 36.62142 | L26: 13.628744 | M26: 20.771015 | N26: 23.458034 | O26: 21.050359 | P26: 27.543973
B27: 当月单台完成率 | D27: =2-D26/D25 -> 1.1270945 | E27: =2-E26/E25 -> 1.1369985 | F27: =2-F26/F25 -> 1.016581 | G27: =2-G26/G25 -> 1.0935292 | H27: =2-H26/H25 -> 1.0753236 | I27: =2-I26/I25 -> 0.67883237 | J27: =2-J26/J25 -> 0.8514505 | K27: =2-K26/K25 -> 0.94366353 | ... P27: =2-P26/P25 -> 1.10338
B28: 目标同期优化率 | D28: =D25/D24-1 -> 0.34855609 | E28: =E25/E24-1 -> 0.37260549 | F28: =F25/F24-1 -> 0.12353347 | G28: =G25/G24-1 -> -0.081701912 | H28: =H25/H24-1 -> 0.41631559 | I28: =I25/I24-1 -> -0.085885797 | J28: =J25/J24-1 -> -0.14831311 | K28: =K25/K24-1 -> -0.48094597 | ... O28: =O25/O24-1 -> -0.31220629
B29: 当月单台同期优化率 | D29: =(D24-D26)/D24 -> -0.17716208 | E29: =(E24-E26)/E24 -> -0.18456058 | F29: =(F24-F26)/F24 -> -0.10490414 | G29: =(G24-G26)/G24 -> 0.1675896 | H29: =(H24-H26)/H24 -> -0.30963362 | I29: =(I24-I26)/I24 -> -0.2076981 | J29: =(J24-J26)/J24 -> 0.021795455 | K29: =(K24-K26)/K24 -> 0.4517043 | ... P29: =(P24-P26)/P24 -> 0.17186654
B30: 当月费用额
B31: 单台（累计） | C31: 同期 | D31: =D40/D59*1000 -> 29.694717 | E31: =E40/E59*1000 -> 28.57184 | F31: =F40/F59*1000 -> 28.765671 | G31: =G40/G59*1000 -> 29.379754 | H31: =H40/H59*1000 -> 27.679999 | I31: =I40/I59*1000 -> 28.12694 | J31: =J40/J59*1000 -> 28.593526 | K31: =K40/K59*1000 -> 31.118641 | ... P31: =P40/P59*1000 -> 33.260307
C32: 目标 | D32: =D41/D60*1000 -> 40.544617 | E32: =E41/E60*1000 -> 79.658846 | F32: =F41/F60*1000 -> 94.425972 | G32: =G41/G60*1000 -> 115.15805 | H32: =H41/H60*1000 -> 164.17325 | I32: =I41/I60*1000 -> 176.23716 | J32: =J41/J60*1000 -> 204.36599 | K32: =K41/K60*1000 -> 300.0071 | ... P32: =P41/P60*1000 -> 30.470192
C33: 25年 | D33: =D42/D61*1000 -> 39.554295 | E33: =E42/E61*1000 -> 75.173442 | F33: =F42/F61*1000 -> 103.28811 | G33: =G42/G61*1000 -> 126.51068 | H33: =H42/H61*1000 -> 167.7567 | I33: =I42/I61*1000 -> 252.85709 | J33: =J42/J61*1000 -> 279.54817 | K33: =K42/K61*1000 -> 413.32275 | ... P33: =P42/P61*1000 -> 32.080891
B34: 累计单台完成率 | D34: =2-D33/D32 -> 1.0244255 | E34: =2-E33/E32 -> 1.0563077 | F34: =2-F33/F32 -> 0.90614726 | G34: =2-G33/G32 -> 0.90141703 | H34: =2-H33/H32 -> 0.97817279 | I34: =2-I33/I32 -> 0.56524526 | J34: =2-J33/J32 -> 0.63211992 | K34: =2-K33/K32 -> 0.62229011 | ... O34: =2-O33/O32 -> 0.82757831 | P34: =O34 -> 0.82757831
B35: 累计单台同期优化率 | D35: =(D31-D33)/D31 -> -0.33203136 | E35: =(E31-E33)/E31 -> -1.6310326 | F35: =(F31-F33)/F31 -> -2.5906727 | G35: =(G31-G33)/G31 -> -3.3060495 | H35: =(H31-H33)/H31 -> -5.0605745 | I35: =(I31-I33)/I31 -> -7.9898543 | J35: =(J31-J33)/J31 -> -8.7766246 | K35: =(K31-K33)/K31 -> -12.282159 | ... O35: =(O31-O33)/O31 -> -12.37638 | P35: =O35 -> -12.37638
B36: 累计费用额 | D36: =D42 -> 3152.9519 | E36: =E42 -> 6172.1155 | F36: =F42 -> 9570.3663 | G36: =G42 -> 12484.959 | H36: =H42 -> 15660.591 | I36: =I42 -> 18987.545 | J36: =J42 -> 21748.568 | K36: =K42 -> 24308.338 | ... O36: =O42 -> 33614.165
B37: 费用金额 | C37: 同期 | D37: 2593.4475 | E37: 3050.8909 | F37: 3306.8193 | G37: 3411.6374 | H37: 3545.5095 | I37: 3666.6677 | J37: 3994.8426 | K37: 3897.2096 | L37: 3768.4323 | M37: 4039.4601 | N37: 3990.0321 | O37: 3556.4319 | P37: 42821.381
C38: 目标 | D38: 3085.8508 | E38: 2924.0109 | F38: 3243.6004 | G38: 3113.4765 | H38: 3114.5993 | I38: 2879.0254 | J38: 2712.4316 | K38: 2722.6683 | L38: 2938.9074 | M38: 2864.1988 | N38: 2851.7672 | O38: 2848.0531 | P38: 35298.59
C39: 25年 | D39: 3152.9519 | E39: 3019.1635 | F39: 3398.2508 | G39: 2914.5928 | H39: 3175.6318 | I39: 3326.954 | J39: 2761.0229 | K39: 2559.7697 | L39: 1617.1885 | M39: 2702.8444 | N39: 2999.4201 | O39: 1986.374 | P39: 33614.307
B40: 费用金额（累计） | C40: 同期 | D40: =D37 -> 2593.4475 | E40: =D40+E37 -> 5644.3384 | F40: =E40+F37 -> 8951.1577 | G40: =F40+G37 -> 12362.795 | H40: =G40+H37 -> 15908.305 | I40: =H40+I37 -> 19574.972 | J40: =I40+J37 -> 23569.815 | K40: =J40+K37 -> 27467.024 | L40: =K40+L37 -> 31235.457 | ... O40: =N40+O37 -> 42821.381 | P40: =O40 -> 42821.381
...

Sheet 25年厨电费用指标到月测算汇总表
B1: 土耳其厨电费用指标统计
A3: 费 | B3: 序号 | C3: / | D3: 1月份 | E3: 2月份 | F3: 3月份 | G3: 4月份 | H3: 5月份 | I3: 6月份 | J3: 7月份 | K3: 8月份 | L3: 9月份 | M3: 10月份 | N3: 11月份 | O3: 12月份 | P3: 年度
B4: 费率 | C4: 销售收入（25年预测） | D4: 11387.793 | E4: 11383.957 | F4: 11384.182 | G4: 10843.261 | H4: 8301.8079 | I4: 12020.11 | J4: 9489.0377 | K4: 8834.8314 | L4: 12125.496 | M4: 10955.642 | N4: 11601.048 | O4: 9179.1981 | P4: 127506.36
C5: 销售收入（25年实际） | D5: 11599.19 | E5: 10318.459 | F5: 10279.816 | G5: 10804.991 | H5: 11868.184 | I5: 6637.8974 | J5: 9550.8211 | K5: 7188.5794 | L5: 5817.7726 | M5: 5854.6235 | N5: 7485.28 | O5: 8923.716 | P5: 106138.64
C6: 单价（同期） | D6: 238.80897 | E6: 224.15352 | F6: 221.84897 | G6: 218.88846 | H6: 220.99255 | I6: 223.76947 | J6: 228.17739 | K6: 224.80468 | L6: 205.80772 | M6: 223.36513 | N6: 220 | O6: 212 | P6: 222
C7: 单价（实际） | D7: 225.66619 | E7: 225.66619 | F7: 225.66619 | G7: 225.66619 | H7: 225.66619 | I7: 225.66619 | J7: 225.66619 | K7: 225.66619 | L7: 225.66619 | M7: 225.66619 | N7: 225.66619 | O7: 225.66619 | P7: 225.66619
C8: 制造费用（25年预测） | D8: 1838.2556 | E8: 1852.3924 | F8: 1893.0365 | G8: 1849.6673 | H8: 1928.8688 | I8: 1870.4326 | J8: 1859.2351 | K8: 1842.1673 | L8: 1948.6868 | M8: 1894.9246 | N8: 1861.9628 | O8: 1947.1505 | P8: 22586.78
C9: 制造费用（25年实际） | D9: 1702.2213 | E9: 1632.2334 | F9: 1827.8999 | G9: 1591.5968 | H9: 1866.987 | I9: 1737.9 | J9: 1637.4123 | K9: 1533.5455 | L9: 1597.8553 | M9: 1443.0898 | N9: 1758.5061 | O9: 1502.3028 | P9: 19831.55
C10: 同期 | D10: 0.14675346 | E10: 0.15818577 | F10: 0.17781446 | G10: 0.147302 | H10: 0.15731025 | I10: 0.26181483 | J10: 0.17144205 | K10: 0.21333082 | L10: 0.2746507 | M10: 0.24648721 | N10: 0.23492856 | O10: 0.16834947 | P10: 0.18684571
C11: 目标 | D11: 0.16142334 | E11: 0.16271955 | F11: 0.16628656 | G11: 0.17058221 | H11: 0.23234323 | I11: 0.15560861 | J11: 0.19593505 | K11: 0.20851188 | L11: 0.16070986 | M11: 0.17296335 | N11: 0.16049954 | O11: 0.21212643 | P11: 0.17714238
C12: 25年 | D12: =D8/D4 -> 0.16142334 | E12: =E8/E4 -> 0.16271955 | F12: =F8/F4 -> 0.16628656 | G12: =G8/G4 -> 0.17058221 | H12: =H8/H4 -> 0.23234323 | I12: =I8/I4 -> 0.15560861 | J12: =J8/J4 -> 0.19593505 | K12: =K8/K4 -> 0.20851188 | ... P12: =P8/P4 -> 0.17714238
B13: 降幅 | D13: =(D10-D12)/D10 -> -0.09996281 | E13: =(E10-E12)/E10 -> -0.028661121 | F13: =(F10-F12)/F10 -> 0.064831052 | G13: =(G10-G12)/G10 -> -0.15804409 | H13: =(H10-H12)/H10 -> -0.47697446 | I13: =(I10-I12)/I10 -> 0.40565396 | J13: =(J10-J12)/J10 -> -0.14286464 | K13: =(K10-K12)/K10 -> 0.022589029 | ... P13: =(P10-P12)/P10 -> 0.051932324
B14: 完成率 | D14: =2-D12/D11 -> 1 | E14: =2-E12/E11 -> 1 | F14: =2-F12/F11 -> 1 | G14: =2-G12/G11 -> 1 | H14: =2-H12/H11 -> 1 | I14: =2-I12/I11 -> 1 | J14: =2-J12/J11 -> 1 | K14: =2-K12/K11 -> 1 | ... O14: =2-O12/O11 -> 1
B15: 费率（累计） | C15: 累计销售收入（25年预测） | D15: =D4 -> 11387.793 | E15: =D15+E4 -> 22771.75 | F15: =E15+F4 -> 34155.932 | G15: =F15+G4 -> 44999.193 | H15: =G15+H4 -> 53301.001 | I15: =H15+I4 -> 65321.11 | J15: =I15+J4 -> 74810.148 | K15: =J15+K4 -> 83644.98 | L15: =K15+L4 -> 95770.476 | ... O15: =N15+O4 -> 127506.36 | P15: =O15 -> 127506.36
C16: 累计销售收入（25年实际） | D16: =D5 -> 11599.19 | E16: =D16+E5 -> 21917.65 | F16: =E16+F5 -> 32197.465 | G16: =F16+G5 -> 43002.456 | H16: =G16+H5 -> 54870.64 | I16: =H16+I5 -> 61508.538 | J16: =I16+J5 -> 71059.359 | K16: =J16+K5 -> 78247.938 | L16: =K16+L5 -> 84065.711 | ... O16: =N16+O5 -> 106329.33 | P16: =O16 -> 106329.33
C17: 累计制造费用（25年预测） | D17: =D8 -> 1838.2556 | E17: =D17+E8 -> 3690.648 | F17: =E17+F8 -> 5583.6845 | G17: =F17+G8 -> 7433.3518 | H17: =G17+H8 -> 9362.2206 | I17: =H17+I8 -> 11232.653 | J17: =I17+J8 -> 13091.888 | K17: =J17+K8 -> 14934.056 | L17: =K17+L8 -> 16882.742 | ... O17: =N17+O8 -> 22586.78 | P17: =O17 -> 22586.78
C18: 累计制造费用（25年实际） | D18: =D9 -> 1702.2213 | E18: =D18+E9 -> 3334.4547 | F18: =E18+F9 -> 5162.3545 | G18: =F18+G9 -> 6753.9513 | H18: =G18+H9 -> 8620.9383 | I18: =H18+I9 -> 10358.838 | J18: =I18+J9 -> 11996.251 | K18: =J18+K9 -> 13529.796 | L18: =K18+L9 -> 15127.651 | ... O18: =N18+O9 -> 19831.55 | P18: =O18 -> 19831.55
C19: 同期 | D19: =D18/D16 -> 0.14675346 | E19: =E18/E16 -> 0.1521356 | F19: =F18/F16 -> 0.16033419 | G19: =G18/G16 -> 0.15705966 | H19: =H18/H16 -> 0.15711386 | I19: =I18/I16 -> 0.16841302 | J19: =J18/J16 -> 0.16882014 | K19: =K18/K16 -> 0.1729093 | ... P19: =P18/P16 -> 0.18651063
C20: 目标 | D20: 0.16142334 | E20: 0.16207134 | F20: 0.16347627 | G20: 0.16518856 | H20: 0.17564812 | I20: 0.17196054 | J20: 0.1750015 | K20: 0.17854097 | L20: 0.17628337 | M20: 0.17594257 | N20: 0.1744285 | O20: 0.17714238 | P20: 0.17714238
C21: 25年 | D21: =D17/D15 -> 0.16142334 | E21: =E17/E15 -> 0.16207134 | F21: =F17/F15 -> 0.16347627 | G21: =G17/G15 -> 0.16518856 | H21: =H17/H15 -> 0.17564812 | I21: =I17/I15 -> 0.17196054 | J21: =J17/J15 -> 0.1750015 | K21: =K17/K15 -> 0.17854097 | ... P21: =P17/P15 -> 0.17714238
B22: 降幅 | D22: =(D19-D21)/D19 -> -0.09996281 | E22: =(E19-E21)/E19 -> -0.065308465 | F22: =(F19-F21)/F19 -> -0.019597081 | G22: =(G19-G21)/G19 -> -0.05175674 | H22: =(H19-H21)/H19 -> -0.11796704 | I22: =(I19-I21)/I19 -> -0.021064411 | J22: =(J19-J21)/J19 -> -0.036615098 | K22: =(K19-K21)/K19 -> -0.032570075 | ... O22: =(O19-O21)/O19 -> 0.050229047
B23: 完成率 | D23: =2-D21/D20 -> 1 | E23: =2-E21/E20 -> 1 | F23: =2-F21/F20 -> 1 | G23: =2-G21/G20 -> 1 | H23: =2-H21/H20 -> 1 | I23: =2-I21/I20 -> 1 | J23: =2-J21/J20 -> 1 | K23: 0.06 | L23: =2-L21/L20 -> 1 | M23: =2-M21/M20 -> 1 | N23: =2-N21/N20 -> 1 | O23: =2-O21/O20 -> 1 | P23: =2-P21/P20 -> 1
B24: 单台 | C24: 同期 | D24: 29.694717 | E24: 27.682021 | F24: 29.102664 | G24: 31.122967 | H24: 23.033408 | I24: 30.245796 | J24: 31.123389 | K24: 66.79137 | L24: 34.287464 | M24: 34.79144 | N24: 37.649627 | O24: 48.840682 | P24: 33.260307
C25: 目标 | D25: 40.044992 | E25: 37.996493 | F25: 32.697817 | G25: 28.580161 | H25: 32.622575 | I25: 27.648112 | J25: 26.507382 | K25: 34.668329 | L25: 22.833595 | M25: 28.518712 | N25: 30.947958 | O25: 33.592314 | P25: 30.719784
C26: 25年 | D26: 34.955495 | E26: 32.791031 | F26: 32.155654 | G26: 25.907081 | H26: 30.165326 | I26: 36.527791 | J26: 30.44504 | K26: 36.62142 | L26: 13.628744 | M26: 20.771015 | N26: 23.458034 | O26: 21.050359 | P26: 27.543973
B27: 当月单台完成率 | D27: =2-D26/D25 -> 1.1270945 | E27: =2-E26/E25 -> 1.1369985 | F27: =2-F26/F25 -> 1.016581 | G27: =2-G26/G25 -> 1.0935292 | H27: =2-H26/H25 -> 1.0753236 | I27: =2-I26/I25 -> 0.67883237 | J27: =2-J26/J25 -> 0.8514505 | K27: =2-K26/K25 -> 0.94366353 | ... P27: =2-P26/P25 -> 1.10338
B28: 目标同期优化率 | D28: =D25/D24-1 -> 0.34855609 | E28: =E25/E24-1 -> 0.37260549 | F28: =F25/F24-1 -> 0.12353347 | G28: =G25/G24-1 -> -0.081701912 | H28: =H25/H24-1 -> 0.41631559 | I28: =I25/I24-1 -> -0.085885797 | J28: =J25/J24-1 -> -0.14831311 | K28: =K25/K24-1 -> -0.48094597 | ... O28: =O25/O24-1 -> -0.31220629
B29: 当月单台同期优化率 | D29: =(D24-D26)/D24 -> -0.17716208 | E29: =(E24-E26)/E24 -> -0.18456058 | F29: =(F24-F26)/F24 -> -0.10490414 | G29: =(G24-G26)/G24 -> 0.1675896 | H29: =(H24-H26)/H24 -> -0.30963362 | I29: =(I24-I26)/I24 -> -0.2076981 | J29: =(J24-J26)/J24 -> 0.021795455 | K29: =(K24-K26)/K24 -> 0.4517043 | ... P29: =(P24-P26)/P24 -> 0.17186654
B30: 当月费用额
B31: 单台（累计） | C31: 同期
C32: 目标
C33: 25年
B34: 累计单台完成率 | D34: =2-D33/D32 -> #DIV/0! | E34: =2-E33/E32 -> #DIV/0! | F34: =2-F33/F32 -> #DIV/0! | G34: =2-G33/G32 -> #DIV/0! | H34: =2-H33/H32 -> #DIV/0! | I34: =2-I33/I32 -> #DIV/0! | J34: =2-J33/J32 -> #DIV/0! | K34: =2-K33/K32 -> #DIV/0! | ... O34: =2-O33/O32 -> #DIV/0! | P34: =O34 -> #DIV/0!
B35: 累计单台同期优化率 | D35: =(D31-D33)/D31 -> #DIV/0! | E35: =(E31-E33)/E31 -> #DIV/0! | F35: =(F31-F33)/F31 -> #DIV/0! | G35: =(G31-G33)/G31 -> #DIV/0! | H35: =(H31-H33)/H31 -> #DIV/0! | I35: =(I31-I33)/I31 -> #DIV/0! | J35: =(J31-J33)/J31 -> #DIV/0! | K35: =(K31-K33)/K31 -> #DIV/0! | ... O35: =(O31-O33)/O31 -> #DIV/0! | P35: =O35 -> #DIV/0!
B36: 累计费用额 | D36: =D42 -> 0 | E36: =E42 -> 0 | F36: =F42 -> 0 | G36: =G42 -> 0 | H36: =H42 -> 0 | I36: =I42 -> 0 | J36: =J42 -> 0 | K36: =K42 -> 0 | ... O36: =O42 -> 0
B37: 费用金额 | C37: 同期
C38: 目标
C39: 25年
B40: 费用金额（累计） | C40: 同期 | D40: =D37 -> 0 | E40: =D40+E37 -> 0 | F40: =E40+F37 -> 0 | G40: =F40+G37 -> 0 | H40: =G40+H37 -> 0 | I40: =H40+I37 -> 0 | J40: =I40+J37 -> 0 | K40: =J40+K37 -> 0 | L40: =K40+L37 -> 0 | ... O40: =N40+O37 -> 0 | P40: =O40 -> 0
C41: 目标 | D41: =D38 -> 0 | E41: =D41+E38 -> 0 | F41: =E41+F38 -> 0 | G41: =F41+G38 -> 0 | H41: =G41+H38 -> 0 | I41: =H41+I38 -> 0 | J41: =I41+J38 -> 0 | K41: =J41+K38 -> 0 | L41: =K41+L38 -> 0 | ... O41: =N41+O38 -> 0 | P41: =O41 -> 0
...

Sheet 厨电1月 
A1: 维度 | B1: KPI | C1: 25年实际 | D1: 26年预算 | E1: 26年实际 | F1: 预算差异 | G1: 实际比同期差异 | H1: 制造费差额 | I1: 差异原因
A2: 单 | B2: 产量 | C2: 79712 | D2: 116704 | E2: 97611 | F2: =E2-D2 -> -19093 | G2: =E2-C2 -> 17899 | H2: /
A3: 时 | B3: 工作天数 | C3: 20 | D3: 25 | E3: 20 | F3: =E3-D3 -> -5 | G3: =E3-C3 -> 0
A4: 人 | B4: 人工 | C4: 279 | D4: 286 | E4: 294 | F4: =E4-D4 -> 8 | G4: =E4-C4 -> 15
B5: 人工工资 | C5: =E48*1000/C4 -> 1950.3887 | D5: 2117.668 | E5: 2008.2043 | F5: =E5-D5 -> -109.46368 | G5: =E5-C5 -> 57.815646
B6: 间接人工 | C6: 170 | D6: 133 | E6: 127 | F6: =E6-D6 -> -6 | G6: =E6-C6 -> -43
B7: 间接人工工资 | C7: =E133*1000/C6 -> 2269.8431 | D7: =G133*1000/D6 -> 2373.6641 | E7: =I133*1000/E6 -> 2579.7282 | F7: =E7-D7 -> 206.06412 | G7: =E7-C7 -> 309.88507
B8: 白领人数 | C8: 58 | D8: 34 | E8: 31 | F8: =E8-D8 -> -3 | G8: =E8-C8 -> -27
B9: 白领人工工资 | C9: =E141*1000/C8 -> 4761.5476 | D9: =G141*1000/D8 -> 4538.8768 | E9: =I141*1000/E8 -> 5496.6681 | F9: =E9-D9 -> 957.79131 | G9: =E9-C9 -> 735.12048
A10: 效 | B10: UPPH | C10: =C2/C3/C4 -> 14.285305 | D10: =D2/D3/D4 -> 16.322238 | E10: =E2/E3/E4 -> 16.60051 | F10: =E10-D10 -> 0.27827244 | G10: =E10-C10 -> 2.3152055
A11: 费 | B11: 单台制造费 | C11: =SUM(C12:C24) -> 34.951093 | D11: =SUM(D12:D24) -> 22.524007 | E11: =SUM(E12:E24) -> 25.548148 | F11: =E11-D11 -> 3.024141 | G11: =E11-C11 -> -9.4029453 | H11: =G11*$E$2 -> -917830.89
B12: 折旧 | C12: 9.66 | D12: 6.9891943 | E12: 8.3836085 | F12: =E12-D12 -> 1.3944142 | G12: =E12-C12 -> -1.2763915 | H12: =G12*$E$2 -> -124589.85
B13: 运营费 | C13: 1.2015967 | D13: 0.83683288 | E13: 0.73678274 | F13: =E13-D13 -> -0.10005014 | G13: =E13-C13 -> -0.46481401 | H13: =G13*$E$2 -> -45370.96
B14: 存货跌价准备 | C14: 0.437119 | D14: 0.10710858 | E14: 0.12805934 | F14: =E14-D14 -> 0.020950755 | G14: =E14-C14 -> -0.30905967 | H14: =G14*$E$2 -> -30167.623
B15: 固定能源费 | C15: 0.59142187 | D15: 0.28191353 | E15: 0.35446702 | F15: =E15-D15 -> 0.072553489 | G15: =E15-C15 -> -0.23695485 | H15: =G15*$E$2 -> -23129.4
B16: 间接人工成本-辅助人员 | C16: 4.8408437 | D16: 2.7051114 | E16: 3.3564402 | F16: =E16-D16 -> 0.65132875 | G16: =E16-C16 -> -1.4844035 | H16: =G16*$E$2 -> -144894.11
B17: 固定人工-白领 | C17: 3.4645945 | D17: 1.3223352 | E17: 1.7456712 | F17: =E17-D17 -> 0.42333596 | G17: =E17-C17 -> -1.7189234 | H17: =G17*$E$2 -> -167785.83
B18: 半固定-班车/工作服 | C18: 2.7563919 | D18: 2.772445 | E18: 1.6519728 | F18: =E18-D18 -> -1.1204721 | G18: =E18-C18 -> -1.1044191 | H18: =G18*$E$2 -> -107803.45
B19: 直接人工 | C19: 6.8265561 | D19: 4.950356 | E19: 6.0486223 | F19: =E19-D19 -> 1.0982663 | G19: =E19-C19 -> -0.77793382 | H19: =G19*$E$2 -> -75934.898
B20: 可回收废料 | C20: 0.37641911 | D20: 0.4945089 | E20: 0.48670396 | F20: =E20-D20 -> -0.0078049397 | G20: =E20-C20 -> 0.11028485 | H20: =G20*$E$2 -> 10765.014
B21: 生产耗用品 | C21: -0.077533746 | D21: 0.35303919 | E21: 0.092804807 | F21: =E21-D21 -> -0.26023438 | G21: =E21-C21 -> 0.17033855 | H21: =G21*$E$2 -> 16626.917
B22: 废品回收 | C22: -0.45678217 | D22: -0.74328409 | E22: -0.67364313 | F22: =E22-D22 -> 0.069640954 | G22: =E22-C22 -> -0.21686097 | H22: =G22*$E$2 -> -21168.016
B23: 变动能源费 | C23: 0.3388057 | D23: 0.61137691 | E23: 0.39488972 | F23: =E23-D23 -> -0.2164872 | G23: =E23-C23 -> 0.056084015 | H23: =G23*$E$2 -> 5474.4168
B24: 园区分摊费用 | C24: 4.9916604 | D24: 1.843069 | E24: 2.8417683 | F24: =E24-D24 -> 0.99869936 | G24: =E24-C24 -> -2.149892 | H24: =G24*$E$2 -> -209853.11
B25: IT Expense-Internal Charge Out | C25: 3.1717704 | D25: 0.81376731 | E25: 0.96941113 | F25: 0.15564382 | G25: -2.2023592
B26: Association dues | C26: 0.1065285 | D26: 0.054769786 | E26: 0.050926842 | F26: -0.0038429439 | G26: -0.05560166
B27: G&A | C27: 1.7133615 | D27: 0.97453189 | E27: 1.8203277 | F27: 0.84579584 | G27: 0.10696625 | H27: Analysis required
A28: Type 类型 | B28: Code 编码 | C28: Description(EN) 描述 | D28: Description(CN) 描述 | E28: 单位千欧 | F28: 同期台数 | G28: 79712 | H28: 预算台数 | I28: 116704.08 | J28: 实际台数 | K28: 97611
E29: MFG 2025 同期制造费 | F29: CPU 2025 同期单台 | G29: Budget 2026 预算 | H29: Budget-CPU 2026 单台预算 | I29: ACT 2026 实际 | J29: ACT-CPU 2026 单台实际 | K29: CPU-Y0Y 单台同期 | L29: Budget-ACT VARIANCE 实际-预算 | M29: CPU-Y0Y Analysis 单台同期分析 | N29: Budget-ACT VARIANCE Analysis 预算实际分析
A30: 折旧 | B30: 6666110101 | C30: 6666110101 Depreciation of buildings | D30: 建筑物折旧 | E30: 73.06366 | F30: =E30*1000/$G$28 -> 0.91659549 | G30: 73.437796 | H30: 0.62926501 | I30: 75.41415 | J30: 0.77259889 | K30: =J30-F30 -> -0.14399661 | L30: 0.14333388
B31: 6666110106 | C31: 6666110106 Depreciation of R&D facilities | D31: 研发设施折旧 | E31: 0 | F31: =E31*1000/$G$28 -> 0 | G31: 0 | H31: 0 | I31: 0 | J31: 0 | K31: =J31-F31 -> 0 | L31: 0
B32: 6666110107 | C32: 6666110107 Depreciation of mold | D32: 模具折旧 | E32: 211.90984 | F32: =E32*1000/$G$28 -> 2.6584434 | G32: 204.71583 | H32: 1.7541446 | I32: 204.24196 | J32: 2.0924072 | K32: =J32-F32 -> -0.56603619 | L32: 0.33826263
B33: 6666110110 | C33: 6666110110 Depreciation-Plant & Machinery | D33: 6666110110 折旧-厂房及机械 | E33: 407.33455 | F33: =E33*1000/$G$28 -> 5.1100782 | G33: 446.50044 | H33: 3.8259196 | I33: 447.68976 | J33: 4.5864683 | K33: =J33-F33 -> -0.52360983 | L33: 0.76054872 | N33: 单台上涨0.76，费用持平
B34: 6666110112 | C34: 6666110112 Depreciation of Furniture & Fixture | D34: 6666110112 家具及装置折旧 | E34: 36.9678 | F34: =E34*1000/$G$28 -> 0.46376706 | G34: 58.855828 | H34: 0.50431679 | I34: 58.82951 | J34: 0.60269345 | K34: =J34-F34 -> 0.13892639 | L34: 0.098376658
B35: 6666110204 | C35: 6666110204 Amortization of license, trademarks and | D35: 6666110204 许可证、商标及摊销 | E35: 2.81415 | F35: =E35*1000/$G$28 -> 0.035303969 | G35: 32.15703 | H35: 0.27554332 | I35: 2.81415 | J35: 0.028830255 | K35: =J35-F35 -> -0.0064737145 | L35: -0.24671306
B36: 6666110207 | C36: 6666110207 Amortization of Software | D36: 6666110207 软件摊销 | E36: 35.04763 | F36: =E36*1000/$G$28 -> 0.43967822 | G36: 0 | H36: 0 | I36: 26.11824 | J36: 0.26757476 | K36: =J36-F36 -> -0.17210346 | L36: 0.26757476
B37: 6666110506 | C37: 6666110506 Amortization-Leasehold Improvement | D37: 6666110506 租赁改良摊销 | E37: 3.15121 | F37: =E37*1000/$G$28 -> 0.039532442 | G37: 0 | H37: 0 | I37: 3.08533 | J37: 0.031608425 | K37: =J37-F37 -> -0.0079240165 | L37: 0.031608425
B38: 6666110206 | C38: 6666110206 Amortization of Patents | D38: 6666110206 专利摊销 | E38: 0.07998 | F38: =E38*1000/$G$28 -> 0.0010033621 | G38: 0 | H38: 0 | I38: 0.13931 | J38: 0.0014271957 | K38: =J38-F38 -> 0.0004238336 | L38: 0.0014271957
B39: FIX | C39: * CS_Depreciation | D39: * CS_折旧 | E39: =SUM(E30:E38) -> 770.36882 | F39: =SUM(F30:F38) -> 9.6644021 | G39: 815.66693 | H39: 6.9891893 | I39: 818.33241 | J39: 8.3836085 | K39: =J39-F39 -> -1.2807936 | L39: 1.3944192
A40: 直接人工 | B40: 5001010205 | C40: 5001010205 Unemployment Insurance -blue collar-Dire | D40: 5001010205 失业保险-蓝领-直接 | E40: 8.97535 | F40: 0.11259723 | G40: 9.3776031 | H40: 0.080353684 | I40: 9.61211 | J40: 0.098473635 | K40: =J40-F40 -> -0.01412359 | L40: 0.018119951
...

Sheet 厨电2月 
A1: 总结： 2月同期36.8欧元/台，实际单台费用22.1元/台，较同期↓39.8%；降费155.7万欧 变动： 直接人工离职补偿30人费用合计，单台影响0.94欧 福利费用差异11.2万欧，为6.1万欧工会福利费谈判后上涨，其中5.1万欧为释放预提
A2: 维度 | B2: KPI | C2: 25年实际 | D2: 26年预算 | E2: 26年实际 | F2: 预算差异 | G2: 实际比同期差异 | H2: 制造费差额 | I2: 差异原因
A3: 单 | B3: 产量 | C3: 79712 | D3: 116204 | E3: 106294 | F3: =E3-D3 -> -9910 | G3: =E3-C3 -> 26582 | H3: / | J3: =(E3-D3)/D3 -> -0.085281057
A4: 时 | B4: 工作天数 | C4: 20 | D4: 20 | E4: 20 | F4: =E4-D4 -> 0 | G4: =E4-C4 -> 0
A5: 人 | B5: 直接人工 | C5: 296 | D5: 317 | E5: 294 | F5: =E5-D5 -> -23 | G5: =E5-C5 -> -2
B6: 人工工资 | C6: =F49*1000/C5 -> 1584.5274 | D6: =H49*1000/D5 -> 2122.1951 | E6: =618/E5*1000 -> 2102.0408 | F6: =E6-D6 -> -20.154298 | G6: =E6-C6 -> 517.51342
B7: 间接人工 | C7: 181 | D7: 136 | E7: 127 | F7: =E7-D7 -> -9 | G7: =E7-C7 -> -54
B8: 间接人工工资 | C8: =F134*1000/C7 -> 1979.0352 | D8: =H134*1000/D7 -> 2493.3963 | E8: =J134*1000/E7 -> 2437.8975 | F8: =E8-D8 -> -55.498823 | G8: =E8-C8 -> 458.86229
B9: 白领人数 | C9: 58 | D9: 34 | E9: 31 | F9: =E9-D9 -> -3 | G9: =E9-C9 -> -27
B10: 白领人工工资 | C10: =F142*1000/C9 -> 3333.6203 | D10: =H142*1000/D9 -> 4782.8924 | E10: =J142*1000/E9 -> 5013.6442 | F10: =E10-D10 -> 230.75179 | G10: =E10-C10 -> 1680.0238
A11: 效 | B11: UPPH | C11: =C3/C4/C5 -> 13.464865 | D11: =D3/D4/D5 -> 18.328707 | E11: =E3/E4/E5 -> 18.077211 | F11: =E11-D11 -> -0.25149574 | G11: =E11-C11 -> 4.612346
A12: 费 | B12: 单台制造费 | C12: =SUM(C13:C25) -> 32.790782 | D12: =SUM(D13:D25) -> 22.807982 | E12: =SUM(E13:E25) -> 22.115933 | F12: =E12-D12 -> -0.69204871 | G12: =E12-C12 -> -10.674849 | H12: =G12*E3 -> -1134672.4
B13: 折旧 | C13: 9.03 | D13: 6.7092041 | E13: 5.7670235 | F13: =E13-D13 -> -0.94218056 | G13: =E13-C13 -> -3.2629765 | H13: =G13*$E$3 -> -346834.82
B14: 运营费 | C14: 1.3241945 | D14: 0.9895902 | E14: 0.95019474 | F14: =E14-D14 -> -0.039395454 | G14: =E14-C14 -> -0.37399976 | H14: =G14*$E$3 -> -39753.931
B15: 存货跌价准备 | C15: 0.35143755 | D15: 0.10756945 | E15: 0 | F15: =E15-D15 -> -0.10756945 | G15: =E15-C15 -> -0.35143755 | H15: =G15*$E$3 -> -37355.703
B16: 固定能源费 | C16: 0.4284247 | D16: 0.28057364 | E16: 0.25401246 | F16: =E16-D16 -> -0.026561182 | G16: =E16-C16 -> -0.17441224 | H16: =G16*$E$3 -> -18538.975
B17: 间接人工成本-辅助人员 | C17: 4.3627717 | D17: 2.9181603 | E17: 2.9127983 | F17: =E17-D17 -> -0.0053620045 | G17: =E17-C17 -> -1.4499734 | H17: =G17*$E$3 -> -154123.47
B18: 固定人工-白领 | C18: 2.3549112 | D18: 1.3994212 | E18: 1.4621989 | F18: =E18-D18 -> 0.062777697 | G18: =E18-C18 -> -0.89271225 | H18: =G18*$E$3 -> -94889.956
B19: 半固定-班车/工作服 | C19: 2.6847029 | D19: 1.8786839 | E19: 2.8491931 | F19: =E19-D19 -> 0.97050922 | G19: =E19-C19 -> 0.16449021 | H19: =G19*$E$3 -> 17484.322
B20: 直接人工 | C20: 5.7124427 | D20: 5.7892659 | E20: 5.8140629 | F20: =E20-D20 -> 0.024797012 | G20: =E20-C20 -> 0.10162016 | H20: =G20*$E$3 -> 10801.613
B21: 可回收废料 | C21: 0.39080799 | D21: 0.60667009 | E21: 0.49861704 | F21: =E21-D21 -> -0.10805304 | G21: =E21-C21 -> 0.10780905 | H21: =G21*$E$3 -> 11459.456
B22: 生产耗用品 | C22: -0.066185738 | D22: 0.27739662 | E22: 0.25401246 | F22: =E22-D22 -> -0.023384168 | G22: =E22-C22 -> 0.32019819 | H22: =G22*$E$3 -> 34035.147
B23: 废品回收 | C23: -0.46684611 | D23: -0.7495329 | E23: -0.80907671 | F23: =E23-D23 -> -0.05954381 | G23: =E23-C23 -> -0.3422306 | H23: =G23*$E$3 -> -36377.059
B24: 变动能源费 | C24: 0.50243676 | D24: 0.74894869 | E24: 0.43150733 | F24: =E24-D24 -> -0.31744137 | G24: =E24-C24 -> -0.070929429 | H24: =G24*$E$3 -> -7539.3727
B25: 园区分摊费用 | C25: 6.1816841 | D25: 1.8520307 | E25: 1.7313891 | F25: =E25-D25 -> -0.12064161 | G25: =E25-C25 -> -4.450295 | H25: =G25*$E$3 -> -473039.66
B26: IT Expense-Internal Charge Out | C26: 3.0793272 | D26: 0.81726877 | E26: 0.89547698 | F26: =E26-D26 -> 0.07820821 | G26: =E26-C26 -> -2.1838502
B27: Association dues | C27: 0.10600402 | D27: 0.055005448 | E27: 0.022996406 | F27: -0.032009042 | G27: -0.083007613
B28: G&A | C28: 2.9963528 | D28: 0.97975646 | E28: 0.81291569 | F28: -0.16684078 | G28: -2.1834372
B29: Type 类型 | C29: Code 编码 | D29: Description(EN) 描述 | E29: Description(CN) 描述 | F29: 单位千欧 | G29: 同期台数 | H29: 82105 | I29: 预算台数 | J29: 116204 | K29: 实际台数 | L29: 106294
F30: MFG 2025 同期制造费 | G30: CPU 2025 同期单台 | H30: Budget 2026 预算 | I30: Budget-CPU 2026 单台预算 | J30: ACT 2026 实际 | K30: ACT-CPU 2026 单台实际 | L30: CPU-Y0Y 单台同期 | M30: Budget-ACT VARIANCE 预算同比 | N30: CPU-Y0Y Analysis 单台同期分析 | O30: Budget-ACT VARIANCE Analysis 预算实际分析
B31: 折旧 | C31: 6666110101 | D31: 6666110101 Depreciation of buildings | E31: 建筑物折旧 | F31: 66.46563 | G31: =F31*1000/$H$29 -> 0.80951988 | H31: 67.063126 | I31: 0.57711547 | J31: 61.69588 | K31: 0.58042674 | L31: =K31-G31 -> -0.22909314 | M31: 0.0033112752
C32: 6666110106 | D32: 6666110106 Depreciation of R&D facilities | E32: 研发设施折旧 | F32: 0 | G32: =F32*1000/$H$29 -> 0 | H32: 0 | I32: 0 | J32: 0 | K32: 0 | L32: =K32-G32 -> 0 | M32: 0
C33: 6666110107 | D33: 6666110107 Depreciation of mold | E33: 模具折旧 | F33: 205.33288 | G33: =F33*1000/$H$29 -> 2.5008572 | H33: 200.43546 | I33: 1.7248586 | J33: 138.62046 | K33: 1.3041231 | L33: =K33-G33 -> -1.1967341 | M33: -0.42073547
C34: 6666110110 | D34: 6666110110 Depreciation-Plant & Machinery | E34: 6666110110 折旧-厂房及机械 | F34: 392.86982 | G34: =F34*1000/$H$29 -> 4.7849683 | H34: 423.32463 | I34: 3.6429437 | J34: 331.39545 | K34: 3.1177249 | L34: =K34-G34 -> -1.6672434 | M34: -0.52521884 | O34: 单台下降0.53，费用下降9万欧
C35: 6666110112 | D35: 6666110112 Depreciation of Furniture & Fixture | E35: 6666110112 家具及装置折旧 | F35: 37.32028 | G35: =F35*1000/$H$29 -> 0.45454333 | H35: 57.029978 | I35: 0.49077466 | J35: 53.90234 | K35: 0.50710614 | L35: =K35-G35 -> 0.052562811 | M35: 0.016331481
C36: 6666110204 | D36: 6666110204 Amortization of license, trademarks and | E36: 6666110204 许可证、商标及摊销 | F36: 2.81412 | G36: =F36*1000/$H$29 -> 0.034274648 | H36: 31.78315 | I36: 0.27351167 | J36: 2.81412 | K36: 0.026474872 | L36: =K36-G36 -> -0.0077997767 | M36: -0.2470368
