Workbook

Sheet Monthly Scorecard Haier
B1: CK
B2: Operational KPIs | D2: Unit | E2: Data | F2: J | G2: F | H2: M | I2: A | J2: M | K2: J | L2: J | M2: A | N2: S | O2: O | P2: N | Q2: D
B3: EEH&S | C3: Incident rate (incl.Recordable) | D3: Number | E3: YTD 2025 | F3: 0 | G3: 0 | H3: 7.78 | I3: 5.54 | J3: 4.25 | K3: 3.32 | L3: 5.38 | M3: 7.04 | N3: 11.74 | O3: 10.32 | P3: 9.04 | Q3: 8.18
E4: YTD 2026 | F4: ='EEH&S'!$B$3 -> 0 | G4: ='EEH&S'!$B$4 -> 6.37 | H4: ='EEH&S'!$B$5 -> 4.2 | I4: ='EEH&S'!$B$6 -> 0 | J4: ='EEH&S'!$B$7 -> 0 | K4: ='EEH&S'!$B$8 -> 0 | L4: ='EEH&S'!$B$9 -> 0 | M4: ='EEH&S'!$B$10 -> 0 | N4: ='EEH&S'!$B$11 -> 0 | O4: ='EEH&S'!$B$12 -> 0 | P4: ='EEH&S'!$B$13 -> 0 | Q4: ='EEH&S'!$B$14 -> 0
E5: Target 2026 | F5: ='EEH&S tgt'!$B$3 -> 0 | G5: ='EEH&S tgt'!$B$4 -> 6.01 | H5: ='EEH&S tgt'!$B$5 -> 3.96 | I5: ='EEH&S tgt'!$B$6 -> 3.03 | J5: ='EEH&S tgt'!$B$7 -> 2.62 | K5: ='EEH&S tgt'!$B$8 -> 4.31 | L5: ='EEH&S tgt'!$B$9 -> 3.8 | M5: ='EEH&S tgt'!$B$10 -> 3.41 | N5: ='EEH&S tgt'!$B$11 -> 4.44 | O5: ='EEH&S tgt'!$B$12 -> 3.96 | P5: ='EEH&S tgt'!$B$13 -> 3.51 | Q5: ='EEH&S tgt'!$B$14 -> 3.27
C6: Accidents | D6: Number | E6: YTD 2025 | F6: 0 | G6: 0 | H6: 0 | I6: 0 | J6: 0 | K6: 0 | L6: 0 | M6: 0 | N6: 0 | O6: 0 | P6: 0 | Q6: 0
E7: YTD 2026 | F7: ='EEH&S'!C3 -> 0 | G7: ='EEH&S'!C4 -> 0 | H7: ='EEH&S'!C5 -> 0 | I7: ='EEH&S'!C6 -> 0 | J7: ='EEH&S'!C7 -> 0 | K7: ='EEH&S'!C8 -> 0 | L7: ='EEH&S'!C9 -> 0 | M7: ='EEH&S'!C10 -> 0 | N7: ='EEH&S'!C11 -> 0 | O7: ='EEH&S'!C12 -> 0 | P7: ='EEH&S'!C13 -> 0 | Q7: ='EEH&S'!C14 -> 0
E8: Target 2026 | F8: ='EEH&S tgt'!C3 -> 0 | G8: ='EEH&S tgt'!C4 -> 0 | H8: ='EEH&S tgt'!C5 -> 0 | I8: ='EEH&S tgt'!C6 -> 0 | J8: ='EEH&S tgt'!C7 -> 0 | K8: ='EEH&S tgt'!C8 -> 0 | L8: ='EEH&S tgt'!C9 -> 0 | M8: ='EEH&S tgt'!C10 -> 0 | N8: ='EEH&S tgt'!C11 -> 0 | O8: ='EEH&S tgt'!C12 -> 0 | P8: ='EEH&S tgt'!C13 -> 0 | Q8: ='EEH&S tgt'!C14 -> 0
C9: Energy Consumption | D9: KWh/Unit | E9: Actual 2025 | F9: 4.85 | G9: 4.8 | H9: 5.19 | I9: 4.78 | J9: 6.51 | K9: 6.16 | L9: 6.24 | M9: 6.9 | N9: 6.08 | O9: 5.09 | P9: 5.17 | Q9: 6.04
E10: YTD 2026 | F10: ='EEH&S'!$D$3 -> 5.29 | G10: ='EEH&S'!$D$4 -> 4.7 | H10: ='EEH&S'!$D$5 -> 4.94 | I10: ='EEH&S'!$D$6 -> 0 | J10: ='EEH&S'!$D$7 -> 0 | K10: ='EEH&S'!$D$8 -> 0 | L10: ='EEH&S'!$D$9 -> 0 | M10: ='EEH&S'!$D$10 -> 0 | N10: ='EEH&S'!$D$11 -> 0 | O10: ='EEH&S'!$D$12 -> 0 | P10: ='EEH&S'!$D$13 -> 0 | Q10: ='EEH&S'!$D$14 -> 0
E11: Target 2026 | F11: ='EEH&S tgt'!$D$3 -> 6.4 | G11: ='EEH&S tgt'!$D$4 -> 6.79 | H11: ='EEH&S tgt'!$D$5 -> 7.02 | I11: ='EEH&S tgt'!$D$6 -> 6.95 | J11: ='EEH&S tgt'!$D$7 -> 8.04 | K11: ='EEH&S tgt'!$D$8 -> 7.19 | L11: ='EEH&S tgt'!$D$9 -> 8.47 | M11: ='EEH&S tgt'!$D$10 -> 7.97 | N11: ='EEH&S tgt'!$D$11 -> 7.17 | O11: ='EEH&S tgt'!$D$12 -> 6.98 | P11: ='EEH&S tgt'!$D$13 -> 6.78 | Q11: ='EEH&S tgt'!$D$14 -> 7.48
C12: GHG Emissions | D12: KgCO2/unit | E12: Actual 2025 | F12: 2.31 | G12: 1.93 | H12: 2.65 | I12: 2.1 | J12: 2.47 | K12: 2.33 | L12: 2.36 | M12: 2.29 | N12: 2.16 | O12: 2.08 | P12: 2.23 | Q12: 2.56
E13: YTD 2026 | F13: ='EEH&S'!$E$3 -> 2.48 | G13: ='EEH&S'!$E$4 -> 2.07 | H13: ='EEH&S'!$E$5 -> 2.14 | I13: ='EEH&S'!$E$6 -> 0 | J13: ='EEH&S'!$E$7 -> 0 | K13: ='EEH&S'!$E$8 -> 0 | L13: ='EEH&S'!$E$9 -> 0 | M13: ='EEH&S'!$E$10 -> 0 | N13: ='EEH&S'!$E$11 -> 0 | O13: ='EEH&S'!$E$12 -> 0 | P13: ='EEH&S'!$E$13 -> 0 | Q13: ='EEH&S'!$E$14 -> 0
E14: Target 2026 | F14: ='EEH&S tgt'!$E$3 -> 2.6537 | G14: ='EEH&S tgt'!$E$4 -> 3.0551 | H14: ='EEH&S tgt'!$E$5 -> 3.0105 | I14: ='EEH&S tgt'!$E$6 -> 2.8767 | J14: ='EEH&S tgt'!$E$7 -> 2.9882 | K14: ='EEH&S tgt'!$E$8 -> 2.6983 | L14: ='EEH&S tgt'!$E$9 -> 2.7652 | M14: ='EEH&S tgt'!$E$10 -> 2.7875 | N14: ='EEH&S tgt'!$E$11 -> 2.6537 | O14: ='EEH&S tgt'!$E$12 -> 2.9436 | P14: ='EEH&S tgt'!$E$13 -> 2.8767 | Q14: ='EEH&S tgt'!$E$14 -> 3.2112
C15: Natural Gas Consumption | D15: Cubic meters/Unit | E15: Actual 2025 | F15: 1.05 | G15: 0.88 | H15: 1.2 | I15: 0.96 | J15: 1.12 | K15: 1.06 | L15: 1.07 | M15: 1.04 | N15: 0.98 | O15: 0.95 | P15: 1.02 | Q15: 1.16
E16: YTD 2026 | F16: ='EEH&S'!$F$3 -> 1.11 | G16: ='EEH&S'!$F$4 -> 0.93 | H16: ='EEH&S'!$F$5 -> 0.96 | I16: ='EEH&S'!$F$6 -> 0 | J16: ='EEH&S'!$F$7 -> 0 | K16: ='EEH&S'!$F$8 -> 0 | L16: ='EEH&S'!$F$9 -> 0 | M16: ='EEH&S'!$F$10 -> 0 | N16: ='EEH&S'!$F$11 -> 0 | O16: ='EEH&S'!$F$12 -> 0 | P16: ='EEH&S'!$F$13 -> 0 | Q16: ='EEH&S'!$F$14 -> 0
E17: Target 2026 | F17: ='EEH&S tgt'!$F$3 -> 1.19 | G17: ='EEH&S tgt'!$F$4 -> 1.37 | H17: ='EEH&S tgt'!$F$5 -> 1.35 | I17: ='EEH&S tgt'!$F$6 -> 1.29 | J17: ='EEH&S tgt'!$F$7 -> 1.34 | K17: ='EEH&S tgt'!$F$8 -> 1.21 | L17: ='EEH&S tgt'!$F$9 -> 1.24 | M17: ='EEH&S tgt'!$F$10 -> 1.25 | N17: ='EEH&S tgt'!$F$11 -> 1.19 | O17: ='EEH&S tgt'!$F$12 -> 1.32 | P17: ='EEH&S tgt'!$F$13 -> 1.29 | Q17: ='EEH&S tgt'!$F$14 -> 1.44
C18: Total waste | D18: Kg/Unit | E18: Actual 2025 | F18: 2.74 | G18: 3.28 | H18: 6.21 | I18: 4.05 | J18: 4.46 | K18: 4.12 | L18: 4.4 | M18: 3.64 | N18: 3.6 | O18: 3.31 | P18: 3.41 | Q18: 4.03
E19: YTD 2026 | F19: ='EEH&S'!$G$3 -> 3.2 | G19: ='EEH&S'!$G$4 -> 3.22 | H19: ='EEH&S'!$G$5 -> 3.12 | I19: ='EEH&S'!$G$6 -> 0 | J19: ='EEH&S'!$G$7 -> 0 | K19: ='EEH&S'!$G$8 -> 0 | L19: ='EEH&S'!$G$9 -> 0 | M19: ='EEH&S'!$G$10 -> 0 | N19: ='EEH&S'!$G$11 -> 0 | O19: ='EEH&S'!$G$12 -> 0 | P19: ='EEH&S'!$G$13 -> 0 | Q19: ='EEH&S'!$G$14 -> 0
E20: Target 2026 | F20: ='EEH&S tgt'!$G$3 -> 4 | G20: ='EEH&S tgt'!$G$4 -> 4 | H20: ='EEH&S tgt'!$G$5 -> 4 | I20: ='EEH&S tgt'!$G$6 -> 4 | J20: ='EEH&S tgt'!$G$7 -> 4 | K20: ='EEH&S tgt'!$G$8 -> 4 | L20: ='EEH&S tgt'!$G$9 -> 4 | M20: ='EEH&S tgt'!$G$10 -> 4 | N20: ='EEH&S tgt'!$G$11 -> 4 | O20: ='EEH&S tgt'!$G$12 -> 4 | P20: ='EEH&S tgt'!$G$13 -> 4 | Q20: ='EEH&S tgt'!$G$14 -> 4
C21: Waste recycled | D21: % | E21: Actual 2025 | F21: 1 | G21: 1 | H21: 1 | I21: 1 | J21: 1 | K21: 1 | L21: 1 | M21: 1 | N21: 1 | O21: 1 | P21: 1 | Q21: 1
E22: YTD 2026 | F22: ='EEH&S'!$H$3 -> 1 | G22: ='EEH&S'!$H$4 -> 0.99 | H22: ='EEH&S'!$H$5 -> 1 | I22: ='EEH&S'!$H$6 -> 0 | J22: ='EEH&S'!$H$7 -> 0 | K22: ='EEH&S'!$H$8 -> 0 | L22: ='EEH&S'!$H$9 -> 0 | M22: ='EEH&S'!$H$10 -> 0 | N22: ='EEH&S'!$H$11 -> 0 | O22: ='EEH&S'!$H$12 -> 0 | P22: ='EEH&S'!$H$13 -> 0 | Q22: ='EEH&S'!$H$14 -> 0
E23: Target 2026 | F23: ='EEH&S tgt'!$H$3 -> 0.99 | G23: ='EEH&S tgt'!$H$4 -> 0.99 | H23: ='EEH&S tgt'!$H$5 -> 0.99 | I23: ='EEH&S tgt'!$H$6 -> 0.99 | J23: ='EEH&S tgt'!$H$7 -> 0.99 | K23: ='EEH&S tgt'!$H$8 -> 0.99 | L23: ='EEH&S tgt'!$H$9 -> 0.99 | M23: ='EEH&S tgt'!$H$10 -> 0.99 | N23: ='EEH&S tgt'!$H$11 -> 0.99 | O23: ='EEH&S tgt'!$H$12 -> 0.99 | P23: ='EEH&S tgt'!$H$13 -> 0.99 | Q23: ='EEH&S tgt'!$H$14 -> 0.99
C24: Compliance Ratio | D24: Number | E24: Actual 2025 | F24: 0 | G24: 0 | H24: 0 | I24: 0 | J24: 0 | K24: 0 | L24: 0 | M24: 0 | N24: 0 | O24: 0 | P24: 0 | Q24: 16.9
E25: Actual 2026 | F25: ='EEH&S'!$I$3 -> 0 | G25: ='EEH&S'!$I$4 -> 0 | H25: ='EEH&S'!$I$5 -> 0 | I25: ='EEH&S'!$I$6 -> 0 | J25: ='EEH&S'!$I$7 -> 0 | K25: ='EEH&S'!$I$8 -> 0 | L25: ='EEH&S'!$I$9 -> 0 | M25: ='EEH&S'!$I$10 -> 0 | N25: ='EEH&S'!$I$11 -> 0 | O25: ='EEH&S'!$I$12 -> 0 | P25: ='EEH&S'!$I$13 -> 0 | Q25: ='EEH&S'!$I$14 -> 0
E26: Target 2026 | F26: ='EEH&S tgt'!$I$3 -> 20 | G26: ='EEH&S tgt'!$I$4 -> 20 | H26: ='EEH&S tgt'!$I$5 -> 20 | I26: ='EEH&S tgt'!$I$6 -> 20 | J26: ='EEH&S tgt'!$I$7 -> 20 | K26: ='EEH&S tgt'!$I$8 -> 20 | L26: ='EEH&S tgt'!$I$9 -> 20 | M26: ='EEH&S tgt'!$I$10 -> 20 | N26: ='EEH&S tgt'!$I$11 -> 20 | O26: ='EEH&S tgt'!$I$12 -> 20 | P26: ='EEH&S tgt'!$I$13 -> 20 | Q26: ='EEH&S tgt'!$I$14 -> 20
B27: Quality | C27: EPQ (M-4) 12 MR - Ovens (Halino) | D27: % | E27: Actual 2025 | F27: 0.018 | G27: 0.019 | H27: 0.02 | I27: 0.019 | J27: 0.019 | K27: 0.02 | L27: 0 | M27: 0.017 | N27: 0.018 | O27: 0.019 | P27: 0.019
E28: Actual 2026 | F28: =Customer!$D$3 -> 0.021 | G28: =Customer!$D$4 -> 0.018 | H28: =Customer!$D$5 -> 0 | I28: =Customer!$D$6 -> 0 | J28: =Customer!$D$7 -> 0 | K28: =Customer!$D$8 -> 0 | L28: =Customer!$D$9 -> 0 | M28: =Customer!$D$10 -> 0 | N28: =Customer!$D$11 -> 0 | O28: =Customer!$D$12 -> 0 | P28: =Customer!$D$13 -> 0 | Q28: =Customer!$D$14 -> 0
E29: Target 2026 | F29: ='Customer tgt'!$D$3 -> 0.015 | G29: ='Customer tgt'!$D$4 -> 0.015 | H29: ='Customer tgt'!$D$5 -> 0.015 | I29: ='Customer tgt'!$D$6 -> 0.015 | J29: ='Customer tgt'!$D$7 -> 0.0145 | K29: ='Customer tgt'!$D$8 -> 0.0145 | L29: ='Customer tgt'!$D$9 -> 0.0145 | M29: ='Customer tgt'!$D$10 -> 0.0145 | N29: ='Customer tgt'!$D$11 -> 0.014 | O29: ='Customer tgt'!$D$12 -> 0.014 | P29: ='Customer tgt'!$D$13 -> 0.014 | Q29: ='Customer tgt'!$D$14 -> 0.014
C30: EPQ (M-4) 12 MR - Ovens-Titanium | D30: % | E30: Actual 2025
E31: Actual 2026 | F31: =Customer!$E$3 -> 0.098 | G31: =Customer!$E$4 -> 0.094 | H31: =Customer!$E$5 -> 0 | I31: =Customer!$E$6 -> 0 | J31: =Customer!$E$7 -> 0 | K31: =Customer!$E$8 -> 0 | L31: =Customer!$E$9 -> 0 | M31: =Customer!$E$10 -> 0 | N31: =Customer!$E$11 -> 0 | O31: =Customer!$E$12 -> 0 | P31: =Customer!$E$13 -> 0 | Q31: =Customer!$E$14 -> 0
E32: Target 2026 | F32: ='Customer tgt'!$E$3 -> 0.05 | G32: ='Customer tgt'!$E$4 -> 0.05 | H32: ='Customer tgt'!$E$5 -> 0.045 | I32: ='Customer tgt'!$E$6 -> 0.045 | J32: ='Customer tgt'!$E$7 -> 0.045 | K32: ='Customer tgt'!$E$8 -> 0.045 | L32: ='Customer tgt'!$E$9 -> 0.04 | M32: ='Customer tgt'!$E$10 -> 0.04 | N32: ='Customer tgt'!$E$11 -> 0.04 | O32: ='Customer tgt'!$E$12 -> 0.035 | P32: ='Customer tgt'!$E$13 -> 0.035 | Q32: ='Customer tgt'!$E$14 -> 0.035
C33: EPQ (M-4) 12 MR -Hobs | D33: % | E33: Actual 2025 | F33: 0.02 | G33: 0.022 | H33: 0.024 | I33: 0.025 | J33: 0.024 | K33: 0.025 | L33: 0 | M33: 0.024 | N33: 0.025 | O33: 0.026 | P33: 0.026
E34: Actual 2026 | F34: =Customer!$F$3 -> 0.027 | G34: =Customer!$F$4 -> 0.031 | H34: =Customer!$F$5 -> 0 | I34: =Customer!$F$6 -> 0 | J34: =Customer!$F$7 -> 0 | K34: =Customer!$F$8 -> 0 | L34: =Customer!$F$9 -> 0 | M34: =Customer!$F$10 -> 0 | N34: =Customer!$F$11 -> 0 | O34: =Customer!$F$12 -> 0 | P34: =Customer!$F$13 -> 0 | Q34: =Customer!$F$14 -> 0
E35: Target 2026 | F35: ='Customer tgt'!$F$3 -> 0.027 | G35: ='Customer tgt'!$F$4 -> 0.026 | H35: ='Customer tgt'!$F$5 -> 0.025 | I35: ='Customer tgt'!$F$6 -> 0.025 | J35: ='Customer tgt'!$F$7 -> 0.024 | K35: ='Customer tgt'!$F$8 -> 0.024 | L35: ='Customer tgt'!$F$9 -> 0.023 | M35: ='Customer tgt'!$F$10 -> 0.023 | N35: ='Customer tgt'!$F$11 -> 0.022 | O35: ='Customer tgt'!$F$12 -> 0.022 | P35: ='Customer tgt'!$F$13 -> 0.021 | Q35: ='Customer tgt'!$F$14 -> 0.021
C36: 1MIS - Ovens(Halino) | D36: ppm | E36: Actual 2025 | F36: 2793 | G36: 3231 | H36: 4219 | I36: 3988 | J36: 4078 | K36: 4495 | L36: 0 | M36: 4071 | N36: 3014
E37: Actual 2026 | F37: =Customer!$G$3 -> 2000 | G37: =Customer!$G$4 -> 2000 | H37: =Customer!$G$5 -> 2000 | I37: =Customer!$G$6 -> 0 | J37: =Customer!$G$7 -> 0 | K37: =Customer!$G$8 -> 0 | L37: =Customer!$G$9 -> 0 | M37: =Customer!$G$10 -> 0 | N37: =Customer!$G$11 -> 0 | O37: =Customer!$G$12 -> 0 | P37: =Customer!$G$13 -> 0 | Q37: =Customer!$G$14 -> 0
E38: Target 2026 | F38: ='Customer tgt'!$G$3 -> 2490 | G38: ='Customer tgt'!$G$4 -> 2490 | H38: ='Customer tgt'!$G$5 -> 2490 | I38: ='Customer tgt'!$G$6 -> 2490 | J38: ='Customer tgt'!$G$7 -> 2407 | K38: ='Customer tgt'!$G$8 -> 2407 | L38: ='Customer tgt'!$G$9 -> 2407 | M38: ='Customer tgt'!$G$10 -> 2407 | N38: ='Customer tgt'!$G$11 -> 2324 | O38: ='Customer tgt'!$G$12 -> 2324 | P38: ='Customer tgt'!$G$13 -> 2324 | Q38: ='Customer tgt'!$G$14 -> 2324
C39: 1MIS - Ovens-Titanium | D39: ppm | E39: Actual 2025
E40: Actual 2026 | F40: =Customer!$H$3 -> 14430 | G40: =Customer!$H$4 -> 14534 | H40: =Customer!$H$5 -> 0 | I40: =Customer!$H$6 -> 0 | J40: =Customer!$H$7 -> 0 | K40: =Customer!$H$8 -> 0 | L40: =Customer!$H$9 -> 0 | M40: =Customer!$H$10 -> 0 | N40: =Customer!$H$11 -> 0 | O40: =Customer!$H$12 -> 0 | P40: =Customer!$H$13 -> 0 | Q40: =Customer!$H$14 -> 0
...

Sheet EEH&S
A1: ReferenceMonth | B1: Incident Rate | C1: Accidents | D1: Energy Consumption | E1: GHG Emissions | F1: Natural Gas Consumption | G1: Total Waste | H1: Recycled Waste Percentage | I1: Compliance Ratio
B2: Number | C2: Number | D2: KWh/Unit | E2: kgCO2/Unit | F2: Cubic meters/Unit | G2: Kg/Unit | H2: % | I2: Number
A3: 46023 | B3: 0 | C3: 0 | D3: 5.29 | E3: 2.48 | F3: 1.11 | G3: 3.2 | H3: 1 | I3: 0
A4: 46054 | B4: 6.37 | C4: 0 | D4: 4.7 | E4: 2.07 | F4: 0.93 | G4: 3.22 | H4: 0.99 | I4: 0
A5: 46082 | B5: 4.2 | C5: 0 | D5: 4.94 | E5: 2.14 | F5: 0.96 | G5: 3.12 | H5: 1 | I5: 0
A6: 46113
A7: 46143
A8: 46174
A9: 46204
A10: 46235
A11: 46266
A12: 46296
A13: 46327
A14: 46357

Sheet EEH&S tgt
A1: ReferenceMonth | B1: Incident Rate | C1: Accidents | D1: Energy Consumption | E1: GHG Emissions | F1: Natural Gas Consumption | G1: Total Waste | H1: Waste Recycled | I1: Compliance Ratio
B2: Number | C2: Number | D2: KWh/Unit | E2: kgCO2/Unit | F2: Cubic meters/Unit | G2: Kg/Unit | H2: % | I2: Number
A3: 46023 | B3: 0 | C3: 0 | D3: 6.4 | E3: 2.6537 | F3: 1.19 | G3: 4 | H3: 0.99 | I3: 20
A4: 46054 | B4: 6.01 | C4: 0 | D4: 6.79 | E4: 3.0551 | F4: 1.37 | G4: 4 | H4: 0.99 | I4: 20
A5: 46082 | B5: 3.96 | C5: 0 | D5: 7.02 | E5: 3.0105 | F5: 1.35 | G5: 4 | H5: 0.99 | I5: 20
A6: 46113 | B6: 3.03 | C6: 0 | D6: 6.95 | E6: 2.8767 | F6: 1.29 | G6: 4 | H6: 0.99 | I6: 20
A7: 46143 | B7: 2.62 | C7: 0 | D7: 8.04 | E7: 2.9882 | F7: 1.34 | G7: 4 | H7: 0.99 | I7: 20
A8: 46174 | B8: 4.31 | C8: 0 | D8: 7.19 | E8: 2.6983 | F8: 1.21 | G8: 4 | H8: 0.99 | I8: 20
A9: 46204 | B9: 3.8 | C9: 0 | D9: 8.47 | E9: 2.7652 | F9: 1.24 | G9: 4 | H9: 0.99 | I9: 20
A10: 46235 | B10: 3.41 | C10: 0 | D10: 7.97 | E10: 2.7875 | F10: 1.25 | G10: 4 | H10: 0.99 | I10: 20
A11: 46266 | B11: 4.44 | C11: 0 | D11: 7.17 | E11: 2.6537 | F11: 1.19 | G11: 4 | H11: 0.99 | I11: 20
A12: 46296 | B12: 3.96 | C12: 0 | D12: 6.98 | E12: 2.9436 | F12: 1.32 | G12: 4 | H12: 0.99 | I12: 20
A13: 46327 | B13: 3.51 | C13: 0 | D13: 6.78 | E13: 2.8767 | F13: 1.29 | G13: 4 | H13: 0.99 | I13: 20
A14: 46357 | B14: 3.27 | C14: 0 | D14: 7.48 | E14: 3.2112 | F14: 1.44 | G14: 4 | H14: 0.99 | I14: 20

Sheet Customer
A1: ReferenceMonth | B1: Voice of Consumer Offenders-OVEN | C1: Voice of Consumer Offenders-HOBS | D1: EPQ (M-4) 12 MR - Ovens (Halino) | E1: EPQ (M-4) 12 MR - Ovens (TITANIUM) | F1: EPQ (M-4) 12 MR - HOBS | G1: 1MIS - Ovens(Halino) | H1: 1MIS - Ovens-Titanium | I1: 1MIS -Hobs | J1: Defects @ Finished Products audit | K1: ODL | L1: CFE | M1: Right First Time (FPY)-OVENS | N1: Right First Time (FPY)-HOBS | O1: EFE | P1: Supplier
B2: % | C2: % | D2: % | E2: % | F2: % | G2: ppm | H2: ppm | I2: ppm | J2: ppm | K2: ppm | L2: % | M2: % | N2: % | O2: % | P2: ppm | S2: 0.395 | T2: 0.392 | U2: 0.392 | V2: 0.269
A3: 46023 | D3: 0.021 | E3: 0.098 | F3: 0.027 | G3: 2000 | H3: 14430 | I3: 4000 | J3: 114583 | K3: 19376 | M3: 0.932 | N3: 0.869 | P3: 54
A4: 46054 | D4: 0.018 | E4: 0.094 | F4: 0.031 | G4: 2000 | H4: 14534 | I4: 3000 | J4: 31250 | K4: 18239 | M4: 0.931 | N4: 0.914 | P4: 75
A5: 46082 | G5: 2000 | I5: 3000 | J5: 36320 | K5: 22069 | M5: 0.933 | N5: 0.926 | P5: 67
A6: 46113
A7: 46143
A8: 46174
A9: 46204
A10: 46235
A11: 46266
A12: 46296
A13: 46327
A14: 46357

Sheet Customer tgt
A1: ReferenceMonth | B1: Voice of Consumer Offenders-OVEN | C1: Voice of Consumer Offenders-HOBS | D1: EPQ (M-4) 12 MR - Ovens (Halino) | E1: EPQ (M-4) 12 MR - Ovens (TITANIUM) | F1: EPQ (M-4) 12 MR - HOBS | G1: 1MIS - Ovens(Halino) | H1: 1MIS - Ovens-Titanium | I1: 1MIS -Hobs | J1: Defects @ Finished Products audit | K1: ODL | L1: CFE | M1: Right First Time (FPY)-OVENS | N1: Right First Time (FPY)-HOBS | O1: EFE | P1: Supplier
B2: % | C2: % | D2: % | E2: % | F2: % | G2: ppm | H2: ppm | I2: ppm | J2: ppm | K2: ppm | L2: % | M2: % | N2: % | O2: % | P2: ppm
A3: 46023 | D3: 0.015 | E3: 0.05 | F3: 0.027 | G3: 2490 | H3: 7100 | I3: 4644 | J3: 90000 | K3: 30000 | M3: 0.92 | N3: 0.87 | P3: 66
A4: 46054 | D4: 0.015 | E4: 0.05 | F4: 0.026 | G4: 2490 | H4: 7100 | I4: 4472 | J4: 90000 | K4: 30000 | M4: 0.92 | N4: 0.88 | P4: 66
A5: 46082 | D5: 0.015 | E5: 0.045 | F5: 0.025 | G5: 2490 | H5: 6390 | I5: 4300 | J5: 75000 | K5: 25000 | M5: 0.92 | N5: 0.89 | P5: 66
A6: 46113 | D6: 0.015 | E6: 0.045 | F6: 0.025 | G6: 2490 | H6: 6390 | I6: 4300 | J6: 75000 | K6: 25000 | M6: 0.93 | N6: 0.9 | P6: 66
A7: 46143 | D7: 0.0145 | E7: 0.045 | F7: 0.024 | G7: 2407 | H7: 6390 | I7: 4128 | J7: 75000 | K7: 25000 | M7: 0.93 | N7: 0.91 | P7: 66
A8: 46174 | D8: 0.0145 | E8: 0.045 | F8: 0.024 | G8: 2407 | H8: 6390 | I8: 4128 | J8: 75000 | K8: 25000 | M8: 0.93 | N8: 0.91 | P8: 66
A9: 46204 | D9: 0.0145 | E9: 0.04 | F9: 0.023 | G9: 2407 | H9: 5680 | I9: 3956 | J9: 60000 | K9: 20000 | M9: 0.94 | N9: 0.92 | P9: 66
A10: 46235 | D10: 0.0145 | E10: 0.04 | F10: 0.023 | G10: 2407 | H10: 5680 | I10: 3956 | J10: 60000 | K10: 20000 | M10: 0.94 | N10: 0.93 | P10: 66
A11: 46266 | D11: 0.014 | E11: 0.04 | F11: 0.022 | G11: 2324 | H11: 5680 | I11: 3784 | J11: 75000 | K11: 25000 | M11: 0.94 | N11: 0.92 | P11: 66
A12: 46296 | D12: 0.014 | E12: 0.035 | F12: 0.022 | G12: 2324 | H12: 4970 | I12: 3784 | J12: 90000 | K12: 30000 | M12: 0.95 | N12: 0.88 | P12: 66
A13: 46327 | D13: 0.014 | E13: 0.035 | F13: 0.021 | G13: 2324 | H13: 4970 | I13: 3612 | J13: 75000 | K13: 25000 | M13: 0.95 | N13: 0.89 | P13: 66
A14: 46357 | D14: 0.014 | E14: 0.035 | F14: 0.021 | G14: 2324 | H14: 4970 | I14: 3612 | J14: 60000 | K14: 20000 | M14: 0.95 | N14: 0.9 | P14: 66

Sheet People
A1: ReferenceMonth | B1: Paid Absenteeism drect blue collars | C1: Unpaid Absenteeism drect blue collars | D1: HC - Direct BC | E1: Budget Volumes | F1: HC - Indirect BC | G1: HC - White Collars | H1: Overtime - Direct BC | I1: Overtime - Indirect BC
B2: % | C2: % | D2: Number | F2: Number | G2: Number | H2: % | I2: %
A3: 46023 | B3: 0.007 | C3: 0.035 | D3: 294 | F3: 127 | G3: 30 | H3: 0.021 | I3: 0.025
A4: 46054 | B4: 0.006 | C4: 0.033 | D4: 300 | F4: 126 | G4: 31 | H4: 0.039 | I4: 0.03
A5: 46082 | B5: 0.004 | C5: 0.03 | D5: 325 | F5: 125 | G5: 30 | H5: 0.043 | I5: 0.043
A6: 46113 | B6: 0.0038 | C6: 0.0315 | D6: 265 | F6: 113 | G6: 27.67 | H6: 0.034 | I6: 0.046
A7: 46143
A8: 46174
A9: 46204
A10: 46235
A11: 46266
A12: 46296
A13: 46327
A14: 46357
K18: 97960 | L18: 100290 | M18: 120750 | N18: 85671
K19: 38

Sheet People tgt
A1: ReferenceMonth | B1: Paid Absenteeism drect blue collars | C1: Unpaid Absenteeism drect blue collars | D1: Headcount Direct Blue Collars | E1: Headcount Indirect Blue Collars | F1: Headcount White Collars | G1: Overtime Direct Blue Collars | H1: Overtime Indirect Blue Collars
B2: % | D2: Number | E2: Number | F2: Number | G2: % | H2: %
A3: 46023 | B3: 0.04 | C3: 0.02 | D3: 286 | E3: 133 | F3: 34 | G3: 0.002 | H3: 0.04
A4: 46054 | B4: 0.04 | C4: 0.02 | D4: 317 | E4: 136 | F4: 34 | G4: 0.002 | H4: 0.04
A5: 46082 | B5: 0.04 | C5: 0.02 | D5: 317 | E5: 136 | F5: 34 | G5: 0.002 | H5: 0.04
A6: 46113 | B6: 0.04 | C6: 0.02 | D6: 258 | E6: 127 | F6: 34 | G6: 0.002 | H6: 0.04
A7: 46143 | B7: 0.04 | C7: 0.02 | D7: 258 | E7: 127 | F7: 34 | G7: 0.002 | H7: 0.04
A8: 46174 | B8: 0.04 | C8: 0.02 | D8: 258 | E8: 127 | F8: 34 | G8: 0.002 | H8: 0.04
A9: 46204 | B9: 0.04 | C9: 0.02 | D9: 258 | E9: 127 | F9: 34 | G9: 0.002 | H9: 0.04
A10: 46235 | B10: 0.04 | C10: 0.02 | D10: 258 | E10: 127 | F10: 34 | G10: 0.002 | H10: 0.04
A11: 46266 | B11: 0.04 | C11: 0.02 | D11: 295 | E11: 133 | F11: 34 | G11: 0.002 | H11: 0.04
A12: 46296 | B12: 0.04 | C12: 0.02 | D12: 295 | E12: 133 | F12: 34 | G12: 0.002 | H12: 0.04
A13: 46327 | B13: 0.04 | C13: 0.02 | D13: 343 | E13: 142 | F13: 34 | G13: 0.002 | H13: 0.04
A14: 46357 | B14: 0.04 | C14: 0.02 | D14: 343 | E14: 142 | F14: 34 | G14: 0.002 | H14: 0.04

Sheet Production
A1: ReferenceMonth | B1: Assembly Yield | C1: Production Efficiency | D1: Productivity Index | E1: OEE QS WELDING LINE | F1: OEE DOOR SILICON HALINO | G1: OEE UNIHOB TRANSFER | H1: Hold products | I1: Scrap Cost
B2: % | C2: % | D2: % | E2: % | F2: % | G2: % | H2: # | I2: €/unit
A3: 46023 | B3: 0.878 | C3: 0.854 | D3: 1 | E3: 0.864 | F3: 0.833 | G3: 0.85 | H3: 1854 | I3: 0.52
A4: 46054 | B4: 0.921 | C4: 0.846 | D4: 1.014 | E4: 0.897 | F4: 0.835 | G4: 0.851 | H4: 4841 | I4: 0.56
A5: 46082 | B5: 0.918 | C5: 0.861 | D5: 1.013 | E5: 0.902 | F5: 0.844 | G5: 0.853 | H5: 3412 | I5: 0.57
A6: 46113
A7: 46143
A8: 46174
A9: 46204
A10: 46235
A11: 46266
A12: 46296
A13: 46327
A14: 46357

Sheet Production tgt
A1: ReferenceMonth | B1: Assembly Yield | C1: Production Efficiency | D1: Productivity Index | E1: OEE QS WELDING LINE | F1: OEE DOOR SILICON HALINO | G1: OEE UNIHOB TRANSFER | H1: Hold products | I1: Scrap Cost
B2: % | C2: % | D2: % | E2: % | F2: % | G2: % | H2: # | I2: €/unit
A3: 46023 | B3: 1 | C3: 0.916 | D3: 1 | E3: 0.85 | F3: 0.8 | G3: 0.82 | H3: 0 | I3: 0.57
A4: 46054 | B4: 1 | C4: 0.893 | D4: 1.002 | E4: 0.85 | F4: 0.8 | G4: 0.82 | H4: 0 | I4: 0.57
A5: 46082 | B5: 1 | C5: 0.843 | D5: 1.002 | E5: 0.85 | F5: 0.8 | G5: 0.82 | H5: 0 | I5: 0.57
A6: 46113 | B6: 1 | C6: 0.926 | D6: 1.002 | E6: 0.85 | F6: 0.81 | G6: 0.83 | H6: 0 | I6: 0.57
A7: 46143 | B7: 1 | C7: 0.877 | D7: 1.002 | E7: 0.85 | F7: 0.81 | G7: 0.83 | H7: 0 | I7: 0.57
A8: 46174 | B8: 1 | C8: 0.943 | D8: 1.002 | E8: 0.85 | F8: 0.81 | G8: 0.83 | H8: 0 | I8: 0.57
A9: 46204 | B9: 1 | C9: 0.909 | D9: 1.002 | E9: 0.85 | F9: 0.82 | G9: 0.83 | H9: 0 | I9: 0.57
A10: 46235 | B10: 1 | C10: 0.948 | D10: 1.025 | E10: 0.85 | F10: 0.82 | G10: 0.83 | H10: 0 | I10: 0.57
A11: 46266 | B11: 1 | C11: 0.872 | D11: 1.025 | E11: 0.85 | F11: 0.82 | G11: 0.83 | H11: 0 | I11: 0.57
A12: 46296 | B12: 1 | C12: 0.91 | D12: 1.025 | E12: 0.85 | F12: 0.82 | G12: 0.83 | H12: 0 | I12: 0.57
A13: 46327 | B13: 1 | C13: 0.918 | D13: 1.04 | E13: 0.85 | F13: 0.82 | G13: 0.83 | H13: 0 | I13: 0.57
A14: 46357 | B14: 1 | C14: 0.938 | D14: 1.04 | E14: 0.85 | F14: 0.82 | G14: 0.83 | H14: 0 | I14: 0.57
A17: 1 | B17: 1.002 | C17: 1.002 | D17: 1.002 | E17: 1.002 | F17: 1.002 | G17: 1.002 | H17: 1.025 | I17: 1.025 | J17: 1.025 | K17: 1.04 | L17: 1.04

Sheet Supply Chain
A1: ReferenceMonth | B1: Logistics Indirect Workers | C1: Logistics White Collars | D1: Mix accuracy | E1: Days of Stock | F1: Spare Parts Back Order Lines | G1: Customer Service Back Order Volumes
B2: Number | C2: Number | D2: % | E2: Days | F2: % | G2: %
A3: 46023 | D3: 0.25 | E3: 37.8 | F3: 0.11
A4: 46054 | D4: 0.71 | E4: 39.6 | F4: 0.03
A5: 46082 | D5: 0.772 | E5: 38 | F5: 0.03
A6: 46113
A7: 46143
A8: 46174
A9: 46204
A10: 46235
A11: 46266
A12: 46296
A13: 46327
A14: 46357

Sheet Supply Chain tgt
A1: ReferenceMonth | B1: Logistics Indirect Workers | C1: Logistics White Collars | D1: Mix accuracy | E1: Industrial inventory DOS | F1: Spare Parts Back Orders Lines | G1: Spare Parts Back Order Volumes
B2: Number | C2: Number | D2: % | E2: Days | F2: % | G2: %
A3: 46023 | D3: 0.85 | E3: 38.9 | F3: 0.04
A4: 46054 | D4: 0.85 | E4: 40.5 | F4: 0.04
A5: 46082 | D5: 0.85 | E5: 42.29 | F5: 0.04
A6: 46113 | D6: 0.85 | E6: 39.15 | F6: 0.04
A7: 46143 | D7: 0.85 | E7: 38.48 | F7: 0.04
A8: 46174 | D8: 0.85 | E8: 39.51 | F8: 0.04
A9: 46204 | D9: 0.85 | E9: 39.86 | F9: 0.04
A10: 46235 | D10: 0.85 | E10: 38.2 | F10: 0.04
A11: 46266 | D11: 0.85 | E11: 39.21 | F11: 0.04
A12: 46296 | D12: 0.85 | E12: 35.57 | F12: 0.04
A13: 46327 | D13: 0.85 | E13: 34.75 | F13: 0.04
A14: 46357 | D14: 0.85 | E14: 33.46 | F14: 0.04
E16: 38.9
E17: 40.5
E18: 42.29
E19: 39.15
E20: 38.48
E21: 39.51
E22: 39.86
E23: 38.2
E24: 39.21
E25: 35.57
E26: 34.75
E27: 33.46
