Workbook
Name \0: #REF!
Name \0: #REF!
Name \0: #REF!
Name \A: #REF!
Name \A: #REF!
Name \A: #REF!
Name \b: #REF!
Name \B: #REF!
Name \B: #REF!
Name \c: #REF!
Name \C: #REF!
Name \C: #REF!
Name \e: #REF!
Name \e: #REF!
Name \m: #REF!
Name \m: #REF!
Name \P: #REF!
Name \P: #REF!
Name \P: #REF!
Name \Q: #REF!
Name \Q: #REF!
Name \Q: #REF!
Name \R: #REF!
Name \R: #REF!
Name \R: #REF!
Name \s: #REF!
Name \S: #REF!
Name \S: #REF!
Name \t: #REF!
Name \T: #REF!
Name \T: #REF!
Name \v: #N/A
Name \w: #REF!
Name \w: #REF!
Name \x: #REF!
Name \X: #REF!
Name \X: #REF!
Name _: #REF!
Name _: #REF!
Name ___CNQ07: #REF!
Name ___CON1: #REF!
Name ___CON1: #REF!
Name ___CON1: #REF!
Name ___CON2: #REF!
Name ___CON2: #REF!
Name ___CON2: #REF!
Name ___ddn400: #REF!
Name ___ddn400: #REF!
Name ___ddn400: #REF!
Name ___ddn600: #REF!
Name ___ddn600: #REF!
Name ___ddn600: #REF!
Name ___E99999: #REF!
Name ___E99999: #REF!
Name ___E99999: #REF!
Name ___gon4: #REF!
Name ___gon4: #REF!
Name ___IV999999: #REF!
Name ___IV999999: #REF!
Name ___IV999999: #REF!

Sheet Instruction
B1: Actual Reporting
B2: 1. | C2: Please update copertura for the period / data entry - line 53 onwords
B3: 2. | C3: Please update the actual cost for the period / data entry - line 75 onwords
B4: 3. | C4: Update columns "Q" & "R" in the data entry and budget assumption tab
B6: 4. | C6: YTD and MTD variances, as well as the report is populated automatically
B7: 5. | C7: Please provide the rootcauses for the variances YTD and MTD Report (column J-P)
C8: Checkline in column "U" needs to be zero in each line
B9: 6. | C9: SAP extraction actual cost lines as separate sheet
B11: FCST Reporting
B13: 1. | C13: Please fill in the copertura and actuals for the upcoming months _ data entry tab - lines 53-94
B14: 2. | C14: FCST tab is populated automatically , please check the correctness
B15: 3. | C15: Provide root cause split for the upcoming periods variances
B16: 4. | C16: Paste values previous submitted FCST in "FCST25" sheet lines 47-87
B17: 5. | C17: Check variances vs last forecast in "FCST25" sheet lines 91-131
B18: 6. | C18: Update column AE & AF in "FCST CPU"
B19: 7. | C19: Update Material & Freight In part in "FCST CPU"

Sheet Root cause explanations
B2: Budget Cost | C2: Budgeted cost of the period @ Budget FX rate
B4: ACE | C4: Permanent saving, linked to ACE projects. This line needs to give us the deviation versus the budgeted ACE improvements
B6: MFG Efficiency | C6: Saving / Cost in relation with current year standard production process not linked to price , one off or ACE ; e.g delay of hiring , not spending the budget for a specific line or additional consumption due to breakdown etc
B8: S&OP | C8: Increase or decrease of cost due to volume fluctuations; Excess of Manpower, Additional / less vertical closure days impact, Incremental cost increase / decrease on the fixed cost due to volume change
B10: Price / Inflation | C10: Pure Price or Inflation impact
B12: fX translation | C12: fx impact act fx versus budget fx
B14: One off | C14: Extraordinary expense/income not linked to current year standard production process; previous years income/ loss, write off and sale of assets , one time expenses like restructuring program, cost related to opening ceremony, extra ordinary donations etc
B16: Oth Functions | C16: Cost related to claims , which in the past was recharged to R&D, Procurement , Logistics
B18: Actual Cost | C18: Actual cost of the period converted @ actual fx rate

Sheet HC 2026
A1: Headcount 2026 (ACT + FCST)
C3: Jan | D3: Feb | E3: March | F3: April | G3: May | H3: June | I3: July | J3: August | K3: Sept | L3: Oct | M3: Nov | N3: Dec | O3: Total
A4: Direct HC | B4: Production | C4: 236.73 | D4: 215 | E4: 132 | F4: 222 | G4: 261 | H4: =163+98 -> 261 | I4: 264 | J4: 264 | K4: 264 | L4: 242 | M4: 243 | N4: 245 | O4: =AVERAGE(C4:N4) -> 237.4775 | P4: FOR YTG 100 ISKUR HDC untl October
B5: Shared | O5: =AVERAGE(C5:N5) -> #DIV/0!
B6: Total | C6: =C4+C5 -> 236.73 | D6: =D4+D5 -> 215 | E6: =E4+E5 -> 132 | F6: =F4+F5 -> 222 | G6: =G4+G5 -> 261 | H6: =H4+H5 -> 261 | I6: =I4+I5 -> 264 | J6: =J4+J5 -> 264 | ... N6: =N4+N5 -> 245 | O6: =AVERAGE(C6:N6) -> 237.4775
B8: Assigned hours | O8: =AVERAGE(C8:N8) -> #DIV/0!
C10: Jan | D10: Feb | E10: March | F10: April | G10: May | H10: June | I10: July | J10: August | K10: Sept | L10: Oct | M10: Nov | N10: Dec | O10: Total
A11: Indirect HC | B11: Production | C11: 85 | D11: 82 | E11: 69 | F11: 79 | G11: 82 | H11: =81+1 -> 82 | I11: 84 | J11: 84 | K11: 84 | L11: 84 | M11: 84 | N11: 84 | O11: =AVERAGE(C11:N11) -> 81.916667
B12: Shared | O12: =AVERAGE(C12:N12) -> #DIV/0!
B13: Total | C13: =C11+C12 -> 85 | D13: =D11+D12 -> 82 | E13: =E11+E12 -> 69 | F13: =F11+F12 -> 79 | G13: =G11+G12 -> 82 | H13: =H11+H12 -> 82 | I13: =I11+I12 -> 84 | J13: =J11+J12 -> 84 | ... N13: =N11+N12 -> 84 | O13: =AVERAGE(C13:N13) -> 81.916667
C16: Jan | D16: Feb | E16: March | F16: April | G16: May | H16: June | I16: July | J16: August | K16: Sept | L16: Oct | M16: Nov | N16: Dec | O16: Total
A17: Fixed HC | B17: Production | C17: 22 | D17: 22 | E17: 22 | F17: 22 | G17: 22 | H17: 22 | I17: 22 | J17: 23 | K17: 23 | L17: 23 | M17: 23 | N17: 23 | O17: =AVERAGE(C17:N17) -> 22.416667
B18: Shared | C18: 3.5 | D18: 3.5 | E18: 3.5 | F18: 2.7 | G18: 2.7 | H18: 2.7 | I18: 3.5 | J18: 3.5 | K18: 3.5 | L18: 3.5 | M18: 3.5 | N18: 3.5 | O18: =AVERAGE(C18:N18) -> 3.3
B19: Lapro | O19: =AVERAGE(C19:N19) -> #DIV/0!
B20: Total | C20: =C17+C18+C19 -> 25.5 | D20: =D17+D18+D19 -> 25.5 | E20: =E17+E18+E19 -> 25.5 | F20: =F17+F18+F19 -> 24.7 | G20: =G17+G18+G19 -> 24.7 | H20: =H17+H18+H19 -> 24.7 | I20: =I17+I18+I19 -> 25.5 | J20: =J17+J18+J19 -> 26.5 | ... N20: =N17+N18+N19 -> 26.5 | O20: =AVERAGE(C20:N20) -> 25.716667
C22: =SUM(C17:C18) -> 25.5 | D22: =SUM(D17:D18) -> 25.5 | E22: =SUM(E17:E18) -> 25.5 | F22: =SUM(F17:F18) -> 24.7 | G22: =SUM(G17:G18) -> 24.7 | H22: =SUM(H17:H18) -> 24.7 | I22: =SUM(I17:I18) -> 25.5
C24: Jan | D24: Feb | E24: March | F24: April | G24: May | H24: June | I24: July | J24: Aug | K24: Sep | L24: Oct | M24: Nov | N24: Dec | O24: Total
B25: Direct HC | C25: =+C6 -> 236.73 | D25: =+D6 -> 215 | E25: =+E6 -> 132 | F25: =+F6 -> 222 | G25: =+G6 -> 261 | H25: =+H6 -> 261 | I25: =+I6 -> 264 | J25: =+J6 -> 264 | ... N25: =+N6 -> 245 | O25: =O6 -> 237.4775
B26: Indirect HC | C26: =+C13 -> 85 | D26: =+D13 -> 82 | E26: =+E13 -> 69 | F26: =+F13 -> 79 | G26: =+G13 -> 82 | H26: =+H13 -> 82 | I26: =+I13 -> 84 | J26: =+J13 -> 84 | ... N26: =+N13 -> 84 | O26: =O13 -> 81.916667
B27: Total HC | C27: =C25+C26 -> 321.73 | D27: =D25+D26 -> 297 | E27: =E25+E26 -> 201 | F27: =F25+F26 -> 301 | G27: =G25+G26 -> 343 | H27: =H25+H26 -> 343 | I27: =I25+I26 -> 348 | J27: =J25+J26 -> 348 | ... O27: =O25+O26 -> 319.39417
B29: Temporary ratio | C29: =+C26/C27 -> 0.26419669 | D29: =+D26/D27 -> 0.27609428 | E29: =+E26/E27 -> 0.34328358 | F29: =+F26/F27 -> 0.26245847 | G29: =+G26/G27 -> 0.23906706 | H29: =+H26/H27 -> 0.23906706 | I29: =+I26/I27 -> 0.24137931 | J29: =+J26/J27 -> 0.24137931 | ... N29: =+N26/N27 -> 0.25531915
A32: BUDGET | C32: Jan | D32: Feb | E32: March | F32: April | G32: May | H32: June | I32: July | J32: August | K32: Sept | L32: Oct | M32: Nov | N32: Dec | O32: Total
A33: Direct HC | B33: Production | C33: 244 | D33: 244 | E33: 244 | F33: 244 | G33: 247 | H33: 245 | I33: 245 | J33: 251 | K33: 252 | L33: 250 | M33: 251 | N33: 252 | O33: =AVERAGE(C33:N33) -> 247.41667
B34: Shared | O34: =AVERAGE(C34:N34) -> #DIV/0!
B35: Total | C35: =C33+C34 -> 244 | D35: =D33+D34 -> 244 | E35: =E33+E34 -> 244 | F35: =F33+F34 -> 244 | G35: =G33+G34 -> 247 | H35: =H33+H34 -> 245 | I35: =I33+I34 -> 245 | J35: =J33+J34 -> 251 | ... N35: =N33+N34 -> 252 | O35: =AVERAGE(C35:N35) -> 247.41667
B37: Assigned hours | O37: =AVERAGE(C37:N37) -> #DIV/0!
A39: BUDGET | C39: Jan | D39: Feb | E39: March | F39: April | G39: May | H39: June | I39: July | J39: August | K39: Sept | L39: Oct | M39: Nov | N39: Dec | O39: Total
A40: Indirect HC | B40: Production | C40: 85 | D40: 85 | E40: 85 | F40: 85 | G40: 85 | H40: 85 | I40: 85 | J40: 85 | K40: 85 | L40: 85 | M40: 85 | N40: 85 | O40: =AVERAGE(C40:N40) -> 85
B41: Shared | O41: =AVERAGE(C41:N41) -> #DIV/0!
B42: Total | C42: =C40+C41 -> 85 | D42: =D40+D41 -> 85 | E42: =E40+E41 -> 85 | F42: =F40+F41 -> 85 | G42: =G40+G41 -> 85 | H42: =H40+H41 -> 85 | I42: =I40+I41 -> 85 | J42: =J40+J41 -> 85 | ... N42: =N40+N41 -> 85 | O42: =AVERAGE(C42:N42) -> 85
A45: BUDGET | C45: Jan | D45: Feb | E45: March | F45: April | G45: May | H45: June | I45: July | J45: August | K45: Sept | L45: Oct | M45: Nov | N45: Dec | O45: Total
A46: Fixed HC | B46: Production | C46: 22 | D46: 22 | E46: 22 | F46: 22 | G46: 22 | H46: 22 | I46: 22 | J46: 23 | K46: 23 | L46: 23 | M46: 23 | N46: 23 | O46: =AVERAGE(C46:N46) -> 22.416667
B47: Shared | C47: 4.5 | D47: 4.5 | E47: 4.5 | F47: 4.5 | G47: 4.5 | H47: 4.5 | I47: 4.5 | J47: 4.5 | K47: 4.5 | L47: 4.5 | M47: 4.5 | N47: 4.5 | O47: =AVERAGE(C47:N47) -> 4.5 | P47: 1.5 hqd included
B48: Lapro | O48: =AVERAGE(C48:N48) -> #DIV/0!
B49: Total | C49: =C46+C47+C48 -> 26.5 | D49: =D46+D47+D48 -> 26.5 | E49: =E46+E47+E48 -> 26.5 | F49: =F46+F47+F48 -> 26.5 | G49: =G46+G47+G48 -> 26.5 | H49: =H46+H47+H48 -> 26.5 | I49: =I46+I47+I48 -> 26.5 | J49: =J46+J47+J48 -> 27.5 | ... N49: =N46+N47+N48 -> 27.5 | O49: =AVERAGE(C49:N49) -> 26.916667

Sheet G&A _Out of Per_
C2: RENTA | I2: EURASIA | K2: TOTAL
C3: TD | D3: DW | E3: CK | F3: INFRA | G3: TOTAL | I3: TOTAL | M3: Highlights;
B4: Association dues (MESS Payment) | G4: =SUM(C4:F4) -> 0 | K4: =G4+I4 -> 0
B5: G&A Recharge Eurosia - Renta | G5: =SUM(C5:F5) -> 0 | K5: =G5+I5 -> 0
B6: IT Recharge Group | G6: =SUM(C6:F6) -> 0 | K6: =G6+I6 -> 0
B7: Controlling Expenses | G7: =SUM(C7:F7) -> 0 | K7: =G7+I7 -> 0
B8: Enterprice Property Insurance | G8: =SUM(C8:F8) -> 0 | K8: =G8+I8 -> 0
B9: Profit on Asset Sale | G9: =SUM(C9:F9) -> 0 | K9: =G9+I9 -> 0
B10: Loss on Asset Sale | G10: =SUM(C10:F10) -> 0 | K10: =G10+I10 -> 0
B11: Litigation fee | G11: =SUM(C11:F11) -> 0 | K11: =G11+I11 -> 0
B12: INFRA | G12: =SUM(C12:F12) -> 0 | K12: =G12+I12 -> 0
B13: …...... | G13: =SUM(C13:F13) -> 0 | K13: =G13+I13 -> 0
B14: G&A _ Out of Perimeter | C14: =SUM(C4:C13) -> 0 | D14: =SUM(D4:D13) -> 0 | E14: =SUM(E4:E13) -> 0 | F14: =SUM(F4:F13) -> 0 | G14: =SUM(G4:G13) -> 0 | I14: =SUM(I4:I13) -> 0 | K14: =SUM(K4:K13) -> 0

Sheet CC
I2: MFG | J2: PTK4M00WAB
J3: PTK4M00WAC
J4: PTK4M00WAD
J5: PTK4M00WAE
J6: PTK4M00WAF
J7: PTK4M00WAG
J8: PTK4M00WAH
J9: PTK4M00WAI
J10: PTK4M00WAJ
J11: PTK4M00WAK
J12: PTK4M00WYD
I13: Overhead | J13: PTK4Y00WYE

Sheet ACE 2026
A1: YTD | B1: =IF($V$3>=B$2,1,0) -> 1 | C1: =IF($V$3>=C$2,1,0) -> 0 | D1: =IF($V$3>=D$2,1,0) -> 0 | E1: =IF($V$3>=E$2,1,0) -> 0 | F1: =IF($V$3>=F$2,1,0) -> 0 | G1: =IF($V$3>=G$2,1,0) -> 0 | H1: =IF($V$3>=H$2,1,0) -> 0 | I1: =IF($V$3>=I$2,1,0) -> 0 | ... M1: =IF($V$3>=M$2,1,0) -> 0
A2: MTD | B2: 1 | C2: 2 | D2: 3 | E2: 4 | F2: 5 | G2: 6 | H2: 7 | I2: 8 | J2: 9 | K2: 10 | L2: 11 | M2: 12
T3: Month | U3: Jan | V3: =VLOOKUP(U3,List!$C$2:$D$13,2,0) -> 1 | W3: =VLOOKUP(U3,List!$C$2:$E$13,3,0) -> 1
A4: ACE Budget | B4: Jan | C4: Feb | D4: March | E4: April | F4: May | G4: June | H4: July | I4: August | J4: Sept | K4: Oct | L4: Nov | M4: Dec | N4: Total | P4: MTD | Q4: YTD
A5: Direct Labour | B5: 4644.3971 | C5: 5010.6746 | D5: 5057.5234 | E5: 4872.7558 | F5: 15380.89 | G5: 49280.033 | H5: 49328.755 | I5: 49547.308 | J5: 58604.946 | K5: 54442.467 | L5: 52437.071 | M5: 52468.259 | N5: =SUM(B5:M5) -> 401075.08 | P5: =+SUMIFS(B5:M5,$B$2:$M$2,$V$3)/1000 -> 4.6443971 | Q5: =+SUMIFS(B5:M5,$B$1:$M$1,$W$3)/1000 -> 4.6443971
A6: Variable Utilities | B6: 0 | C6: 0 | D6: 0 | E6: 0 | F6: 0 | G6: 0 | H6: 0 | I6: 0 | J6: 0 | K6: 0 | L6: 0 | M6: 0 | N6: =SUM(B6:M6) -> 0 | P6: =+SUMIFS(B6:M6,$B$2:$M$2,$V$3)/1000 -> 0 | Q6: =+SUMIFS(B6:M6,$B$1:$M$1,$W$3)/1000 -> 0
A7: Scrap | B7: 0 | C7: 0 | D7: 0 | E7: 6811.5 | F7: 5019 | G7: 7528.5 | H7: 6094.5 | I7: 5557.5 | J7: 7780.5 | K7: 6669 | L7: 7410 | M7: 5570.25 | N7: =SUM(B7:M7) -> 58440.75 | P7: =+SUMIFS(B7:M7,$B$2:$M$2,$V$3)/1000 -> 0 | Q7: =+SUMIFS(B7:M7,$B$1:$M$1,$W$3)/1000 -> 0
A8: Scrap Reselling | B8: 0 | C8: 0 | D8: 0 | E8: 0 | F8: 0 | G8: 0 | H8: 0 | I8: 0 | J8: 0 | K8: 0 | L8: 0 | M8: 0 | N8: =SUM(B8:M8) -> 0 | P8: =+SUMIFS(B8:M8,$B$2:$M$2,$V$3)/1000 -> 0 | Q8: =+SUMIFS(B8:M8,$B$1:$M$1,$W$3)/1000 -> 0
A9: Variable Costs | B9: 1000 | C9: 1000 | D9: 1000 | E9: 1000 | F9: 1000 | G9: 1000 | H9: 1000 | I9: 1000 | J9: 1000 | K9: 1000 | L9: 1000 | M9: 1000 | N9: =SUM(B9:M9) -> 12000 | P9: =+SUMIFS(B9:M9,$B$2:$M$2,$V$3)/1000 -> 1 | Q9: =+SUMIFS(B9:M9,$B$1:$M$1,$W$3)/1000 -> 1
A10: VARIABLE CONVERSION | B10: =SUM(B5:B9) -> 5644.3971 | C10: =SUM(C5:C9) -> 6010.6746 | D10: =SUM(D5:D9) -> 6057.5234 | E10: =SUM(E5:E9) -> 12684.256 | F10: =SUM(F5:F9) -> 21399.89 | G10: =SUM(G5:G9) -> 57808.533 | H10: =SUM(H5:H9) -> 56423.255 | I10: =SUM(I5:I9) -> 56104.808 | ... M10: =SUM(M5:M9) -> 59038.509 | N10: =SUM(B10:M10) -> 471515.83 | P10: =SUM(P5:P9) -> 5.6443971 | Q10: =SUM(Q5:Q9) -> 5.6443971
A11: Indirect Labour | B11: 0 | C11: 0 | D11: 0 | E11: 0 | F11: 0 | G11: 0 | H11: 0 | I11: 0 | J11: 0 | K11: 0 | L11: 0 | M11: 0 | N11: =SUM(B11:M11) -> 0 | P11: =+SUMIFS(B11:M11,$B$2:$M$2,$V$3)/1000 -> 0 | Q11: =+SUMIFS(B11:M11,$B$1:$M$1,$W$3)/1000 -> 0
A12: Fixed Labour | B12: 0 | C12: 0 | D12: 0 | E12: 0 | F12: 0 | G12: 0 | H12: 0 | I12: 0 | J12: 0 | K12: 0 | L12: 0 | M12: 0 | N12: =SUM(B12:M12) -> 0 | P12: =+SUMIFS(B12:M12,$B$2:$M$2,$V$3)/1000 -> 0 | Q12: =+SUMIFS(B12:M12,$B$1:$M$1,$W$3)/1000 -> 0
A13: Semifixed | B13: 0 | C13: 0 | D13: 0 | E13: 0 | F13: 0 | G13: 0 | H13: 0 | I13: 0 | J13: 0 | K13: 0 | L13: 0 | M13: 0 | N13: =SUM(B13:M13) -> 0 | P13: =+SUMIFS(B13:M13,$B$2:$M$2,$V$3)/1000 -> 0 | Q13: =+SUMIFS(B13:M13,$B$1:$M$1,$W$3)/1000 -> 0
A14: Fixed utilities | B14: 1100 | C14: 1100 | D14: 1100 | E14: 1100 | F14: 1100 | G14: 1100 | H14: 1100 | I14: 1100 | J14: 1100 | K14: 1100 | L14: 1100 | M14: 1100 | N14: =SUM(B14:M14) -> 13200 | P14: =+SUMIFS(B14:M14,$B$2:$M$2,$V$3)/1000 -> 1.1 | Q14: =+SUMIFS(B14:M14,$B$1:$M$1,$W$3)/1000 -> 1.1
A15: Fixed Cost | B15: 0 | C15: 0 | D15: 0 | E15: 0 | F15: 0 | G15: 0 | H15: 0 | I15: 0 | J15: 0 | K15: 0 | L15: 0 | M15: 0 | N15: =SUM(B15:M15) -> 0 | P15: =+SUMIFS(B15:M15,$B$2:$M$2,$V$3)/1000 -> 0 | Q15: =+SUMIFS(B15:M15,$B$1:$M$1,$W$3)/1000 -> 0
A16: Obsolete | N16: =SUM(B16:M16) -> 0 | P16: =+SUMIFS(B16:M16,$B$2:$M$2,$V$3)/1000 -> 0 | Q16: =+SUMIFS(B16:M16,$B$1:$M$1,$W$3)/1000 -> 0
A17: Depreciation | N17: =SUM(B17:M17) -> 0 | P17: =+SUMIFS(B17:M17,$B$2:$M$2,$V$3)/1000 -> 0 | Q17: =+SUMIFS(B17:M17,$B$1:$M$1,$W$3)/1000 -> 0
A18: FIXED CONVERSION | B18: =SUM(B11:B17) -> 1100 | C18: =SUM(C11:C17) -> 1100 | D18: =SUM(D11:D17) -> 1100 | E18: =SUM(E11:E17) -> 1100 | F18: =SUM(F11:F17) -> 1100 | G18: =SUM(G11:G17) -> 1100 | H18: =SUM(H11:H17) -> 1100 | I18: =SUM(I11:I17) -> 1100 | ... M18: =SUM(M11:M17) -> 1100 | N18: =SUM(B18:M18) -> 13200 | P18: =SUM(P11:P17) -> 1.1 | Q18: =SUM(Q11:Q17) -> 1.1
A19: OVH AND OTHERS | B19: 0 | C19: 0 | D19: 0 | E19: 0 | F19: 0 | G19: 0 | H19: 0 | I19: 0 | J19: 0 | K19: 0 | L19: 0 | M19: 0 | N19: =SUM(B19:M19) -> 0 | P19: =+SUMIFS(B19:M19,$B$2:$M$2,$V$3)/1000 -> 0 | Q19: =+SUMIFS(B19:M19,$B$1:$M$1,$W$3)/1000 -> 0
A20: Grand Total | B20: =SUM(B10,B18,B19) -> 6744.3971 | C20: =SUM(C10,C18,C19) -> 7110.6746 | D20: =SUM(D10,D18,D19) -> 7157.5234 | E20: =SUM(E10,E18,E19) -> 13784.256 | F20: =SUM(F10,F18,F19) -> 22499.89 | G20: =SUM(G10,G18,G19) -> 58908.533 | H20: =SUM(H10,H18,H19) -> 57523.255 | I20: =SUM(I10,I18,I19) -> 57204.808 | ... M20: =SUM(M10,M18,M19) -> 60138.509 | N20: =SUM(B20:M20) -> 484715.83 | P20: =P18+P10+P19 -> 6.7443971 | Q20: =Q18+Q10+Q19 -> 6.7443971
A23: F-Matrix Actual | B23: Jan | C23: Feb | D23: March | E23: April | F23: May | G23: June | H23: July | I23: August | J23: Sept | K23: Oct | L23: Nov | M23: Dec | N23: Total | P23: MTD | Q23: YTD
A24: Direct Labour | B24: =+'ACE Details_FULL'!D25-'ACE Details_FULL'!D5+'ACE Details_FULL'!D30+'ACE Details_FULL'!D32 -> 40450.38 | C24: =+SUM('ACE Details_FULL'!E25,'ACE Details_FULL'!E30,'ACE Details_FULL'!E32,'ACE Details_FULL'!E32) -> 48560.941 | D24: =+SUM('ACE Details_FULL'!F25,'ACE Details_FULL'!F30,'ACE Details_FULL'!F32) -> 24543.182 | E24: =+SUM('ACE Details_FULL'!G25,'ACE Details_FULL'!G30,'ACE Details_FULL'!G32) -> 26853.444 | F24: =SUM('ACE Details_FULL'!H25:H32) -> 27917.878 | G24: =SUM('ACE Details_FULL'!I25:I32) -> 31020.665 | H24: =+SUM('ACE Details_FULL'!J25,'ACE Details_FULL'!J30,'ACE Details_FULL'!J32) -> 27265.034 | I24: =+SUM('ACE Details_FULL'!K25,'ACE Details_FULL'!K30,'ACE Details_FULL'!K32) -> 27115.925 | J24: =+SUM('ACE Details_FULL'!L25,'ACE Details_FULL'!L30,'ACE Details_FULL'!L32) -> 29457.764 | K24: =+SUM('ACE Details_FULL'!M25,'ACE Details_FULL'!M30,'ACE Details_FULL'!M32) -> 28696.971 | L24: =+SUM('ACE Details_FULL'!N25,'ACE Details_FULL'!N30,'ACE Details_FULL'!N32) -> 29000.118 | M24: =+SUM('ACE Details_FULL'!O25,'ACE Details_FULL'!O30,'ACE Details_FULL'!O32) -> 27498.863 | N24: =SUM(B24:M24) -> 368381.16 | P24: =+SUMIFS(B24:M24,$B$2:$M$2,$V$3)/1000 -> 40.45038 | Q24: =+SUMIFS(B24:M24,$B$1:$M$1,$W$3)/1000 -> 40.45038
A25: Variable Utilities | N25: =SUM(B25:M25) -> 0 | P25: =+SUMIFS(B25:M25,$B$2:$M$2,$V$3)/1000 -> 0 | Q25: =+SUMIFS(B25:M25,$B$1:$M$1,$W$3)/1000 -> 0
A26: Scrap | B26: =+'ACE Details_FULL'!D42 -> 0 | C26: =+'ACE Details_FULL'!E42 -> 0 | D26: =+'ACE Details_FULL'!F42 -> 0 | E26: =+'ACE Details_FULL'!G42 -> 0 | F26: =SUM('ACE Details_FULL'!H42) -> 0 | G26: =+'ACE Details_FULL'!I42 -> 0 | H26: =+'ACE Details_FULL'!J42 -> 6460.0226 | I26: =+'ACE Details_FULL'!K42 -> 6306.2731 | J26: =+'ACE Details_FULL'!L42 -> 8720.9988 | K26: =+'ACE Details_FULL'!M42 -> 7936.5266 | L26: =+'ACE Details_FULL'!N42 -> 8249.1084 | M26: =+'ACE Details_FULL'!O42 -> 6701.1299 | N26: =SUM(B26:M26) -> 44374.059 | P26: =+SUMIFS(B26:M26,$B$2:$M$2,$V$3)/1000 -> 0 | Q26: =+SUMIFS(B26:M26,$B$1:$M$1,$W$3)/1000 -> 0
A27: Scrap Reselling | N27: =SUM(B27:M27) -> 0 | P27: =+SUMIFS(B27:M27,$B$2:$M$2,$V$3)/1000 -> 0 | Q27: =+SUMIFS(B27:M27,$B$1:$M$1,$W$3)/1000 -> 0
A28: Variable Costs | B28: =+'ACE Details_FULL'!D33 -> 1000 | C28: =+'ACE Details_FULL'!E33 -> 1000 | D28: =+'ACE Details_FULL'!F33 -> 1000 | E28: =+'ACE Details_FULL'!G33 -> 1000 | F28: =SUM('ACE Details_FULL'!H33) -> 1000 | G28: =+'ACE Details_FULL'!I33 -> 1000 | H28: =+'ACE Details_FULL'!J33 -> 1000 | I28: =+'ACE Details_FULL'!K33 -> 1000 | J28: =+'ACE Details_FULL'!L33 -> 1000 | K28: =+'ACE Details_FULL'!M33 -> 1000 | L28: =+'ACE Details_FULL'!N33 -> 1000 | M28: =+'ACE Details_FULL'!O33 -> 1000 | N28: =SUM(B28:M28) -> 12000 | P28: =+SUMIFS(B28:M28,$B$2:$M$2,$V$3)/1000 -> 1 | Q28: =+SUMIFS(B28:M28,$B$1:$M$1,$W$3)/1000 -> 1
A29: VARIABLE CONVERSION | B29: =SUM(B24:B28) -> 41450.38 | C29: =SUM(C24:C28) -> 49560.941 | D29: =SUM(D24:D28) -> 25543.182 | E29: =SUM(E24:E28) -> 27853.444 | F29: =SUM(F24:F28) -> 28917.878 | G29: =SUM(G24:G28) -> 32020.665 | H29: =SUM(H24:H28) -> 34725.056 | I29: =SUM(I24:I28) -> 34422.198 | ... M29: =SUM(M24:M28) -> 35199.993 | N29: =SUM(B29:M29) -> 424755.22 | P29: =SUM(P24:P28) -> 41.45038 | Q29: =SUM(Q24:Q28) -> 41.45038
A30: Indirect Labour | B30: =+'ACE Details_FULL'!D34 -> 0 | C30: =+'ACE Details_FULL'!E34 -> 2240.8813 | D30: =+'ACE Details_FULL'!F34 -> 2240.8813 | E30: =+'ACE Details_FULL'!G34 -> 2240.8813 | F30: =SUM('ACE Details_FULL'!H34,'ACE Details_FULL'!H35) -> 4481.7626 | G30: =SUM('ACE Details_FULL'!I34,'ACE Details_FULL'!I35) -> 4481.7626 | H30: =+'ACE Details_FULL'!J34 -> 2240.8813 | I30: =+'ACE Details_FULL'!K34 -> 2240.8813 | J30: =+'ACE Details_FULL'!L34 -> 2240.8813 | K30: =+'ACE Details_FULL'!M34 -> 2240.8813 | L30: =+'ACE Details_FULL'!N34 -> 2240.8813 | M30: =+'ACE Details_FULL'!O34 -> 2240.8813 | N30: =SUM(B30:M30) -> 29131.457 | P30: =+SUMIFS(B30:M30,$B$2:$M$2,$V$3)/1000 -> 0 | Q30: =+SUMIFS(B30:M30,$B$1:$M$1,$W$3)/1000 -> 0
A31: Fixed Labour | N31: =SUM(B31:M31) -> 0 | P31: =+SUMIFS(B31:M31,$B$2:$M$2,$V$3)/1000 -> 0 | Q31: =+SUMIFS(B31:M31,$B$1:$M$1,$W$3)/1000 -> 0
A32: Semifixed | B32: =+'ACE Details_FULL'!D40+'ACE Details_FULL'!D38 -> 0 | C32: =+'ACE Details_FULL'!E40+'ACE Details_FULL'!E38 -> 211.30421 | D32: =+'ACE Details_FULL'!F40+'ACE Details_FULL'!F38 -> 211.30421 | E32: =+'ACE Details_FULL'!G40+'ACE Details_FULL'!G38 -> 211.30421 | F32: =SUM('ACE Details_FULL'!H38,'ACE Details_FULL'!H39) -> 422.60842 | G32: =SUM('ACE Details_FULL'!I38,'ACE Details_FULL'!I39) -> 422.60842 | H32: =+'ACE Details_FULL'!J40+'ACE Details_FULL'!J38 -> 845.21684 | I32: =+'ACE Details_FULL'!K40+'ACE Details_FULL'!K38 -> 845.21684 | J32: =+'ACE Details_FULL'!L40+'ACE Details_FULL'!L38 -> 845.21684 | K32: =+'ACE Details_FULL'!M40+'ACE Details_FULL'!M38 -> 845.21684 | L32: =+'ACE Details_FULL'!N40+'ACE Details_FULL'!N38 -> 845.21684 | M32: =+'ACE Details_FULL'!O40+'ACE Details_FULL'!O38 -> 845.21684 | N32: =SUM(B32:M32) -> 6550.4305 | P32: =+SUMIFS(B32:M32,$B$2:$M$2,$V$3)/1000 -> 0 | Q32: =+SUMIFS(B32:M32,$B$1:$M$1,$W$3)/1000 -> 0
A33: Fixed utilities | B33: =+'ACE Details_FULL'!D36+'ACE Details_FULL'!D37 -> 0 | C33: =+'ACE Details_FULL'!E36+'ACE Details_FULL'!E37 -> 0 | D33: =+'ACE Details_FULL'!F36+'ACE Details_FULL'!F37 -> 222.8 | E33: =+'ACE Details_FULL'!G36+'ACE Details_FULL'!G37 -> 222.8 | F33: =SUM('ACE Details_FULL'!H36,'ACE Details_FULL'!H37) -> 222.8 | G33: =SUM('ACE Details_FULL'!I36,'ACE Details_FULL'!I37) -> 222.8 | H33: =+'ACE Details_FULL'!J36+'ACE Details_FULL'!J37 -> 922.8 | I33: =+'ACE Details_FULL'!K36+'ACE Details_FULL'!K37 -> 922.8 | J33: =+'ACE Details_FULL'!L36+'ACE Details_FULL'!L37 -> 922.8 | K33: =+'ACE Details_FULL'!M36+'ACE Details_FULL'!M37 -> 922.8 | L33: =+'ACE Details_FULL'!N36+'ACE Details_FULL'!N37 -> 922.8 | M33: =+'ACE Details_FULL'!O36+'ACE Details_FULL'!O37 -> 922.8 | N33: =SUM(B33:M33) -> 6428 | P33: =+SUMIFS(B33:M33,$B$2:$M$2,$V$3)/1000 -> 0 | Q33: =+SUMIFS(B33:M33,$B$1:$M$1,$W$3)/1000 -> 0
A34: Fixed Cost | N34: =SUM(B34:M34) -> 0 | P34: =+SUMIFS(B34:M34,$B$2:$M$2,$V$3)/1000 -> 0 | Q34: =+SUMIFS(B34:M34,$B$1:$M$1,$W$3)/1000 -> 0
A35: Obsolete | N35: =SUM(B35:M35) -> 0 | P35: =+SUMIFS(B35:M35,$B$2:$M$2,$V$3)/1000 -> 0 | Q35: =+SUMIFS(B35:M35,$B$1:$M$1,$W$3)/1000 -> 0
A36: Depreciation | N36: =SUM(B36:M36) -> 0 | P36: =+SUMIFS(B36:M36,$B$2:$M$2,$V$3)/1000 -> 0 | Q36: =+SUMIFS(B36:M36,$B$1:$M$1,$W$3)/1000 -> 0
A37: FIXED CONVERSION | B37: =SUM(B30:B36) -> 0 | C37: =SUM(C30:C36) -> 2452.1855 | D37: =SUM(D30:D36) -> 2674.9855 | E37: =SUM(E30:E36) -> 2674.9855 | F37: =SUM(F30:F36) -> 5127.171 | G37: =SUM(G30:G36) -> 5127.171 | H37: =SUM(H30:H36) -> 4008.8981 | I37: =SUM(I30:I36) -> 4008.8981 | ... M37: =SUM(M30:M36) -> 4008.8981 | N37: =SUM(B37:M37) -> 42109.887 | P37: =SUM(P30:P36) -> 0 | Q37: =SUM(Q30:Q36) -> 0
A38: OVH AND OTHERS | N38: =SUM(B38:M38) -> 0 | P38: =+SUMIFS(B38:M38,$B$2:$M$2,$V$3)/1000 -> 0 | Q38: =+SUMIFS(B38:M38,$B$1:$M$1,$W$3)/1000 -> 0
A39: Grand Total | B39: =B29+B37+B38 -> 41450.38 | C39: =C29+C37+C38 -> 52013.126 | D39: =D29+D37+D38 -> 28218.168 | E39: =E29+E37+E38 -> 30528.429 | F39: =F29+F37+F38 -> 34045.049 | G39: =G29+G37+G38 -> 37147.836 | H39: =H29+H37+H38 -> 38733.954 | I39: =I29+I37+I38 -> 38431.096 | ... M39: =M29+M37+M38 -> 39208.891 | N39: =SUM(B39:M39) -> 466865.11 | P39: =P37+P29+P38 -> 41.45038 | Q39: =Q37+Q29+Q38 -> 41.45038
A42: Over /Underabsorption | B42: Jan | C42: Feb | D42: March | E42: April | F42: May | G42: June | H42: July | I42: August | J42: Sept | K42: Oct | L42: Nov | M42: Dec | N42: Total | P42: MTD | Q42: YTD
A43: Direct Labour | B43: =B24-B5 -> 35805.983 | C43: =C24-C5 -> 43550.266 | D43: =D24-D5 -> 19485.659 | E43: =E24-E5 -> 21980.688 | F43: =F24-F5 -> 12536.988 | G43: =G24-G5 -> -18259.368 | H43: =H24-H5 -> -22063.721 | I43: =I24-I5 -> -22431.383 | ... M43: =M24-M5 -> -24969.396 | N43: =SUM(B43:M43) -> -32693.916 | P43: =+SUMIFS(B43:M43,$B$2:$M$2,$V$3)/1000 -> 35.805983 | Q43: =+SUMIFS(B43:M43,$B$1:$M$1,$W$3)/1000 -> 35.805983
A44: Variable Utilities | B44: =B25-B6 -> 0 | C44: =C25-C6 -> 0 | D44: =D25-D6 -> 0 | E44: =E25-E6 -> 0 | F44: =F25-F6 -> 0 | G44: =G25-G6 -> 0 | H44: =H25-H6 -> 0 | I44: =I25-I6 -> 0 | ... M44: =M25-M6 -> 0 | N44: =SUM(B44:M44) -> 0 | P44: =+SUMIFS(B44:M44,$B$2:$M$2,$V$3)/1000 -> 0 | Q44: =+SUMIFS(B44:M44,$B$1:$M$1,$W$3)/1000 -> 0
...

Sheet VOLUME
B2: MTD | C2: Jan | D2: Feb | E2: Mar | F2: Apr | G2: May | H2: Jun | I2: Jul | J2: Aug | K2: Sep | L2: Oct | M2: Nov | N2: Dec | O2: Total
B3: Budget Volume | C3: 50463 | D3: 50446 | E3: 50447 | F3: 48050 | G3: 36788 | H3: 53265 | I3: 42049 | J3: 39150 | K3: 53732 | L3: 48548 | M3: 51408 | N3: 40676 | O3: =SUM(C3:N3) -> 565022
B5: STD Volume | C5: 46000 | D5: 46000 | E5: 46000 | F5: 48300 | G5: 32200 | H5: 71500 | I5: 57750 | J5: 52250 | K5: 71500 | L5: 71500 | M5: 68750 | N5: 62561 | O5: =SUM(C5:N5) -> 674311
B7: Actual Volume | C7: =+C10 -> 47357 | D7: =+D10 -> 42593 | E7: =+E10 -> 23002 | F7: =+F10 -> 40893 | G7: =+G10 -> 33043 | H7: =+H10 -> 53186 | I7: =+I10 -> 41500 | J7: =+J10 -> 39000 | ... N7: =+N10 -> 42190 | O7: =SUM(C7:N7) -> 518285
C8: =C9-C10 -> 0 | D8: =D9-D10 -> 0 | E8: =E9-E10 -> 0 | F8: =F9-F10 -> 0 | G8: =G9-G10 -> 0 | H8: =H9-H10 -> 1714 | I8: =I9-I10 -> 0 | J8: =J9-J10 -> 0 | ... N8: =N9-N10 -> 0
C9: 47357 | D9: 42593 | E9: 23002 | F9: 40893 | G9: 33043 | H9: 54900 | I9: 41500 | J9: 39000 | K9: 54085 | L9: 49500 | M9: 51936 | N9: 42190
B10: DW 2 | C10: =SUM(C11:C13) -> 47357 | D10: =SUM(D11:D13) -> 42593 | E10: =SUM(E11:E13) -> 23002 | F10: =SUM(F11:F13) -> 40893 | G10: =SUM(G11:G13) -> 33043 | H10: =SUM(H11:H13) -> 53186 | I10: =SUM(I11:I13) -> 41500 | J10: =SUM(J11:J13) -> 39000 | ... N10: =SUM(N11:N13) -> 42190 | O10: =SUM(C10:N10) -> 518285
B11: FS | C11: 19805 | D11: 18495 | E11: 10482 | F11: 14837 | G11: 14006 | H11: 24548 | I11: 15800 | J11: 15600 | K11: 20600 | L11: 19800 | M11: 25500 | N11: 20024 | O11: =SUM(C11:N11) -> 219497
B12: BI | C12: 27552 | D12: 24098 | E12: 12520 | F12: 26056 | G12: 19037 | H12: 28638 | I12: 23700 | J12: 23400 | K12: 30900 | L12: 29700 | M12: 25500 | N12: 20024 | O12: =SUM(C12:N12) -> 291125
B13: KIT | H13: 0 | I13: 2000 | J13: 0 | K13: 2585 | L13: 0 | M13: 936 | N13: 2142 | O13: =SUM(C13:N13) -> 7663

Sheet HQD
A1: PERIMETER | B1: HQD REPORTING -EXCLUDED COST ITEMS | C1: IN | D1: OUT
A3: PERIMETER | B3: Direct Labor | C3: X
A4: PERIMETER | B4: Variable Utilities | C4: X
A5: PERIMETER | B5: Scrap | D5: X
A6: PERIMETER | B6: Scrap Reselling | D6: X
A7: PERIMETER | B7: Other Variable (Production Consumable, Inventory ADJ)
A8: PERIMETER | B8: Inventory Adjustment | D8: X
A9: PERIMETER | B9: Production Consummables | C9: X
A10: PERIMETER | B10: Variable Conv.
A11: PERIMETER | B11: Indirect Labour | C11: X
A12: PERIMETER | B12: Fixed Labour | C12: X
A13: PERIMETER | B13: Semifixed | C13: X
A14: PERIMETER | B14: Fixed utilities | C14: X
A15: PERIMETER | B15: Fixed Cost | C15: X
A16: PERIMETER | B16: IT LOCAL | C16: Should be under shares
A17: PERIMETER | B17: Security | C17: Should be under shares
A18: PERIMETER | B18: Obsolete | D18: X
A19: PERIMETER | B19: Depreciation | C19: X
A20: PERIMETER | B20: Fixed Conv.
A21: PERIMETER | B21: TOTAL MFG COST w/o SHARES
A22: PERIMETER | B22: TOTAL SHARES
A23: PERIMETER | B23: Mess Union Fee | C23: X | E23: Target'tan çıkarılırken bütçe değerleri alınabilir.
A24: PERIMETER | B24: IT LOCAL | C24: X | E24: Target'tan çıkarılırken bütçe değerleri alınabilir.
A25: PERIMETER | B25: Security | C25: X | E25: Target'tan çıkarılırken bütçe değerleri alınabilir.
A26: PERIMETER | B26: IT GLOBAL | D26: X
A27: PERIMETER | B27: G&A(Insurance included) | D27: X
A28: PERIMETER | B28: TOTAL MFG COST w/ SHARES
A29: PERIMETER | B29: Functional Currency Impact | C29: X
A32: OTHERS | B32: Scrap
A33: OTHERS | B33: Scrap Reselling
A34: OTHERS | B34: Inventory Adjustment
A35: OTHERS | B35: Obsolete
A36: OTHERS | B36: Asset Sales
A38: OVERHEAD | B38: IT GLOBAL
A39: OVERHEAD | B39: G&A(Insurance included)

Sheet >>>

Sheet MTD Report  (HQD) (deneme)
B2: TD MTD Oct | C2: Actual Cost | I2: GP | M2: TC ALL | N2: TC WO GP | O2: GP TC
M3: 38.12 | N3: 37.43 | O3: 49.19 | P3: =O3/M3-1 -> 0.29039874 | T3: HC | U3: Unit price TRY
C4: ='data entry '!Q115 -> 53186 | I4: 6565 | T4: =(G7+G11+G12) -> 47.196781
B5: - Gain / +Loss | S5: Working meal | T5: =T4 -> 47.196781 | U5: 165.3 | V5: =T5*U5 -> 7801.6279
C6: EUR/000 | D6: €/pc | F6: HC | G6: GP | I6: EUR/000 | J6: €/pc | S6: Transport | T6: =T5 -> 47.196781 | U6: 185.43 | V6: =T6*U6*2 -> 17503.398
A7: MFG PERIMETER | B7: Direct Labor | C7: 961.83748 | D7: 8.5640541 | F7: 447 | G7: 34 | I7: =C7/F7*G7 -> 73.159898 | J7: =I7/$I$4*1000 -> 11.14393 | M7: =J7/D7-1 -> 0.30124465 | V7: =SUM(V4:V6) -> 25305.026
A8: MFG PERIMETER | B8: Variable Utilities | C8: 63.35664 | D8: 0.56411785 | I8: =D8*$I$4/1000 -> 3.7034337 | J8: =I8/$I$4*1000 -> 0.56411785
A9: MFG PERIMETER | B9: Other Variable (Production Consumable) | C9: 41.55311 | D9: 0.36998255 | I9: =D9*$I$4/1000 -> 2.4289354 | J9: =I9/$I$4*1000 -> 0.36998255
A10: MFG PERIMETER | B10: Variable Conv. | C10: 1066.7472 | D10: 9.4981545 | I10: =SUM(I7:I9) -> 79.292267 | J10: =SUM(J7:J9) -> 12.07803
A11: MFG PERIMETER | B11: Indirect Labour | C11: 409.57862 | D11: 3.6468255 | F11: 157 | G11: =9 -> 9 | I11: =C11/F11*G11 -> 23.479029 | J11: =I11/$I$4*1000 -> 3.5763944 | K11: 4 | M11: =C11/F11*K11 -> 10.435124 | N11: =M11*1000/I4 -> 1.5895086 | O11: CKD Impact
A12: MFG PERIMETER | B12: Fixed Labour | C12: 105.67001 | D12: 0.94086964 | F12: 34 | G12: =F12/C4*I4 -> 4.1967811 | I12: =D12*I4/1000 -> 6.1768092 | J12: =I12/$I$4*1000 -> 0.94086964
A13: MFG PERIMETER | B13: Semifixed | C13: 191.79625 | D13: 1.7077245 | I13: =D13*I4/1000 -> 11.211212 | J13: =I13/$I$4*1000 -> 1.7077245
A14: MFG PERIMETER | B14: Fixed utilities | C14: 4.03094 | D14: 0.035890874 | I14: =D14*$I$4/1000 -> 0.23562359 | J14: =I14/$I$4*1000 -> 0.035890874
A15: MFG PERIMETER | B15: Fixed Cost | C15: 52.07714 | D15: 0.46368691 | I15: =D15*$I$4/1000 -> 3.0441045 | J15: =I15/$I$4*1000 -> 0.46368691
A16: MFG PERIMETER | B16: Depreciation | C16: 78.79631 | D16: 0.70159032 | I16: =D16*$I$4/1000 -> 4.6059404 | J16: =I16/$I$4*1000 -> 0.70159032
A17: MFG PERIMETER | B17: Fixed Conv. | C17: 841.94927 | D17: 7.4965878 | I17: =SUM(I11:I16) -> 48.752718 | J17: =SUM(J11:J16) -> 7.4261567
A18: MFG PERIMETER | B18: TOTAL MFG COST w/o SHARES | C18: 1908.6965 | D18: 16.994742 | I18: =I17+I10 -> 128.04499 | J18: =I18/$I$4*1000 -> 19.504187
A19: MFG PERIMETER | B19: TOTAL SHARES | C19: 16.80699 | D19: 0.14964687 | I19: =D19*$I$4/1000 -> 0.98243172 | J19: =I19/$I$4*1000 -> 0.14964687
A20: MFG PERIMETER | B20: TOTAL MFG COST w/ SHARES | C20: 1925.5035 | D20: 17.144389 | I20: =I19+I18 -> 129.02742 | J20: =I20/$I$4*1000 -> 19.653834
A21: MFG PERIMETER | B21: Functional Currency Impact | C21: 263.21196 | D21: 2.3435991 | I21: =D21*$I$4/1000 -> 15.385728 | J21: =I21/$I$4*1000 -> 2.3435991
A22: MFG PERIMETER | B22: TOTAL Including FC | C22: 2188.7155 | D22: 19.487988 | I22: =I21+I20 -> 144.41315 | J22: =I22/$I$4*1000 -> 21.997433 | M22: =J22/D22-1 -> 0.12876878
J23: =I23/$I$4*1000 -> 0
A24: OTHERS | B24: Scrap | C24: 43.39548 | D24: 0.38638673 | J24: =I24/$I$4*1000 -> 0
A25: OTHERS | B25: Scrap Reselling | C25: -128.11905 | D25: -1.1407525 | J25: =I25/$I$4*1000 -> 0
A26: OTHERS | B26: Other Variable (Inventory Adj) | C26: 11.52424 | D26: 0.10261007 | J26: =I26/$I$4*1000 -> 0
A27: OTHERS | B27: Obsolete | C27: 25 | D27: 0.22259618 | J27: =I27/$I$4*1000 -> 0
A28: OTHERS | B28: Asset Sales | C28: 0 | D28: 0 | J28: =I28/$I$4*1000 -> 0
A29: OTHERS | B29: TOTAL OTHERS | C29: -48.19933 | D29: -0.42915948 | J29: =I29/$I$4*1000 -> 0
J30: =I30/$I$4*1000 -> 0
A31: OVERHEAD | B31: IT GLOBAL | C31: 213.47408 | D31: 1.9007406 | J31: =I31/$I$4*1000 -> 0
A32: OVERHEAD | B32: G&A(Insurance included) | C32: 93.09748 | D32: 0.82892575 | J32: =I32/$I$4*1000 -> 0
A33: OVERHEAD | B33: TOTAL OVERHEAD | C33: 306.57156 | D33: 2.7296664 | J33: =I33/$I$4*1000 -> 0
J34: =I34/$I$4*1000 -> 0
A35: ALL | B35: TOTAL ALL | C35: 2447.0877 | D35: 21.788495 | J35: =I35/$I$4*1000 -> 0
A37: Check | C37: 0 | D37: 0

Sheet MTD Report  (HQD)
B2: DW MTD May | C2: Budget26 | F2: Actual Cost | I2: 5+7Forecast | L2: Delta FCST vs ACT
C4: =+'MTD Report(HQD)_variance'!B4 -> 53265 | F4: =+'MTD Report(HQD)_variance'!Q4 -> 53186 | I4: 54900 | L4: =+F4-I4 -> -1714
B5: - Gain / +Loss
C6: EUR/000 | D6: €/pc | F6: EUR/000 | G6: €/pc | I6: EUR/000 | J6: €/pc
A7: MFG PERIMETER | B7: Direct Labor | C7: =+'MTD Report(HQD)_variance'!B7 -> 503 | D7: =+C7*1000/$C$4 -> 9.4433493 | F7: =+'MTD Report(HQD)_variance'!Q7 -> 391.63361 | G7: =+F7*1000/$F$4 -> 7.3634718 | I7: 460.9901 | J7: =+I7*1000/$I$4 -> 8.3969052 | L7: =+F7-I7 -> -69.356488 | M7: -28 k€ ISKUR impact(more efficient than FCST), -16 k€recharges to suppliers&ITCY, -13 k€ more efficienct than FCST, -5 k€ salary mix impact, -5 k€ less ovt than FCST -2k€ annual leave days accrual gain
A8: MFG PERIMETER | B8: Variable Utilities | C8: =+'MTD Report(HQD)_variance'!B8 -> 35.762038 | D8: =+C8*1000/$C$4 -> 0.67139844 | F8: =+'MTD Report(HQD)_variance'!Q8 -> 28.66065 | G8: =+F8*1000/$F$4 -> 0.53887583 | I8: 39.635645 | J8: =+I8*1000/$I$4 -> 0.72196076 | L8: =+F8-I8 -> -10.974995
A9: MFG PERIMETER | B9: Other Variable (Production Consumable) | C9: =+'MTD Report(HQD)_variance'!B9 -> 17.5665 | D9: =+C9*1000/$C$4 -> 0.32979442 | F9: =+'MTD Report(HQD)_variance'!Q9 -> 28.88567 | G9: =+F9*1000/$F$4 -> 0.54310664 | I9: 17.076248 | J9: =+I9*1000/$I$4 -> 0.31104278 | L9: =+F9-I9 -> 11.809422
A10: MFG PERIMETER | B10: Variable Conv. | C10: =+'MTD Report(HQD)_variance'!B10 -> 556.32854 | D10: =+C10*1000/$C$4 -> 10.444542 | F10: =+'MTD Report(HQD)_variance'!Q10 -> 449.17993 | G10: =+F10*1000/$F$4 -> 8.4454543 | I10: 517.70199 | J10: =+I10*1000/$I$4 -> 9.4299088 | L10: =+F10-I10 -> -68.522062
A11: MFG PERIMETER | B11: Indirect Labour | C11: =+'MTD Report(HQD)_variance'!B11 -> 217.31856 | D11: =+C11*1000/$C$4 -> 4.0799504 | F11: =+'MTD Report(HQD)_variance'!Q11 -> 229.24062 | G11: =+F11*1000/$F$4 -> 4.3101685 | I11: 221.9721 | J11: =+I11*1000/$I$4 -> 4.0432076 | L11: =+F11-I11 -> 7.2685249
A12: MFG PERIMETER | B12: Fixed Labour | C12: =+'MTD Report(HQD)_variance'!B12 -> 107.62726 | D12: =+C12*1000/$C$4 -> 2.0206001 | F12: =+'MTD Report(HQD)_variance'!Q12 -> 111.60063 | G12: =+F12*1000/$F$4 -> 2.0983084 | I12: 109.70635 | J12: =+I12*1000/$I$4 -> 1.9982942 | L12: =+F12-I12 -> 1.8942799
A13: MFG PERIMETER | B13: Semifixed | C13: =+'MTD Report(HQD)_variance'!B13 -> 188.37864 | D13: =+C13*1000/$C$4 -> 3.5366307 | F13: =+'MTD Report(HQD)_variance'!Q13 -> 111.35076 | G13: =+F13*1000/$F$4 -> 2.0936103 | I13: 196.44185 | J13: =+I13*1000/$I$4 -> 3.5781758 | L13: =+F13-I13 -> -85.09109 | M13: 56 k€ less expense on mnt
A14: MFG PERIMETER | B14: Fixed utilities | C14: =+'MTD Report(HQD)_variance'!B14 -> 6 | D14: =+C14*1000/$C$4 -> 0.11264433 | F14: =+'MTD Report(HQD)_variance'!Q14 -> 2.00758 | G14: =+F14*1000/$F$4 -> 0.037746399 | I14: 6.731241 | J14: =+I14*1000/$I$4 -> 0.12260913 | L14: =+F14-I14 -> -4.723661
A15: MFG PERIMETER | B15: Fixed Cost | C15: =+'MTD Report(HQD)_variance'!B15 -> 43.825739 | D15: =+C15*1000/$C$4 -> 0.82278681 | F15: =+'MTD Report(HQD)_variance'!Q15 -> 50.4317 | G15: =+F15*1000/$F$4 -> 0.94821382 | I15: 48.289824 | J15: =+I15*1000/$I$4 -> 0.87959606 | L15: =+F15-I15 -> 2.1418763
A16: MFG PERIMETER | B16: Depreciation | C16: =+'MTD Report(HQD)_variance'!B16 -> 152.87378 | D16: =+C16*1000/$C$4 -> 2.8700606 | F16: =+'MTD Report(HQD)_variance'!Q16 -> 132.04277 | G16: =+F16*1000/$F$4 -> 2.4826603 | I16: 140.00134 | J16: =+I16*1000/$I$4 -> 2.5501155 | L16: =+F16-I16 -> -7.9585723
A17: MFG PERIMETER | B17: Fixed Conv. | C17: =+'MTD Report(HQD)_variance'!B17 -> 716.02398 | D17: =+C17*1000/$C$4 -> 13.442673 | F17: =+'MTD Report(HQD)_variance'!Q17 -> 636.67406 | G17: =+F17*1000/$F$4 -> 11.970708 | I17: 723.1427 | J17: =+I17*1000/$I$4 -> 13.171998 | L17: =+F17-I17 -> -86.468642
A18: MFG PERIMETER | B18: TOTAL MFG COST w/o SHARES | C18: =+'MTD Report(HQD)_variance'!B18 -> 1272.3525 | D18: =+C18*1000/$C$4 -> 23.887215 | F18: =+'MTD Report(HQD)_variance'!Q18 -> 1085.854 | G18: =+F18*1000/$F$4 -> 20.416162 | I18: 1240.8447 | J18: =+I18*1000/$I$4 -> 22.601907 | L18: =+F18-I18 -> -154.9907
A19: MFG PERIMETER | B19: TOTAL SHARES | C19: =+'MTD Report(HQD)_variance'!B19 -> 20.474517 | D19: =+C19*1000/$C$4 -> 0.3843897 | F19: =+'MTD Report(HQD)_variance'!Q19 -> 5.0717 | G19: =+F19*1000/$F$4 -> 0.095357801 | I19: 13.453346 | J19: =+I19*1000/$I$4 -> 0.24505184 | L19: =+F19-I19 -> -8.3816461
A20: MFG PERIMETER | B20: TOTAL MFG COST w/ SHARES | C20: =+'MTD Report(HQD)_variance'!B20 -> 1292.827 | D20: =+C20*1000/$C$4 -> 24.271605 | F20: =+'MTD Report(HQD)_variance'!Q20 -> 1090.9257 | G20: =+F20*1000/$F$4 -> 20.51152 | I20: 1254.298 | J20: =+I20*1000/$I$4 -> 22.846959 | L20: =+F20-I20 -> -163.37235
A21: MFG PERIMETER | B21: Functional Currency Impact | C21: =+'MTD Report(HQD)_variance'!B22 -> 416.35266 | D21: =+C21*1000/$C$4 -> 7.8166274 | F21: =+'MTD Report(HQD)_variance'!Q22 -> 301.40709 | G21: =+F21*1000/$F$4 -> 5.6670381 | I21: 304.784 | J21: =+I21*1000/$I$4 -> 5.5516211 | L21: =+F21-I21 -> -3.37691
A22: MFG PERIMETER | B22: TOTAL Including FC | C22: =+C21+C20 -> 1709.1797 | D22: =+C22*1000/$C$4 -> 32.088232 | F22: =+F21+F20 -> 1392.3328 | G22: =+F22*1000/$F$4 -> 26.178558 | I22: 1559.082 | J22: =+I22*1000/$I$4 -> 28.39858 | L22: =+F22-I22 -> -166.74926
A24: OTHERS | B24: Scrap | C24: =+'MTD Report(HQD)_variance'!B25 -> 21 | D24: =+C24*1000/$C$4 -> 0.39425514 | F24: =+'MTD Report(HQD)_variance'!Q25 -> 27.97038 | G24: =+F24*1000/$F$4 -> 0.52589742 | I24: 23.30592 | J24: =+I24*1000/$I$4 -> 0.42451585 | L24: =+F24-I24 -> 4.66446
A25: OTHERS | B25: Scrap Reselling | C25: =+'MTD Report(HQD)_variance'!B26 -> -53 | D25: =+C25*1000/$C$4 -> -0.99502488 | F25: =+'MTD Report(HQD)_variance'!Q26 -> -74.14161 | G25: =+F25*1000/$F$4 -> -1.3940061 | I25: -51.571118 | J25: =+I25*1000/$I$4 -> -0.93936463 | L25: =+F25-I25 -> -22.570492
A26: OTHERS | B26: Other Variable (Inventory Adj) | C26: =+'MTD Report(HQD)_variance'!B27 -> 0 | D26: =+C26*1000/$C$4 -> 0 | F26: =+'MTD Report(HQD)_variance'!Q27 -> -8.91442 | G26: =+F26*1000/$F$4 -> -0.16760839 | I26: 0 | J26: =+I26*1000/$I$4 -> 0 | L26: =+F26-I26 -> -8.91442
A27: OTHERS | B27: Obsolete | C27: =+'MTD Report(HQD)_variance'!B28 -> 8 | D27: =+C27*1000/$C$4 -> 0.15019243 | F27: =+'MTD Report(HQD)_variance'!Q28 -> -30.71528 | G27: =+F27*1000/$F$4 -> -0.57750686 | I27: 14.970477 | J27: =+I27*1000/$I$4 -> 0.27268628 | L27: =+F27-I27 -> -45.685757
A28: OTHERS | B28: Asset Sales | C28: =+'MTD Report(HQD)_variance'!B29 -> 0 | D28: =+C28*1000/$C$4 -> 0 | F28: =+'MTD Report(HQD)_variance'!Q29 -> 0 | G28: =+F28*1000/$F$4 -> 0 | I28: 0 | J28: =+I28*1000/$I$4 -> 0 | L28: =+F28-I28 -> 0 | M28: Aging risk is decreased especially for active materials
A29: OTHERS | B29: TOTAL OTHERS | C29: =+'MTD Report(HQD)_variance'!B30 -> -24 | D29: =+C29*1000/$C$4 -> -0.4505773 | F29: =+'MTD Report(HQD)_variance'!Q30 -> -85.80093 | G29: =+F29*1000/$F$4 -> -1.613224 | I29: -13.294721 | J29: =+I29*1000/$I$4 -> -0.2421625 | L29: =+F29-I29 -> -72.506209
A31: OVERHEAD | B31: IT GLOBAL | C31: =+'MTD Report(HQD)_variance'!B32 -> 90.697223 | D31: =+C31*1000/$C$4 -> 1.7027546 | F31: =+'MTD Report(HQD)_variance'!Q32 -> 89.41512 | G31: =+F31*1000/$F$4 -> 1.6811778 | I31: 90.697222 | J31: =+I31*1000/$I$4 -> 1.6520441 | L31: =+F31-I31 -> -1.2821024
A32: OVERHEAD | B32: G&A(Insurance included) | C32: =+'MTD Report(HQD)_variance'!B33 -> 94.532002 | D32: =+C32*1000/$C$4 -> 1.7747489 | F32: =+'MTD Report(HQD)_variance'!Q33 -> 43.15732 | G32: =+F32*1000/$F$4 -> 0.81144136 | I32: 48.601049 | J32: =+I32*1000/$I$4 -> 0.88526502 | L32: =+F32-I32 -> -5.4437294
A33: OVERHEAD | B33: TOTAL OVERHEAD | C33: =SUM(C31:C32) -> 185.22922 | D33: =+C33*1000/$C$4 -> 3.4775035 | F33: =SUM(F31:F32) -> 132.57244 | G33: =+F33*1000/$F$4 -> 2.4926191 | I33: 139.29827 | J33: =+I33*1000/$I$4 -> 2.5373091 | L33: =+F33-I33 -> -6.7258318
A35: ALL | B35: GRAND TOTAL | C35: =+C33+C29+C22 -> 1870.4089 | D35: =+C35*1000/$C$4 -> 35.115159 | F35: =+F33+F29+F22 -> 1439.1043 | G35: =+F35*1000/$F$4 -> 27.057953 | I35: 1685.0856 | J35: =+I35*1000/$I$4 -> 30.693727 | L35: =+F35-I35 -> -245.9813
A37: Check | C37: =+C35*1000-'MTD Report(HQD)_variance'!B36*1000 -> 0 | F37: =+F35*1000-'MTD Report(HQD)_variance'!Q36*1000 -> 0

Sheet YTD Report  (HQD)
B2: DW YTD MAY | C2: Budget26 | F2: Actual Cost | I2: 5+7 Forecast | L2: Delta FCST vs ACT
C4: =+'YTD Report(HQD)_variance '!B4 -> 289459 | F4: =+'YTD Report(HQD)_variance '!Q4 -> 240074 | I4: 241788 | L4: =+F4-I4 -> -1714
B5: - Gain / +Loss
C6: EUR/000 | D6: €/pc | F6: EUR/000 | G6: €/pc | I6: EUR/000 | J6: €/pc
A7: MFG PERIMETER | B7: Direct Labor | C7: =+'YTD Report(HQD)_variance '!B7 -> 3129 | D7: =+C7*1000/$C$4 -> 10.809821 | F7: =+'YTD Report(HQD)_variance '!Q7 -> 2418.8816 | G7: =+F7*1000/$F$4 -> 10.075567 | I7: 2488.2381 | J7: =+I7*1000/$I$4 -> 10.290991 | L7: =+F7-I7 -> -69.356488
A8: MFG PERIMETER | B8: Variable Utilities | C8: =+'YTD Report(HQD)_variance '!B8 -> 209.56944 | D8: =+C8*1000/$C$4 -> 0.72400387 | F8: =+'YTD Report(HQD)_variance '!Q8 -> 151.60735 | G8: =+F8*1000/$F$4 -> 0.63150258 | I8: 162.58235 | J8: =+I8*1000/$I$4 -> 0.67241693 | L8: =+F8-I8 -> -10.974995
A9: MFG PERIMETER | B9: Other Variable (Production Consumable) | C9: =+'YTD Report(HQD)_variance '!B9 -> 95.361 | D9: =+C9*1000/$C$4 -> 0.32944562 | F9: =+'YTD Report(HQD)_variance '!Q9 -> 113.14721 | G9: =+F9*1000/$F$4 -> 0.47130139 | I9: 101.33779 | J9: =+I9*1000/$I$4 -> 0.41911835 | L9: =+F9-I9 -> 11.809422
A10: MFG PERIMETER | B10: Variable Conv. | C10: =+'YTD Report(HQD)_variance '!B10 -> 3433.9304 | D10: =+C10*1000/$C$4 -> 11.863271 | F10: =+'YTD Report(HQD)_variance '!Q10 -> 2683.6361 | G10: =+F10*1000/$F$4 -> 11.178371 | I10: 2752.1582 | J10: =+I10*1000/$I$4 -> 11.382526 | L10: =+F10-I10 -> -68.522062
A11: MFG PERIMETER | B11: Indirect Labour | C11: =+'YTD Report(HQD)_variance '!B11 -> 1264.7213 | D11: =+C11*1000/$C$4 -> 4.369259 | F11: =+'YTD Report(HQD)_variance '!Q11 -> 1325.2768 | G11: =+F11*1000/$F$4 -> 5.5202847 | I11: 1318.0083 | J11: =+I11*1000/$I$4 -> 5.4510906 | L11: =+F11-I11 -> 7.2685249
A12: MFG PERIMETER | B12: Fixed Labour | C12: =+'YTD Report(HQD)_variance '!B12 -> 644.90809 | D12: =+C12*1000/$C$4 -> 2.2279773 | F12: =+'YTD Report(HQD)_variance '!Q12 -> 636.09685 | G12: =+F12*1000/$F$4 -> 2.6495866 | I12: 634.20257 | J12: =+I12*1000/$I$4 -> 2.6229696 | L12: =+F12-I12 -> 1.8942799
A13: MFG PERIMETER | B13: Semifixed | C13: =+'YTD Report(HQD)_variance '!B13 -> 1060.8528 | D13: =+C13*1000/$C$4 -> 3.66495 | F13: =+'YTD Report(HQD)_variance '!Q13 -> 906.21602 | G13: =+F13*1000/$F$4 -> 3.7747362 | I13: 991.30711 | J13: =+I13*1000/$I$4 -> 4.099902 | L13: =+F13-I13 -> -85.09109
A14: MFG PERIMETER | B14: Fixed utilities | C14: =+'YTD Report(HQD)_variance '!B14 -> 32 | D14: =+C14*1000/$C$4 -> 0.11055106 | F14: =+'YTD Report(HQD)_variance '!Q14 -> 16.25655 | G14: =+F14*1000/$F$4 -> 0.067714746 | I14: 20.980211 | J14: =+I14*1000/$I$4 -> 0.086771101 | L14: =+F14-I14 -> -4.723661
A15: MFG PERIMETER | B15: Fixed Cost | C15: =+'YTD Report(HQD)_variance '!B15 -> 262.61091 | D15: =+C15*1000/$C$4 -> 0.90724733 | F15: =+'YTD Report(HQD)_variance '!Q15 -> 205.53572 | G15: =+F15*1000/$F$4 -> 0.85613486 | I15: 203.39384 | J15: =+I15*1000/$I$4 -> 0.84120735 | L15: =+F15-I15 -> 2.1418763
A16: MFG PERIMETER | B16: Depreciation | C16: =+'YTD Report(HQD)_variance '!B16 -> 935.32923 | D16: =+C16*1000/$C$4 -> 3.2313013 | F16: =+'YTD Report(HQD)_variance '!Q16 -> 748.35691 | G16: =+F16*1000/$F$4 -> 3.1171926 | I16: 756.31548 | J16: =+I16*1000/$I$4 -> 3.1280108 | L16: =+F16-I16 -> -7.9585723
A17: MFG PERIMETER | B17: Fixed Conv. | C17: =+'YTD Report(HQD)_variance '!B17 -> 4200.4223 | D17: =+C17*1000/$C$4 -> 14.511286 | F17: =+'YTD Report(HQD)_variance '!Q17 -> 3837.7389 | G17: =+F17*1000/$F$4 -> 15.98565 | I17: 3924.2075 | J17: =+I17*1000/$I$4 -> 16.229951 | L17: =+F17-I17 -> -86.468642
A18: MFG PERIMETER | B18: TOTAL MFG COST w/o SHARES | C18: =+'YTD Report(HQD)_variance '!B18 -> 7634.3528 | D18: =+C18*1000/$C$4 -> 26.374557 | F18: =+'YTD Report(HQD)_variance '!Q18 -> 6521.375 | G18: =+F18*1000/$F$4 -> 27.16402 | I18: 6676.3657 | J18: =+I18*1000/$I$4 -> 27.612478 | L18: =+F18-I18 -> -154.9907
... A20: MFG PERIMETER | B20: TOTAL MFG COST w/ SHARES | C20: =+'YTD Report(HQD)_variance '!B20 -> 7759.6885 | D20: =+C20*1000/$C$4 -> 26.807557 | F20: =+'YTD Report(HQD)_variance '!Q20 -> 6623.8096 | G20: =+F20*1000/$F$4 -> 27.5907 | I20: 6787.1819 | J20: =+I20*1000/$I$4 -> 28.070797 | L20: =+F20-I20 -> -163.37235
A21: MFG PERIMETER | B21: Functional Currency Impact | C21: =+'YTD Report(HQD)_variance '!B22 -> 2478.1861 | D21: =+C21*1000/$C$4 -> 8.5614407 | F21: =+'YTD Report(HQD)_variance '!Q22 -> 1802.1403 | G21: =+F21*1000/$F$4 -> 7.5066036 | I21: 1805.5173 | J21: =+I21*1000/$I$4 -> 7.4673567 | L21: =+F21-I21 -> -3.37691
A22: MFG PERIMETER | B22: TOTAL Including FC | C22: =+'YTD Report(HQD)_variance '!B23 -> 10237.875 | D22: =+C22*1000/$C$4 -> 35.368997 | F22: =+F21+F20 -> 8425.9499 | G22: =+F22*1000/$F$4 -> 35.097303 | I22: 8592.6992 | J22: =+I22*1000/$I$4 -> 35.538154 | L22: =+F22-I22 -> -166.74926
A24: OTHERS | B24: Scrap | C24: =+'YTD Report(HQD)_variance '!B25 -> 136 | D24: =+C24*1000/$C$4 -> 0.46984202 | F24: =+'YTD Report(HQD)_variance '!Q25 -> 136.63113 | G24: =+F24*1000/$F$4 -> 0.5691209 | I24: 131.96667 | J24: =+I24*1000/$I$4 -> 0.54579495 | L24: =+F24-I24 -> 4.66446
A25: OTHERS | B25: Scrap Reselling | C25: =+'YTD Report(HQD)_variance '!B26 -> -303 | D25: =+C25*1000/$C$4 -> -1.0467804 | F25: =+'YTD Report(HQD)_variance '!Q26 -> -306.81066 | G25: =+F25*1000/$F$4 -> -1.2779837 | I25: -284.24017 | J25: =+I25*1000/$I$4 -> -1.175576 | L25: =+F25-I25 -> -22.570492
A26: OTHERS | B26: Other Variable (Inventory Adj) | C26: =+'YTD Report(HQD)_variance '!B27 -> 0 | D26: =+C26*1000/$C$4 -> 0 | F26: =+'YTD Report(HQD)_variance '!Q27 -> 63.28184 | G26: =+F26*1000/$F$4 -> 0.26359306 | I26: 72.19626 | J26: =+I26*1000/$I$4 -> 0.29859323 | L26: =+F26-I26 -> -8.91442
A27: OTHERS | B27: Obsolete | C27: =+'YTD Report(HQD)_variance '!B28 -> 52 | D27: =+C27*1000/$C$4 -> 0.17964548 | F27: =+'YTD Report(HQD)_variance '!Q28 -> 17.3384 | G27: =+F27*1000/$F$4 -> 0.072221065 | I27: 63.024157 | J27: =+I27*1000/$I$4 -> 0.26065875 | L27: =+F27-I27 -> -45.685757
A28: OTHERS | B28: Asset Sales | C28: =+'YTD Report(HQD)_variance '!B29 -> 0 | D28: =+C28*1000/$C$4 -> 0 | F28: =+'YTD Report(HQD)_variance '!Q29 -> 0 | G28: =+F28*1000/$F$4 -> 0 | I28: 0 | J28: =+I28*1000/$I$4 -> 0 | L28: =+F28-I28 -> 0
A29: OTHERS | B29: TOTAL OTHERS | C29: =+'YTD Report(HQD)_variance '!B30 -> -115 | D29: =+C29*1000/$C$4 -> -0.39729288 | F29: =+'YTD Report(HQD)_variance '!Q30 -> -89.55929 | G29: =+F29*1000/$F$4 -> -0.37304868 | I29: -17.053081 | J29: =+I29*1000/$I$4 -> -0.070529064 | L29: =+F29-I29 -> -72.506209
A31: OVERHEAD | B31: IT GLOBAL | C31: =+'YTD Report(HQD)_variance '!B32 -> 544.18334 | D31: =+C31*1000/$C$4 -> 1.8800014 | F31: =+'YTD Report(HQD)_variance '!Q32 -> 535.96594 | G31: =+F31*1000/$F$4 -> 2.2325031 | I31: 537.24804 | J31: =+I31*1000/$I$4 -> 2.2219798 | L31: =+F31-I31 -> -1.2821024
A32: OVERHEAD | B32: G&A(Insurance included) | C32: =+'YTD Report(HQD)_variance '!B33 -> 567.19201 | D32: =+C32*1000/$C$4 -> 1.95949 | F32: =+'YTD Report(HQD)_variance '!Q33 -> 538.91129 | G32: =+F32*1000/$F$4 -> 2.2447716 | I32: 544.35502 | J32: =+I32*1000/$I$4 -> 2.2513732 | L32: =+F32-I32 -> -5.4437294
A33: OVERHEAD | B33: TOTAL OVERHEAD | C33: =SUM(C31:C32) -> 1111.3753 | D33: =+C33*1000/$C$4 -> 3.8394914 | F33: =SUM(F31:F32) -> 1074.8772 | G33: =+F33*1000/$F$4 -> 4.4772746 | I33: 1081.6031 | J33: =+I33*1000/$I$4 -> 4.4733529 | L33: =+F33-I33 -> -6.7258318
A35: ALL | B35: GRAND TOTAL | C35: =+C33+C29+C22 -> 11234.25 | D35: =+C35*1000/$C$4 -> 38.811196 | F35: =+F33+F29+F22 -> 9411.2679 | G35: =+F35*1000/$F$4 -> 39.201529 | I35: 9657.2492 | J35: =+I35*1000/$I$4 -> 39.940978 | L35: =+F35-I35 -> -245.9813
A37: Check | C37: =+C35*1000-'YTD Report(HQD)_variance '!B36*1000 -> 0 | F37: =+F35*1000-'YTD Report(HQD)_variance '!Q36*1000 -> 0

Sheet MTD VAR 
A1: Volume | B1: =+'Budget assumption'!Q35 -> 71500 | C1: =H1-B1 -> -18235 | H1: ='Budget assumption'!Q66 -> 53265 | I1: ='Budget assumption'!Q321 -> 0 | K1: ='data entry '!Q82 -> 53186 | M1: ='data entry '!Q115 -> 53186 | AA1: EFF | AB1: variable cost | AC1: Actual minus Copertura
B2: EUR | C2: EUR | H2: EUR | I2: EUR | K2: EUR | M2: EUR | Q2: Variances vs Budget | V2: Variances vs STD | AB2: fixed cost | AC2: Actual minus Budget
A3: Cost Elements | B3: STD | C3: Delta Volume | D3: ACE | E3: HW / TW | F3: Price FX | G3: Seasonality | H3: Plan Costs | I3: Budget VAR | K3: Copertura | M3: Act. Costs | O3: Variance vs STD | Q3: EFF | R3: FCA | S3: Total Variance | V3: EFF | W3: FCA | X3: Total Variance
D4: ACE
I5: FCA
A6: Direct Labour | B6: ='Budget assumption'!Q37 -> 813.54709 | C6: ='Budget assumption'!Q70 -> -207.48295 | D6: ='Budget assumption'!Q118 -> -49.280033 | E6: ='Budget assumption'!Q149 -> -38.746752 | F6: ='Budget assumption'!Q180 -> 66.129739 | G6: ='Budget assumption'!Q242+'Budget assumption'!Q273 -> -81.167087 | H6: ='Budget assumption'!Q211 -> 503 | J6: =H6-SUM(B6:G6) -> 0 | K6: ='data entry '!Q84 -> 598.40414 | M6: ='data entry '!Q117 -> 391.63361 | O6: =M6-K6 -> -206.77053 | Q6: =M6-K6-E6-F6-D6-G6 -> -103.7064 | S6: =Q6+R6 -> -103.7064 | V6: =M6-K6 -> -206.77053 | X6: =V6+W6 -> -206.77053
A7: Variable Utilities | B7: ='Budget assumption'!Q38 -> 55.137763 | C7: ='Budget assumption'!Q71 -> -14.062057 | D7: ='Budget assumption'!Q119 -> 0 | E7: ='Budget assumption'!Q150 -> 0 | F7: ='Budget assumption'!Q181 -> -4.1759045 | G7: ='Budget assumption'!Q243+'Budget assumption'!Q274 -> -1.1377628 | H7: ='Budget assumption'!Q212 -> 35.762038 | J7: =H7-SUM(B7:G7) -> 0 | K7: ='data entry '!Q85 -> 39.841032 | M7: ='data entry '!Q118 -> 28.66065 | O7: =M7-K7 -> -11.180382 | Q7: =M7-K7-E7-F7-D7-G7 -> -5.8667146 | S7: =Q7+R7 -> -5.8667146 | V7: =M7-K7 -> -11.180382 | X7: =V7+W7 -> -11.180382
A8: Variable Costs | B8: ='Budget assumption'!Q39 -> 25.133277 | C8: ='Budget assumption'!Q72 -> -6.4098644 | D8: ='Budget assumption'!Q120 -> -1 | E8: ='Budget assumption'!Q151 -> 0 | F8: ='Budget assumption'!Q182 -> -0.15363563 | G8: ='Budget assumption'!Q244+'Budget assumption'!Q275 -> -0.0032767818 | H8: ='Budget assumption'!Q213 -> 17.5665 | J8: =H8-SUM(B8:G8) -> 0 | K8: ='data entry '!Q86 -> 17.021983 | M8: ='data entry '!Q119 -> 28.88567 | O8: =M8-K8 -> 11.863687 | Q8: =M8-K8-E8-F8-D8-G8 -> 13.020599 | S8: =Q8+R8 -> 13.020599 | V8: =M8-K8 -> 11.863687 | X8: =V8+W8 -> 11.863687
A9: VARIABLE CONVERSION | B9: =SUM(B6:B8) -> 893.81813 | C9: =SUM(C6:C8) -> -227.95487 | D9: =SUM(D6:D8) -> -50.280033 | E9: =SUM(E6:E8) -> -38.746752 | F9: =SUM(F6:F8) -> 61.800199 | G9: =SUM(G6:G8) -> -82.308127 | H9: =SUM(H6:H8) -> 556.32854 | I9: =SUM(I6:I8) -> 0 | J9: =H9-SUM(B9:G9) -> 0 | K9: =SUM(K6:K8) -> 655.26716 | M9: =SUM(M6:M8) -> 449.17993 | O9: =SUM(O6:O8) -> -206.08723 | Q9: =SUM(Q6:Q8) -> -96.552512 | R9: =SUM(R6:R8) -> 0 | S9: =SUM(S6:S8) -> -96.552512 | V9: =SUM(V6:V8) -> -206.08723 | W9: =SUM(W6:W8) -> 0 | X9: =SUM(X6:X8) -> -206.08723
A10: Indirect Labour | B10: ='Budget assumption'!Q41 -> 319.09496 | D10: ='Budget assumption'!Q122 -> 0 | E10: ='Budget assumption'!Q153 -> -42 | F10: ='Budget assumption'!Q184 -> -18.861442 | G10: ='Budget assumption'!Q246+'Budget assumption'!Q277 -> -40.914958 | H10: ='Budget assumption'!Q215 -> 217.31856 | I10: ='Budget assumption'!Q323 -> 81.380371 | J10: =H10-SUM(B10:G10) -> 0 | K10: ='data entry '!Q88 -> 236.64471 | M10: ='data entry '!Q121 -> 229.24062 | O10: =M10-K10 -> -7.4040914 | Q10: =M10-H10 -> 11.922062 | R10: =H10-K10-E10-I10-F10-G10-D10 -> 1.0698749 | S10: =Q10+R10 -> 12.991937 | V10: =M10-B10 -> -89.854338 | W10: =B10-K10 -> 82.450246 | X10: =V10+W10 -> -7.4040914
A11: Fixed Labour | B11: ='Budget assumption'!Q42 -> 115.42242 | D11: ='Budget assumption'!Q123 -> 0 | E11: ='Budget assumption'!Q154 -> 7 | F11: ='Budget assumption'!Q185 -> 12.297265 | G11: ='Budget assumption'!Q247+'Budget assumption'!Q278 -> -27.092424 | H11: ='Budget assumption'!Q216 -> 107.62726 | I11: ='Budget assumption'!Q324 -> 29.436754 | J11: =H11-SUM(B11:G11) -> 0 | K11: ='data entry '!Q89 -> 83.695495 | M11: ='data entry '!Q122 -> 111.60063 | O11: =M11-K11 -> 27.905135 | Q11: =M11-H11 -> 3.9733651 | R11: =H11-K11-E11-I11-F11-G11-D11 -> 2.2901751 | S11: =Q11+R11 -> 6.2635402 | V11: =M11-B11 -> -3.8217938 | W11: =B11-K11 -> 31.726929 | X11: =V11+W11 -> 27.905135
A12: Semifixed | B12: ='Budget assumption'!Q43 -> 222.84033 | D12: ='Budget assumption'!Q124 -> 0 | E12: ='Budget assumption'!Q155 -> -13.429082 | F12: ='Budget assumption'!Q186 -> -4.3322822 | G12: ='Budget assumption'!Q248+'Budget assumption'!Q279 -> -16.700329 | H12: ='Budget assumption'!Q217 -> 188.37864 | I12: ='Budget assumption'!Q325 -> 56.832075 | J12: =H12-SUM(B12:G12) -> 0 | K12: ='data entry '!Q90 -> 162.06681 | M12: ='data entry '!Q123 -> 111.35076 | O12: =M12-K12 -> -50.716054 | Q12: =M12-H12 -> -77.027875 | R12: =H12-K12-E12-I12-F12-G12-D12 -> 3.941439 | S12: =Q12+R12 -> -73.086436 | V12: =M12-B12 -> -111.48957 | W12: =B12-K12 -> 60.773514 | X12: =V12+W12 -> -50.716054
A13: Fixed utilities | B13: ='Budget assumption'!Q44 -> 14.176767 | D13: ='Budget assumption'!Q125 -> -1.1 | E13: ='Budget assumption'!Q156 -> -2 | F13: ='Budget assumption'!Q187 -> -5.17 | G13: ='Budget assumption'!Q249+'Budget assumption'!Q280 -> 0.0932329 | H13: ='Budget assumption'!Q218 -> 6 | I13: ='Budget assumption'!Q326 -> 3.6155713 | J13: =H13-SUM(B13:G13) -> 0 | K13: ='data entry '!Q91 -> 8.8590025 | M13: ='data entry '!Q124 -> 2.00758 | O13: =M13-K13 -> -6.8514225 | Q13: =M13-H13 -> -3.99242 | R13: =H13-K13-E13-I13-F13-G13-D13 -> 1.7021933 | S13: =Q13+R13 -> -2.2902267 | V13: =M13-B13 -> -12.169187 | W13: =B13-K13 -> 5.3177646 | X13: =V13+W13 -> -6.8514225
A14: Fixed Cost | B14: ='Budget assumption'!Q45 -> 49.7397 | D14: ='Budget assumption'!Q126 -> 0 | E14: ='Budget assumption'!Q157 -> 0 | F14: ='Budget assumption'!Q188 -> 4.7347992 | G14: ='Budget assumption'!Q250+'Budget assumption'!Q281 -> -10.64876 | H14: ='Budget assumption'!Q219 -> 43.825739 | I14: ='Budget assumption'!Q327 -> 12.685363 | J14: =H14-SUM(B14:G14) -> 0 | K14: ='data entry '!Q92 -> 41.414629 | M14: ='data entry '!Q125 -> 50.4317 | O14: =M14-K14 -> 9.0170707 | Q14: =M14-H14 -> 6.6059608 | R14: =H14-K14-E14-I14-F14-G14-D14 -> -4.3602923 | S14: =Q14+R14 -> 2.2456685 | V14: =M14-B14 -> 0.69200048 | W14: =B14-K14 -> 8.3250702 | X14: =V14+W14 -> 9.0170707
A15: Depreciation | B15: ='Budget assumption'!Q46 -> 194.73892 | D15: ='Budget assumption'!Q127 -> 0 | E15: ='Budget assumption'!Q158 -> 1.1397408 | F15: ='Budget assumption'!Q189 -> -0.0033 | G15: ='Budget assumption'!Q251+'Budget assumption'!Q282 -> -43.001579 | H15: ='Budget assumption'!Q220 -> 152.87378 | I15: ='Budget assumption'!Q329 -> 49.665233 | J15: =H15-SUM(B15:G15) -> 0 | K15: ='data entry '!Q93 -> 543.42574 | M15: ='data entry '!Q126 -> 132.04277 | O15: =M15-K15 -> -411.38297 | Q15: =M15-H15 -> -20.83101 | R15: =H15-K15-E15-I15-F15-G15-D15 -> -398.35205 | S15: =Q15+R15 -> -419.18306 | V15: =M15-B15 -> -62.696148 | W15: =B15-K15 -> -348.68682 | X15: =V15+W15 -> -411.38297
A16: FIXED CONVERSION | B16: =SUM(B10:B15) -> 916.0131 | C16: =SUM(C10:C15) -> 0 | D16: =SUM(D10:D15) -> -1.1 | E16: =SUM(E10:E15) -> -49.289342 | F16: =SUM(F10:F15) -> -11.33496 | G16: =SUM(G10:G15) -> -138.26482 | H16: =SUM(H10:H15) -> 716.02398 | I16: =SUM(I10:I15) -> 233.61537 | J16: =H16-SUM(B16:G16) -> 0 | K16: =SUM(K10:K15) -> 1076.1064 | M16: =SUM(M10:M15) -> 636.67406 | O16: =SUM(O10:O15) -> -439.43233 | Q16: =SUM(Q10:Q15) -> -79.349918 | R16: =SUM(R10:R15) -> -393.70866 | S16: =Q16+R16 -> -473.05858 | V16: =SUM(V10:V15) -> -279.33904 | W16: =SUM(W10:W15) -> -160.09329 | X16: =SUM(X10:X15) -> -439.43233
A17: TOTAL MFG COST w/o SHARES | B17: =B9+B16 -> 1809.8312 | C17: =C9+C16 -> -227.95487 | D17: =D9+D16 -> -51.380033 | E17: =E9+E16 -> -88.036094 | F17: =F9+F16 -> 50.465239 | G17: =G9+G16 -> -220.57294 | H17: =H9+H16 -> 1272.3525 | I17: =I9+I16 -> 233.61537 | J17: =H17-SUM(B17:G17) -> 0 | K17: =K9+K16 -> 1731.3735 | M17: =M9+M16 -> 1085.854 | O17: =M17-K17 -> -645.51956 | Q17: =Q9+Q16 -> -175.90243 | R17: =R9+R16 -> -393.70866 | S17: =Q17+R17 -> -569.61109 | V17: =V9+V16 -> -485.42626 | W17: =W9+W16 -> -160.09329 | X17: =X9+X16 -> -645.51956
A18: TOTAL SHARES | B18: ='Budget assumption'!Q49 -> 12.784403 | D18: ='Budget assumption'!Q130 -> 0 | E18: ='Budget assumption'!Q161 -> 0 | F18: ='Budget assumption'!Q192 -> 0 | G18: ='Budget assumption'!Q254+'Budget assumption'!Q285 -> 7.6901145 | H18: ='Budget assumption'!Q223 -> 20.474517 | I18: ='Budget assumption'!V49 -> 0 | J18: =H18-SUM(B18:G18) -> 0 | K18: ='data entry '!Q96 -> 0 | M18: ='data entry '!Q129 -> 5.0717 | O18: =M18-K18 -> 5.0717 | Q18: =M18-H18 -> -15.402817 | R18: =H18-K18-E18-I18-F18-G18-D18 -> 12.784403 | S18: =Q18+R18 -> -2.6184145 | V18: =M18-B18 -> -7.7127029 | W18: =B18-K18 -> 12.784403 | X18: =V18+W18 -> 5.0717
A19: TOTAL MFG COST w/ SHARES | B19: =B17+B18 -> 1822.6156 | C19: =C17+C18 -> -227.95487 | D19: =D17+D18 -> -51.380033 | E19: =E17+E18 -> -88.036094 | F19: =F17+F18 -> 50.465239 | G19: =G17+G18 -> -212.88283 | H19: =H17+H18 -> 1292.827 | I19: =I17+I18 -> 233.61537 | J19: =H19-SUM(B19:G19) -> 0 | K19: =K17+K18 -> 1731.3735 | M19: =M17+M18 -> 1090.9257 | O19: =O17+O18 -> -640.44786 | Q19: =Q17+Q18 -> -191.30525 | R19: =R17+R18 -> -380.92426 | S19: =Q19+R19 -> -572.22951 | V19: =V17+V18 -> -493.13896 | W19: =W17+W18 -> -147.30889 | X19: =X17+X18 -> -640.44786
A20: Functional Currency Impact | B20: ='Budget assumption'!Q51 -> 535.28082 | D20: ='Budget assumption'!Q132 -> 0 | E20: ='Budget assumption'!Q163 -> 0 | F20: ='Budget assumption'!Q194 -> 0 | G20: ='Budget assumption'!Q256+'Budget assumption'!Q287 -> -118.92816 | H20: ='Budget assumption'!Q225 -> 416.35266 | I20: ='Budget assumption'!Q333 -> 136.51533 | J20: =H20-SUM(B20:G20) -> 0 | K20: ='data entry '!Q98 -> 0 | M20: ='data entry '!Q131 -> 301.40709 | O20: =M20-K20 -> 301.40709 | Q20: =M20-H20 -> -114.94557 | R20: =H20-K20-E20-I20-F20-G20-D20 -> 398.7655 | S20: =Q20+R20 -> 283.81992 | V20: =M20-B20 -> -233.87373 | W20: =B20-K20 -> 535.28082 | X20: =V20+W20 -> 301.40709
A21: TOTAL Including FC | B21: =B19+B20 -> 2357.8964 | C21: =C19+C20 -> -227.95487 | D21: =D19+D20 -> -51.380033 | E21: =E19+E20 -> -88.036094 | F21: =F19+F20 -> 50.465239 | G21: =G19+G20 -> -331.81099 | H21: =H19+H20 -> 1709.1797 | I21: =I19+I20 -> 370.13069 | J21: =H21-SUM(B21:G21) -> 0 | K21: =K19+K20 -> 1731.3735 | M21: =M19+M20 -> 1392.3328 | O21: =M21-K21 -> -339.04077 | Q21: =Q19+Q20 -> -306.25082 | R21: =R19+R20 -> 17.841236 | S21: =Q21+R21 -> -288.40958 | V21: =V19+V20 -> -727.01269 | W21: =W19+W20 -> 387.97193 | X21: =X19+X20 -> -339.04077
A22: Scrap | B22: ='Budget assumption'!Q53 -> 35.781227 | C22: ='Budget assumption'!Q74 -> -9.125464 | D22: ='Budget assumption'!Q134 -> -7.5285 | E22: ='Budget assumption'!Q165 -> 0 | F22: ='Budget assumption'!Q196 -> 1.8727369 | G22: ='Budget assumption'!Q258+'Budget assumption'!Q289 -> 0 | H22: ='Budget assumption'!Q227 -> 21 | J22: =H22-SUM(B22:G22) -> 0 | K22: ='data entry '!Q100 -> 25.432898 | M22: ='data entry '!Q133 -> 27.97038 | O22: =M22-K22 -> 2.5374816 | Q22: =M22-K22-E22-F22-D22-G22 -> 8.1932446 | S22: =Q22+R22 -> 8.1932446 | V22: =M22-K22 -> 2.5374816 | X22: =V22+W22 -> 2.5374816
