Workbook
Name \1: #REF!
Name \1: #REF!
Name \2: #REF!
Name \2: #REF!
Name \3: #REF!
Name \3: #REF!
Name \4: #REF!
Name \4: #REF!
Name \A: #REF!
Name \A: #REF!
Name \B: #REF!
Name \B: #REF!
Name \C: #REF!
Name \C: #REF!
Name \P: #REF!
Name \P: #REF!
Name \Q: #REF!
Name \Q: #REF!
Name \R: #REF!
Name \R: #REF!
Name \S: #REF!
Name \S: #REF!
Name \T: #REF!
Name \T: #REF!
Name \X: #REF!
Name \X: #REF!
Name ___CON1: #REF!
Name ___CON1: #REF!
Name ___CON2: #REF!
Name ___CON2: #REF!
Name ___ddn400: #REF!
Name ___ddn400: #REF!
Name ___ddn600: #REF!
Name ___ddn600: #REF!
Name ___E99999: #REF!
Name ___E99999: #REF!
Name ___ETI2: #REF!
Name ___ETI2: #REF!
Name ___gon4: #REF!
Name ___gon4: #REF!
Name ___IV999999: #REF!
Name ___IV999999: #REF!
Name ___IZ53: #REF!
Name ___IZ53: #REF!
Name ___JZ123: #REF!
Name ___JZ123: #REF!
Name ___lap1: #REF!
Name ___lap1: #REF!
Name ___lap2: #REF!
Name ___lap2: #REF!
Name ___LI1: OFFSET(#REF!,4,0,COUNTA(#REF!)-1,1)
Name ___LI1: OFFSET(#REF!,4,0,COUNTA(#REF!)-1,1)
Name ___LI10: OFFSET(#REF!,4,0,COUNTA(#REF!)-1,1)
Name ___LI10: OFFSET(#REF!,4,0,COUNTA(#REF!)-1,1)
Name ___LI11: OFFSET(#REF!,4,0,COUNTA(#REF!)-1,1)
Name ___LI11: OFFSET(#REF!,4,0,COUNTA(#REF!)-1,1)
Name ___LI12: OFFSET(#REF!,4,0,COUNTA(#REF!)-1,1)
Name ___LI12: OFFSET(#REF!,4,0,COUNTA(#REF!)-1,1)
Name ___LI13: OFFSET(#REF!,4,0,COUNTA(#REF!)-1,1)
Name ___LI13: OFFSET(#REF!,4,0,COUNTA(#REF!)-1,1)

Sheet 大厨电
C2: 24年实际
B3: 千欧 | C3: 科目 | D3: 24年1月 | E3: 24年2月 | F3: 24年3月 | G3: 24年4月 | H3: 24年5月 | I3: 24年6月 | J3: 24年7月 | K3: 24年8月 | L3: 24年9月 | M3: 24年10月 | N3: 24年11月 | O3: 24年12月 | P3: 合计 | Q3: 单台 | R3: 占比 | S3: 费率 | T3: 同比
B4: 平均单价 | P4: =AVERAGE(D4:O4) -> #DIV/0!
B5: 产量 | D5: =厨电!D5+洗碗机!D5 -> 103382 | E5: =厨电!E5+洗碗机!E5 -> 129964 | F5: =厨电!F5+洗碗机!F5 -> 133663 | G5: =厨电!G5+洗碗机!G5 -> 137661 | H5: =厨电!H5+洗碗机!H5 -> 194723 | I5: =厨电!I5+洗碗机!I5 -> 152205 | J5: =厨电!J5+洗碗机!J5 -> 162832 | K5: =厨电!K5+洗碗机!K5 -> 83927 | ... O5: =厨电!O5+洗碗机!O5 -> 98970 | P5: =SUM(D5:O5) -> 1653718
B6: 固定制造 | C6: 折旧-不含FC | D6: =厨电!D6+洗碗机!D6 -> 779.26812 | E6: =厨电!E6+洗碗机!E6 -> 1069.3452 | F6: =厨电!F6+洗碗机!F6 -> 1075.7581 | G6: =厨电!G6+洗碗机!G6 -> 1083.3709 | H6: =厨电!H6+洗碗机!H6 -> 1146.8274 | I6: =厨电!I6+洗碗机!I6 -> 1276.0461 | J6: =厨电!J6+洗碗机!J6 -> 1185.7026 | K6: =厨电!K6+洗碗机!K6 -> 1171.6177 | ... O6: =厨电!O6+洗碗机!O6 -> 1241.6148 | P6: =SUM(D6:O6) -> 13446.54 | Q6: =P6/$P$5*1000 -> 8.1310964 | R6: =P6/$P$22 -> 0.23367425 | S6: =Q6/$P$4 -> #DIV/0!
C7: 运营费 | D7: =厨电!D7+洗碗机!D7 -> 120.9141 | E7: =厨电!E7+洗碗机!E7 -> 154.9804 | F7: =厨电!F7+洗碗机!F7 -> 196.5469 | G7: =厨电!G7+洗碗机!G7 -> 91.549433 | H7: =厨电!H7+洗碗机!H7 -> 153.18612 | I7: =厨电!I7+洗碗机!I7 -> 147.42758 | J7: =厨电!J7+洗碗机!J7 -> 284.03263 | K7: =厨电!K7+洗碗机!K7 -> -4.2988168 | ... O7: =厨电!O7+洗碗机!O7 -> 134.3931 | P7: =SUM(D7:O7) -> 1728.309 | Q7: =P7/$P$5*1000 -> 1.045105 | R7: =P7/$P$22 -> 0.030034588 | S7: =Q7/$P$4 -> #DIV/0!
C8: 存货跌价准备 | D8: =厨电!D8+洗碗机!D8 -> 28.412404 | E8: =厨电!E8+洗碗机!E8 -> 28.379922 | F8: =厨电!F8+洗碗机!F8 -> 14.473723 | G8: =厨电!G8+洗碗机!G8 -> 28.281947 | H8: =厨电!H8+洗碗机!H8 -> 28.270956 | I8: =厨电!I8+洗碗机!I8 -> 28.257603 | J8: =厨电!J8+洗碗机!J8 -> 397.95655 | K8: =厨电!K8+洗碗机!K8 -> 397.02774 | ... O8: =厨电!O8+洗碗机!O8 -> 436.53859 | P8: =SUM(D8:O8) -> 2813.6902 | Q8: =P8/$P$5*1000 -> 1.7014329 | R8: =P8/$P$22 -> 0.048896365 | S8: =Q8/$P$4 -> #DIV/0!
C9: 固定能源费 | D9: =厨电!D9+洗碗机!D9 -> 28.253599 | E9: =厨电!E9+洗碗机!E9 -> 1.7394932 | F9: =厨电!F9+洗碗机!F9 -> 29.04951 | G9: =厨电!G9+洗碗机!G9 -> 20.763787 | H9: =厨电!H9+洗碗机!H9 -> 6.5275961 | I9: =厨电!I9+洗碗机!I9 -> 4.6551348 | J9: =厨电!J9+洗碗机!J9 -> 5.0573918 | K9: =厨电!K9+洗碗机!K9 -> 8.6256962 | ... O9: =厨电!O9+洗碗机!O9 -> 19.670155 | P9: =SUM(D9:O9) -> 152.86065 | Q9: =P9/$P$5*1000 -> 0.092434531 | R9: =P9/$P$22 -> 0.0026564154 | S9: =Q9/$P$4 -> #DIV/0!
C10: 间接人工成本-辅助人员 | D10: =厨电!D10+洗碗机!D10 -> 365.56135 | E10: =厨电!E10+洗碗机!E10 -> 577.61784 | F10: =厨电!F10+洗碗机!F10 -> 689.72849 | G10: =厨电!G10+洗碗机!G10 -> 633.9929 | H10: =厨电!H10+洗碗机!H10 -> 656.31253 | I10: =厨电!I10+洗碗机!I10 -> 671.49986 | J10: =厨电!J10+洗碗机!J10 -> 627.03387 | K10: =厨电!K10+洗碗机!K10 -> 578.51089 | ... O10: =厨电!O10+洗碗机!O10 -> 700.26856 | P10: =SUM(D10:O10) -> 7496.4209 | Q10: =P10/$P$5*1000 -> 4.5330708 | R10: =P10/$P$22 -> 0.13027295 | S10: =Q10/$P$4 -> #DIV/0!
C11: 固定人工-白领 | D11: =厨电!D11+洗碗机!D11 -> 229.5068 | E11: =厨电!E11+洗碗机!E11 -> 162.78929 | F11: =厨电!F11+洗碗机!F11 -> 260.26961 | G11: =厨电!G11+洗碗机!G11 -> 240.19025 | H11: =厨电!H11+洗碗机!H11 -> 271.3336 | I11: =厨电!I11+洗碗机!I11 -> 288.59303 | J11: =厨电!J11+洗碗机!J11 -> 342.81746 | K11: =厨电!K11+洗碗机!K11 -> 328.95984 | ... O11: =厨电!O11+洗碗机!O11 -> 258.17259 | P11: =SUM(D11:O11) -> 3181.6033 | Q11: =P11/$P$5*1000 -> 1.9239092 | R11: =P11/$P$22 -> 0.055289967 | S11: =Q11/$P$4 -> #DIV/0!
C12: 半固定-班车/工作服 | D12: =厨电!D12+洗碗机!D12 -> 254.91522 | E12: =厨电!E12+洗碗机!E12 -> 299.62616 | F12: =厨电!F12+洗碗机!F12 -> 409.17661 | G12: =厨电!G12+洗碗机!G12 -> 376.82461 | H12: =厨电!H12+洗碗机!H12 -> 362.67674 | I12: =厨电!I12+洗碗机!I12 -> 425.16019 | J12: =厨电!J12+洗碗机!J12 -> 380.33989 | K12: =厨电!K12+洗碗机!K12 -> 252.23967 | ... O12: =厨电!O12+洗碗机!O12 -> 253.73661 | P12: =SUM(D12:O12) -> 4070.7214 | Q12: =P12/$P$5*1000 -> 2.4615571 | R12: =P12/$P$22 -> 0.070741078 | S12: =Q12/$P$4 -> #DIV/0!
B13: 变动制造 | C13: 直接人工 | D13: =厨电!D13+洗碗机!D13 -> 597.46818 | E13: =厨电!E13+洗碗机!E13 -> 739.37611 | F13: =厨电!F13+洗碗机!F13 -> 583.51977 | G13: =厨电!G13+洗碗机!G13 -> 994.38489 | H13: =厨电!H13+洗碗机!H13 -> 1014.6894 | I13: =厨电!I13+洗碗机!I13 -> 1059.6095 | J13: =厨电!J13+洗碗机!J13 -> 955.26573 | K13: =厨电!K13+洗碗机!K13 -> 883.51069 | ... O13: =厨电!O13+洗碗机!O13 -> 819.0595 | P13: =SUM(D13:O13) -> 10721.197 | Q13: =P13/$P$5*1000 -> 6.4830863 | R13: =P13/$P$22 -> 0.18631317 | S13: =Q13/$P$4 -> #DIV/0!
C14: 废料 | D14: =厨电!D14+洗碗机!D14 -> 26.324516 | E14: =厨电!E14+洗碗机!E14 -> 62.322607 | F14: =厨电!F14+洗碗机!F14 -> 46.877662 | G14: =厨电!G14+洗碗机!G14 -> 73.192417 | H14: =厨电!H14+洗碗机!H14 -> 111.71128 | I14: =厨电!I14+洗碗机!I14 -> 78.031684 | J14: =厨电!J14+洗碗机!J14 -> 83.166879 | K14: =厨电!K14+洗碗机!K14 -> 47.645265 | ... O14: =厨电!O14+洗碗机!O14 -> 81.862185 | P14: =SUM(D14:O14) -> 785.65563 | Q14: =P14/$P$5*1000 -> 0.4750844 | R14: =P14/$P$22 -> 0.013653139 | S14: =Q14/$P$4 -> #DIV/0!
C15: 生产耗用品 | D15: =厨电!D15+洗碗机!D15 -> -2.2935624 | E15: =厨电!E15+洗碗机!E15 -> 2.6206302 | F15: =厨电!F15+洗碗机!F15 -> 26.963748 | G15: =厨电!G15+洗碗机!G15 -> 61.216313 | H15: =厨电!H15+洗碗机!H15 -> 63.885472 | I15: =厨电!I15+洗碗机!I15 -> 44.476742 | J15: =厨电!J15+洗碗机!J15 -> -3.0117491 | K15: =厨电!K15+洗碗机!K15 -> 74.110438 | ... O15: =厨电!O15+洗碗机!O15 -> 75.801337 | P15: =SUM(D15:O15) -> 480.46717 | Q15: =P15/$P$5*1000 -> 0.29053755 | R15: =P15/$P$22 -> 0.0083495682 | S15: =Q15/$P$4 -> #DIV/0!
C16: 废品收入 | D16: =厨电!D16+洗碗机!D16 -> -78.443595 | E16: =厨电!E16+洗碗机!E16 -> -106.8524 | F16: =厨电!F16+洗碗机!F16 -> -125.44641 | G16: =厨电!G16+洗碗机!G16 -> -131.92906 | H16: =厨电!H16+洗碗机!H16 -> -180.5009 | I16: =厨电!I16+洗碗机!I16 -> -137.85001 | J16: =厨电!J16+洗碗机!J16 -> -159.74739 | K16: =厨电!K16+洗碗机!K16 -> -107.52558 | ... O16: =厨电!O16+洗碗机!O16 -> -103.50766 | P16: =SUM(D16:O16) -> -1580.9556 | Q16: =P16/$P$5*1000 -> -0.95600071 | R16: =P16/$P$22 -> -0.027473878 | S16: =Q16/$P$4 -> #DIV/0!
C17: 变动能源费 | D17: =厨电!D17+洗碗机!D17 -> 144.17801 | E17: =厨电!E17+洗碗机!E17 -> 30.240509 | F17: =厨电!F17+洗碗机!F17 -> 105.79044 | G17: =厨电!G17+洗碗机!G17 -> 133.97283 | H17: =厨电!H17+洗碗机!H17 -> 131.14769 | I17: =厨电!I17+洗碗机!I17 -> 97.475812 | J17: =厨电!J17+洗碗机!J17 -> 95.205029 | K17: =厨电!K17+洗碗机!K17 -> 99.804389 | ... O17: =厨电!O17+洗碗机!O17 -> 94.785612 | P17: =SUM(D17:O17) -> 1264.3049 | Q17: =P17/$P$5*1000 -> 0.76452269 | R17: =P17/$P$22 -> 0.021971117 | S17: =Q17/$P$4 -> #DIV/0!
B18: 分摊 | C18: 分摊费用 | D18: =厨电!D18+洗碗机!D18 -> 549.35903 | E18: =厨电!E18+洗碗机!E18 -> 491.27192 | F18: =厨电!F18+洗碗机!F18 -> 567.26019 | G18: =厨电!G18+洗碗机!G18 -> 592.2887 | H18: =厨电!H18+洗碗机!H18 -> 531.88513 | I18: =厨电!I18+洗碗机!I18 -> 520.11704 | J18: =厨电!J18+洗碗机!J18 -> 606.26397 | K18: =厨电!K18+洗碗机!K18 -> 802.30109 | ... O18: =厨电!O18+洗碗机!O18 -> 380.24112 | P18: =SUM(D18:O18) -> 6792.3339 | Q18: =P18/$P$5*1000 -> 4.1073109 | R18: =P18/$P$22 -> 0.11803732 | S18: =Q18/$P$4 -> #DIV/0!
C19: IT Expense-Internal Charge Out | D19: =厨电!D19+洗碗机!D19 -> 314.52539 | E19: =厨电!E19+洗碗机!E19 -> 440.27359 | F19: =厨电!F19+洗碗机!F19 -> 494.49209 | G19: =厨电!G19+洗碗机!G19 -> 452.18563 | H19: =厨电!H19+洗碗机!H19 -> 469.34009 | I19: =厨电!I19+洗碗机!I19 -> 451.8314 | J19: =厨电!J19+洗碗机!J19 -> 523.08639 | K19: =厨电!K19+洗碗机!K19 -> 509.3 | ... O19: =厨电!O19+洗碗机!O19 -> 360.25711 | P19: =SUM(D19:O19) -> 5554.8871 | Q19: =P19/$P$5*1000 -> 3.3590292 | S19: =Q19/$P$4 -> #DIV/0!
C20: Association dues | D20: =厨电!D20+洗碗机!D20 -> 3.3545015 | E20: =厨电!E20+洗碗机!E20 -> 9.5692914 | F20: =厨电!F20+洗碗机!F20 -> 2.0080192 | G20: =厨电!G20+洗碗机!G20 -> 13.615264 | H20: =厨电!H20+洗碗机!H20 -> 13.123118 | I20: =厨电!I20+洗碗机!I20 -> 13.368661 | J20: =厨电!J20+洗碗机!J20 -> 12.646808 | K20: =厨电!K20+洗碗机!K20 -> 11.888594 | ... O20: =厨电!O20+洗碗机!O20 -> 11.96886 | P20: =SUM(D20:O20) -> 125.76025 | Q20: =P20/$P$5*1000 -> 0.076046972 | S20: =Q20/$P$4 -> #DIV/0!
C21: G&A | D21: =厨电!D21+洗碗机!D21 -> 231.47914 | E21: =厨电!E21+洗碗机!E21 -> 41.429036 | F21: =厨电!F21+洗碗机!F21 -> 70.760072 | G21: =厨电!G21+洗碗机!G21 -> 126.48781 | H21: =厨电!H21+洗碗机!H21 -> 49.421912 | I21: =厨电!I21+洗碗机!I21 -> 54.916982 | J21: =厨电!J21+洗碗机!J21 -> 70.530774 | K21: =厨电!K21+洗碗机!K21 -> 281.1125 | ... O21: =厨电!O21+洗碗机!O21 -> 8.0151415 | P21: =SUM(D21:O21) -> 1111.6866 | Q21: =P21/$P$5*1000 -> 0.6722347 | S21: =Q21/$P$4 -> #DIV/0!
B22: 合计 | D22: =厨电!D22+洗碗机!D22 -> 3572.3056 | E22: =厨电!E22+洗碗机!E22 -> 4042.3391 | F22: =厨电!F22+洗碗机!F22 -> 4408.8497 | G22: =厨电!G22+洗碗机!G22 -> 4726.9814 | H22: =厨电!H22+洗碗机!H22 -> 4826.8344 | I22: =厨电!I22+洗碗机!I22 -> 5032.3817 | J22: =厨电!J22+洗碗机!J22 -> 5328.9643 | K22: =厨电!K22+洗碗机!K22 -> 5061.4104 | ... O22: =厨电!O22+洗碗机!O22 -> 4765.7466 | P22: =SUM(D22:O22) -> 57543.954
B23: 单台 | D23: =D22/D5*1000 -> 34.554425 | E23: =E22/E5*1000 -> 31.103529 | F23: =F22/F5*1000 -> 32.984818 | G23: =G22/G5*1000 -> 34.33784 | H23: =H22/H5*1000 -> 24.788209 | I23: =I22/I5*1000 -> 33.063183 | J23: =J22/J5*1000 -> 32.726763 | K23: =K22/K5*1000 -> 60.307296 | ... P23: =P22/P5*1000 -> 34.796715 | Q23: =P23 -> 34.796715 | S23: =Q23/$P$4 -> #DIV/0!
B25: 青岛不包含科目 | D25: =('24年CK1'!D158+'24年CK2'!D150)/1000 -> 341.802 | E25: =('24年CK1'!E158+'24年CK2'!E150)/1000 -> 327.68597 | F25: =('24年CK1'!F158+'24年CK2'!F150)/1000 -> 365.93252 | G25: =('24年CK1'!G158+'24年CK2'!G150)/1000 -> 383.45643 | H25: =('24年CK1'!H158+'24年CK2'!H150)/1000 -> 419.76833 | I25: =('24年CK1'!I158+'24年CK2'!I150)/1000 -> 551.74142 | J25: =('24年CK1'!J158+'24年CK2'!J150)/1000 -> 906.90377 | K25: =('24年CK1'!K158+'24年CK2'!K150)/1000 -> 986.05575 | ... O25: =('24年CK1'!O158+'24年CK2'!O150)/1000 -> 910.23683 | P25: =SUM(D25:O25) -> 7984.5405
B26: functional currency | D26: =厨电!D26+洗碗机!D26 -> 1094.4907 | E26: =厨电!E26+洗碗机!E26 -> 1094.4907 | F26: =厨电!F26+洗碗机!F26 -> 1094.4907 | G26: =厨电!G26+洗碗机!G26 -> 1094.4907 | H26: =厨电!H26+洗碗机!H26 -> 1094.4907 | I26: =厨电!I26+洗碗机!I26 -> 1094.4907 | J26: =厨电!J26+洗碗机!J26 -> 1094.4907 | K26: =厨电!K26+洗碗机!K26 -> 1094.4907 | ... O26: =厨电!O26+洗碗机!O26 -> 856.04029 | P26: =SUM(D26:O26) -> 12895.438 | Q26: =P26/$P$5*1000 -> 7.7978461
Q27: =Q23+Q26 -> 42.594561 | S27: =Q23/P4 -> #DIV/0!
C28: 大厨电25年实际
A29: 年累 | C29: 科目 | D29: 25年1月 | E29: 25年2月 | F29: 25年3月 | G29: 25年4月 | H29: 25年5月 | I29: 25年6月 | J29: 25年7月 | K29: 25年8月 | L29: 25年9月 | M29: 25年10月 | N29: 25年11月 | O29: 25年12月 | P29: 合计 | Q29: 单台 | R29: 占比 | S29: 费率 | T29: 同比
A30: 125 | B30: 平均单价（自制） | D30: 162.48841 | E30: 160.90377 | F30: 156.89927 | G30: 161.78509 | H30: 154.82189 | I30: 155.33307 | J30: 147.70531 | K30: 157.18622 | L30: 144.0859 | M30: 146.91137 | N30: 147.83429 | O30: 157.09858 | P30: =AVERAGE(D30:O30) -> 154.4211 | Q30: =AVERAGE(D30:O30) -> 154.4211
A31: =SUM(D31:F31) -> 395415 | C31: 产量 | D31: =厨电!D31+洗碗机!D31 -> 128283 | E31: =厨电!E31+洗碗机!E31 -> 128138 | F31: =厨电!F31+洗碗机!F31 -> 138994 | G31: =厨电!G31+洗碗机!G31 -> 148050 | H31: =厨电!H31+洗碗机!H31 -> 147057 | I31: =厨电!I31+洗碗机!I31 -> 104756 | J31: =厨电!J31+洗碗机!J31 -> 119656 | K31: =厨电!K31+洗碗机!K31 -> 90789 | ... O31: =厨电!O31+洗碗机!O31 -> 117647 | P31: =SUM(D31:O31) -> 1525896
A32: =SUM(D32:F32) -> 3895.9228 | B32: 固定制造 | C32: 折旧 | D32: =厨电!D32+洗碗机!D32 -> 1317.1753 | E32: =厨电!E32+洗碗机!E32 -> 1253.7334 | F32: =厨电!F32+洗碗机!F32 -> 1325.0141 | G32: =厨电!G32+洗碗机!G32 -> 1316.6541 | H32: =厨电!H32+洗碗机!H32 -> 1411.2359 | I32: =厨电!I32+洗碗机!I32 -> 1388.0214 | J32: =厨电!J32+洗碗机!J32 -> 1418.1628 | K32: =厨电!K32+洗碗机!K32 -> 1160.6474 | ... O32: =厨电!O32+洗碗机!O32 -> 1377.9119 | P32: =SUM(D32:O32) -> 15634.26 | Q32: =P32/$P$31*1000 -> 10.245954 | R32: =P32/$P$48 -> 0.32108504 | S32: =Q32/$P$30 -> 0.066350738
A33: =SUM(D33:F33) -> 555.07614 | C33: 运营费 | D33: =厨电!D33+洗碗机!D33 -> 143.31599 | E33: =厨电!E33+洗碗机!E33 -> 164.6474 | F33: =厨电!F33+洗碗机!F33 -> 247.11275 | G33: =厨电!G33+洗碗机!G33 -> 52.76386 | H33: =厨电!H33+洗碗机!H33 -> 121.69989 | I33: =厨电!I33+洗碗机!I33 -> 118.21183 | J33: =厨电!J33+洗碗机!J33 -> 113.72722 | K33: =厨电!K33+洗碗机!K33 -> 124.99486 | ... O33: =厨电!O33+洗碗机!O33 -> 61.40762 | P33: =SUM(D33:O33) -> 1567.3922 | Q33: =P33/$P$31*1000 -> 1.0271946 | R33: =P33/$P$48 -> 0.032189959 | S33: =Q33/$P$30 -> 0.006651906
A34: =SUM(D34:F34) -> 99.23558 | C34: 存货跌价准备 | D34: =厨电!D34+洗碗机!D34 -> 37.35936 | E34: =厨电!E34+洗碗机!E34 -> 30.93811 | F34: =厨电!F34+洗碗机!F34 -> 30.93811 | G34: =厨电!G34+洗碗机!G34 -> 30.93811 | H34: =厨电!H34+洗碗机!H34 -> 30.93811 | I34: =厨电!I34+洗碗机!I34 -> 290.7142 | J34: =厨电!J34+洗碗机!J34 -> 8.85478 | K34: =厨电!K34+洗碗机!K34 -> 8.855 | ... O34: =厨电!O34+洗碗机!O34 -> -283.32317 | P34: =SUM(D34:O34) -> -1027.686 | Q34: =P34/$P$31*1000 -> -0.67349675 | R34: =P34/$P$48 -> -0.021105866 | S34: =Q34/$P$30 -> -0.0043614296
A35: =SUM(D35:F35) -> 159.29147 | C35: 固定能源费 | D35: =厨电!D35+洗碗机!D35 -> 54.19819 | E35: =厨电!E35+洗碗机!E35 -> 46.66486 | F35: =厨电!F35+洗碗机!F35 -> 58.42842 | G35: =厨电!G35+洗碗机!G35 -> 10.602999 | H35: =厨电!H35+洗碗机!H35 -> 34.21968 | I35: =厨电!I35+洗碗机!I35 -> 19.02607 | J35: =厨电!J35+洗碗机!J35 -> 24.56847 | K35: =厨电!K35+洗碗机!K35 -> 36.77566 | ... O35: =厨电!O35+洗碗机!O35 -> 39.69396 | P35: =SUM(D35:O35) -> 431.18694 | Q35: =P35/$P$31*1000 -> 0.28257951 | R35: =P35/$P$48 -> 0.0088554033 | S35: =Q35/$P$30 -> 0.0018299281
A36: =SUM(D36:F36) -> 1850.9144 | C36: 间接人工成本-辅助人员 | D36: =厨电!D36+洗碗机!D36 -> 593.9138 | E36: =厨电!E36+洗碗机!E36 -> 519.57438 | F36: =厨电!F36+洗碗机!F36 -> 737.42617 | G36: =厨电!G36+洗碗机!G36 -> 613.43502 | H36: =厨电!H36+洗碗机!H36 -> 693.47583 | I36: =厨电!I36+洗碗机!I36 -> 598.46574 | J36: =厨电!J36+洗碗机!J36 -> 487.85191 | K36: =厨电!K36+洗碗机!K36 -> 473.02536 | ... O36: =厨电!O36+洗碗机!O36 -> 692.89474 | P36: =SUM(D36:O36) -> 7126.7577 | Q36: =P36/$P$31*1000 -> 4.6705396 | R36: =P36/$P$48 -> 0.14636416 | S36: =Q36/$P$30 -> 0.030245476
A37: =SUM(D37:F37) -> 1015.4306 | C37: 固定人工-白领 | D37: =厨电!D37+洗碗机!D37 -> 410.48672 | E37: =厨电!E37+洗碗机!E37 -> 316.5566 | F37: =厨电!F37+洗碗机!F37 -> 288.38723 | G37: =厨电!G37+洗碗机!G37 -> 205.71739 | H37: =厨电!H37+洗碗机!H37 -> 280.41396 | I37: =厨电!I37+洗碗机!I37 -> 258.39155 | J37: =厨电!J37+洗碗机!J37 -> 231.49671 | K37: =厨电!K37+洗碗机!K37 -> 227.51409 | ... O37: =厨电!O37+洗碗机!O37 -> 187.23786 | P37: =SUM(D37:O37) -> 2984.8065 | Q37: =P37/$P$31*1000 -> 1.9561009 | R37: =P37/$P$48 -> 0.061299781 | S37: =Q37/$P$30 -> 0.012667316
A38: =SUM(D38:F38) -> 1002.4131 | C38: 半固定-班车/工作服 | D38: =厨电!D38+洗碗机!D38 -> 326.27796 | E38: =厨电!E38+洗碗机!E38 -> 374.3963 | F38: =厨电!F38+洗碗机!F38 -> 301.73887 | G38: =厨电!G38+洗碗机!G38 -> 273.98815 | H38: =厨电!H38+洗碗机!H38 -> 305.50347 | I38: =厨电!I38+洗碗机!I38 -> 248.03449 | J38: =厨电!J38+洗碗机!J38 -> 253.39644 | K38: =厨电!K38+洗碗机!K38 -> 218.02976 | ... O38: =厨电!O38+洗碗机!O38 -> 309.08275 | P38: =SUM(D38:O38) -> 3464.0048 | Q38: =P38/$P$31*1000 -> 2.2701448 | R38: =P38/$P$48 -> 0.071141207 | S38: =Q38/$P$30 -> 0.014701001
A39: =SUM(D39:F39) -> 3034.8452 | B39: 变动制造 | C39: 直接人工 | D39: =厨电!D39+洗碗机!D39 -> 1016.1174 | E39: =厨电!E39+洗碗机!E39 -> 812.4108 | F39: =厨电!F39+洗碗机!F39 -> 1206.3169 | G39: =厨电!G39+洗碗机!G39 -> 1042.1462 | H39: =厨电!H39+洗碗机!H39 -> 1208.068 | I39: =厨电!I39+洗碗机!I39 -> 978.48413 | J39: =厨电!J39+洗碗机!J39 -> 969.54525 | K39: =厨电!K39+洗碗机!K39 -> 784.28839 | ... O39: =厨电!O39+洗碗机!O39 -> 983.23408 | P39: =SUM(D39:O39) -> 11924.424 | Q39: =P39/$P$31*1000 -> 7.8147029 | R39: =P39/$P$48 -> 0.24489513 | S39: =Q39/$P$30 -> 0.050606446
A40: =SUM(D40:F40) -> 164.12315 | C40: 废料 | D40: =厨电!D40+洗碗机!D40 -> 53.20349 | E40: =厨电!E40+洗碗机!E40 -> 54.68028 | F40: =厨电!F40+洗碗机!F40 -> 56.23938 | G40: =厨电!G40+洗碗机!G40 -> 60.85428 | H40: =厨电!H40+洗碗机!H40 -> 66.56418 | I40: =厨电!I40+洗碗机!I40 -> 60.09286 | J40: =厨电!J40+洗碗机!J40 -> 52.11769 | K40: =厨电!K40+洗碗机!K40 -> 50.89797 | ... O40: =厨电!O40+洗碗机!O40 -> 97.6763 | P40: =SUM(D40:O40) -> 733.57 | Q40: =P40/$P$31*1000 -> 0.48074705 | R40: =P40/$P$48 -> 0.015065526 | S40: =Q40/$P$30 -> 0.0031132213
A41: =SUM(D41:F41) -> 63.87373 | C41: 生产耗用品 | D41: =厨电!D41+洗碗机!D41 -> 6.03099 | E41: =厨电!E41+洗碗机!E41 -> 26.94665 | F41: =厨电!F41+洗碗机!F41 -> 30.89609 | G41: =厨电!G41+洗碗机!G41 -> -15.84372 | H41: =厨电!H41+洗碗机!H41 -> -4.43767 | I41: =厨电!I41+洗碗机!I41 -> 25.46166 | J41: =厨电!J41+洗碗机!J41 -> -88.20429 | K41: =厨电!K41+洗碗机!K41 -> 88.19468 | ... O41: =厨电!O41+洗碗机!O41 -> -53.65688 | P41: =SUM(D41:O41) -> 78.83959 | Q41: =P41/$P$31*1000 -> 0.051667735 | R41: =P41/$P$48 -> 0.0016191501 | S41: =Q41/$P$30 -> 0.00033458987
A42: =SUM(D42:F42) -> -332.20269 | C42: 废品收入 | D42: =厨电!D42+洗碗机!D42 -> -94.64742 | E42: =厨电!E42+洗碗机!E42 -> -91.95947 | F42: =厨电!F42+洗碗机!F42 -> -145.5958 | G42: =厨电!G42+洗碗机!G42 -> -159.63492 | H42: =厨电!H42+洗碗机!H42 -> -153.25855 | I42: =厨电!I42+洗碗机!I42 -> -151.92839 | J42: =厨电!J42+洗碗机!J42 -> -128.04073 | K42: =厨电!K42+洗碗机!K42 -> -98.08811 | ... O42: =厨电!O42+洗碗机!O42 -> -123.5865 | P42: =SUM(D42:O42) -> -1517.447 | Q42: =P42/$P$31*1000 -> -0.99446293 | R42: =P42/$P$48 -> -0.031164221 | S42: =Q42/$P$30 -> -0.0064399421
...

Sheet 厨电
C2: 24年实际 | V2: 额 | AH2: 单台 | AT2: 费率
B3: 千欧 | C3: 科目 | D3: 24年1月 | E3: 24年2月 | F3: 24年3月 | G3: 24年4月 | H3: 24年5月 | I3: 24年6月 | J3: 24年7月 | K3: 24年8月 | L3: 24年9月 | M3: 24年10月 | N3: 24年11月 | O3: 24年12月 | P3: 合计 | Q3: 单台 | R3: 占比 | S3: 费率 | T3: 同比 | U3: 备注 | V3: 2月年累 | W3: 3月年累 | X3: 4月年累 | Y3: 5月年累 | Z3: 6月年累 | AA3: 7月年累 | AB3: 8月年累 | AC3: 9月年累 | AD3: 10月年累 | AE3: 11月年累 | AF3: 12月年累 | AH3: 2月年累 | AI3: 3月年累 | AJ3: 4月年累 | AK3: 5月年累 | AL3: 6月年累 | AM3: 7月年累 | AN3: 8月年累 | AO3: 9月年累 | AP3: 10月年累 | AQ3: 11月年累 | AR3: 12月年累 | AT3: 2月年累 | AU3: 3月年累 | AV3: 4月年累 | AW3: 5月年累 | AX3: 6月年累 | AY3: 7月年累 | AZ3: 8月年累 | BA3: 9月年累 | BB3: 10月年累 | BC3: 11月年累 | BD3: 12月年累
B4: 平均单价 | D4: 132.50001 | E4: 125.23284 | F4: 123.16608 | G4: 121.99032 | H4: 122.66935 | I4: 119.61187 | J4: 122.49963 | K4: 123.97736 | L4: 116.13849 | M4: 123.19497 | N4: 117.49913 | O4: 120.2801 | P4: =AVERAGE(D4:O4) -> 122.39668 | AT4: =$P$4 -> 122.39668 | AU4: =$P$4 -> 122.39668 | AV4: =$P$4 -> 122.39668 | AW4: =$P$4 -> 122.39668 | AX4: =$P$4 -> 122.39668 | AY4: =$P$4 -> 122.39668 | AZ4: =$P$4 -> 122.39668 | BA4: =$P$4 -> 122.39668 | ... BD4: =$P$4 -> 122.39668
B5: 产量 | D5: ='24年CK1'!D1+'24年CK2'!D1 -> 87337 | E5: ='24年CK1'!E1+'24年CK2'!E1 -> 110212 | F5: ='24年CK1'!F1+'24年CK2'!F1 -> 113626 | G5: ='24年CK1'!G1+'24年CK2'!G1 -> 109618 | H5: ='24年CK1'!H1+'24年CK2'!H1 -> 153929 | I5: ='24年CK1'!I1+'24年CK2'!I1 -> 121229 | J5: ='24年CK1'!J1+'24年CK2'!J1 -> 128355 | K5: ='24年CK1'!K1+'24年CK2'!K1 -> 58349 | ... O5: ='24年CK1'!O1+'24年CK2'!O1 -> 72817 | P5: =SUM(D5:O5) -> 1287462 | V5: =D5+E5 -> 197549 | W5: =V5+F5 -> 311175 | X5: =W5+G5 -> 420793 | Y5: =X5+H5 -> 574722 | Z5: =Y5+I5 -> 695951 | AA5: =Z5+J5 -> 824306 | AB5: =AA5+K5 -> 882655 | AC5: =AB5+L5 -> 992562 | AD5: =AC5+M5 -> 1108667 | ... AF5: =AE5+O5 -> 1287462
B6: 固定制造 | C6: 折旧-不含FC | D6: =('24年CK1'!D144+'24年CK2'!D136)/1000 -> 85.774829 | E6: =('24年CK1'!E144+'24年CK2'!E136)/1000 -> 351.93788 | F6: =('24年CK1'!F144+'24年CK2'!F136)/1000 -> 352.07193 | G6: =('24年CK1'!G144+'24年CK2'!G136)/1000 -> 339.96967 | H6: =('24年CK1'!H144+'24年CK2'!H136)/1000 -> 403.5684 | I6: =('24年CK1'!I144+'24年CK2'!I136)/1000 -> 524.02594 | J6: =('24年CK1'!J144+'24年CK2'!J136)/1000 -> 431.48432 | K6: =('24年CK1'!K144+'24年CK2'!K136)/1000 -> 417.90218 | ... O6: =('24年CK1'!O144+'24年CK2'!O136)/1000 -> 471.31418 | P6: =SUM(D6:O6) -> 4549.6106 | Q6: =P6/$P$5*1000 -> 3.5337824 | R6: =P6/$P$22 -> 0.12420254 | S6: =Q6/$P$4 -> 0.028871554 | V6: =D6+E6 -> 437.71271 | W6: =V6+F6 -> 789.78464 | X6: =W6+G6 -> 1129.7543 | Y6: =X6+H6 -> 1533.3227 | Z6: =Y6+I6 -> 2057.3487 | AA6: =Z6+J6 -> 2488.833 | AB6: =AA6+K6 -> 2906.7352 | AC6: =AB6+L6 -> 3167.3488 | AD6: =AC6+M6 -> 3614.9724 | ... AF6: =AE6+O6 -> 4549.6106 | AH6: =V6/V$5*1000 -> 2.2157172 | AI6: =W6/W$5*1000 -> 2.5380723 | AJ6: =X6/X$5*1000 -> 2.684822 | AK6: =Y6/Y$5*1000 -> 2.6679381 | AL6: =Z6/Z$5*1000 -> 2.9561688 | AM6: =AA6/AA$5*1000 -> 3.0193071 | AN6: =AB6/AB$5*1000 -> 3.2931725 | AO6: =AC6/AC$5*1000 -> 3.1910841 | ... AR6: =AF6/AF$5*1000 -> 3.5337824 | AT6: =AH6/AT$4 -> 0.018102755 | AU6: =AI6/AU$4 -> 0.020736447 | AV6: =AJ6/AV$4 -> 0.021935415 | AW6: =AK6/AW$4 -> 0.021797471 | AX6: =AL6/AX$4 -> 0.024152361 | AY6: =AM6/AY$4 -> 0.024668211 | AZ6: =AN6/AZ$4 -> 0.026905734 | BA6: =AO6/BA$4 -> 0.026071656 | ... BD6: =AR6/BD$4 -> 0.028871554
C7: 运营费 | D7: =('24年CK1'!D145+'24年CK2'!D137)/1000 -> 79.235716 | E7: =('24年CK1'!E145+'24年CK2'!E137)/1000 -> 99.823853 | F7: =('24年CK1'!F145+'24年CK2'!F137)/1000 -> 148.24952 | G7: =('24年CK1'!G145+'24年CK2'!G137)/1000 -> 39.559414 | H7: =('24年CK1'!H145+'24年CK2'!H137)/1000 -> 105.48256 | I7: =('24年CK1'!I145+'24年CK2'!I137)/1000 -> 101.51889 | J7: =('24年CK1'!J145+'24年CK2'!J137)/1000 -> 236.5676 | K7: =('24年CK1'!K145+'24年CK2'!K137)/1000 -> -51.40182 | ... O7: =('24年CK1'!O145+'24年CK2'!O137)/1000 -> 163.94473 | P7: =SUM(D7:O7) -> 1286.7491 | Q7: =P7/$P$5*1000 -> 0.9994463 | R7: =P7/$P$22 -> 0.035127735 | S7: =Q7/$P$4 -> 0.0081656324 | V7: =D7+E7 -> 179.05957 | W7: =V7+F7 -> 327.30909 | X7: =W7+G7 -> 366.8685 | Y7: =X7+H7 -> 472.35107 | Z7: =Y7+I7 -> 573.86995 | AA7: =Z7+J7 -> 810.43755 | AB7: =AA7+K7 -> 759.03573 | AC7: =AB7+L7 -> 907.11574 | AD7: =AC7+M7 -> 1011.2655 | ... AF7: =AE7+O7 -> 1286.7491 | AH7: =V7/V$5*1000 -> 0.90640585 | AI7: =W7/W$5*1000 -> 1.0518489 | AJ7: =X7/X$5*1000 -> 0.8718503 | AK7: =Y7/Y$5*1000 -> 0.82187747 | AL7: =Z7/Z$5*1000 -> 0.82458385 | AM7: =AA7/AA$5*1000 -> 0.98317561 | AN7: =AB7/AB$5*1000 -> 0.85994611 | AO7: =AC7/AC$5*1000 -> 0.91391343 | ... AR7: =AF7/AF$5*1000 -> 0.9994463 | AT7: =AH7/AT$4 -> 0.0074054774 | AU7: =AI7/AU$4 -> 0.00859377 | AV7: =AJ7/AV$4 -> 0.0071231532 | AW7: =AK7/AW$4 -> 0.0067148674 | AX7: =AL7/AX$4 -> 0.0067369789 | AY7: =AM7/AY$4 -> 0.0080326983 | AZ7: =AN7/AZ$4 -> 0.0070258941 | BA7: =AO7/BA$4 -> 0.0074668155 | ... BD7: =AR7/BD$4 -> 0.0081656324
C8: 存货跌价准备 | D8: =('24年CK1'!D146+'24年CK2'!D138)/1000 -> 26 | E8: =('24年CK1'!E146+'24年CK2'!E138)/1000 -> 26 | F8: =('24年CK1'!F146+'24年CK2'!F138)/1000 -> 12.200314 | G8: =('24年CK1'!G146+'24年CK2'!G138)/1000 -> 26 | H8: =('24年CK1'!H146+'24年CK2'!H138)/1000 -> 26 | I8: =('24年CK1'!I146+'24年CK2'!I138)/1000 -> 26 | J8: =('24年CK1'!J146+'24年CK2'!J138)/1000 -> 373.56136 | K8: =('24年CK1'!K146+'24年CK2'!K138)/1000 -> 373.56136 | ... O8: =('24年CK1'!O146+'24年CK2'!O138)/1000 -> 506.99463 | P8: =SUM(D8:O8) -> 2787.7922 | Q8: =P8/$P$5*1000 -> 2.1653394 | R8: =P8/$P$22 -> 0.076105607 | S8: =Q8/$P$4 -> 0.017691161 | V8: =D8+E8 -> 52 | W8: =V8+F8 -> 64.200314 | X8: =W8+G8 -> 90.200314 | Y8: =X8+H8 -> 116.20031 | Z8: =Y8+I8 -> 142.20031 | AA8: =Z8+J8 -> 515.76167 | AB8: =AA8+K8 -> 889.32303 | AC8: =AB8+L8 -> 1291.9923 | AD8: =AC8+M8 -> 1786.3282 | ... AF8: =AE8+O8 -> 2787.7922 | AH8: =V8/V$5*1000 -> 0.26322583 | AI8: =W8/W$5*1000 -> 0.20631578 | AJ8: =X8/X$5*1000 -> 0.21435792 | AK8: =Y8/Y$5*1000 -> 0.20218526 | AL8: =Z8/Z$5*1000 -> 0.20432518 | AM8: =AA8/AA$5*1000 -> 0.62569201 | AN8: =AB8/AB$5*1000 -> 1.0075545 | AO8: =AC8/AC$5*1000 -> 1.3016741 | ... AR8: =AF8/AF$5*1000 -> 2.1653394 | AT8: =AH8/AT$4 -> 0.0021505962 | AU8: =AI8/AU$4 -> 0.0016856322 | AV8: =AJ8/AV$4 -> 0.0017513377 | AW8: =AK8/AW$4 -> 0.0016518851 | AX8: =AL8/AX$4 -> 0.0016693687 | AY8: =AM8/AY$4 -> 0.0051120014 | AZ8: =AN8/AZ$4 -> 0.0082318778 | BA8: =AO8/BA$4 -> 0.010634881 | ... BD8: =AR8/BD$4 -> 0.017691161
C9: 固定能源费 | D9: =('24年CK1'!D147+'24年CK2'!D139)/1000 -> 12.400184 | E9: =('24年CK1'!E147+'24年CK2'!E139)/1000 -> -1.0670255 | F9: =('24年CK1'!F147+'24年CK2'!F139)/1000 -> 16.256636 | G9: =('24年CK1'!G147+'24年CK2'!G139)/1000 -> 6.0209282 | H9: =('24年CK1'!H147+'24年CK2'!H139)/1000 -> 6.1583453 | I9: =('24年CK1'!I147+'24年CK2'!I139)/1000 -> 5.5907489 | J9: =('24年CK1'!J147+'24年CK2'!J139)/1000 -> 5.5766195 | K9: =('24年CK1'!K147+'24年CK2'!K139)/1000 -> 6.6059645 | ... O9: =('24年CK1'!O147+'24年CK2'!O139)/1000 -> 7.49769 | P9: =SUM(D9:O9) -> 81.060862 | Q9: =P9/$P$5*1000 -> 0.062961751 | R9: =P9/$P$22 -> 0.002212929 | S9: =Q9/$P$4 -> 0.00051440735 | V9: =D9+E9 -> 11.333159 | W9: =V9+F9 -> 27.589794 | X9: =W9+G9 -> 33.610723 | Y9: =X9+H9 -> 39.769068 | Z9: =Y9+I9 -> 45.359817 | AA9: =Z9+J9 -> 50.936436 | AB9: =AA9+K9 -> 57.542401 | AC9: =AB9+L9 -> 63.417406 | AD9: =AC9+M9 -> 69.850742 | ... AF9: =AE9+O9 -> 81.060862 | AH9: =V9/V$5*1000 -> 0.057368849 | AI9: =W9/W$5*1000 -> 0.088663275 | AJ9: =X9/X$5*1000 -> 0.079874719 | AK9: =Y9/Y$5*1000 -> 0.069197052 | AL9: =Z9/Z$5*1000 -> 0.065176739 | AM9: =AA9/AA$5*1000 -> 0.061793116 | AN9: =AB9/AB$5*1000 -> 0.065192403 | AO9: =AC9/AC$5*1000 -> 0.06389264 | ... AR9: =AF9/AF$5*1000 -> 0.062961751 | AT9: =AH9/AT$4 -> 0.00046871246 | AU9: =AI9/AU$4 -> 0.00072439281 | AV9: =AJ9/AV$4 -> 0.00065258893 | AW9: =AK9/AW$4 -> 0.00056535072 | AX9: =AL9/AX$4 -> 0.00053250414 | AY9: =AM9/AY$4 -> 0.00050485941 | AZ9: =AN9/AZ$4 -> 0.00053263212 | BA9: =AO9/BA$4 -> 0.00052201285 | ... BD9: =AR9/BD$4 -> 0.00051440735
C10: 间接人工成本-辅助人员 | D10: =('24年CK1'!D148+'24年CK2'!D140)/1000 -> 224.16848 | E10: =('24年CK1'!E148+'24年CK2'!E140)/1000 -> 414.34793 | F10: =('24年CK1'!F148+'24年CK2'!F140)/1000 -> 456.9152 | G10: =('24年CK1'!G148+'24年CK2'!G140)/1000 -> 424.5319 | H10: =('24年CK1'!H148+'24年CK2'!H140)/1000 -> 449.10915 | I10: =('24年CK1'!I148+'24年CK2'!I140)/1000 -> 453.03789 | J10: =('24年CK1'!J148+'24年CK2'!J140)/1000 -> 415.64357 | K10: =('24年CK1'!K148+'24年CK2'!K140)/1000 -> 394.26511 | ... O10: =('24年CK1'!O148+'24年CK2'!O140)/1000 -> 473.50299 | P10: =SUM(D10:O10) -> 5078.6667 | Q10: =P10/$P$5*1000 -> 3.9447119 | R10: =P10/$P$22 -> 0.13864556 | S10: =Q10/$P$4 -> 0.032228913 | V10: =D10+E10 -> 638.5164 | W10: =V10+F10 -> 1095.4316 | X10: =W10+G10 -> 1519.9635 | Y10: =X10+H10 -> 1969.0726 | Z10: =Y10+I10 -> 2422.1105 | AA10: =Z10+J10 -> 2837.7541 | AB10: =AA10+K10 -> 3232.0192 | AC10: =AB10+L10 -> 3702.2507 | AD10: =AC10+M10 -> 4178.6777 | ... AF10: =AE10+O10 -> 5078.6667 | AH10: =V10/V$5*1000 -> 3.2321925 | AI10: =W10/W$5*1000 -> 3.5203072 | AJ10: =X10/X$5*1000 -> 3.6121407 | AK10: =Y10/Y$5*1000 -> 3.4261306 | AL10: =Z10/Z$5*1000 -> 3.4802889 | AM10: =AA10/AA$5*1000 -> 3.4425979 | AN10: =AB10/AB$5*1000 -> 3.6617016 | AO10: =AC10/AC$5*1000 -> 3.7299944 | ... AR10: =AF10/AF$5*1000 -> 3.9447119 | AT10: =AH10/AT$4 -> 0.026407518 | AU10: =AI10/AU$4 -> 0.02876146 | AV10: =AJ10/AV$4 -> 0.029511753 | AW10: =AK10/AW$4 -> 0.027992023 | AX10: =AL10/AX$4 -> 0.028434504 | AY10: =AM10/AY$4 -> 0.028126563 | AZ10: =AN10/AZ$4 -> 0.029916674 | BA10: =AO10/BA$4 -> 0.030474637 | ... BD10: =AR10/BD$4 -> 0.032228913
C11: 固定人工-白领 | D11: =('24年CK1'!D149+'24年CK2'!D141)/1000 -> 122.23615 | E11: =('24年CK1'!E149+'24年CK2'!E141)/1000 -> 84.280247 | F11: =('24年CK1'!F149+'24年CK2'!F141)/1000 -> 158.11684 | G11: =('24年CK1'!G149+'24年CK2'!G141)/1000 -> 163.96534 | H11: =('24年CK1'!H149+'24年CK2'!H141)/1000 -> 195.26381 | I11: =('24年CK1'!I149+'24年CK2'!I141)/1000 -> 201.13422 | J11: =('24年CK1'!J149+'24年CK2'!J141)/1000 -> 244.86138 | K11: =('24年CK1'!K149+'24年CK2'!K141)/1000 -> 223.19253 | ... O11: =('24年CK1'!O149+'24年CK2'!O141)/1000 -> 184.89072 | P11: =SUM(D11:O11) -> 2090.5711 | Q11: =P11/$P$5*1000 -> 1.6237925 | R11: =P11/$P$22 -> 0.057071753 | S11: =Q11/$P$4 -> 0.013266638 | V11: =D11+E11 -> 206.5164 | W11: =V11+F11 -> 364.63324 | X11: =W11+G11 -> 528.59858 | Y11: =X11+H11 -> 723.86239 | Z11: =Y11+I11 -> 924.99662 | AA11: =Z11+J11 -> 1169.858 | AB11: =AA11+K11 -> 1393.0505 | AC11: =AB11+L11 -> 1594.5213 | AD11: =AC11+M11 -> 1687.354 | ... AF11: =AE11+O11 -> 2090.5711 | AH11: =V11/V$5*1000 -> 1.0453933 | AI11: =W11/W$5*1000 -> 1.1717948 | AJ11: =X11/X$5*1000 -> 1.2561962 | AK11: =Y11/Y$5*1000 -> 1.2595001 | AL11: =Z11/Z$5*1000 -> 1.3291117 | AM11: =AA11/AA$5*1000 -> 1.4192035 | AN11: =AB11/AB$5*1000 -> 1.5782503 | AO11: =AC11/AC$5*1000 -> 1.6064702 | ... AR11: =AF11/AF$5*1000 -> 1.6237925 | AT11: =AH11/AT$4 -> 0.0085410266 | AU11: =AI11/AU$4 -> 0.0095737464 | AV11: =AJ11/AV$4 -> 0.010263319 | AW11: =AK11/AW$4 -> 0.010290312 | AX11: =AL11/AX$4 -> 0.01085905 | AY11: =AM11/AY$4 -> 0.011595115 | AZ11: =AN11/AZ$4 -> 0.012894552 | BA11: =AO11/BA$4 -> 0.013125112 | ... BD11: =AR11/BD$4 -> 0.013266638
C12: 半固定-班车/工作服 | D12: =('24年CK1'!D150+'24年CK2'!D142)/1000 -> 142.51708 | E12: =('24年CK1'!E150+'24年CK2'!E142)/1000 -> 171.20656 | F12: =('24年CK1'!F150+'24年CK2'!F142)/1000 -> 283.62613 | G12: =('24年CK1'!G150+'24年CK2'!G142)/1000 -> 231.25393 | H12: =('24年CK1'!H150+'24年CK2'!H142)/1000 -> 215.49158 | I12: =('24年CK1'!I150+'24年CK2'!I142)/1000 -> 249.63048 | J12: =('24年CK1'!J150+'24年CK2'!J142)/1000 -> 228.76015 | K12: =('24年CK1'!K150+'24年CK2'!K142)/1000 -> 189.02819 | ... O12: =('24年CK1'!O150+'24年CK2'!O142)/1000 -> 172.45257 | P12: =SUM(D12:O12) -> 2548.2886 | Q12: =P12/$P$5*1000 -> 1.9793117 | R12: =P12/$P$22 -> 0.069567257 | S12: =Q12/$P$4 -> 0.016171286 | V12: =D12+E12 -> 313.72364 | W12: =V12+F12 -> 597.34977 | X12: =W12+G12 -> 828.60369 | Y12: =X12+H12 -> 1044.0953 | Z12: =Y12+I12 -> 1293.7258 | AA12: =Z12+J12 -> 1522.4859 | AB12: =AA12+K12 -> 1711.5141 | AC12: =AB12+L12 -> 1900.2893 | AD12: =AC12+M12 -> 2216.2574 | ... AF12: =AE12+O12 -> 2548.2886 | AH12: =V12/V$5*1000 -> 1.5880801 | AI12: =W12/W$5*1000 -> 1.9196586 | AJ12: =X12/X$5*1000 -> 1.969148 | AK12: =Y12/Y$5*1000 -> 1.8166962 | AL12: =Z12/Z$5*1000 -> 1.8589322 | AM12: =AA12/AA$5*1000 -> 1.8469912 | AN12: =AB12/AB$5*1000 -> 1.9390522 | AO12: =AC12/AC$5*1000 -> 1.9145296 | ... AR12: =AF12/AF$5*1000 -> 1.9793117 | AT12: =AH12/AT$4 -> 0.012974863 | AU12: =AI12/AU$4 -> 0.015683911 | AV12: =AJ12/AV$4 -> 0.016088247 | AW12: =AK12/AW$4 -> 0.014842692 | AX12: =AL12/AX$4 -> 0.015187767 | AY12: =AM12/AY$4 -> 0.015090206 | AZ12: =AN12/AZ$4 -> 0.015842359 | BA12: =AO12/BA$4 -> 0.015642006 | ... BD12: =AR12/BD$4 -> 0.016171286
B13: 变动制造 | C13: 直接人工 | D13: =('24年CK1'!D151+'24年CK2'!D143)/1000 -> 421.24519 | E13: =('24年CK1'!E151+'24年CK2'!E143)/1000 -> 551.94817 | F13: =('24年CK1'!F151+'24年CK2'!F143)/1000 -> 421.62088 | G13: =('24年CK1'!G151+'24年CK2'!G143)/1000 -> 612.54001 | H13: =('24年CK1'!H151+'24年CK2'!H143)/1000 -> 635.19802 | I13: =('24年CK1'!I151+'24年CK2'!I143)/1000 -> 679.02858 | J13: =('24年CK1'!J151+'24年CK2'!J143)/1000 -> 619.58928 | K13: =('24年CK1'!K151+'24年CK2'!K143)/1000 -> 534.65847 | ... O13: =('24年CK1'!O151+'24年CK2'!O143)/1000 -> 456.13529 | P13: =SUM(D13:O13) -> 6732.5969 | Q13: =P13/$P$5*1000 -> 5.2293558 | R13: =P13/$P$22 -> 0.18379719 | S13: =Q13/$P$4 -> 0.042724654 | V13: =D13+E13 -> 973.19336 | W13: =V13+F13 -> 1394.8142 | X13: =W13+G13 -> 2007.3542 | Y13: =X13+H13 -> 2642.5523 | Z13: =Y13+I13 -> 3321.5808 | AA13: =Z13+J13 -> 3941.1701 | AB13: =AA13+K13 -> 4475.8286 | AC13: =AB13+L13 -> 5091.447 | AD13: =AC13+M13 -> 5705.6343 | ... AF13: =AE13+O13 -> 6732.5969 | AH13: =V13/V$5*1000 -> 4.9263391 | AI13: =W13/W$5*1000 -> 4.482411 | AJ13: =X13/X$5*1000 -> 4.7704079 | AK13: =Y13/Y$5*1000 -> 4.5979661 | AL13: =Z13/Z$5*1000 -> 4.7727223 | AM13: =AA13/AA$5*1000 -> 4.7811979 | AN13: =AB13/AB$5*1000 -> 5.0708698 | AO13: =AC13/AC$5*1000 -> 5.129601 | ... AR13: =AF13/AF$5*1000 -> 5.2293558 | AT13: =AH13/AT$4 -> 0.04024896 | AU13: =AI13/AU$4 -> 0.036621998 | AV13: =AJ13/AV$4 -> 0.038974978 | AW13: =AK13/AW$4 -> 0.037566101 | AX13: =AL13/AX$4 -> 0.038993887 | AY13: =AM13/AY$4 -> 0.039063134 | AZ13: =AN13/AZ$4 -> 0.041429799 | BA13: =AO13/BA$4 -> 0.041909642 | ... BD13: =AR13/BD$4 -> 0.042724654
C14: 废料 | D14: =('24年CK1'!D152+'24年CK2'!D144)/1000 -> 20.146721 | E14: =('24年CK1'!E152+'24年CK2'!E144)/1000 -> 53.452345 | F14: =('24年CK1'!F152+'24年CK2'!F144)/1000 -> 38.048936 | G14: =('24年CK1'!G152+'24年CK2'!G144)/1000 -> 61.072459 | H14: =('24年CK1'!H152+'24年CK2'!H144)/1000 -> 94.598057 | I14: =('24年CK1'!I152+'24年CK2'!I144)/1000 -> 50.382744 | J14: =('24年CK1'!J152+'24年CK2'!J144)/1000 -> 63.028552 | K14: =('24年CK1'!K152+'24年CK2'!K144)/1000 -> 32.375367 | ... O14: =('24年CK1'!O152+'24年CK2'!O144)/1000 -> 52.074158 | P14: =SUM(D14:O14) -> 579.12434 | Q14: =P14/$P$5*1000 -> 0.44981859 | R14: =P14/$P$22 -> 0.015809862 | S14: =Q14/$P$4 -> 0.0036750881 | V14: =D14+E14 -> 73.599065 | W14: =V14+F14 -> 111.648 | X14: =W14+G14 -> 172.72046 | Y14: =X14+H14 -> 267.31852 | Z14: =Y14+I14 -> 317.70126 | AA14: =Z14+J14 -> 380.72981 | AB14: =AA14+K14 -> 413.10518 | AC14: =AB14+L14 -> 450.34704 | AD14: =AC14+M14 -> 496.81843 | ... AF14: =AE14+O14 -> 579.12434 | AH14: =V14/V$5*1000 -> 0.37256106 | AI14: =W14/W$5*1000 -> 0.35879489 | AJ14: =X14/X$5*1000 -> 0.41046419 | AK14: =Y14/Y$5*1000 -> 0.46512665 | AL14: =Z14/Z$5*1000 -> 0.45649947 | AM14: =AA14/AA$5*1000 -> 0.46187922 | AN14: =AB14/AB$5*1000 -> 0.46802565 | AO14: =AC14/AC$5*1000 -> 0.45372183 | ... AR14: =AF14/AF$5*1000 -> 0.44981859 | AT14: =AH14/AT$4 -> 0.0030438821 | AU14: =AI14/AU$4 -> 0.0029314103 | AV14: =AJ14/AV$4 -> 0.0033535566 | AW14: =AK14/AW$4 -> 0.0038001574 | AX14: =AL14/AX$4 -> 0.003729672 | AY14: =AM14/AY$4 -> 0.0037736254 | AZ14: =AN14/AZ$4 -> 0.0038238427 | BA14: =AO14/BA$4 -> 0.0037069782 | ... BD14: =AR14/BD$4 -> 0.0036750881
C15: 生产耗用品 | D15: =('24年CK1'!D153+'24年CK2'!D145)/1000 -> -5.3140542 | E15: =('24年CK1'!E153+'24年CK2'!E145)/1000 -> 2.6393653 | F15: =('24年CK1'!F153+'24年CK2'!F145)/1000 -> 15.297229 | G15: =('24年CK1'!G153+'24年CK2'!G145)/1000 -> 47.314716 | H15: =('24年CK1'!H153+'24年CK2'!H145)/1000 -> 36.021673 | I15: =('24年CK1'!I153+'24年CK2'!I145)/1000 -> 24.306903 | J15: =('24年CK1'!J153+'24年CK2'!J145)/1000 -> -22.42083 | K15: =('24年CK1'!K153+'24年CK2'!K145)/1000 -> 117.45385 | ... O15: =('24年CK1'!O153+'24年CK2'!O145)/1000 -> 61.90531 | P15: =SUM(D15:O15) -> 386.72453 | Q15: =P15/$P$5*1000 -> 0.30037743 | R15: =P15/$P$22 -> 0.010557424 | S15: =Q15/$P$4 -> 0.0024541305 | V15: =D15+E15 -> -2.6746889 | W15: =V15+F15 -> 12.62254 | X15: =W15+G15 -> 59.937256 | Y15: =X15+H15 -> 95.958929 | Z15: =Y15+I15 -> 120.26583 | AA15: =Z15+J15 -> 97.845002 | AB15: =AA15+K15 -> 215.29885 | AC15: =AB15+L15 -> 258.07749 | AD15: =AC15+M15 -> 286.69124 | ... AF15: =AE15+O15 -> 386.72453 | AH15: =V15/V$5*1000 -> -0.01353937 | AI15: =W15/W$5*1000 -> 0.04056412 | AJ15: =X15/X$5*1000 -> 0.14243881 | AK15: =Y15/Y$5*1000 -> 0.16696582 | AL15: =Z15/Z$5*1000 -> 0.1728079 | AM15: =AA15/AA$5*1000 -> 0.11869985 | AN15: =AB15/AB$5*1000 -> 0.24392186 | AO15: =AC15/AC$5*1000 -> 0.26001145 | ... AR15: =AF15/AF$5*1000 -> 0.30037743 | AT15: =AH15/AT$4 -> -0.00011061877 | AU15: =AI15/AU$4 -> 0.0003314152 | AV15: =AJ15/AV$4 -> 0.0011637474 | AW15: =AK15/AW$4 -> 0.0013641368 | AX15: =AL15/AX$4 -> 0.0014118676 | AY15: =AM15/AY$4 -> 0.00096979635 | AZ15: =AN15/AZ$4 -> 0.0019928797 | BA15: =AO15/BA$4 -> 0.0021243342 | ... BD15: =AR15/BD$4 -> 0.0024541305
C16: 废品收入 | D16: =('24年CK1'!D154+'24年CK2'!D146)/1000 -> -64.159226 | E16: =('24年CK1'!E154+'24年CK2'!E146)/1000 -> -81.22218 | F16: =('24年CK1'!F154+'24年CK2'!F146)/1000 -> -93.278408 | G16: =('24年CK1'!G154+'24年CK2'!G146)/1000 -> -96.845092 | H16: =('24年CK1'!H154+'24年CK2'!H146)/1000 -> -132.97674 | I16: =('24年CK1'!I154+'24年CK2'!I146)/1000 -> -100.33 | J16: =('24年CK1'!J154+'24年CK2'!J146)/1000 -> -115.20764 | K16: =('24年CK1'!K154+'24年CK2'!K146)/1000 -> -77.008382 | ... O16: =('24年CK1'!O154+'24年CK2'!O146)/1000 -> -68.619842 | P16: =SUM(D16:O16) -> -1123.5815 | Q16: =P16/$P$5*1000 -> -0.87271045 | R16: =P16/$P$22 -> -0.030673325 | S16: =Q16/$P$4 -> -0.0071301807 | V16: =D16+E16 -> -145.38141 | W16: =V16+F16 -> -238.65981 | X16: =W16+G16 -> -335.50491 | Y16: =X16+H16 -> -468.48164 | Z16: =Y16+I16 -> -568.81164 | AA16: =Z16+J16 -> -684.01929 | AB16: =AA16+K16 -> -761.02767 | AC16: =AB16+L16 -> -847.18663 | AD16: =AC16+M16 -> -946.67481 | ... AF16: =AE16+O16 -> -1123.5815 | AH16: =V16/V$5*1000 -> -0.7359258 | AI16: =W16/W$5*1000 -> -0.76696333 | AJ16: =X16/X$5*1000 -> -0.7973158 | AK16: =Y16/Y$5*1000 -> -0.81514479 | AL16: =Z16/Z$5*1000 -> -0.81731565 | AM16: =AA16/AA$5*1000 -> -0.82981234 | AN16: =AB16/AB$5*1000 -> -0.86220286 | AO16: =AC16/AC$5*1000 -> -0.85353523 | ... AR16: =AF16/AF$5*1000 -> -0.87271045 | AT16: =AH16/AT$4 -> -0.0060126288 | AU16: =AI16/AU$4 -> -0.0062662102 | AV16: =AJ16/AV$4 -> -0.0065141946 | AW16: =AK16/AW$4 -> -0.0066598603 | AX16: =AL16/AX$4 -> -0.0066775965 | AY16: =AM16/AY$4 -> -0.0067796964 | AZ16: =AN16/AZ$4 -> -0.0070443321 | BA16: =AO16/BA$4 -> -0.0069735161 | ... BD16: =AR16/BD$4 -> -0.0071301807
C17: 变动能源费 | D17: =('24年CK1'!D155+'24年CK2'!D147)/1000 -> 128.91707 | E17: =('24年CK1'!E155+'24年CK2'!E147)/1000 -> 13.511551 | F17: =('24年CK1'!F155+'24年CK2'!F147)/1000 -> 76.888153 | G17: =('24年CK1'!G155+'24年CK2'!G147)/1000 -> 91.758476 | H17: =('24年CK1'!H155+'24年CK2'!H147)/1000 -> 105.74127 | I17: =('24年CK1'!I155+'24年CK2'!I147)/1000 -> 74.111514 | J17: =('24年CK1'!J155+'24年CK2'!J147)/1000 -> 59.160388 | K17: =('24年CK1'!K155+'24年CK2'!K147)/1000 -> 78.859311 | ... O17: =('24年CK1'!O155+'24年CK2'!O147)/1000 -> 76.976366 | P17: =SUM(D17:O17) -> 964.90888 | Q17: =P17/$P$5*1000 -> 0.74946591 | R17: =P17/$P$22 -> 0.026341625 | S17: =Q17/$P$4 -> 0.0061232536 | V17: =D17+E17 -> 142.42863 | W17: =V17+F17 -> 219.31678 | X17: =W17+G17 -> 311.07525 | Y17: =X17+H17 -> 416.81652 | Z17: =Y17+I17 -> 490.92804 | AA17: =Z17+J17 -> 550.08843 | AB17: =AA17+K17 -> 628.94774 | AC17: =AB17+L17 -> 707.51845 | AD17: =AC17+M17 -> 789.57736 | ... AF17: =AE17+O17 -> 964.90888 | AH17: =V17/V$5*1000 -> 0.72097872 | AI17: =W17/W$5*1000 -> 0.70480205 | AJ17: =X17/X$5*1000 -> 0.73925958 | AK17: =Y17/Y$5*1000 -> 0.72524894 | AL17: =Z17/Z$5*1000 -> 0.70540604 | AM17: =AA17/AA$5*1000 -> 0.66733522 | AN17: =AB17/AB$5*1000 -> 0.7125635 | AO17: =AC17/AC$5*1000 -> 0.71282041 | ... AR17: =AF17/AF$5*1000 -> 0.74946591 | AT17: =AH17/AT$4 -> 0.0058905088 | AU17: =AI17/AU$4 -> 0.0057583429 | AV17: =AJ17/AV$4 -> 0.0060398662 | AW17: =AK17/AW$4 -> 0.0059253972 | AX17: =AL17/AX$4 -> 0.0057632775 | AY17: =AM17/AY$4 -> 0.005452233 | AZ17: =AN17/AZ$4 -> 0.0058217551 | BA17: =AO17/BA$4 -> 0.0058238541 | ... BD17: =AR17/BD$4 -> 0.0061232536
B18: 分摊 | C18: 分摊费用 | D18: =('24年CK1'!D156+'24年CK2'!D148)/1000 -> 342.51653 | E18: =('24年CK1'!E156+'24年CK2'!E148)/1000 -> 306.2693 | F18: =('24年CK1'!F156+'24年CK2'!F148)/1000 -> 363.04306 | G18: =('24年CK1'!G156+'24年CK2'!G148)/1000 -> 406.73276 | H18: =('24年CK1'!H156+'24年CK2'!H148)/1000 -> 348.09051 | I18: =('24年CK1'!I156+'24年CK2'!I148)/1000 -> 320.46688 | J18: =('24年CK1'!J156+'24年CK2'!J148)/1000 -> 396.47497 | K18: =('24年CK1'!K156+'24年CK2'!K148)/1000 -> 599.95462 | ... O18: =('24年CK1'!O156+'24年CK2'!O148)/1000 -> 251.14301 | P18: =SUM(D18:O18) -> 4477.257 | Q18: =P18/$P$5*1000 -> 3.4775838 | R18: =P18/$P$22 -> 0.12222732 | S18: =Q18/$P$4 -> 0.028412403 | V18: =D18+E18 -> 648.78583 | W18: =V18+F18 -> 1011.8289 | X18: =W18+G18 -> 1418.5616 | Y18: =X18+H18 -> 1766.6522 | Z18: =Y18+I18 -> 2087.119 | AA18: =Z18+J18 -> 2483.594 | AB18: =AA18+K18 -> 3083.5486 | AC18: =AB18+L18 -> 3428.452 | AD18: =AC18+M18 -> 3800.5357 | ... AF18: =AE18+O18 -> 4477.257 | AH18: =V18/V$5*1000 -> 3.2841768 | AI18: =W18/W$5*1000 -> 3.2516394 | AJ18: =X18/X$5*1000 -> 3.3711627 | AK18: =Y18/Y$5*1000 -> 3.0739247 | AL18: =Z18/Z$5*1000 -> 2.9989454 | AM18: =AA18/AA$5*1000 -> 3.0129515 | AN18: =AB18/AB$5*1000 -> 3.4934925 | AO18: =AC18/AC$5*1000 -> 3.454144 | ... AR18: =AF18/AF$5*1000 -> 3.4775838 | AT18: =AH18/AT$4 -> 0.026832237 | AU18: =AI18/AU$4 -> 0.026566402 | AV18: =AJ18/AV$4 -> 0.027542926 | AW18: =AK18/AW$4 -> 0.025114445 | AX18: =AL18/AX$4 -> 0.024501852 | AY18: =AM18/AY$4 -> 0.024616285 | AZ18: =AN18/AZ$4 -> 0.02854238 | BA18: =AO18/BA$4 -> 0.028220896 | ... BD18: =AR18/BD$4 -> 0.028412403
C19: IT Expense-Internal Charge Out | D19: =('24年CK1'!D115+'24年CK2'!D107)/38/1000 -> 182.09794 | E19: =('24年CK1'!E115+'24年CK2'!E107)/38/1000 -> 304.45861 | F19: =('24年CK1'!F115+'24年CK2'!F107)/38/1000 -> 362.88386 | G19: =('24年CK1'!G115+'24年CK2'!G107)/38/1000 -> 320.66614 | H19: =('24年CK1'!H115+'24年CK2'!H107)/38/1000 -> 319.7274 | I19: =('24年CK1'!I115+'24年CK2'!I107)/38/1000 -> 319.91356 | J19: =('24年CK1'!J115+'24年CK2'!J107)/38/1000 -> 372.5827 | K19: =('24年CK1'!K115+'24年CK2'!K107)/38/1000 -> 375.61781 | ... O19: =('24年CK1'!O115+'24年CK2'!O107)/38/1000 -> 228.26902 | P19: =SUM(D19:O19) -> 3918.9001 | Q19: =P19/$P$5*1000 -> 3.0438958 | S19: =Q19/$P$4 -> 0.024869104 | V19: =D19+E19 -> 486.55656 | W19: =V19+F19 -> 849.44042 | X19: =W19+G19 -> 1170.1066 | Y19: =X19+H19 -> 1489.834 | Z19: =Y19+I19 -> 1809.7475 | AA19: =Z19+J19 -> 2182.3302 | AB19: =AA19+K19 -> 2557.948 | AC19: =AB19+L19 -> 2910.952 | AD19: =AC19+M19 -> 3287.7228 | ... AF19: =AE19+O19 -> 3918.9001 | AH19: =V19/V$5*1000 -> 2.4629664 | AI19: =W19/W$5*1000 -> 2.7297836 | AJ19: =X19/X$5*1000 -> 2.7807177 | AK19: =Y19/Y$5*1000 -> 2.5922689 | AL19: =Z19/Z$5*1000 -> 2.600395 | AM19: =AA19/AA$5*1000 -> 2.6474758 | AN19: =AB19/AB$5*1000 -> 2.8980157 | AO19: =AC19/AC$5*1000 -> 2.9327659 | ... AR19: =AF19/AF$5*1000 -> 3.0438958 | AT19: =AH19/AT$4 -> 0.020122821 | AU19: =AI19/AU$4 -> 0.022302759 | AV19: =AJ19/AV$4 -> 0.022718898 | AW19: =AK19/AW$4 -> 0.021179242 | AX19: =AL19/AX$4 -> 0.021245634 | AY19: =AM19/AY$4 -> 0.021630291 | AZ19: =AN19/AZ$4 -> 0.023677241 | BA19: =AO19/BA$4 -> 0.023961156 | ... BD19: =AR19/BD$4 -> 0.024869104
C20: Association dues | D20: =('24年CK1'!D114+'24年CK2'!D106)/38/1000 -> 0 | E20: =('24年CK1'!E114+'24年CK2'!E106)/38/1000 -> 1.8106924 | F20: =('24年CK1'!F114+'24年CK2'!F106)/38/1000 -> 0.15919132 | G20: =('24年CK1'!G114+'24年CK2'!G106)/38/1000 -> 9.5572245 | H20: =('24年CK1'!H114+'24年CK2'!H106)/38/1000 -> 8.6376266 | I20: =('24年CK1'!I114+'24年CK2'!I106)/38/1000 -> 8.7279321 | J20: =('24年CK1'!J114+'24年CK2'!J106)/38/1000 -> 8.4154321 | K20: =('24年CK1'!K114+'24年CK2'!K106)/38/1000 -> 7.8008282 | ... O20: =('24年CK1'!O114+'24年CK2'!O106)/38/1000 -> 7.3971439 | P20: =SUM(D20:O20) -> 75.02988 | Q20: =P20/$P$5*1000 -> 0.058277355 | S20: =Q20/$P$4 -> 0.00047613509 | V20: =D20+E20 -> 1.8106924 | W20: =V20+F20 -> 1.9698837 | X20: =W20+G20 -> 11.527108 | Y20: =X20+H20 -> 20.164735 | Z20: =Y20+I20 -> 28.892667 | AA20: =Z20+J20 -> 37.308099 | AB20: =AA20+K20 -> 45.108927 | AC20: =AB20+L20 -> 53.110412 | AD20: =AC20+M20 -> 60.273355 | ... AF20: =AE20+O20 -> 75.02988 | AH20: =V20/V$5*1000 -> 0.0091657886 | AI20: =W20/W$5*1000 -> 0.006330469 | AJ20: =X20/X$5*1000 -> 0.027393774 | AK20: =Y20/Y$5*1000 -> 0.035086067 | AL20: =Z20/Z$5*1000 -> 0.041515375 | AM20: =AA20/AA$5*1000 -> 0.045260011 | AN20: =AB20/AB$5*1000 -> 0.051105955 | AO20: =AC20/AC$5*1000 -> 0.053508408 | ... AR20: =AF20/AF$5*1000 -> 0.058277355 | AT20: =AH20/AT$4 -> 7.4885925e-05 | AU20: =AI20/AU$4 -> 5.1720921e-05 | AV20: =AJ20/AV$4 -> 0.00022381141 | AW20: =AK20/AW$4 -> 0.00028665865 | AX20: =AL20/AX$4 -> 0.0003391871 | AY20: =AM20/AY$4 -> 0.00036978136 | AZ20: =AN20/AZ$4 -> 0.00041754364 | BA20: =AO20/BA$4 -> 0.00043717205 | ... BD20: =AR20/BD$4 -> 0.00047613509
C21: G&A | D21: =D18-D19-D20 -> 160.41859 | E21: =E18-E19-E20 -> -2.2426505e-14 | F21: =F18-F19-F20 -> 1.1407542e-14 | G21: =G18-G19-G20 -> 76.509399 | H21: =H18-H19-H20 -> 19.725482 | I21: =I18-I19-I20 -> -8.1746113 | J21: =J18-J19-J20 -> 15.476841 | K21: =K18-K19-K20 -> 216.53599 | ... O21: =O18-O19-O20 -> 15.476841 | P21: =SUM(D21:O21) -> 483.32696 | Q21: =P21/$P$5*1000 -> 0.37541066 | S21: =Q21/$P$4 -> 0.0030671637 | V21: =D21+E21 -> 160.41859 | W21: =V21+F21 -> 160.41859 | X21: =W21+G21 -> 236.92799 | Y21: =X21+H21 -> 256.65347 | Z21: =Y21+I21 -> 248.47886 | AA21: =Z21+J21 -> 263.9557 | AB21: =AA21+K21 -> 480.49168 | AC21: =AB21+L21 -> 464.38958 | AD21: =AC21+M21 -> 452.53955 | ... AF21: =AE21+O21 -> 483.32696 | AH21: =V21/V$5*1000 -> 0.81204454 | AI21: =W21/W$5*1000 -> 0.5155253 | AJ21: =X21/X$5*1000 -> 0.56305116 | AK21: =Y21/Y$5*1000 -> 0.44656976 | AL21: =Z21/Z$5*1000 -> 0.35703499 | AM21: =AA21/AA$5*1000 -> 0.32021567 | AN21: =AB21/AB$5*1000 -> 0.54437088 | AO21: =AC21/AC$5*1000 -> 0.4678696 | ... AR21: =AF21/AF$5*1000 -> 0.37541066 | AT21: =AH21/AT$4 -> 0.0066345307 | AU21: =AI21/AU$4 -> 0.0042119223 | AV21: =AJ21/AV$4 -> 0.0046002159 | AW21: =AK21/AW$4 -> 0.0036485447 | AX21: =AL21/AX$4 -> 0.0029170316 | AY21: =AM21/AY$4 -> 0.002616212 | AZ21: =AN21/AZ$4 -> 0.0044475952 | BA21: =AO21/BA$4 -> 0.0038225677 | ... BD21: =AR21/BD$4 -> 0.0030671637
B22: 合计 | D22: =SUM(D6:D18,D26) -> 2064.5661 | E22: =SUM(E6:E18,E26) -> 2522.0094 | F22: =SUM(F6:F18,F26) -> 2777.9378 | G22: =SUM(G6:G18,G26) -> 2882.7559 | H22: =SUM(H6:H18,H26) -> 3016.6281 | I22: =SUM(I6:I18,I26) -> 3137.7862 | J22: =SUM(J6:J18,J26) -> 3465.9611 | K22: =SUM(K6:K18,K26) -> 3368.3282 | ... O22: =SUM(O6:O18,O26) -> 3183.3219 | P22: =SUM(D22:O22) -> 36630.575 | V22: =SUM(V6:V18) -> 3528.8127 | W22: =SUM(W6:W18) -> 5777.8691 | X22: =SUM(X6:X18) -> 8131.7436 | Y22: =SUM(Y6:Y18) -> 10619.49 | Z22: =SUM(Z6:Z18) -> 13228.395 | AA22: =SUM(AA6:AA18) -> 16165.475 | AB22: =SUM(AB6:AB18) -> 19004.921 | AC22: =SUM(AC6:AC18) -> 21715.591 | ... AF22: =SUM(AF6:AF18) -> 30439.769 | AH22: =V22/V$5*1000 -> 17.862974 | AI22: =W22/W$5*1000 -> 18.567909 | AJ22: =X22/X$5*1000 -> 19.324807 | AK22: =Y22/Y$5*1000 -> 18.477612 | AL22: =Z22/Z$5*1000 -> 19.007653 | AM22: =AA22/AA$5*1000 -> 19.611012 | AN22: =AB22/AB$5*1000 -> 21.53154 | AO22: =AC22/AC$5*1000 -> 21.878322 | ... AR22: =AF22/AF$5*1000 -> 23.643237 | AT22: =AH22/AT$4 -> 0.14594329 | AU22: =AI22/AU$4 -> 0.15170272 | AV22: =AJ22/AV$4 -> 0.15788669 | AW22: =AK22/AW$4 -> 0.15096498 | AX22: =AL22/AX$4 -> 0.15529549 | AY22: =AM22/AY$4 -> 0.16022503 | AZ22: =AN22/AZ$4 -> 0.17591605 | BA22: =AO22/BA$4 -> 0.17874931 | ... BD22: =AR22/BD$4 -> 0.19316894
B23: 单台 | D23: =D22/D5*1000 -> 23.639077 | E23: =E22/E5*1000 -> 22.883256 | F23: =F22/F5*1000 -> 24.448083 | G23: =G22/G5*1000 -> 26.298199 | H23: =H22/H5*1000 -> 19.597529 | I23: =I22/I5*1000 -> 25.883132 | J23: =J22/J5*1000 -> 27.002931 | K23: =K22/K5*1000 -> 57.727265 | ... P23: =P22/P5*1000 -> 28.451772 | Q23: =P23 -> 28.451772 | S23: =Q23/$P$4 -> 0.23245542 | V23: =V22/V5*1000 -> 17.862974 | W23: =W22/W5*1000 -> 18.567909 | X23: =X22/X5*1000 -> 19.324807 | Y23: =Y22/Y5*1000 -> 18.477612 | Z23: =Z22/Z5*1000 -> 19.007653 | AA23: =AA22/AA5*1000 -> 19.611012 | AB23: =AB22/AB5*1000 -> 21.53154 | AC23: =AC22/AC5*1000 -> 21.878322 | ... AF23: =AF22/AF5*1000 -> 23.643237
B25: 青岛不包含科目 | D25: =('24年CK1'!D158+'24年CK2'!D150)/1000 -> 341.802 | E25: =('24年CK1'!E158+'24年CK2'!E150)/1000 -> 327.68597 | F25: =('24年CK1'!F158+'24年CK2'!F150)/1000 -> 365.93252 | G25: =('24年CK1'!G158+'24年CK2'!G150)/1000 -> 383.45643 | H25: =('24年CK1'!H158+'24年CK2'!H150)/1000 -> 419.76833 | I25: =('24年CK1'!I158+'24年CK2'!I150)/1000 -> 551.74142 | J25: =('24年CK1'!J158+'24年CK2'!J150)/1000 -> 906.90377 | K25: =('24年CK1'!K158+'24年CK2'!K150)/1000 -> 986.05575 | ... O25: =('24年CK1'!O158+'24年CK2'!O150)/1000 -> 910.23683 | P25: =SUM(D25:O25) -> 7984.5405
B26: functional currency | D26: 528.88143 | E26: 528.88143 | F26: 528.88143 | G26: 528.88143 | H26: 528.88143 | I26: 528.88143 | J26: 528.88143 | K26: 528.88143 | L26: 528.88143 | M26: 528.88143 | N26: 528.88143 | O26: 373.11006 | P26: =SUM(D26:O26) -> 6190.8058 | Q26: =P26/$P$5*1000 -> 4.8085348
Q27: =Q23+Q26 -> 33.260307 | S27: =Q23/P4 -> 0.23245542
C28: 厨电25年实际
A29: 年累 | C29: 科目 | D29: 25年1月 | E29: 25年2月 | F29: 25年3月 | G29: 25年4月 | H29: 25年5月 | I29: 25年6月 | J29: 25年7月 | K29: 25年8月 | L29: 25年9月 | M29: 25年10月 | N29: 25年11月 | O29: 25年12月 | P29: 合计 | Q29: 单台 | R29: 占比 | S29: 费率 | T29: 同比
A30: 125 | B30: 平均单价（自制） | D30: 132.28094 | E30: 126.5203 | F30: 124.52481 | G30: 125.48365 | H30: 119.998 | I30: 117.22308 | J30: 106.8 | K30: 122.15761 | L30: 113.63291 | M30: 119.3915 | N30: 119.78253 | O30: 124.50549 | P30: =AVERAGE(D30:O30) -> 121.02507 | Q30: =AVERAGE(D30:O30) -> 121.02507 | AT30: =$P$30 -> 121.02507 | AU30: =$P$30 -> 121.02507 | AV30: =$P$30 -> 121.02507 | AW30: =$P$30 -> 121.02507 | AX30: =$P$30 -> 121.02507 | AY30: =$P$30 -> 121.02507 | AZ30: =$P$30 -> 121.02507 | BA30: =$P$30 -> 121.02507 | ... BD30: =$P$30 -> 121.02507
A31: =SUM(D31:F31) -> 254474 | C31: 产量 | D31: 79712 | E31: 82105 | F31: 92657 | G31: 98687 | H31: 93353 | I31: 75092 | J31: 77799 | K31: 58812 | L31: 90826 | M31: 111572 | N31: 111625 | O31: 75554 | P31: =SUM(D31:O31) -> 1047794 | U31: 1171 | V31: =D31+E31 -> 161817 | W31: =V31+F31 -> 254474 | X31: =W31+G31 -> 353161 | Y31: =X31+H31 -> 446514 | Z31: =Y31+I31 -> 521606 | AA31: =Z31+J31 -> 599405 | AB31: =AA31+K31 -> 658217 | AC31: =AB31+L31 -> 749043 | AD31: =AC31+M31 -> 860615 | ... AF31: =AE31+O31 -> 1047794
A32: =SUM(D32:F32) -> 2275.3025 | B32: 固定制造 | C32: 折旧 | D32: 770.36882 | E32: 741.42854 | F32: 763.50516 | G32: 766.01624 | H32: 831.68695 | I32: 824.01968 | J32: 839.2091 | K32: 583.2903 | L32: 793.0073 | M32: 589.92044 | N32: 801.39809 | O32: 815.91192 | P32: =SUM(D32:O32) -> 9119.7625 | Q32: =P32/$P$31*1000 -> 8.7037743 | R32: =P32/$P$48 -> 0.3159956 | S32: =Q32/$P$30 -> 0.07191712 | U32: 含FC | V32: =D32+E32 -> 1511.7974 | W32: =V32+F32 -> 2275.3025 | X32: =W32+G32 -> 3041.3188 | Y32: =X32+H32 -> 3873.0057 | Z32: =Y32+I32 -> 4697.0254 | AA32: =Z32+J32 -> 5536.2345 | AB32: =AA32+K32 -> 6119.5248 | AC32: =AB32+L32 -> 6912.5321 | AD32: =AC32+M32 -> 7502.4525 | ... AF32: =AE32+O32 -> 9119.7625 | AH32: =V32/V$31*1000 -> 9.3426362 | AI32: =W32/W$31*1000 -> 8.9411984 | AJ32: =X32/X$31*1000 -> 8.6117062 | AK32: =Y32/Y$31*1000 -> 8.673873 | AL32: =Z32/Z$31*1000 -> 9.0049298 | AM32: =AA32/AA$31*1000 -> 9.2362167 | AN32: =AB32/AB$31*1000 -> 9.2971236 | AO32: =AC32/AC$31*1000 -> 9.228485 | ... AR32: =AF32/AF$31*1000 -> 8.7037743 | AT32: =AH32/AT$30 -> 0.077195877 | AU32: =AI32/AU$30 -> 0.073878896 | AV32: =AJ32/AV$30 -> 0.071156384 | AW32: =AK32/AW$30 -> 0.071670053 | AX32: =AL32/AX$30 -> 0.074405492 | AY32: =AM32/AY$30 -> 0.076316559 | AZ32: =AN32/AZ$30 -> 0.076819817 | BA32: =AO32/BA$30 -> 0.076252674 | ... BD32: =AR32/BD$30 -> 0.07191712
A33: =SUM(D33:F33) -> 407.82934 | C33: 运营费 | D33: 95.78168 | E33: 108.72299 | F33: 203.32467 | G33: 12.16119 | H33: 83.73571 | I33: 82.17874 | J33: 72.26606 | K33: 71.16146 | L33: 85.19357 | M33: 87.58382 | N33: 120.34261 | O33: 75.7403 | P33: =SUM(D33:O33) -> 1098.1928 | Q33: =P33/$P$31*1000 -> 1.0480999 | R33: =P33/$P$48 -> 0.038051879 | S33: =Q33/$P$30 -> 0.0086601886 | V33: =D33+E33 -> 204.50467 | W33: =V33+F33 -> 407.82934 | X33: =W33+G33 -> 419.99053 | Y33: =X33+H33 -> 503.72624 | Z33: =Y33+I33 -> 585.90498 | AA33: =Z33+J33 -> 658.17104 | AB33: =AA33+K33 -> 729.3325 | AC33: =AB33+L33 -> 814.52607 | AD33: =AC33+M33 -> 902.10989 | ... AF33: =AE33+O33 -> 1098.1928 | AH33: =V33/V$31*1000 -> 1.2638021 | AI33: =W33/W$31*1000 -> 1.6026366 | AJ33: =X33/X$31*1000 -> 1.1892325 | AK33: =Y33/Y$31*1000 -> 1.1281309 | AL33: =Z33/Z$31*1000 -> 1.1232712 | AM33: =AA33/AA$31*1000 -> 1.0980406 | AN33: =AB33/AB$31*1000 -> 1.1080426 | AO33: =AC33/AC$31*1000 -> 1.0874223 | ... AR33: =AF33/AF$31*1000 -> 1.0480999 | AT33: =AH33/AT$30 -> 0.010442482 | AU33: =AI33/AU$30 -> 0.013242187 | AV33: =AJ33/AV$30 -> 0.0098263318 | AW33: =AK33/AW$30 -> 0.0093214647 | AX33: =AL33/AX$30 -> 0.00928131 | AY33: =AM33/AY$30 -> 0.0090728363 | AZ33: =AN33/AZ$30 -> 0.0091554804 | BA33: =AO33/BA$30 -> 0.0089850998 | ... BD33: =AR33/BD$30 -> 0.0086601886
A34: =SUM(D34:F34) -> 92.55319 | C34: 存货跌价准备 | D34: 34.84363 | E34: 28.85478 | F34: 28.85478 | G34: 28.85478 | H34: 28.85478 | I34: 222.48895 | J34: 8.85478 | K34: 8.855 | L34: -1281.6854 | M34: 0 | N34: 0 | O34: -375.25241 | P34: =SUM(D34:O34) -> -1266.4763 | Q34: =P34/$P$31*1000 -> -1.2087074 | R34: =P34/$P$48 -> -0.043882826 | S34: =Q34/$P$30 -> -0.009987248 | V34: =D34+E34 -> 63.69841 | W34: =V34+F34 -> 92.55319 | X34: =W34+G34 -> 121.40797 | Y34: =X34+H34 -> 150.26275 | Z34: =Y34+I34 -> 372.7517 | AA34: =Z34+J34 -> 381.60648 | AB34: =AA34+K34 -> 390.46148 | AC34: =AB34+L34 -> -891.22391 | AD34: =AC34+[1]Sheet1!L57 -> -891.10397 | AE34: =AD34+N34 -> -891.10397 | AF34: =AE34+O34 -> -1266.3564 | AH34: =V34/V$31*1000 -> 0.39364473 | AI34: =W34/W$31*1000 -> 0.36370391 | AJ34: =X34/X$31*1000 -> 0.34377513 | AK34: =Y34/Y$31*1000 -> 0.33652416 | AL34: =Z34/Z$31*1000 -> 0.71462311 | AM34: =AA34/AA$31*1000 -> 0.63664214 | AN34: =AB34/AB$31*1000 -> 0.59321087 | AO34: =AC34/AC$31*1000 -> -1.1898168 | ... AR34: =AF34/AF$31*1000 -> -1.2085929 | AT34: =AH34/AT$30 -> 0.0032525884 | AU34: =AI34/AU$30 -> 0.0030051949 | AV34: =AJ34/AV$30 -> 0.0028405283 | AW34: =AK34/AW$30 -> 0.0027806154 | AX34: =AL34/AX$30 -> 0.0059047528 | AY34: =AM34/AY$30 -> 0.0052604155 | AZ34: =AN34/AZ$30 -> 0.0049015537 | BA34: =AO34/BA$30 -> -0.0098311596 | ... BD34: =AR34/BD$30 -> -0.0099863022
A35: =SUM(D35:F35) -> 129.83754 | C35: 固定能源费 | D35: 47.14342 | E35: 35.17581 | F35: 47.51831 | G35: 5.08957 | H35: 27.51429 | I35: 20.25036 | J35: 22.36867 | K35: 29.97052 | L35: 29.52934 | M35: 33.0999 | N35: 27.76599 | O35: 33.87562 | P35: =SUM(D35:O35) -> 359.3018 | Q35: =P35/$P$31*1000 -> 0.34291263 | R35: =P35/$P$48 -> 0.012449643 | S35: =Q35/$P$30 -> 0.0028334017 | V35: =D35+E35 -> 82.31923 | W35: =V35+F35 -> 129.83754 | X35: =W35+G35 -> 134.92711 | Y35: =X35+H35 -> 162.4414 | Z35: =Y35+I35 -> 182.69176 | AA35: =Z35+J35 -> 205.06043 | AB35: =AA35+K35 -> 235.03095 | AC35: =AB35+L35 -> 264.56029 | AD35: =AC35+M35 -> 297.66019 | ... AF35: =AE35+O35 -> 359.3018 | AH35: =V35/V$31*1000 -> 0.50871806 | AI35: =W35/W$31*1000 -> 0.51021928 | AJ35: =X35/X$31*1000 -> 0.38205552 | AK35: =Y35/Y$31*1000 -> 0.36379912 | AL35: =Z35/Z$31*1000 -> 0.35024858 | AM35: =AA35/AA$31*1000 -> 0.34210664 | AN35: =AB35/AB$31*1000 -> 0.35707214 | AO35: =AC35/AC$31*1000 -> 0.35319773 | ... AR35: =AF35/AF$31*1000 -> 0.34291263 | AT35: =AH35/AT$30 -> 0.0042034106 | AU35: =AI35/AU$30 -> 0.0042158148 | AV35: =AJ35/AV$30 -> 0.0031568296 | AW35: =AK35/AW$30 -> 0.0030059815 | AX35: =AL35/AX$30 -> 0.0028940168 | AY35: =AM35/AY$30 -> 0.002826742 | AZ35: =AN35/AZ$30 -> 0.0029503981 | BA35: =AO35/BA$30 -> 0.0029183849 | ... BD35: =AR35/BD$30 -> 0.0028334017
A36: =SUM(D36:F36) -> 1235.8801 | C36: 间接人工成本-辅助人员 | D36: 385.87333 | E36: 358.20537 | F36: 491.80141 | G36: 403.07668 | H36: 452.17888 | I36: 332.25239 | J36: 332.16484 | K36: 279.86157 | L36: 317.01562 | M36: 415.08803 | N36: 361.68076 | O36: 422.62091 | P36: =SUM(D36:O36) -> 4551.8198 | Q36: =P36/$P$31*1000 -> 4.3441934 | R36: =P36/$P$48 -> 0.15771848 | S36: =Q36/$P$30 -> 0.035894988 | U36: 25年3月/9月各涨18% | V36: =D36+E36 -> 744.0787 | W36: =V36+F36 -> 1235.8801 | X36: =W36+G36 -> 1638.9568 | Y36: =X36+H36 -> 2091.1357 | Z36: =Y36+I36 -> 2423.3881 | AA36: =Z36+J36 -> 2755.5529 | AB36: =AA36+K36 -> 3035.4145 | AC36: =AB36+L36 -> 3352.4301 | AD36: =AC36+M36 -> 3767.5181 | ... AF36: =AE36+O36 -> 4551.8198 | AH36: =V36/V$31*1000 -> 4.5982727 | AI36: =W36/W$31*1000 -> 4.8566066 | AJ36: =X36/X$31*1000 -> 4.6408204 | AK36: =Y36/Y$31*1000 -> 4.6832477 | AL36: =Z36/Z$31*1000 -> 4.6460126 | AM36: =AA36/AA$31*1000 -> 4.597147 | AN36: =AB36/AB$31*1000 -> 4.6115711 | AO36: =AC36/AC$31*1000 -> 4.4756177 | ... AR36: =AF36/AF$31*1000 -> 4.3441934 | AT36: =AH36/AT$30 -> 0.037994383 | AU36: =AI36/AU$30 -> 0.040128931 | AV36: =AJ36/AV$30 -> 0.038345944 | AW36: =AK36/AW$30 -> 0.03869651 | AX36: =AL36/AX$30 -> 0.038388845 | AY36: =AM36/AY$30 -> 0.037985081 | AZ36: =AN36/AZ$30 -> 0.038104263 | BA36: =AO36/BA$30 -> 0.036980914 | ... BD36: =AR36/BD$30 -> 0.035894988
A37: =SUM(D37:F37) -> 722.82554 | C37: 固定人工-白领 | D37: 276.16976 | E37: 193.34998 | F37: 253.3058 | G37: 149.25268 | H37: 199.13504 | I37: 153.80926 | J37: 132.57406 | K37: 141.30123 | L37: 119.39319 | M37: 103.52545 | N37: 110.0848 | O37: 106.23428 | P37: =SUM(D37:O37) -> 1938.1355 | Q37: =P37/$P$31*1000 -> 1.8497296 | R37: =P37/$P$48 -> 0.06715551 | S37: =Q37/$P$30 -> 0.015283855 | V37: =D37+E37 -> 469.51974 | W37: =V37+F37 -> 722.82554 | X37: =W37+G37 -> 872.07822 | Y37: =X37+H37 -> 1071.2133 | Z37: =Y37+I37 -> 1225.0225 | AA37: =Z37+J37 -> 1357.5966 | AB37: =AA37+K37 -> 1498.8978 | AC37: =AB37+L37 -> 1618.291 | AD37: =AC37+M37 -> 1721.8164 | ... AF37: =AE37+O37 -> 1938.1355 | AH37: =V37/V$31*1000 -> 2.9015477 | AI37: =W37/W$31*1000 -> 2.8404691 | AJ37: =X37/X$31*1000 -> 2.4693503 | AK37: =Y37/Y$31*1000 -> 2.3990586 | AL37: =Z37/Z$31*1000 -> 2.3485591 | AM37: =AA37/AA$31*1000 -> 2.264907 | AN37: =AB37/AB$31*1000 -> 2.2772092 | AO37: =AC37/AC$31*1000 -> 2.1604781 | ... AR37: =AF37/AF$31*1000 -> 1.8497296 | AT37: =AH37/AT$30 -> 0.023974766 | AU37: =AI37/AU$30 -> 0.023470089 | AV37: =AJ37/AV$30 -> 0.020403627 | AW37: =AK37/AW$30 -> 0.019822824 | AX37: =AL37/AX$30 -> 0.019405559 | AY37: =AM37/AY$30 -> 0.018714363 | AZ37: =AN37/AZ$30 -> 0.018816013 | BA37: =AO37/BA$30 -> 0.017851493 | ... BD37: =AR37/BD$30 -> 0.015283855
A38: =SUM(D38:F38) -> 581.13068 | C38: 半固定-班车/工作服 | D38: 219.71751 | E38: 220.42753 | F38: 140.98564 | G38: 147.58937 | H38: 170.65504 | I38: 126.29138 | J38: 128.75935 | K38: 134.41711 | L38: 147.22651 | M38: 149.29277 | N38: 157.73939 | O38: 168.50673 | P38: =SUM(D38:O38) -> 1911.6083 | Q38: =P38/$P$31*1000 -> 1.8244124 | R38: =P38/$P$48 -> 0.066236355 | S38: =Q38/$P$30 -> 0.015074665 | V38: =D38+E38 -> 440.14504 | W38: =V38+F38 -> 581.13068 | X38: =W38+G38 -> 728.72005 | Y38: =X38+H38 -> 899.37509 | Z38: =Y38+I38 -> 1025.6665 | AA38: =Z38+J38 -> 1154.4258 | AB38: =AA38+K38 -> 1288.8429 | AC38: =AB38+L38 -> 1436.0694 | AD38: =AC38+M38 -> 1585.3622 | ... AF38: =AE38+O38 -> 1911.6083 | AH38: =V38/V$31*1000 -> 2.7200173 | AI38: =W38/W$31*1000 -> 2.2836544 | AJ38: =X38/X$31*1000 -> 2.0634216 | AK38: =Y38/Y$31*1000 -> 2.0142148 | AL38: =Z38/Z$31*1000 -> 1.9663625 | AM38: =AA38/AA$31*1000 -> 1.9259529 | AN38: =AB38/AB$31*1000 -> 1.9580821 | AO38: =AC38/AC$31*1000 -> 1.9172056 | ... AR38: =AF38/AF$31*1000 -> 1.8244124 | AT38: =AH38/AT$30 -> 0.022474826 | AU38: =AI38/AU$30 -> 0.018869268 | AV38: =AJ38/AV$30 -> 0.017049539 | AW38: =AK38/AW$30 -> 0.016642955 | AX38: =AL38/AX$30 -> 0.016247564 | AY38: =AM38/AY$30 -> 0.01591367 | AZ38: =AN38/AZ$30 -> 0.016179145 | BA38: =AO38/BA$30 -> 0.015841393 | ... BD38: =AR38/BD$30 -> 0.015074665
A39: =SUM(D39:F39) -> 1702.2824 | B39: 变动制造 | C39: 直接人工 | D39: 544.15844 | E39: 469.02011 | F39: 689.10387 | G39: 573.04516 | H39: 645.05798 | I39: 596.42251 | J39: 524.39303 | K39: 432.51216 | L39: 570.86096 | M39: 501.28108 | N39: 640.25558 | O39: 557.30606 | P39: =SUM(D39:O39) -> 6743.4169 | Q39: =P39/$P$31*1000 -> 6.4358232 | R39: =P39/$P$48 -> 0.23365632 | S39: =Q39/$P$30 -> 0.053177605 | U39: 25年3月/9月各涨18% | V39: =D39+E39 -> 1013.1786 | W39: =V39+F39 -> 1702.2824 | X39: =W39+G39 -> 2275.3276 | Y39: =X39+H39 -> 2920.3856 | Z39: =Y39+I39 -> 3516.8081 | AA39: =Z39+J39 -> 4041.2011 | AB39: =AA39+K39 -> 4473.7133 | AC39: =AB39+L39 -> 5044.5742 | AD39: =AC39+M39 -> 5545.8553 | ... AF39: =AE39+O39 -> 6743.4169 | AH39: =V39/V$31*1000 -> 6.2612615 | AI39: =W39/W$31*1000 -> 6.6894159 | AJ39: =X39/X$31*1000 -> 6.4427487 | AK39: =Y39/Y$31*1000 -> 6.5404121 | AL39: =Z39/Z$31*1000 -> 6.7422692 | AM39: =AA39/AA$31*1000 -> 6.742021 | AN39: =AB39/AB$31*1000 -> 6.7967149 | AO39: =AC39/AC$31*1000 -> 6.7346924 | ... AR39: =AF39/AF$31*1000 -> 6.4358232 | AT39: =AH39/AT$30 -> 0.051735245 | AU39: =AI39/AU$30 -> 0.055272978 | AV39: =AJ39/AV$30 -> 0.053234828 | AW39: =AK39/AW$30 -> 0.054041797 | AX39: =AL39/AX$30 -> 0.055709692 | AY39: =AM39/AY$30 -> 0.055707641 | AZ39: =AN39/AZ$30 -> 0.056159562 | BA39: =AO39/BA$30 -> 0.055647087 | ... BD39: =AR39/BD$30 -> 0.053177605
