Workbook
Name \1: #REF!
Name \2: #REF!
Name \3: #REF!
Name \4: #REF!
Name \A: #REF!
Name \B: #REF!
Name \C: #REF!
Name \P: #REF!
Name \Q: #REF!
Name \R: #REF!
Name \S: #REF!
Name \T: #REF!
Name \X: #REF!
Name ___CON1: #REF!
Name ___CON2: #REF!
Name ___ddn400: #REF!
Name ___ddn600: #REF!
Name ___E99999: #REF!
Name ___ETI2: #REF!
Name ___gon4: #REF!
Name ___IV999999: #REF!
Name ___IZ53: #REF!
Name ___JZ123: #REF!
Name ___lap1: #REF!
Name ___lap2: #REF!
Name ___LI1: OFFSET(#REF!,4,0,COUNTA(#REF!)-1,1)
Name ___LI10: OFFSET(#REF!,4,0,COUNTA(#REF!)-1,1)
Name ___LI11: OFFSET(#REF!,4,0,COUNTA(#REF!)-1,1)
Name ___LI12: OFFSET(#REF!,4,0,COUNTA(#REF!)-1,1)
Name ___LI13: OFFSET(#REF!,4,0,COUNTA(#REF!)-1,1)
Name ___LI14: OFFSET(#REF!,4,0,COUNTA(#REF!)-1,1)
Name ___LI15: OFFSET(#REF!,4,0,COUNTA(#REF!)-1,1)
Name ___LI16: OFFSET(#REF!,4,0,COUNTA(#REF!)-1,1)
Name ___LI17: OFFSET(#REF!,4,0,COUNTA(#REF!)-1,1)
Name ___LI18: OFFSET(#REF!,4,0,COUNTA(#REF!)-1,1)
Name ___LI19: OFFSET(#REF!,4,0,COUNTA(#REF!)-1,1)
Name ___LI2: OFFSET(#REF!,4,0,COUNTA(#REF!)-1,1)
Name ___LI20: OFFSET(#REF!,4,0,COUNTA(#REF!)-1,1)
Name ___LI21: OFFSET(#REF!,4,0,COUNTA(#REF!)-1,1)
Name ___LI22: OFFSET(#REF!,4,0,COUNTA(#REF!)-1,1)
Name ___LI23: OFFSET(#REF!,4,0,COUNTA(#REF!)-1,1)
Name ___LI24: OFFSET(#REF!,4,0,COUNTA(#REF!)-1,1)
Name ___LI25: OFFSET(#REF!,4,0,COUNTA(#REF!)-1,1)
Name ___LI3: OFFSET(#REF!,4,0,COUNTA(#REF!)-1,1)
Name ___LI30: OFFSET(#REF!,4,0,COUNTA(#REF!)-1,1)
Name ___LI4: OFFSET(#REF!,4,0,COUNTA(#REF!)-1,1)
Name ___LI5: OFFSET(#REF!,4,0,COUNTA(#REF!)-1,1)
Name ___LI6: OFFSET(#REF!,4,0,COUNTA(#REF!)-1,1)
Name ___LI7: OFFSET(#REF!,4,0,COUNTA(#REF!)-1,1)
Name ___LI8: OFFSET(#REF!,4,0,COUNTA(#REF!)-1,1)
Name ___LI9: OFFSET(#REF!,4,0,COUNTA(#REF!)-1,1)
Name ___LZ123: #REF!
Name ___MAC12: #REF!
Name ___MAC46: #REF!
Name ___MZ53: #REF!
Name ___NCL100: #REF!
Name ___NCL200: #REF!
Name ___NCL250: #REF!
Name ___NET2: #REF!
Name ___nin190: #REF!

Sheet CC
B2: MFG | C2: PTK4M00WAB
C3: PTK4M00WAC
C4: PTK4M00WAD
C5: PTK4M00WAE
C6: PTK4M00WAF
C7: PTK4M00WAG
C8: PTK4M00WAH
C9: PTK4M00WAI
C10: PTK4M00WAJ
C11: PTK4M00WAK
C12: PTK4M00WYD
B13: Overhead | C13: PTK4Y00WYE

Sheet DW 2026
B1: Renta DW Cost Evolution | D1: Volume | E1: 47357 | F1: 42593 | G1: 23002 | H1: 44096 | I1: 33043 | J1: 53186 | K1: 40831 | L1: 39000.001 | M1: 54085 | N1: 49968 | O1: 51936 | P1: 42190 | Q1: =+E1+F1+G1+H1+I1+J1+K1+L1+M1+N1+O1+P1 -> 521287
D2: FX Rates_HQE | E2: 50.745776 | F2: 51.632775 | G2: 51.093809 | H2: 52.45 | I2: 53.158395 | J2: 53.3 | K2: 53.76 | L2: 55.623333 | M2: 56.525 | N2: 57.283333 | O2: 58.041667 | P2: 58.8
D3: FX Rates_weighted average (Act TL/Act EUR) | E3: =+E245 -> 55.415196 | F3: =+F245 -> 52.908683 | G3: =+G245 -> 52.478115 | H3: =+H245 -> 0 | I3: =+I245 -> 0 | J3: =+J245 -> 0 | K3: =+K245 -> 0 | L3: =+L245 -> 0 | ... Q3: =+Q245 -> 0
A5: HQD PERIMETER | E5: Jan K€ | F5: Feb K€ | G5: Mar K€ | H5: Apr K€ | I5: May K€ | J5: June K€ | K5: July K€ | L5: Aug K€ | M5: Sep K€ | N5: Oct K€ | O5: Nov K€ | P5: DEC K€ | Q5: YTD K€
A6: YES | B6: 6666110101 | C6: 6666110101 Depreciation of buildings | D6: * CS_Depreciation | E6: =32.52614-E251 -> 9.5887601 | F6: 8.6135783 | G6: =32.53747-G251 -> 9.5496438 | H6: 7.5771286 | I6: 13.807534 | J6: 8.7067803 | K6: 8.7355413 | L6: 451.07175 | M6: 441.19345 | N6: 453.16818 | O6: 446.77673 | P6: 459.37043 | Q6: =F6+E6+G6+H6+I6+J6+K6+L6+M6+N6+O6+P6 -> 2318.1595
A7: YES | B7: 6666110106 | C7: 6666110106 Depreciation of R&D facilities | D7: * CS_Depreciation | E7: =0-E252 -> 0 | F7: 0 | G7: 0 | H7: 0 | I7: 0 | J7: 0 | K7: 0 | L7: 0 | M7: 0 | N7: 0 | O7: 0 | P7: 0 | Q7: =F7+E7+G7+H7+I7+J7+K7+L7+M7+N7+O7+P7 -> 0
A8: YES | B8: 6666110107 | C8: 6666110107 Depreciation of mold | D8: * CS_Depreciation | E8: =224.42191-E253 -> 92.462416 | F8: 87.582816 | G8: =224.82728-G253 -> 92.230816 | H8: -28.532337 | I8: 57.979578 | J8: 62.165871 | K8: 62.303587 | L8: -106.94686 | M8: -107.16719 | N8: -109.11171 | O8: -108.98445 | P8: -144.12936 | Q8: =F8+E8+G8+H8+I8+J8+K8+L8+M8+N8+O8+P8 -> -150.14683
A9: YES | B9: 6666110110 | C9: 6666110110 Depreciation-Plant & Machinery | D9: * CS_Depreciation | E9: =295.75794-E254 -> 63.749081 | F9: 57.049972 | G9: =296.41246-G254 -> 63.876727 | H9: 17.589213 | I9: 50.464631 | J9: 59.732843 | K9: 48.220076 | L9: -179.7257 | M9: -174.32048 | N9: -180.83947 | O9: -175.04577 | P9: -237.55234 | Q9: =F9+E9+G9+H9+I9+J9+K9+L9+M9+N9+O9+P9 -> -586.80122
A10: YES | B10: 6666110112 | C10: 6666110112 Depreciation of Furniture & Fixture | D10: * CS_Depreciation | E10: =8.94279-E255 -> 4.2473878 | F10: 3.5120625 | G10: =8.80315-G255 -> 4.0802573 | H10: -1.8538329 | I10: 1.4199062 | J10: 0.95259662 | K10: 2.3047451 | L10: -0.46773118 | M10: -0.46734558 | N10: -0.62049232 | O10: -0.52596366 | P10: -1.3658423 | Q10: =F10+E10+G10+H10+I10+J10+K10+L10+M10+N10+O10+P10 -> 11.215748
A11: YES | B11: 6666110204 | C11: 6666110204 Amortization of license, trademarks and | D11: * CS_Depreciation | E11: =0.25252-E256 -> 0.17412081 | F11: 0.17112992 | G11: =0.25252-G256 -> 0.17293485 | H11: -0.30079261 | I11: 0.0090222244 | J11: 0.049860056 | K11: 0.048564111 | L11: 1.6232069 | M11: 1.6769447 | N11: 1.6753436 | O11: 1.6162509 | P11: 1.6492861 | Q11: =F11+E11+G11+H11+I11+J11+K11+L11+M11+N11+O11+P11 -> 8.5658714
A12: YES | B12: 6666110207 | C12: 6666110207 Amortization of Software | D12: * CS_Depreciation | E12: =2.34991-E257 -> 1.1264639 | F12: 1.1066886 | G12: =2.34993-G257 -> 1.1187913 | H12: -1.5773002 | I12: -0.06417721 | J12: 0.43481723 | K12: 0.42483049 | L12: -1.1428264 | M12: -0.75593496 | N12: -0.92121231 | O12: -0.97125697 | P12: -1.274676 | Q12: =F12+E12+G12+H12+I12+J12+K12+L12+M12+N12+O12+P12 -> -2.4957925
A13: YES | B13: 6666110506 | C13: 6666110506 Amortization-Leasehold Improvement | D13: * CS_Depreciation | E13: =0-E258 -> 0 | F13: 0 | G13: 0 | H13: 0 | I13: 0 | J13: 0 | K13: 0 | L13: 0 | M13: 0 | N13: 0 | O13: 0 | P13: 0 | Q13: =F13+E13+G13+H13+I13+J13+K13+L13+M13+N13+O13+P13 -> 0
B14: FIX | C14: * CS_Depreciation | E14: =SUM(E6:E13) -> 171.34823 | F14: =SUM(F6:F13) -> 158.03625 | G14: =SUM(G6:G13) -> 171.02917 | H14: =SUM(H6:H13) -> -7.0979216 | I14: =SUM(I6:I13) -> 123.61649 | J14: =SUM(J6:J13) -> 132.04277 | K14: =SUM(K6:K13) -> 122.03734 | L14: =SUM(L6:L13) -> 164.41184 | ... Q14: =SUM(Q6:Q13) -> 1598.4973
A15: YES | B15: 5001010205 | C15: 5001010205 Unemployment Insurance -blue collar-Dire | D15: * CS_Direct Labour | E15: 7.61607 | F15: 6.3086 | G15: 6.05422 | H15: 5.8402799 | I15: 7.1399794 | J15: 6.57644 | K15: 5.76483 | L15: 0 | M15: 0 | N15: 0 | O15: 0 | P15: 0 | Q15: =F15+E15+G15+H15+I15+J15+K15+L15+M15+N15+O15+P15 -> 45.300419
A16: YES | B16: 6666010380 | C16: 6666010380 Incentive | D16: * CS_Direct Labour | E16: -1.8209 | F16: -1.58476 | G16: 0.192 | H16: -0.63535 | I16: -3.83977 | J16: -1.48382 | K16: -2.25762 | L16: 0 | M16: 0 | N16: 0 | O16: 0 | P16: 0 | Q16: =F16+E16+G16+H16+I16+J16+K16+L16+M16+N16+O16+P16 -> -11.43022
A17: YES | B17: 6666010019 | C17: 6666010019 Payroll Taxes - Blue Collar Direct | D17: * CS_Direct Labour | E17: 64.67305 | F17: 53.75998 | G17: 50.63986 | H17: 49.665935 | I17: 61.079734 | J17: 56.41294 | K17: 49.35098 | L17: 355.48086 | M17: 485.59337 | N17: 492.47378 | O17: 476.66858 | P17: 480.28353 | Q17: =F17+E17+G17+H17+I17+J17+K17+L17+M17+N17+O17+P17 -> 2676.0826
A18: YES | B18: 6666010183 | C18: 6666010183 Overtime-Blue Collar-Direct | D18: * CS_Direct Labour | E18: 10.50135 | F18: 13.3775 | G18: -9.43515 | H18: 21.249929 | I18: 16.554552 | J18: 8.86122 | K18: 9.75508 | L18: 0 | M18: 0 | N18: 0 | O18: 0 | P18: 0 | Q18: =F18+E18+G18+H18+I18+J18+K18+L18+M18+N18+O18+P18 -> 70.864481
A19: YES | B19: 6666010229 | C19: 6666010229 Staff Leaving Indemnity - Blue Collar Di | D19: * CS_Direct Labour | E19: 16.69101 | F19: 107.23839 | G19: -345.16488 | H19: 9.97066 | I19: 10.4602 | J19: 10.57159 | K19: 1.16773 | L19: 0 | M19: 0 | N19: 0 | O19: 0 | P19: 0 | Q19: =F19+E19+G19+H19+I19+J19+K19+L19+M19+N19+O19+P19 -> -189.0653
A20: YES | B20: 6666010188 | C20: 6666010188 Salary - Blue collar direct employees | D20: * CS_Direct Labour | E20: 357.71936 | F20: 277.99859 | G20: 573.04631 | H20: 277.01291 | I20: 381.56738 | J20: 312.0039 | K20: 277.45603 | L20: 0 | M20: 0 | N20: 0 | O20: 0 | P20: 0 | Q20: =F20+E20+G20+H20+I20+J20+K20+L20+M20+N20+O20+P20 -> 2456.8045
A21: YES | B21: 5102040406 | C21: 5102040406 Other revenue-Service/Secondment agreeme | D21: * CS_Direct Labour | E21: 0 | F21: 0 | G21: 0 | H21: 0 | I21: 0 | J21: 0 | K21: 0 | L21: 0 | M21: 0 | N21: 0 | O21: 0 | P21: 0 | Q21: =F21+E21+G21+H21+I21+J21+K21+L21+M21+N21+O21+P21 -> 0
A22: YES | B22: 6666010115 | C22: 6666010115 Salary-Blue collar direct employees-Accr | D22: * CS_Direct Labour | E22: -4.2657 | F22: 0.68853 | G22: 0.63223 | H22: 0.63007 | I22: 5.6858 | J22: -1.30866 | K22: 7.8172 | L22: 0 | M22: 0 | N22: 0 | O22: 0 | P22: 0 | Q22: =F22+E22+G22+H22+I22+J22+K22+L22+M22+N22+O22+P22 -> 9.87947
B23: VAR | C23: * CS_Direct Labour | E23: =SUM(E15:E22) -> 451.11424 | F23: =SUM(F15:F22) -> 457.78683 | G23: =SUM(G15:G22) -> 275.96459 | H23: =SUM(H15:H22) -> 363.73443 | I23: =SUM(I15:I22) -> 478.64787 | J23: =SUM(J15:J22) -> 391.63361 | K23: =SUM(K15:K22) -> 349.05423 | L23: =SUM(L15:L22) -> 355.48086 | ... Q23: =SUM(Q15:Q22) -> 5058.4359
A24: NO | B24: 8701530201 | C24: 8701530201 Scrap-Raw Material - Managerial | D24: * CS_SCRAP_VARIABLE | E24: 0 | F24: 0 | G24: 0 | H24: 0 | I24: 0 | J24: 0 | K24: 0 | L24: 0 | M24: 0 | N24: 0 | O24: 0 | P24: 0 | Q24: =F24+E24+G24+H24+I24+J24+K24+L24+M24+N24+O24+P24 -> 0
A25: NO | B25: 6666050309 | C25: 6666050309 SFG scrap | D25: * CS_SCRAP_VARIABLE | E25: 6.0635 | F25: 6.05671 | G25: 5.52431 | H25: 4.28283 | I25: 3.73302 | J25: 4.86599 | K25: 4.04197 | L25: 17.5076 | M25: 24.15908 | N25: 21.98592 | O25: 22.85184 | P25: 18.5636 | Q25: =F25+E25+G25+H25+I25+J25+K25+L25+M25+N25+O25+P25 -> 139.63637
A26: NO | B26: 6666050308 | C26: 6666050308 Raw material scrap | D26: * CS_SCRAP_VARIABLE | E26: 11.57396 | F26: 7.72351 | G26: 2.51955 | H26: 44.86048 | I26: 11.78646 | J26: 22.05431 | K26: 23.36611 | L26: 0 | M26: 0 | N26: 0 | O26: 0 | P26: 0 | Q26: =F26+E26+G26+H26+I26+J26+K26+L26+M26+N26+O26+P26 -> 123.88438
A27: NO | B27: 6666050306 | C27: 6666050306 Finished goods scrap | D27: * CS_SCRAP_VARIABLE | E27: 0.58819 | F27: 0.55747 | G27: 1.51094 | H27: 1.3141 | I27: 0.56572 | J27: 1.05008 | K27: 3.53734 | L27: 0 | M27: 0 | N27: 0 | O27: 0 | P27: 0 | Q27: =F27+E27+G27+H27+I27+J27+K27+L27+M27+N27+O27+P27 -> 9.12384
B28: VAR | C28: * CS_SCRAP_VARIABLE | E28: =SUM(E24:E27) -> 18.22565 | F28: =SUM(F24:F27) -> 14.33769 | G28: =SUM(G24:G27) -> 9.5548 | H28: =SUM(H24:H27) -> 50.45741 | I28: =SUM(I24:I27) -> 16.0852 | J28: =SUM(J24:J27) -> 27.97038 | K28: =SUM(K24:K27) -> 30.94542 | L28: =SUM(L24:L27) -> 17.5076 | ... Q28: =SUM(Q24:Q27) -> 272.64459
A29: YES | B29: 5102010151 | C29: 5102010151 Other Rev.-Interco-Epidemic problem comp | D29: * CS_Fix Cost | E29: 0 | F29: 0 | G29: 0 | H29: 0 | I29: 0 | J29: 0 | K29: 0 | L29: 0 | M29: 0 | N29: 0 | O29: 0 | P29: 0 | Q29: =F29+E29+G29+H29+I29+J29+K29+L29+M29+N29+O29+P29 -> 0
A30: YES | B30: 5001010200 | C30: 5001010200 Cost of Manufacture - Raw Material | D30: * CS_Fix Cost | E30: 0 | F30: 0.00046 | G30: -1.38193 | H30: 0 | I30: 0 | J30: 0 | K30: 0 | L30: 0 | M30: 0 | N30: 0 | O30: 0 | P30: 0 | Q30: =F30+E30+G30+H30+I30+J30+K30+L30+M30+N30+O30+P30 -> -1.38147
A31: YES | B31: 5001010201 | C31: 5001010201 Cost of Manufacture - Raw Material-Freig | D31: * CS_Fix Cost | E31: 0 | F31: 0 | G31: 0 | H31: 0 | I31: 0 | J31: 0 | K31: 0 | L31: 0 | M31: 0 | N31: 0 | O31: 0 | P31: 0 | Q31: =F31+E31+G31+H31+I31+J31+K31+L31+M31+N31+O31+P31 -> 0
A32: YES | B32: 5001010204 | C32: 5001010204 Cost of Manufacture - Finished Good | D32: * CS_Fix Cost | E32: 0 | F32: 0 | G32: 0.51622 | H32: 0 | I32: 0 | J32: 0 | K32: 0 | L32: 0 | M32: 0 | N32: 0 | O32: 0 | P32: 0
A33: YES | B33: 5207000011 | C33: 5207000011 Gain of tangible asset disposal | D33: * CS_Fix Cost | E33: 0 | F33: 0 | G33: 0 | H33: -0.01625 | I33: 0 | J33: 0 | K33: 0 | L33: 1.5 | M33: 1.5 | N33: 1.5 | O33: 1.5 | P33: 1.5 | Q33: =F33+E33+G33+H33+I33+J33+K33+L33+M33+N33+O33+P33 -> 7.48375
A34: YES | B34: 5207000012 | C34: 5207000012 Loss of tangible asset sold | D34: * CS_Fix Cost | E34: 0 | F34: 0 | G34: 0 | H34: 0 | I34: 0 | J34: 0 | K34: 0 | L34: 0 | M34: 0 | N34: 0 | O34: 0 | P34: 0 | Q34: =F34+E34+G34+H34+I34+J34+K34+L34+M34+N34+O34+P34 -> 0
A35: YES | B35: 5207000022 | C35: 5207000022 Loss of intangible asset disposal | D35: * CS_Fix Cost | E35: 0 | F35: 0 | G35: 0 | H35: 0 | I35: 0 | J35: 0 | K35: 0 | L35: 0 | M35: 0 | N35: 0 | O35: 0 | P35: 0 | Q35: =F35+E35+G35+H35+I35+J35+K35+L35+M35+N35+O35+P35 -> 0
A36: YES | B36: 5301060000 | C36: 5301060000 Other Income-Subsidy income | D36: * CS_Fix Cost | E36: 0 | F36: 0 | G36: 0 | H36: -0.14585 | I36: -0.0285 | J36: 0 | K36: 0 | L36: 0 | M36: 0 | N36: 0 | O36: 0 | P36: 0 | Q36: =F36+E36+G36+H36+I36+J36+K36+L36+M36+N36+O36+P36 -> -0.17435
A37: YES | B37: 5301999999 | C37: 5301999999 Non-operation revenue-Other | D37: * CS_Fix Cost | E37: 0 | F37: -0.00545 | G37: -0.09966 | H37: -0.41552 | I37: -0.39233 | J37: -0.28006 | K37: -0.96985 | L37: 0 | M37: 0 | N37: 0 | O37: 0 | P37: 0 | Q37: =F37+E37+G37+H37+I37+J37+K37+L37+M37+N37+O37+P37 -> -2.16287
A38: YES | B38: 5405030000 | C38: 5405030000 Other cost-others | D38: * CS_Fix Cost | E38: 0 | F38: 0 | G38: 0 | H38: 0 | I38: 0 | J38: 0 | K38: 0 | L38: 0 | M38: 0 | N38: 0 | O38: 0 | P38: 0 | Q38: =F38+E38+G38+H38+I38+J38+K38+L38+M38+N38+O38+P38 -> 0
A39: YES | B39: 5601050000 | C39: 5601050000 Non-Operating Expense - Penalty | D39: * CS_Fix Cost | E39: 0 | F39: 0 | G39: 0 | H39: 0 | I39: 0 | J39: 0 | K39: 0 | L39: 0 | M39: 0 | N39: 0 | O39: 0 | P39: 0 | Q39: =F39+E39+G39+H39+I39+J39+K39+L39+M39+N39+O39+P39 -> 0
A40: YES | B40: 5601050100 | C40: 5601050100 Non-operation Expense-Others | D40: * CS_Fix Cost | E40: 0 | F40: 0 | G40: 0 | H40: 0.128 | I40: 0.2642 | J40: 0 | K40: 0.68962 | L40: 0 | M40: 0 | N40: 0 | O40: 0 | P40: 0 | Q40: =F40+E40+G40+H40+I40+J40+K40+L40+M40+N40+O40+P40 -> 1.08182
A41: YES | B41: 5102040893 | C41: 5102040893 Other revenue-Charge out-Test Expense | D41: * CS_Fix Cost | E41: 0 | F41: 0 | G41: -0.25953 | H41: 0 | I41: 0 | J41: 0 | K41: 0 | L41: 0 | M41: 0 | N41: 0 | O41: 0 | P41: 0 | Q41: =F41+E41+G41+H41+I41+J41+K41+L41+M41+N41+O41+P41 -> -0.25953
...

Sheet 1+11 Renta DW _2026
B1: Renta DW Cost Evolution | D1: Volume | E1: 47357 | F1: 42000.001 | G1: 23500.001 | H1: 38000.001 | I1: 33000.001 | J1: 52500.001 | K1: 40672 | L1: 39704 | M1: 54907 | N1: 49968 | O1: 51936 | P1: 42190 | Q1: =+E1+F1+G1+H1+I1+J1+K1+L1+M1+N1+O1+P1 -> 515734.01
D2: FX Rates_HQE | E2: 50.75 | F2: 52.47 | G2: 53.1 | H2: 54.2 | I2: 55.3 | J2: 56.4 | K2: 57.2 | L2: 58 | M2: 58.8 | N2: 59.77 | O2: 60.74 | P2: 61.71
D3: FX Rates_weighted average (Act TL/Act EUR) | E3: =+E239 -> 55.144677 | F3: =+F239 -> 49.764623 | G3: =+G239 -> 48.288145 | H3: =+H239 -> 0 | I3: =+I239 -> 0 | J3: =+J239 -> 0 | K3: =+K239 -> 0 | L3: =+L239 -> 0 | ... Q3: =+Q239 -> 0
A5: HQD PERIMETER | E5: Jan K€ | F5: Feb K€ | G5: Mar K€ | H5: Apr K€ | I5: May K€ | J5: June K€ | K5: July K€ | L5: Aug K€ | M5: Sep K€ | N5: Oct K€ | O5: Nov K€ | P5: DEC K€ | Q5: YTD K€
A6: YES | B6: 6666110101 | C6: 6666110101 Depreciation of buildings | D6: * CS_Depreciation | E6: 9.5887601 | F6: 515.61681 | G6: 558.872 | H6: 545.80149 | I6: 556.90639 | J6: 546.48697 | K6: 575.81023 | L6: 575.98362 | M6: 562.53212 | N6: 577.53857 | O6: 567.49077 | P6: 589.55127 | Q6: =F6+E6+G6+H6+I6+J6+K6+L6+M6+N6+O6+P6 -> 6182.179
A7: YES | B7: 6666110106 | C7: 6666110106 Depreciation of R&D facilities | D7: * CS_Depreciation | E7: 0 | F7: 0 | G7: 0 | H7: 0 | I7: 0 | J7: 0 | K7: 0 | L7: 0 | M7: 0 | N7: 0 | O7: 0 | P7: 0 | Q7: =F7+E7+G7+H7+I7+J7+K7+L7+M7+N7+O7+P7 -> 0
A8: YES | B8: 6666110107 | C8: 6666110107 Depreciation of mold | D8: * CS_Depreciation | E8: 92.462416 | F8: -128.50944 | G8: -132.59646 | H8: -133.13995 | I8: -136.89071 | J8: -137.10294 | K8: -140.22303 | L8: -141.55231 | M8: -141.04043 | N8: -144.04446 | O8: -143.38387 | P8: -146.35032 | Q8: =F8+E8+G8+H8+I8+J8+K8+L8+M8+N8+O8+P8 -> -1432.3715
A9: YES | B9: 6666110110 | C9: 6666110110 Depreciation-Plant & Machinery | D9: * CS_Depreciation | E9: 63.749081 | F9: -231.74042 | G9: -259.88325 | H9: -251.50839 | I9: -259.51547 | J9: -251.33834 | K9: -259.08195 | L9: -258.72828 | M9: -250.19728 | N9: -259.46435 | O9: -251.88662 | P9: -261.15815 | Q9: =F9+E9+G9+H9+I9+J9+K9+L9+M9+N9+O9+P9 -> -2730.7534
A10: YES | B10: 6666110112 | C10: 6666110112 Depreciation of Furniture & Fixture | D10: * CS_Depreciation | E10: 4.2473878 | F10: -4.4504975 | G10: -4.7228927 | H10: -4.7190566 | I10: -3.5097491 | J10: -3.7738651 | K10: -3.8043345 | L10: -3.8799128 | M10: -3.8599245 | N10: -3.9632234 | O10: -3.9341218 | P10: -3.7400681 | Q10: =F10+E10+G10+H10+I10+J10+K10+L10+M10+N10+O10+P10 -> -40.110258
A11: YES | B11: 6666110204 | C11: 6666110204 Amortization of license, trademarks and | D11: * CS_Depreciation | E11: 0.17412081 | F11: -0.081380077 | G11: -0.079585154 | H11: -0.083786041 | I11: -0.087625725 | J11: -0.091313308 | K11: -0.093885298 | L11: -0.096366508 | M11: -0.098790682 | N11: -0.10104916 | O11: -0.10323224 | P11: -0.10537272 | Q11: =F11+E11+G11+H11+I11+J11+K11+L11+M11+N11+O11+P11 -> -0.84826609
A12: YES | B12: 6666110207 | C12: 6666110207 Amortization of Software | D12: * CS_Depreciation | E12: 1.1264639 | F12: -1.2419814 | G12: -1.2311387 | H12: -1.2580058 | I12: -1.2832001 | J12: -1.3067368 | K12: -1.3236228 | L12: -1.438198 | M12: -1.0452677 | N12: -1.219569 | O12: -1.265389 | P12: -1.274676 | Q12: =F12+E12+G12+H12+I12+J12+K12+L12+M12+N12+O12+P12 -> -12.761322
A13: YES | B13: 6666110506 | C13: 6666110506 Amortization-Leasehold Improvement | D13: * CS_Depreciation | E13: 0 | F13: 0 | G13: 0 | H13: 0 | I13: 0 | J13: 0 | K13: 0 | L13: 0 | M13: 0 | N13: 0 | O13: 0 | P13: 0 | Q13: =F13+E13+G13+H13+I13+J13+K13+L13+M13+N13+O13+P13 -> 0
B14: FIX | C14: * CS_Depreciation | E14: =SUM(E6:E13) -> 171.34823 | F14: =SUM(F6:F13) -> 149.59309 | G14: =SUM(G6:G13) -> 160.35867 | H14: =SUM(H6:H13) -> 155.0923 | I14: =SUM(I6:I13) -> 155.61965 | J14: =SUM(J6:J13) -> 152.87378 | K14: =SUM(K6:K13) -> 171.28341 | L14: =SUM(L6:L13) -> 170.28855 | ... Q14: =SUM(Q6:Q13) -> 1965.3342
A15: YES | B15: 5001010205 | C15: 5001010205 Unemployment Insurance -blue collar-Dire | D15: * CS_Direct Labour | E15: 7.61607 | F15: 0 | G15: 0 | H15: 0 | I15: 0 | J15: 0 | K15: 0 | L15: 0 | M15: 0 | N15: 0 | O15: 0 | P15: 0 | Q15: =F15+E15+G15+H15+I15+J15+K15+L15+M15+N15+O15+P15 -> 7.61607
A16: YES | B16: 6666010380 | C16: 6666010380 Incentive | D16: * CS_Direct Labour | E16: -1.8209 | F16: 0 | G16: 0 | H16: 0 | I16: 0 | J16: 0 | K16: 0 | L16: 0 | M16: 0 | N16: 0 | O16: 0 | P16: 0 | Q16: =F16+E16+G16+H16+I16+J16+K16+L16+M16+N16+O16+P16 -> -1.8209
A17: YES | B17: 6666010019 | C17: 6666010019 Payroll Taxes - Blue Collar Direct | D17: * CS_Direct Labour | E17: 64.67305 | F17: 483.16754 | G17: 486.95672 | H17: 464.96081 | I17: 528.14055 | J17: 497.00351 | K17: 446.30187 | L17: 457.45748 | M17: 552.86256 | N17: 505.68643 | O17: 482.52377 | P17: 489.09036 | Q17: =F17+E17+G17+H17+I17+J17+K17+L17+M17+N17+O17+P17 -> 5458.8246
A18: YES | B18: 6666010183 | C18: 6666010183 Overtime-Blue Collar-Direct | D18: * CS_Direct Labour | E18: 10.50135 | F18: 0 | G18: 0 | H18: 0 | I18: 0 | J18: 0 | K18: 0 | L18: 0 | M18: 0 | N18: 0 | O18: 0 | P18: 0 | Q18: =F18+E18+G18+H18+I18+J18+K18+L18+M18+N18+O18+P18 -> 10.50135
A19: YES | B19: 6666010229 | C19: 6666010229 Staff Leaving Indemnity - Blue Collar Di | D19: * CS_Direct Labour | E19: 16.69101 | F19: 0 | G19: 0 | H19: 0 | I19: 0 | J19: 0 | K19: 0 | L19: 0 | M19: 0 | N19: 0 | O19: 0 | P19: 0 | Q19: =F19+E19+G19+H19+I19+J19+K19+L19+M19+N19+O19+P19 -> 16.69101
A20: YES | B20: 6666010188 | C20: 6666010188 Salary - Blue collar direct employees | D20: * CS_Direct Labour | E20: 357.71936 | F20: 0 | G20: 0 | H20: 0 | I20: 0 | J20: 0 | K20: 0 | L20: 0 | M20: 0 | N20: 0 | O20: 0 | P20: 0 | Q20: =F20+E20+G20+H20+I20+J20+K20+L20+M20+N20+O20+P20 -> 357.71936
A21: YES | B21: 5102040406 | C21: 5102040406 Other revenue-Service/Secondment agreeme | D21: * CS_Direct Labour | E21: 0 | F21: 0 | G21: 0 | H21: 0 | I21: 0 | J21: 0 | K21: 0 | L21: 0 | M21: 0 | N21: 0 | O21: 0 | P21: 0 | Q21: =F21+E21+G21+H21+I21+J21+K21+L21+M21+N21+O21+P21 -> 0
A22: YES | B22: 6666010115 | C22: 6666010115 Salary-Blue collar direct employees-Accr | D22: * CS_Direct Labour | E22: -4.2657 | F22: 0 | G22: 0 | H22: 0 | I22: 0 | J22: 0 | K22: 0 | L22: 0 | M22: 0 | N22: 0 | O22: 0 | P22: 0 | Q22: =F22+E22+G22+H22+I22+J22+K22+L22+M22+N22+O22+P22 -> -4.2657
B23: VAR | C23: * CS_Direct Labour | E23: =SUM(E15:E22) -> 451.11424 | F23: =SUM(F15:F22) -> 483.16754 | G23: =SUM(G15:G22) -> 486.95672 | H23: =SUM(H15:H22) -> 464.96081 | I23: =SUM(I15:I22) -> 528.14055 | J23: =SUM(J15:J22) -> 497.00351 | K23: =SUM(K15:K22) -> 446.30187 | L23: =SUM(L15:L22) -> 457.45748 | ... Q23: =SUM(Q15:Q22) -> 5845.2658
A24: NO | B24: 8701530201 | C24: 8701530201 Scrap-Raw Material - Managerial | D24: * CS_SCRAP_VARIABLE | E24: 0 | F24: 0 | G24: 0 | H24: 0 | I24: 0 | J24: 0 | K24: 0 | L24: 0 | M24: 0 | N24: 0 | O24: 0 | P24: 0 | Q24: =F24+E24+G24+H24+I24+J24+K24+L24+M24+N24+O24+P24 -> 0
A25: NO | B25: 6666050309 | C25: 6666050309 SFG scrap | D25: * CS_SCRAP_VARIABLE | E25: 6.0635 | F25: 18.48 | G25: 10.34 | H25: 16.72 | I25: 14.52 | J25: 23.1 | K25: 17.89568 | L25: 17.46976 | M25: 24.15908 | N25: 21.98592 | O25: 22.85184 | P25: 18.5636 | Q25: =F25+E25+G25+H25+I25+J25+K25+L25+M25+N25+O25+P25 -> 212.14938
A26: NO | B26: 6666050308 | C26: 6666050308 Raw material scrap | D26: * CS_SCRAP_VARIABLE | E26: 11.57396 | F26: 0 | G26: 0 | H26: 0 | I26: 0 | J26: 0 | K26: 0 | L26: 0 | M26: 0 | N26: 0 | O26: 0 | P26: 0 | Q26: =F26+E26+G26+H26+I26+J26+K26+L26+M26+N26+O26+P26 -> 11.57396
A27: NO | B27: 6666050306 | C27: 6666050306 Finished goods scrap | D27: * CS_SCRAP_VARIABLE | E27: 0.58819 | F27: 0 | G27: 0 | H27: 0 | I27: 0 | J27: 0 | K27: 0 | L27: 0 | M27: 0 | N27: 0 | O27: 0 | P27: 0 | Q27: =F27+E27+G27+H27+I27+J27+K27+L27+M27+N27+O27+P27 -> 0.58819
B28: VAR | C28: * CS_SCRAP_VARIABLE | E28: =SUM(E24:E27) -> 18.22565 | F28: =SUM(F24:F27) -> 18.48 | G28: =SUM(G24:G27) -> 10.34 | H28: =SUM(H24:H27) -> 16.72 | I28: =SUM(I24:I27) -> 14.52 | J28: =SUM(J24:J27) -> 23.1 | K28: =SUM(K24:K27) -> 17.89568 | L28: =SUM(L24:L27) -> 17.46976 | ... Q28: =SUM(Q24:Q27) -> 224.31153
A29: YES | B29: 5102010151 | C29: 5102010151 Other Rev.-Interco-Epidemic problem comp | D29: * CS_Fix Cost | E29: 0 | F29: 0 | G29: 0 | H29: 0 | I29: 0 | J29: 0 | K29: 0 | L29: 0 | M29: 0 | N29: 0 | O29: 0 | P29: 0 | Q29: =F29+E29+G29+H29+I29+J29+K29+L29+M29+N29+O29+P29 -> 0
A30: YES | B30: 5001010200 | C30: 5001010200 Cost of Manufacture - Raw Material | D30: * CS_Fix Cost | E30: 0 | F30: 0 | G30: 0 | H30: 0 | I30: 0 | J30: 0 | K30: 0 | L30: 0 | M30: 0 | N30: 0 | O30: 0 | P30: 0 | Q30: =F30+E30+G30+H30+I30+J30+K30+L30+M30+N30+O30+P30 -> 0
A31: YES | B31: 5001010201 | C31: 5001010201 Cost of Manufacture - Raw Material-Freig | D31: * CS_Fix Cost | E31: 0 | F31: 0 | G31: 0 | H31: 0 | I31: 0 | J31: 0 | K31: 0 | L31: 0 | M31: 0 | N31: 0 | O31: 0 | P31: 0 | Q31: =F31+E31+G31+H31+I31+J31+K31+L31+M31+N31+O31+P31 -> 0
A32: YES | B32: 5001010204 | C32: 5001010204 Cost of Manufacture - Finished Good | D32: * CS_Fix Cost | E32: 0 | F32: 0 | G32: 0 | H32: 0 | I32: 0 | J32: 0 | K32: 0 | L32: 0 | M32: 0 | N32: 0 | O32: 0 | P32: 0
A33: YES | B33: 5207000011 | C33: 5207000011 Gain of tangible asset disposal | D33: * CS_Fix Cost | E33: 0 | F33: 0 | G33: 0 | H33: 0 | I33: 0 | J33: 0 | K33: 0 | L33: 0 | M33: 0 | N33: 0 | O33: 0 | P33: 0 | Q33: =F33+E33+G33+H33+I33+J33+K33+L33+M33+N33+O33+P33 -> 0
A34: YES | B34: 5207000012 | C34: 5207000012 Loss of tangible asset sold | D34: * CS_Fix Cost | E34: 0 | F34: 0 | G34: 0 | H34: 0 | I34: 0 | J34: 0 | K34: 0 | L34: 0 | M34: 0 | N34: 0 | O34: 0 | P34: 0 | Q34: =F34+E34+G34+H34+I34+J34+K34+L34+M34+N34+O34+P34 -> 0
A35: YES | B35: 5207000022 | C35: 5207000022 Loss of intangible asset disposal | D35: * CS_Fix Cost | E35: 0 | F35: 0 | G35: 0 | H35: 0 | I35: 0 | J35: 0 | K35: 0 | L35: 0 | M35: 0 | N35: 0 | O35: 0 | P35: 0 | Q35: =F35+E35+G35+H35+I35+J35+K35+L35+M35+N35+O35+P35 -> 0
A36: YES | B36: 5301060000 | C36: 5301060000 Other Income-Subsidy income | D36: * CS_Fix Cost | E36: 0 | F36: 0 | G36: 0 | H36: 0 | I36: 0 | J36: 0 | K36: 0 | L36: 0 | M36: 0 | N36: 0 | O36: 0 | P36: 0 | Q36: =F36+E36+G36+H36+I36+J36+K36+L36+M36+N36+O36+P36 -> 0
A37: YES | B37: 5301999999 | C37: 5301999999 Non-operation revenue-Other | D37: * CS_Fix Cost | E37: 0 | F37: 0 | G37: 0 | H37: 0 | I37: 0 | J37: 0 | K37: 0 | L37: 0 | M37: 0 | N37: 0 | O37: 0 | P37: 0 | Q37: =F37+E37+G37+H37+I37+J37+K37+L37+M37+N37+O37+P37 -> 0
A38: YES | B38: 5405030000 | C38: 5405030000 Other cost-others | D38: * CS_Fix Cost | E38: 0 | F38: 0 | G38: 0 | H38: 0 | I38: 0 | J38: 0 | K38: 0 | L38: 0 | M38: 0 | N38: 0 | O38: 0 | P38: 0 | Q38: =F38+E38+G38+H38+I38+J38+K38+L38+M38+N38+O38+P38 -> 0
A39: YES | B39: 5601050000 | C39: 5601050000 Non-Operating Expense - Penalty | D39: * CS_Fix Cost | E39: 0 | F39: 0 | G39: 0 | H39: 0 | I39: 0 | J39: 0 | K39: 0 | L39: 0 | M39: 0 | N39: 0 | O39: 0 | P39: 0 | Q39: =F39+E39+G39+H39+I39+J39+K39+L39+M39+N39+O39+P39 -> 0
A40: YES | B40: 5601050100 | C40: 5601050100 Non-operation Expense-Others | D40: * CS_Fix Cost | E40: 0 | F40: 0 | G40: 0 | H40: 0 | I40: 0 | J40: 0 | K40: 0 | L40: 0 | M40: 0 | N40: 0 | O40: 0 | P40: 0 | Q40: =F40+E40+G40+H40+I40+J40+K40+L40+M40+N40+O40+P40 -> 0
A41: YES | B41: 5102040893 | C41: 5102040893 Other revenue-Charge out-Test Expense | D41: * CS_Fix Cost | E41: 0 | F41: 0 | G41: 0 | H41: 0 | I41: 0 | J41: 0 | K41: 0 | L41: 0 | M41: 0 | N41: 0 | O41: 0 | P41: 0 | Q41: =F41+E41+G41+H41+I41+J41+K41+L41+M41+N41+O41+P41 -> 0
...

Sheet Renta DW _2025 
B1: Renta DW Cost Evolution | D1: Volume | E1: 48571 | H1: 46033 | K1: 46337 | N1: 49363 | Q1: 53704 | T1: 29664 | W1: 41857 | Z1: 31977 | AC1: 28268 | AF1: 26211 | AI1: 34024 | AL1: 42093 | AO1: =+E1+H1+K1+N1+Q1+T1+W1+Z1+AC1+AF1+AI1+AL1 -> 478102
D2: FX Rates | E2: 38.272236 | H2: 39.048375 | K2: 41.597869 | N2: 43.93 | Q2: =+Q229 -> 44.735418 | T2: =+T229 -> 46.437564 | W2: =+W229 -> 45.969819 | Z2: =+Z229 -> 47.671503 | AC2: =+AC229 -> 49.274771 | AF2: =+AF229 -> 47.314102 | AI2: =+AI229 -> 48.040247 | AL2: =+AL229 -> 48.608933 | AO2: =+AO229 -> 44.934681
A4: HQD PERIMETER | E4: Jan K€ | F4: Jan CPU € / pcs | H4: Feb K€ | I4: Feb CPU € / pcs | K4: Mar K€ | L4: Mar CPU € / pcs | N4: Apr K€ | O4: Apr CPU € / pcs | Q4: May K€ | R4: May CPU € / pcs | T4: June K€ | U4: June CPU € / pcs | W4: July K€ | X4: July CPU € / pcs | Z4: Aug K€ | AA4: Aug CPU € / pcs | AC4: Sep K€ | AD4: Sep CPU € / pcs | AF4: Oct K€ | AG4: Oct CPU € / pcs | AI4: Nov K€ | AJ4: Nov CPU € / pcs | AL4: DEC K€ | AM4: Dec CPU € / pcs | AO4: YTD K€ | AP4: YTD DEC CPU € / pcs
A5: YES | B5: 6666110101 | C5: 6666110101 Depreciation of buildings | D5: * CS_Depreciation | E5: 8.58079 | F5: =E5/$E$1*1000 -> 0.17666488 | H5: =27.05117-18.6560404444444 -> 8.3951296 | I5: =H5/$H$1*1000 -> 0.18237198 | K5: =29.88156-21.3282004444444 -> 8.5533596 | L5: =K5/$K$1*1000 -> 0.18459027 | N5: =28.96203-20.445 -> 8.51703 | O5: =N5/$N$1*1000 -> 0.17253874 | Q5: =30.08167-21.15308 -> 8.92859 | R5: =Q5/$Q$1*1000 -> 0.16625559 | T5: =29.67008-T235 -> 8.9335426 | U5: =T5/$T$1*1000 -> 0.30115772 | W5: =30.71618-W235 -> 9.0441604 | X5: =W5/$W$1*1000 -> 0.21607283 | Z5: =30.72552-Z235 -> 8.9882903 | AA5: =Z5/$Z$1*1000 -> 0.2810861 | AC5: =31.25161-AC235 -> 9.43073 | AD5: =AC5/$AC$1*1000 -> 0.33361858 | AF5: =32.26937-AF235 -> 9.699969 | AG5: =AF5/$AF$1*1000 -> 0.37007245 | AI5: =31.25416-AI235 -> 9.3732236 | AJ5: =AI5/$AI$1*1000 -> 0.27548859 | AL5: =32.52616-AL235 -> 9.7032255 | AM5: =AL5/$AL$1*1000 -> 0.23051874 | AO5: =H5+E5+K5+N5+Q5+T5+W5+Z5+AC5+AF5+AI5+AL5 -> 108.14804 | AP5: =AO5/$AO$1*1000 -> 0.22620286
A6: YES | B6: 6666110106 | C6: 6666110106 Depreciation of R&D facilities | D6: * CS_Depreciation | E6: 0 | F6: =E6/$E$1*1000 -> 0 | H6: 0 | I6: =H6/$H$1*1000 -> 0 | K6: 0 | L6: =K6/$K$1*1000 -> 0 | N6: 0 | O6: =N6/$N$1*1000 -> 0 | Q6: 0 | R6: =Q6/$Q$1*1000 -> 0 | T6: 0 | U6: =T6/$T$1*1000 -> 0 | W6: 0 | X6: =W6/$W$1*1000 -> 0 | Z6: 0 | AA6: =Z6/$Z$1*1000 -> 0 | AC6: 0 | AD6: =AC6/$AC$1*1000 -> 0 | AF6: 0 | AG6: =AF6/$AF$1*1000 -> 0 | AI6: 0 | AJ6: =AI6/$AI$1*1000 -> 0 | AL6: 0 | AM6: =AL6/$AL$1*1000 -> 0 | AO6: =H6+E6+K6+N6+Q6+T6+W6+Z6+AC6+AF6+AI6+AL6 -> 0 | AP6: =AO6/$AO$1*1000 -> 0
A7: YES | B7: 6666110107 | C7: 6666110107 Depreciation of mold | D7: * CS_Depreciation | E7: 90.54188 | F7: =E7/$E$1*1000 -> 1.864114 | H7: =208.59611-109.209985777778 -> 99.386124 | I7: =H7/$H$1*1000 -> 2.1590191 | K7: =222.76497-119.675125777778 -> 103.08984 | L7: =K7/$K$1*1000 -> 2.2247846 | N7: =221.08877-117.086 -> 104.00277 | O7: =N7/$N$1*1000 -> 2.1068973 | Q7: =230.92979-126.57762 -> 104.35217 | R7: =Q7/$Q$1*1000 -> 1.9430987 | T7: =226.52287-T237 -> 98.20495 | U7: =T7/$T$1*1000 -> 3.3105768 | W7: =232.94505-W237 -> 98.45024 | X7: =W7/$W$1*1000 -> 2.3520615 | Z7: =233.08123-Z237 -> 97.333463 | AA7: =Z7/$Z$1*1000 -> 3.0438585 | AC7: =229.28602-AC237 -> 94.49625 | AD7: =AC7/$AC$1*1000 -> 3.34287 | AF7: =118.01548-AF237 -> 74.032202 | AG7: =AF7/$AF$1*1000 -> 2.8244707 | AI7: =219.16417-AI237 -> 92.929818 | AJ7: =AI7/$AI$1*1000 -> 2.731302 | AL7: =223.42017-AL237 -> 92.937153 | AM7: =AL7/$AL$1*1000 -> 2.2079004 | AO7: =H7+E7+K7+N7+Q7+T7+W7+Z7+AC7+AF7+AI7+AL7 -> 1149.7569 | AP7: =AO7/$AO$1*1000 -> 2.4048359
A8: YES | B8: 6666110110 | C8: 6666110110 Depreciation-Plant & Machinery | D8: * CS_Depreciation | E8: 62.82441 | F8: =E8/$E$1*1000 -> 1.2934551 | H8: =261.00381-198.482281111111 -> 62.521529 | I8: =H8/$H$1*1000 -> 1.3581893 | K8: =290.93886-225.680081111111 -> 65.258779 | L8: =K8/$K$1*1000 -> 1.4083514 | N8: =284.06253-216.6537 -> 67.40883 | O8: =N8/$N$1*1000 -> 1.365574 | Q8: =299.32499-228.57031 -> 70.75468 | R8: =Q8/$Q$1*1000 -> 1.3174937 | T8: =288.81974-T238 -> 66.024395 | U8: =T8/$T$1*1000 -> 2.2257415 | W8: =297.80019-W238 -> 65.613057 | X8: =W8/$W$1*1000 -> 1.5675528 | Z8: =297.85265-Z238 -> 64.715916 | AA8: =Z8/$Z$1*1000 -> 2.023827 | AC8: =291.39958-AC238 -> 63.49677 | AD8: =AC8/$AC$1*1000 -> 2.246242 | AF8: =207.60475-AF238 -> 39.993225 | AG8: =AF8/$AF$1*1000 -> 1.5258184 | AI8: =283.72663-AI238 -> 61.671035 | AJ8: =AI8/$AI$1*1000 -> 1.8125745 | AL8: =294.42037-AL238 -> 63.391045 | AM8: =AL8/$AL$1*1000 -> 1.5059759 | AO8: =H8+E8+K8+N8+Q8+T8+W8+Z8+AC8+AF8+AI8+AL8 -> 753.67367 | AP8: =AO8/$AO$1*1000 -> 1.5763868
A9: YES | B9: 6666110112 | C9: 6666110112 Depreciation of Furniture & Fixture | D9: * CS_Depreciation | E9: 3.19741 | F9: =E9/$E$1*1000 -> 0.06582961 | H9: =6.81703-3.61013311111111 -> 3.2068969 | I9: =H9/$H$1*1000 -> 0.069665173 | K9: =8.46919-4.13525311111111 -> 4.3339369 | L9: =K9/$K$1*1000 -> 0.093530805 | N9: =8.46194-3.8942 -> 4.56774 | O9: =N9/$N$1*1000 -> 0.092533679 | Q9: =11.26201-5.21228 -> 6.04973 | R9: =Q9/$Q$1*1000 -> 0.11264952 | T9: =11.52002-T239 -> 6.1588719 | U9: =T9/$T$1*1000 -> 0.20762108 | W9: =11.70987-W239 -> 6.0246807 | X9: =W9/$W$1*1000 -> 0.14393484 | Z9: =11.77284-Z239 -> 5.4610633 | AA9: =Z9/$Z$1*1000 -> 0.17078098 | AC9: =9.89618-AC239 -> 4.84602 | AD9: =AC9/$AC$1*1000 -> 0.1714313 | AF9: =9.79722-AF239 -> 5.0633714 | AG9: =AF9/$AF$1*1000 -> 0.19317734 | AI9: =10.12633-AI239 -> 5.0687601 | AJ9: =AI9/$AI$1*1000 -> 0.14897602 | AL9: =8.94347-AL239 -> 4.310794 | AM9: =AL9/$AL$1*1000 -> 0.10241119 | AO9: =H9+E9+K9+N9+Q9+T9+W9+Z9+AC9+AF9+AI9+AL9 -> 58.289275 | AP9: =AO9/$AO$1*1000 -> 0.12191807
A10: YES | B10: 6666110204 | C10: 6666110204 Amortization of license, trademarks and | D10: * CS_Depreciation | E10: 0.00252 | F10: =E10/$E$1*1000 -> 5.1882811e-05 | H10: =0.25251--0.0561566666666667 -> 0.30866667 | I10: =H10/$H$1*1000 -> 0.0067053346 | K10: =0.25252-0.0561666666666667 -> 0.19635333 | L10: =K10/$K$1*1000 -> 0.0042375064 | N10: =0.25252-0.0562 -> 0.19632 | O10: =N10/$N$1*1000 -> 0.0039770678 | Q10: =0.25251-(50.73/1000) -> 0.20178 | R10: =Q10/$Q$1*1000 -> 0.003757262 | T10: =0.25252-T240 -> 0.1944745 | U10: =T10/$T$1*1000 -> 0.0065559096 | W10: =0.25252-W240 -> 0.18806389 | X10: =W10/$W$1*1000 -> 0.0044930094 | Z10: =0.25251-Z240 -> 0.18602561 | AA10: =Z10/$Z$1*1000 -> 0.0058174815 | AC10: =0.25252-AC240 -> 0.18222 | AD10: =AC10/$AC$1*1000 -> 0.0064461582 | AF10: =0.25252-AF240 -> 0.18151023 | AG10: =AF10/$AF$1*1000 -> 0.0069249641 | AI10: =0.25251-AI240 -> 0.18072725 | AJ10: =AI10/$AI$1*1000 -> 0.005311758 | AL10: =0.25252-AL240 -> 0.17682586 | AM10: =AL10/$AL$1*1000 -> 0.0042008378 | AO10: =H10+E10+K10+N10+Q10+T10+W10+Z10+AC10+AF10+AI10+AL10 -> 2.1954874 | AP10: =AO10/$AO$1*1000 -> 0.0045920899
A11: YES | B11: 6666110207 | C11: 6666110207 Amortization of Software | D11: * CS_Depreciation | E11: 3.61797 | F11: =E11/$E$1*1000 -> 0.074488275 | H11: =7.67016-4.05927644444445 -> 3.6108836 | I11: =H11/$H$1*1000 -> 0.078441196 | K11: =8.28781-4.67692644444444 -> 3.6108836 | L11: =K11/$K$1*1000 -> 0.077926572 | N11: =6.89599-3.2851 -> 3.61089 | O11: =N11/$N$1*1000 -> 0.073149728 | Q11: =6.78395-(3308.9/1000) -> 3.47505 | R11: =Q11/$Q$1*1000 -> 0.064707471 | T11: =6.30245-T241 -> 3.0508154 | U11: =T11/$T$1*1000 -> 0.10284572 | W11: =4.61586-W241 -> 2.8164364 | X11: =W11/$W$1*1000 -> 0.067287106 | Z11: =2.82269-Z241 -> 2.0440043 | AA11: =Z11/$Z$1*1000 -> 0.063921078 | AC11: =2.28113-AC241 -> 1.19932 | AD11: =AC11/$AC$1*1000 -> 0.042426772 | AF11: =2.34755-AF241 -> 1.2346426 | AG11: =AF11/$AF$1*1000 -> 0.047103988 | AI11: =2.31588-AI241 -> 1.2158296 | AJ11: =AI11/$AI$1*1000 -> 0.035734469 | AL11: =2.35319-AL241 -> 1.143964 | AM11: =AL11/$AL$1*1000 -> 0.027177061 | AO11: =H11+E11+K11+N11+Q11+T11+W11+Z11+AC11+AF11+AI11+AL11 -> 30.630689 | AP11: =AO11/$AO$1*1000 -> 0.064067269
A12: YES | B12: 6666110506 | C12: 6666110506 Amortization-Leasehold Improvement | D12: * CS_Depreciation | E12: 0.91407 | F12: =E12/$E$1*1000 -> 0.018819254 | H12: =0.91407-0.250798 -> 0.663272 | I12: =H12/$H$1*1000 -> 0.01440862 | K12: =0.91407-0.250798 -> 0.663272 | L12: =K12/$K$1*1000 -> 0.01431409 | N12: =0.91407-0.2508 -> 0.66327 | O12: =N12/$N$1*1000 -> 0.013436582 | Q12: =0.91407-(232.48/1000) -> 0.68159 | R12: =Q12/$Q$1*1000 -> 0.012691606 | T12: =0.91407-T242 -> 0.65692541 | U12: =T12/$T$1*1000 -> 0.022145544 | W12: =0.91407-W242 -> 0.63527068 | X12: =W12/$W$1*1000 -> 0.015177167 | Z12: =0.91408-Z242 -> 0.62838544 | AA12: =Z12/$Z$1*1000 -> 0.019651169 | AC12: 0 | AD12: =AC12/$AC$1*1000 -> 0 | AF12: 0 | AG12: =AF12/$AF$1*1000 -> 0 | AI12: 0 | AJ12: =AI12/$AI$1*1000 -> 0 | AL12: 0 | AM12: =AL12/$AL$1*1000 -> 0 | AO12: =H12+E12+K12+N12+Q12+T12+W12+Z12+AC12+AF12+AI12+AL12 -> 5.5060555 | AP12: =AO12/$AO$1*1000 -> 0.011516487
B13: FIX | C13: * CS_Depreciation | E13: 169.67905 | F13: =E13/$E$1*1000 -> 3.493423 | H13: =SUM(H5:H12) -> 178.0925 | I13: =H13/$H$1*1000 -> 3.8688007 | K13: =SUM(K5:K12) -> 185.70643 | L13: =K13/$K$1*1000 -> 4.0077353 | N13: =SUM(N5:N12) -> 188.96685 | O13: =N13/$N$1*1000 -> 3.8281071 | Q13: =SUM(Q5:Q12) -> 194.44359 | R13: =Q13/$Q$1*1000 -> 3.6206538 | T13: =SUM(T5:T12) -> 183.22398 | U13: =T13/$T$1*1000 -> 6.1766443 | W13: =SUM(W5:W12) -> 182.77191 | X13: =W13/$W$1*1000 -> 4.3665793 | Z13: =SUM(Z5:Z12) -> 179.35715 | AA13: =Z13/$Z$1*1000 -> 5.6089423 | AC13: =SUM(AC5:AC12) -> 173.65131 | AD13: =AC13/$AC$1*1000 -> 6.1430349 | AF13: =SUM(AF5:AF12) -> 130.20492 | AG13: =AF13/$AF$1*1000 -> 4.9675678 | AI13: =SUM(AI5:AI12) -> 170.43939 | AJ13: =AI13/$AI$1*1000 -> 5.0093873 | AL13: =SUM(AL5:AL12) -> 171.66301 | AM13: =AL13/$AL$1*1000 -> 4.0781842 | AO13: =SUM(AO5:AO12) -> 2108.2001 | AP13: =AO13/$AO$1*1000 -> 4.4095195
A14: YES | B14: 5001010205 | C14: 5001010205 Unemployment Insurance -blue collar-Dire | D14: * CS_Direct Labour | E14: 7.24866 | F14: =E14/$E$1*1000 -> 0.14923843 | H14: 6.31439 | I14: =H14/$H$1*1000 -> 0.13717094 | K14: 8.11537 | L14: =K14/$K$1*1000 -> 0.17513801 | N14: 7.33205 | O14: =N14/$N$1*1000 -> 0.14853331 | Q14: 9.34405 | R14: =Q14/$Q$1*1000 -> 0.1739917 | T14: 7.35114 | U14: =T14/$T$1*1000 -> 0.24781351 | W14: 6.70939 | X14: =W14/$W$1*1000 -> 0.16029314 | Z14: 4.55939 | AA14: =Z14/$Z$1*1000 -> 0.14258342 | AC14: 4.69046 | AD14: =AC14/$AC$1*1000 -> 0.16592826 | AF14: 4.86146 | AG14: =AF14/$AF$1*1000 -> 0.18547404 | AI14: 7.98073 | AJ14: =AI14/$AI$1*1000 -> 0.23456178 | AL14: 8.07355 | AM14: =AL14/$AL$1*1000 -> 0.19180268 | AO14: =H14+E14+K14+N14+Q14+T14+W14+Z14+AC14+AF14+AI14+AL14 -> 82.58064 | AP14: =AO14/$AO$1*1000 -> 0.17272599
A15: YES | B15: 6666010380 | C15: 6666010380 Incentive | D15: * CS_Direct Labour | E15: -1.66916 | F15: =E15/$E$1*1000 -> -0.034365362 | H15: -1.5004 | I15: =H15/$H$1*1000 -> -0.032594009 | K15: -1.56596 | L15: =K15/$K$1*1000 -> -0.033795023 | N15: -1.42469 | O15: =N15/$N$1*1000 -> -0.028861495 | Q15: -0.35328 | R15: =Q15/$Q$1*1000 -> -0.0065782809 | T15: -1.15203 | U15: =T15/$T$1*1000 -> -0.038835963 | W15: -1.09401 | X15: =W15/$W$1*1000 -> -0.026136847 | Z15: -0.95339 | AA15: =Z15/$Z$1*1000 -> -0.029814867 | AC15: 4.29009 | AD15: =AC15/$AC$1*1000 -> 0.15176489 | AF15: 4.40298 | AG15: =AF15/$AF$1*1000 -> 0.16798214 | AI15: 3.89863 | AJ15: =AI15/$AI$1*1000 -> 0.1145847 | AL15: 3.47141 | AM15: =AL15/$AL$1*1000 -> 0.082470007 | AO15: =H15+E15+K15+N15+Q15+T15+W15+Z15+AC15+AF15+AI15+AL15 -> 6.35019 | AP15: =AO15/$AO$1*1000 -> 0.013282082
A16: YES | B16: 6666010019 | C16: 6666010019 Payroll Taxes - Blue Collar Direct | D16: * CS_Direct Labour | E16: 57.92585 | F16: =E16/$E$1*1000 -> 1.1926016 | H16: 50.47935 | I16: =H16/$H$1*1000 -> 1.0965905 | K16: 64.9104 | L16: =K16/$K$1*1000 -> 1.400833 | N16: 58.63925 | O16: =N16/$N$1*1000 -> 1.1879191 | Q16: 73.69048 | R16: =Q16/$Q$1*1000 -> 1.37216 | T16: 58.78984 | U16: =T16/$T$1*1000 -> 1.9818581 | W16: 53.64949 | X16: =W16/$W$1*1000 -> 1.2817328 | Z16: 36.41908 | AA16: =Z16/$Z$1*1000 -> 1.1389148 | AC16: 37.40107 | AD16: =AC16/$AC$1*1000 -> 1.3230887 | AF16: 38.74085 | AG16: =AF16/$AF$1*1000 -> 1.4780378 | AI16: 63.85492 | AJ16: =AI16/$AI$1*1000 -> 1.8767611 | AL16: 64.57704 | AM16: =AL16/$AL$1*1000 -> 1.5341515 | AO16: =H16+E16+K16+N16+Q16+T16+W16+Z16+AC16+AF16+AI16+AL16 -> 659.07762 | AP16: =AO16/$AO$1*1000 -> 1.3785293
A17: YES | B17: 6666010183 | C17: 6666010183 Overtime-Blue Collar-Direct | D17: * CS_Direct Labour | E17: 13.55408 | F17: =E17/$E$1*1000 -> 0.27905705 | H17: 18.85745 | I17: =H17/$H$1*1000 -> 0.40965069 | K17: 26.26231 | L17: =K17/$K$1*1000 -> 0.56676759 | N17: 51.24566 | O17: =N17/$N$1*1000 -> 1.0381391 | Q17: 94.37846 | R17: =Q17/$Q$1*1000 -> 1.7573823 | T17: 20.87175 | U17: =T17/$T$1*1000 -> 0.70360538 | W17: 15.76442 | X17: =W17/$W$1*1000 -> 0.37662565 | Z17: 11.10426 | AA17: =Z17/$Z$1*1000 -> 0.34725772 | AC17: 11.05797 | AD17: =AC17/$AC$1*1000 -> 0.39118332 | AF17: 10.29058 | AG17: =AF17/$AF$1*1000 -> 0.39260539 | AI17: 24.6245 | AJ17: =AI17/$AI$1*1000 -> 0.72373913 | AL17: 19.13579 | AM17: =AL17/$AL$1*1000 -> 0.45460742 | AO17: =H17+E17+K17+N17+Q17+T17+W17+Z17+AC17+AF17+AI17+AL17 -> 317.14723 | AP17: =AO17/$AO$1*1000 -> 0.66334638
A18: YES | B18: 6666010229 | C18: 6666010229 Staff Leaving Indemnity - Blue Collar Di | D18: * CS_Direct Labour | E18: 31.74454 | F18: =E18/$E$1*1000 -> 0.65356983 | H18: -40.04254 | I18: =H18/$H$1*1000 -> -0.86986597 | K18: 11.24318 | L18: =K18/$K$1*1000 -> 0.24263936 | N18: 10.77437 | O18: =N18/$N$1*1000 -> 0.21826814 | Q18: 10.89326 | R18: =Q18/$Q$1*1000 -> 0.20283889 | T18: 11.22168 | U18: =T18/$T$1*1000 -> 0.37829288 | W18: 23.15531 | X18: =W18/$W$1*1000 -> 0.55320042 | Z18: 7.05833 | AA18: =Z18/$Z$1*1000 -> 0.22073146 | AC18: 7.16637 | AD18: =AC18/$AC$1*1000 -> 0.25351528 | AF18: 7.24789 | AG18: =AF18/$AF$1*1000 -> 0.27652093 | AI18: 13.57379 | AJ18: =AI18/$AI$1*1000 -> 0.39894751 | AL18: 14.07397 | AM18: =AL18/$AL$1*1000 -> 0.33435417 | AO18: =H18+E18+K18+N18+Q18+T18+W18+Z18+AC18+AF18+AI18+AL18 -> 108.11015 | AP18: =AO18/$AO$1*1000 -> 0.22612361
A19: YES | B19: 6666010188 | C19: 6666010188 Salary - Blue collar direct employees | D19: * CS_Direct Labour | E19: 362.36537 | F19: =E19/$E$1*1000 -> 7.4605293 | H19: 309.36539 | I19: =H19/$H$1*1000 -> 6.7205133 | K19: 408.16624 | L19: =K19/$K$1*1000 -> 8.8086462 | N19: 342.65633 | O19: =N19/$N$1*1000 -> 6.9415621 | Q19: 370.23077 | R19: =Q19/$Q$1*1000 -> 6.8939142 | T19: 287.47624 | U19: =T19/$T$1*1000 -> 9.6910814 | W19: 348.43376 | X19: =W19/$W$1*1000 -> 8.3243845 | Z19: 294.87662 | AA19: =Z19/$Z$1*1000 -> 9.2215223 | AC19: 283.45492 | AD19: =AC19/$AC$1*1000 -> 10.027413 | AF19: 316.22481 | AG19: =AF19/$AF$1*1000 -> 12.064584 | AI19: 362.38001 | AJ19: =AI19/$AI$1*1000 -> 10.650717 | AL19: 377.54838 | AM19: =AL19/$AL$1*1000 -> 8.9693864 | AO19: =H19+E19+K19+N19+Q19+T19+W19+Z19+AC19+AF19+AI19+AL19 -> 4063.1788 | AP19: =AO19/$AO$1*1000 -> 8.4985606
A20: YES | B20: 5102040406 | C20: 5102040406 Other revenue-Service/Secondment agreeme | D20: * CS_Direct Labour | E20: 0 | F20: =E20/$E$1*1000 -> 0 | H20: 0 | I20: =H20/$H$1*1000 -> 0 | K20: 0 | L20: =K20/$K$1*1000 -> 0 | N20: 0 | O20: =N20/$N$1*1000 -> 0 | Q20: 0 | R20: =Q20/$Q$1*1000 -> 0 | T20: 0 | U20: =T20/$T$1*1000 -> 0 | W20: 0 | X20: =W20/$W$1*1000 -> 0 | Z20: 0 | AA20: =Z20/$Z$1*1000 -> 0 | AC20: 0 | AD20: =AC20/$AC$1*1000 -> 0 | AF20: 0 | AG20: =AF20/$AF$1*1000 -> 0 | AI20: 0 | AJ20: =AI20/$AI$1*1000 -> 0 | AL20: 0 | AM20: =AL20/$AL$1*1000 -> 0 | AO20: =H20+E20+K20+N20+Q20+T20+W20+Z20+AC20+AF20+AI20+AL20 -> 0 | AP20: =AO20/$AO$1*1000 -> 0
A21: YES | B21: 6666010115 | C21: 6666010115 Salary-Blue collar direct employees-Accr | D21: * CS_Direct Labour | E21: 0.78963 | F21: =E21/$E$1*1000 -> 0.016257232 | H21: -0.08295 | I21: =H21/$H$1*1000 -> -0.0018019682 | K21: 0.08153 | L21: =K21/$K$1*1000 -> 0.001759501 | N21: -0.12195 | O21: =N21/$N$1*1000 -> -0.0024704738 | Q21: 4.82629 | R21: =Q21/$Q$1*1000 -> 0.089868352 | T21: -2.497 | U21: =T21/$T$1*1000 -> -0.084176106 | W21: -1.46614 | X21: =W21/$W$1*1000 -> -0.035027355 | Z21: -1.28806 | AA21: =Z21/$Z$1*1000 -> -0.040280827 | AC21: 0.75016 | AD21: =AC21/$AC$1*1000 -> 0.026537427 | AF21: 1.48075 | AG21: =AF21/$AF$1*1000 -> 0.056493457 | AI21: 3.04219 | AJ21: =AI21/$AI$1*1000 -> 0.089413061 | AL21: -60.95212 | AM21: =AL21/$AL$1*1000 -> -1.4480346 | AO21: =H21+E21+K21+N21+Q21+T21+W21+Z21+AC21+AF21+AI21+AL21 -> -55.43767 | AP21: =AO21/$AO$1*1000 -> -0.11595365
B22: VAR | C22: * CS_Direct Labour | E22: 471.95897 | F22: =E22/$E$1*1000 -> 9.7168881 | H22: =SUM(H14:H21) -> 343.39069 | I22: =H22/$H$1*1000 -> 7.4596635 | K22: =SUM(K14:K21) -> 517.21307 | L22: =K22/$K$1*1000 -> 11.161989 | N22: =SUM(N14:N21) -> 469.10102 | O22: =N22/$N$1*1000 -> 9.5030898 | Q22: =SUM(Q14:Q21) -> 563.01003 | R22: =Q22/$Q$1*1000 -> 10.483577 | T22: =SUM(T14:T21) -> 382.06162 | U22: =T22/$T$1*1000 -> 12.879639 | W22: =SUM(W14:W21) -> 445.15222 | X22: =W22/$W$1*1000 -> 10.635072 | Z22: =SUM(Z14:Z21) -> 351.77623 | AA22: =Z22/$Z$1*1000 -> 11.000914 | AC22: =SUM(AC14:AC21) -> 348.81104 | AD22: =AC22/$AC$1*1000 -> 12.339431 | AF22: =SUM(AF14:AF21) -> 383.24932 | AG22: =AF22/$AF$1*1000 -> 14.621698 | AI22: =SUM(AI14:AI21) -> 479.35477 | AJ22: =AI22/$AI$1*1000 -> 14.088725 | AL22: =SUM(AL14:AL21) -> 425.92802 | AM22: =AL22/$AL$1*1000 -> 10.118738 | AO22: =SUM(AO14:AO21) -> 5181.007 | AP22: =AO22/$AO$1*1000 -> 10.836614
A23: NO | B23: 8701530201 | C23: 8701530201 Scrap-Raw Material - Managerial | D23: * CS_SCRAP_VARIABLE | E23: 0 | F23: =E23/$E$1*1000 -> 0 | H23: 0 | I23: =H23/$H$1*1000 -> 0 | K23: 0 | L23: =K23/$K$1*1000 -> 0 | N23: 0 | O23: =N23/$N$1*1000 -> 0 | Q23: 0 | R23: =Q23/$Q$1*1000 -> 0 | T23: 0 | U23: =T23/$T$1*1000 -> 0 | W23: 0 | X23: =W23/$W$1*1000 -> 0 | AA23: =Z23/$Z$1*1000 -> 0 | AC23: 0 | AD23: =AC23/$AC$1*1000 -> 0 | AF23: 0 | AG23: =AF23/$AF$1*1000 -> 0 | AI23: 0 | AJ23: =AI23/$AI$1*1000 -> 0 | AL23: 0 | AM23: =AL23/$AL$1*1000 -> 0 | AO23: =H23+E23+K23+N23+Q23+T23+W23+Z23+AC23+AF23+AI23+AL23 -> 0 | AP23: =AO23/$AO$1*1000 -> 0
A24: NO | B24: 6666050309 | C24: 6666050309 SFG scrap | D24: * CS_SCRAP_VARIABLE | E24: 11.07122 | F24: =E24/$E$1*1000 -> 0.22793889 | H24: 15.19826 | I24: =H24/$H$1*1000 -> 0.3301601 | K24: 16.14383 | L24: =K24/$K$1*1000 -> 0.34840041 | N24: 12.85146 | O24: =N24/$N$1*1000 -> 0.26034601 | Q24: 15.24772 | R24: =Q24/$Q$1*1000 -> 0.2839215 | T24: 5.09867 | U24: =T24/$T$1*1000 -> 0.17188073 | W24: 5.68261 | X24: =W24/$W$1*1000 -> 0.13576248 | Z24: 4.55538 | AA24: =Z24/$Z$1*1000 -> 0.14245802 | AC24: 4.17634 | AD24: =AC24/$AC$1*1000 -> 0.14774091 | AF24: 6.77505 | AG24: =AF24/$AF$1*1000 -> 0.25848117 | AI24: 6.67286 | AJ24: =AI24/$AI$1*1000 -> 0.19612215 | AL24: 20.85026 | AM24: =AL24/$AL$1*1000 -> 0.49533794 | AO24: =H24+E24+K24+N24+Q24+T24+W24+Z24+AC24+AF24+AI24+AL24 -> 124.32366 | AP24: =AO24/$AO$1*1000 -> 0.26003585
A25: NO | B25: 6666050308 | C25: 6666050308 Raw material scrap | D25: * CS_SCRAP_VARIABLE | E25: 12.13983 | F25: =E25/$E$1*1000 -> 0.24993988 | H25: 7.13567 | I25: =H25/$H$1*1000 -> 0.15501206 | K25: 6.75416 | L25: =K25/$K$1*1000 -> 0.1457617 | N25: 9.48485 | O25: =N25/$N$1*1000 -> 0.19214493 | Q25: 12.98944 | R25: =Q25/$Q$1*1000 -> 0.241871 | T25: 15.08068 | U25: =T25/$T$1*1000 -> 0.50838323 | W25: 11.5278 | X25: =W25/$W$1*1000 -> 0.27540913 | Z25: 12.4678 | AA25: =Z25/$Z$1*1000 -> 0.38989899 | AC25: 13.43581 | AD25: =AC25/$AC$1*1000 -> 0.47530105 | AF25: 9.35193 | AG25: =AF25/$AF$1*1000 -> 0.35679409 | AI25: 10.2868 | AJ25: =AI25/$AI$1*1000 -> 0.30233953 | AL25: 24.54833 | AM25: =AL25/$AL$1*1000 -> 0.58319269 | AO25: =H25+E25+K25+N25+Q25+T25+W25+Z25+AC25+AF25+AI25+AL25 -> 145.2031 | AP25: =AO25/$AO$1*1000 -> 0.30370737
A26: NO | B26: 6666050306 | C26: 6666050306 Finished goods scrap | D26: * CS_SCRAP_VARIABLE | E26: -0.01268 | F26: =E26/$E$1*1000 -> -0.00026106113 | H26: 0.25906 | I26: =H26/$H$1*1000 -> 0.0056277019 | K26: 0 | L26: =K26/$K$1*1000 -> 0 | N26: 0.26438 | O26: =N26/$N$1*1000 -> 0.0053558333 | Q26: 0 | R26: =Q26/$Q$1*1000 -> 0 | T26: 0.18359 | U26: =T26/$T$1*1000 -> 0.0061889833 | W26: 0.20456 | X26: =W26/$W$1*1000 -> 0.0048871157 | AA26: =Z26/$Z$1*1000 -> 0 | AC26: 0.22243 | AD26: =AC26/$AC$1*1000 -> 0.0078686147 | AF26: 0.36773 | AG26: =AF26/$AF$1*1000 -> 0.014029606 | AI26: 0.41342 | AJ26: =AI26/$AI$1*1000 -> 0.012150835 | AL26: 0.95812 | AM26: =AL26/$AL$1*1000 -> 0.022761979 | AO26: =H26+E26+K26+N26+Q26+T26+W26+Z26+AC26+AF26+AI26+AL26 -> 2.86061 | AP26: =AO26/$AO$1*1000 -> 0.005983263
B27: VAR | C27: * CS_SCRAP_VARIABLE | E27: 23.19837 | F27: =E27/$E$1*1000 -> 0.47761771 | H27: =SUM(H23:H26) -> 22.59299 | I27: =H27/$H$1*1000 -> 0.49079986 | K27: =SUM(K23:K26) -> 22.89799 | L27: =K27/$K$1*1000 -> 0.49416212 | N27: =SUM(N23:N26) -> 22.60069 | O27: =N27/$N$1*1000 -> 0.45784677 | Q27: =SUM(Q23:Q26) -> 28.23716 | R27: =Q27/$Q$1*1000 -> 0.52579249 | T27: =SUM(T23:T26) -> 20.36294 | U27: =T27/$T$1*1000 -> 0.68645294 | W27: =SUM(W23:W26) -> 17.41497 | X27: =W27/$W$1*1000 -> 0.41605872 | Z27: =SUM(Z23:Z26) -> 17.02318 | AA27: =Z27/$Z$1*1000 -> 0.53235701 | AC27: =SUM(AC23:AC26) -> 17.83458 | AD27: =AC27/$AC$1*1000 -> 0.63091057 | AF27: =SUM(AF23:AF26) -> 16.49471 | AG27: =AF27/$AF$1*1000 -> 0.62930487 | AI27: =SUM(AI23:AI26) -> 17.37308 | AJ27: =AI27/$AI$1*1000 -> 0.51061251 | AL27: =SUM(AL23:AL26) -> 46.35671 | AM27: =AL27/$AL$1*1000 -> 1.1012926 | AO27: =SUM(AO23:AO26) -> 272.38737 | AP27: =AO27/$AO$1*1000 -> 0.56972648
A28: YES | B28: 5102010151 | C28: 5102010151 Other Rev.-Interco-Epidemic problem comp | D28: * CS_Fix Cost | E28: 0 | F28: =E28/$E$1*1000 -> 0 | H28: 0 | I28: =H28/$H$1*1000 -> 0 | K28: 0 | L28: =K28/$K$1*1000 -> 0 | N28: 0 | O28: =N28/$N$1*1000 -> 0 | Q28: 0 | R28: =Q28/$Q$1*1000 -> 0 | T28: 0 | U28: =T28/$T$1*1000 -> 0 | W28: 0 | X28: =W28/$W$1*1000 -> 0 | Z28: 0 | AA28: =Z28/$Z$1*1000 -> 0 | AC28: 0 | AD28: =AC28/$AC$1*1000 -> 0 | AF28: 0 | AG28: =AF28/$AF$1*1000 -> 0 | AI28: 0 | AJ28: =AI28/$AI$1*1000 -> 0 | AL28: 0 | AM28: =AL28/$AL$1*1000 -> 0 | AO28: =H28+E28+K28+N28+Q28+T28+W28+Z28+AC28+AF28+AI28+AL28 -> 0 | AP28: =AO28/$AO$1*1000 -> 0
A29: YES | B29: 5001010200 | C29: 5001010200 Cost of Manufacture - Raw Material | D29: * CS_Fix Cost | E29: 0.17197 | F29: =E29/$E$1*1000 -> 0.0035405901 | H29: 0 | I29: =H29/$H$1*1000 -> 0 | K29: 0 | L29: =K29/$K$1*1000 -> 0 | N29: 0 | O29: =N29/$N$1*1000 -> 0 | Q29: 0.01851 | R29: =Q29/$Q$1*1000 -> 0.00034466706 | T29: 0.00921 | U29: =T29/$T$1*1000 -> 0.00031047735 | W29: 0 | X29: =W29/$W$1*1000 -> 0 | Z29: 0 | AA29: =Z29/$Z$1*1000 -> 0 | AC29: 0.01387 | AD29: =AC29/$AC$1*1000 -> 0.00049066082 | AF29: 0.01495 | AG29: =AF29/$AF$1*1000 -> 0.00057037122 | AI29: 0 | AJ29: =AI29/$AI$1*1000 -> 0 | AL29: 0 | AM29: =AL29/$AL$1*1000 -> 0 | AO29: =H29+E29+K29+N29+Q29+T29+W29+Z29+AC29+AF29+AI29+AL29 -> 0.22851 | AP29: =AO29/$AO$1*1000 -> 0.0004779524
A30: YES | B30: 5001010201 | C30: 5001010201 Cost of Manufacture - Raw Material-Freig | D30: * CS_Fix Cost | E30: 0.00056 | F30: =E30/$E$1*1000 -> 1.1529513e-05 | H30: 0 | I30: =H30/$H$1*1000 -> 0 | K30: 0 | L30: =K30/$K$1*1000 -> 0 | N30: 0 | O30: =N30/$N$1*1000 -> 0 | Q30: 0.00247 | R30: =Q30/$Q$1*1000 -> 4.599285e-05 | T30: 0.17793 | U30: =T30/$T$1*1000 -> 0.0059981796 | W30: 0 | X30: =W30/$W$1*1000 -> 0 | Z30: 0 | AA30: =Z30/$Z$1*1000 -> 0 | AC30: 0.00228 | AD30: =AC30/$AC$1*1000 -> 8.0656573e-05 | AF30: 0 | AG30: =AF30/$AF$1*1000 -> 0 | AI30: 0 | AJ30: =AI30/$AI$1*1000 -> 0 | AL30: 0 | AM30: =AL30/$AL$1*1000 -> 0 | AO30: =H30+E30+K30+N30+Q30+T30+W30+Z30+AC30+AF30+AI30+AL30 -> 0.18324 | AP30: =AO30/$AO$1*1000 -> 0.0003832655
A31: YES | B31: 5207000011 | C31: 5207000011 Gain of tangible asset disposal | D31: * CS_Fix Cost | E31: 0 | F31: =E31/$E$1*1000 -> 0 | H31: 0 | I31: =H31/$H$1*1000 -> 0 | K31: 0 | L31: =K31/$K$1*1000 -> 0 | N31: 0 | O31: =N31/$N$1*1000 -> 0 | Q31: 0 | R31: =Q31/$Q$1*1000 -> 0 | T31: 0 | U31: =T31/$T$1*1000 -> 0 | W31: 0 | X31: =W31/$W$1*1000 -> 0 | Z31: 0 | AA31: =Z31/$Z$1*1000 -> 0 | AC31: 0 | AD31: =AC31/$AC$1*1000 -> 0 | AF31: 0 | AG31: =AF31/$AF$1*1000 -> 0 | AI31: 0 | AJ31: =AI31/$AI$1*1000 -> 0 | AL31: 0 | AM31: =AL31/$AL$1*1000 -> 0 | AO31: =H31+E31+K31+N31+Q31+T31+W31+Z31+AC31+AF31+AI31+AL31 -> 0 | AP31: =AO31/$AO$1*1000 -> 0
A32: YES | B32: 5207000012 | C32: 5207000012 Loss of tangible asset sold | D32: * CS_Fix Cost | E32: 0 | F32: =E32/$E$1*1000 -> 0 | H32: 0 | I32: =H32/$H$1*1000 -> 0 | K32: 0 | L32: =K32/$K$1*1000 -> 0 | N32: 0 | O32: =N32/$N$1*1000 -> 0 | Q32: 0 | R32: =Q32/$Q$1*1000 -> 0 | T32: 0 | U32: =T32/$T$1*1000 -> 0 | W32: 0 | X32: =W32/$W$1*1000 -> 0 | Z32: 0 | AA32: =Z32/$Z$1*1000 -> 0 | AC32: 0 | AD32: =AC32/$AC$1*1000 -> 0 | AF32: 0 | AG32: =AF32/$AF$1*1000 -> 0 | AI32: 0 | AJ32: =AI32/$AI$1*1000 -> 0 | AL32: 0 | AM32: =AL32/$AL$1*1000 -> 0 | AO32: =H32+E32+K32+N32+Q32+T32+W32+Z32+AC32+AF32+AI32+AL32 -> 0 | AP32: =AO32/$AO$1*1000 -> 0
A33: YES | B33: 5207000022 | C33: 5207000022 Loss of intangible asset disposal | D33: * CS_Fix Cost | E33: 0 | F33: =E33/$E$1*1000 -> 0 | H33: 0 | I33: =H33/$H$1*1000 -> 0 | K33: 0 | L33: =K33/$K$1*1000 -> 0 | N33: 0 | O33: =N33/$N$1*1000 -> 0 | Q33: 0 | R33: =Q33/$Q$1*1000 -> 0 | T33: 0 | U33: =T33/$T$1*1000 -> 0 | W33: 0 | X33: =W33/$W$1*1000 -> 0 | Z33: 0 | AA33: =Z33/$Z$1*1000 -> 0 | AC33: 0 | AD33: =AC33/$AC$1*1000 -> 0 | AF33: 0 | AG33: =AF33/$AF$1*1000 -> 0 | AI33: 0 | AJ33: =AI33/$AI$1*1000 -> 0 | AL33: 0 | AM33: =AL33/$AL$1*1000 -> 0 | AO33: =H33+E33+K33+N33+Q33+T33+W33+Z33+AC33+AF33+AI33+AL33 -> 0 | AP33: =AO33/$AO$1*1000 -> 0
A34: YES | B34: 5301060000 | C34: 5301060000 Other Income-Subsidy income | D34: * CS_Fix Cost | E34: 0 | F34: =E34/$E$1*1000 -> 0 | H34: 0 | I34: =H34/$H$1*1000 -> 0 | K34: 0 | L34: =K34/$K$1*1000 -> 0 | N34: 0 | O34: =N34/$N$1*1000 -> 0 | Q34: 0 | R34: =Q34/$Q$1*1000 -> 0 | T34: 0 | U34: =T34/$T$1*1000 -> 0 | W34: 0 | X34: =W34/$W$1*1000 -> 0 | Z34: 0 | AA34: =Z34/$Z$1*1000 -> 0 | AC34: 0 | AD34: =AC34/$AC$1*1000 -> 0 | AF34: 0 | AG34: =AF34/$AF$1*1000 -> 0 | AI34: 0 | AJ34: =AI34/$AI$1*1000 -> 0 | AL34: 0 | AM34: =AL34/$AL$1*1000 -> 0 | AO34: =H34+E34+K34+N34+Q34+T34+W34+Z34+AC34+AF34+AI34+AL34 -> 0 | AP34: =AO34/$AO$1*1000 -> 0
A35: YES | B35: 5301999999 | C35: 5301999999 Non-operation revenue-Other | D35: * CS_Fix Cost | E35: 0 | F35: =E35/$E$1*1000 -> 0 | H35: 0 | I35: =H35/$H$1*1000 -> 0 | K35: 0 | L35: =K35/$K$1*1000 -> 0 | N35: 0 | O35: =N35/$N$1*1000 -> 0 | Q35: 0 | R35: =Q35/$Q$1*1000 -> 0 | T35: 0 | U35: =T35/$T$1*1000 -> 0 | W35: 0 | X35: =W35/$W$1*1000 -> 0 | Z35: 0 | AA35: =Z35/$Z$1*1000 -> 0 | AC35: 0 | AD35: =AC35/$AC$1*1000 -> 0 | AF35: 0 | AG35: =AF35/$AF$1*1000 -> 0 | AI35: -0.06594 | AJ35: =AI35/$AI$1*1000 -> -0.0019380437 | AL35: 0 | AM35: =AL35/$AL$1*1000 -> 0 | AO35: =H35+E35+K35+N35+Q35+T35+W35+Z35+AC35+AF35+AI35+AL35 -> -0.06594 | AP35: =AO35/$AO$1*1000 -> -0.00013792036
A36: YES | B36: 5405030000 | C36: 5405030000 Other cost-others | D36: * CS_Fix Cost | E36: 0.0094 | F36: =E36/$E$1*1000 -> 0.00019353112 | H36: =13.41/1000 -> 0.01341 | I36: =H36/$H$1*1000 -> 0.00029131275 | K36: =738.36/1000 -> 0.73836 | L36: =K36/$K$1*1000 -> 0.015934566 | N36: 0.04654 | O36: =N36/$N$1*1000 -> 0.00094281142 | Q36: 0.00024 | R36: =Q36/$Q$1*1000 -> 4.4689409e-06 | T36: -0.03325 | U36: =T36/$T$1*1000 -> -0.0011208873 | W36: 0.1626 | X36: =W36/$W$1*1000 -> 0.0038846549 | Z36: 0.10378 | AA36: =Z36/$Z$1*1000 -> 0.0032454577 | AC36: 0.13156 | AD36: =AC36/$AC$1*1000 -> 0.0046540258 | AF36: 0 | AG36: =AF36/$AF$1*1000 -> 0 | AI36: 0.29868 | AJ36: =AI36/$AI$1*1000 -> 0.0087785093 | AL36: 0.00145 | AM36: =AL36/$AL$1*1000 -> 3.4447533e-05 | AO36: =H36+E36+K36+N36+Q36+T36+W36+Z36+AC36+AF36+AI36+AL36 -> 1.47277 | AP36: =AO36/$AO$1*1000 -> 0.0030804515
A37: YES | B37: 5601050000 | C37: 5601050000 Non-Operating Expense - Penalty | D37: * CS_Fix Cost | E37: 0 | F37: =E37/$E$1*1000 -> 0 | H37: 0 | I37: =H37/$H$1*1000 -> 0 | K37: 0 | L37: =K37/$K$1*1000 -> 0 | N37: 0 | O37: =N37/$N$1*1000 -> 0 | Q37: 0 | R37: =Q37/$Q$1*1000 -> 0 | T37: 0.002 | U37: =T37/$T$1*1000 -> 6.7421791e-05 | W37: 0.01063 | X37: =W37/$W$1*1000 -> 0.00025395991 | Z37: 0 | AA37: =Z37/$Z$1*1000 -> 0 | AC37: 0.05263 | AD37: =AC37/$AC$1*1000 -> 0.0018618226 | AF37: 0 | AG37: =AF37/$AF$1*1000 -> 0 | AI37: 0 | AJ37: =AI37/$AI$1*1000 -> 0 | AL37: 0 | AM37: =AL37/$AL$1*1000 -> 0 | AO37: =H37+E37+K37+N37+Q37+T37+W37+Z37+AC37+AF37+AI37+AL37 -> 0.06526 | AP37: =AO37/$AO$1*1000 -> 0.00013649807
A38: YES | B38: 5601050100 | C38: 5601050100 Non-operation Expense-Others | D38: * CS_Fix Cost | E38: 0.01682 | F38: =E38/$E$1*1000 -> 0.00034629717 | H38: 0 | I38: =H38/$H$1*1000 -> 0 | K38: 0 | L38: =K38/$K$1*1000 -> 0 | N38: 0 | O38: =N38/$N$1*1000 -> 0 | Q38: 0 | R38: =Q38/$Q$1*1000 -> 0 | T38: 0 | U38: =T38/$T$1*1000 -> 0 | W38: 0 | X38: =W38/$W$1*1000 -> 0 | Z38: 0 | AA38: =Z38/$Z$1*1000 -> 0 | AC38: 0 | AD38: =AC38/$AC$1*1000 -> 0 | AF38: 0 | AG38: =AF38/$AF$1*1000 -> 0 | AI38: 0 | AJ38: =AI38/$AI$1*1000 -> 0 | AL38: 0.03479 | AM38: =AL38/$AL$1*1000 -> 0.00082650322 | AO38: =H38+E38+K38+N38+Q38+T38+W38+Z38+AC38+AF38+AI38+AL38 -> 0.05161 | AP38: =AO38/$AO$1*1000 -> 0.00010794768
A39: YES | B39: 5102040893 | C39: 5102040893 Other revenue-Charge out-Test Expense | D39: * CS_Fix Cost | T39: 0 | U39: =T39/$T$1*1000 -> 0 | W39: 0 | X39: =W39/$W$1*1000 -> 0 | Z39: 0 | AA39: =Z39/$Z$1*1000 -> 0 | AC39: 0 | AD39: =AC39/$AC$1*1000 -> 0 | AF39: 0 | AG39: =AF39/$AF$1*1000 -> 0 | AI39: 0 | AJ39: =AI39/$AI$1*1000 -> 0 | AL39: 0 | AM39: =AL39/$AL$1*1000 -> 0 | AO39: =H39+E39+K39+N39+Q39+T39+W39+Z39+AC39+AF39+AI39+AL39 -> 0 | AP39: =AO39/$AO$1*1000 -> 0
A40: YES | B40: 5801000041 | C40: 5801000041 Previous year Sundry cost | D40: * CS_Fix Cost | E40: 0 | F40: =E40/$E$1*1000 -> 0 | H40: 0 | I40: =H40/$H$1*1000 -> 0 | K40: 0 | L40: =K40/$K$1*1000 -> 0 | N40: 0 | O40: =N40/$N$1*1000 -> 0 | Q40: 0 | R40: =Q40/$Q$1*1000 -> 0 | T40: 0 | U40: =T40/$T$1*1000 -> 0 | W40: 0 | X40: =W40/$W$1*1000 -> 0 | Z40: 0 | AA40: =Z40/$Z$1*1000 -> 0 | AC40: 0 | AD40: =AC40/$AC$1*1000 -> 0 | AF40: 0 | AG40: =AF40/$AF$1*1000 -> 0 | AI40: 0 | AJ40: =AI40/$AI$1*1000 -> 0 | AL40: 0 | AM40: =AL40/$AL$1*1000 -> 0 | AO40: =H40+E40+K40+N40+Q40+T40+W40+Z40+AC40+AF40+AI40+AL40 -> 0 | AP40: =AO40/$AO$1*1000 -> 0
A41: YES | B41: 6666010322 | C41: 6666010322 fuel allowance | D41: * CS_Fix Cost | E41: 2.19309 | F41: =E41/$E$1*1000 -> 0.045152251 | H41: 0.51196 | I41: =H41/$H$1*1000 -> 0.011121587 | K41: 2.69789 | L41: =K41/$K$1*1000 -> 0.058223234 | N41: 1.01857 | O41: =N41/$N$1*1000 -> 0.020634281 | Q41: 1.25877 | R41: =Q41/$Q$1*1000 -> 0.023439036 | T41: 1.28891 | U41: =T41/$T$1*1000 -> 0.04345031 | W41: 0.95107 | X41: =W41/$W$1*1000 -> 0.022721886 | Z41: 1.49429 | AA41: =Z41/$Z$1*1000 -> 0.04673015 | AC41: 1.20561 | AD41: =AC41/$AC$1*1000 -> 0.042649285 | AF41: 1.3803 | AG41: =AF41/$AF$1*1000 -> 0.052661096 | AI41: 0.62515 | AJ41: =AI41/$AI$1*1000 -> 0.018373795 | AL41: 1.46341 | AM41: =AL41/$AL$1*1000 -> 0.034766113 | AO41: =H41+E41+K41+N41+Q41+T41+W41+Z41+AC41+AF41+AI41+AL41 -> 16.08902 | AP41: =AO41/$AO$1*1000 -> 0.033651857
...

Sheet Renta DW _2024 new format 
B1: Renta DW Cost Evolution | D1: Volume | F1: ='2024_ACT@ACT FX old format '!E3 -> 16045 | J1: ='2024_ACT@ACT FX old format '!F3 -> 19752 | N1: ='2024_ACT@ACT FX old format '!G3 -> 20037 | R1: ='2024_ACT@ACT FX old format '!H3 -> 28043 | V1: ='2024_ACT@ACT FX old format '!I3 -> 40794 | Z1: ='2024_ACT@ACT FX old format '!J3 -> 30976 | AD1: ='2024_ACT@ACT FX old format '!K3 -> 34477 | AH1: ='2024_ACT@ACT FX old format '!L3 -> 25578 | AL1: ='2024_ACT@ACT FX old format '!M3 -> 40104 | AP1: ='2024_ACT@ACT FX old format '!N3 -> 41187 | AT1: ='2024_ACT@ACT FX old format '!O3 -> 43110 | AX1: ='2024_ACT@ACT FX old format '!P3 -> 26153 | BB1: =SUM(E1:AX1) -> 366256
D2: FX Rates | F2: 32.8165 | J2: ='2024_ACT@ACT FX old format '!F2 -> 33.2644 | N2: ='2024_ACT@ACT FX old format '!G2 -> 34.8229 | R2: ='2024_ACT@ACT FX old format '!H2 -> 34.6926 | V2: ='2024_ACT@ACT FX old format '!I2 -> 34.8605 | Z2: ='2024_ACT@ACT FX old format '!J2 -> 35.0667 | AD2: ='2024_ACT@ACT FX old format '!K2 -> 35.6969 | AH2: ='2024_ACT@ACT FX old format '!L2 -> 37.1098 | AL2: ='2024_ACT@ACT FX old format '!M2 -> 37.823824 | AP2: ='2024_ACT@ACT FX old format '!N2 -> 37.347309 | AT2: ='2024_ACT@ACT FX old format '!O2 -> 36.6237 | AX2: ='2024_ACT@ACT FX old format '!P2 -> 36.65884 | BB2: =BA191/BB191 -> 35.655612
A4: Row Labels | E4: Jan KLC | F4: JAN K€ | G4: Jan CPU € / pcs | I4: FEB KLC | J4: FEB K€ | K4: CPU € / pcs | M4: March KLC | N4: March K€ | O4: CPU € / pcs | Q4: Apr KLC | R4: Apr K€ | S4: CPU € / pcs | U4: MAY KLC | V4: May K€ | W4: CPU € / pcs | Y4: June KLC | Z4: June K€ | AA4: CPU € / pcs | AC4: July KLC | AD4: July K€ | AE4: CPU € / pcs | AG4: Aug KLC | AH4: Aug K€ | AI4: CPU € / pcs | AK4: Sept KLC | AL4: Sept K€ | AM4: CPU € / pcs | AO4: Oct KLC | AP4: Oct K€ | AQ4: CPU € / pcs | AS4: Nov KLC | AT4: Nov K€ | AU4: CPU € / pcs | AW4: Dec KLC | AX4: Dec K€ | AY4: CPU € / pcs | BA4: FY KLC | BB4: FY K€ | BC4: CPU € / pcs
