Workbook
Name \0: #REF!
Name \2: #REF!
Name \a: #REF!
Name \b: #REF!
Name \b1: #REF!
Name \m: #REF!
Name \p: '[4]FA-LISTING'!#REF!
Name \v: '[4]FA-LISTING'!#REF!
Name ___: #REF!
Name _______5월국내제품: #REF!
Name _______AEM14: #REF!
Name _______CAR05: #REF!
Name _______FED18: #REF!
Name _______GMC1: #REF!
Name _______GMC2: #REF!
Name ______ST2: #REF!
Name _____5월국내제품: #REF!
Name _____AEM14: #REF!
Name _____CAR05: #REF!
Name _____FED18: #REF!
Name _____GMC1: #REF!
Name _____GMC2: #REF!
Name ____5월국내제품: #REF!
Name ____AEM14: #REF!
Name ____CAR05: #REF!
Name ____FED18: #REF!
Name ____GMC1: #REF!
Name ____GMC2: #REF!
Name ____ST2: #REF!
Name ___5월국내제품: #REF!
Name ___AEM14: #REF!
Name ___CAR05: #REF!
Name ___FED18: #REF!
Name __5월국내제품: #REF!
Name __a66000: #REF!
Name __a69000: #REF!
Name __act2: #REF!
Name __act3: #REF!
Name __act4: #REF!
Name __AEM14: #REF!
Name __afo3: #REF!
Name __all22: [5]PLALL!$A$1:$BM$137
Name __CAR05: #REF!
Name __Col3: [6]Tables!$S$7
Name __Col6: [6]Tables!$S$12
Name __CSD3: #REF!
Name __DAT1: '[7]Raw materials'!#REF!
Name __DAT10: #REF!
Name __DAT11: #REF!
Name __DAT12: #REF!
Name __DAT13: #REF!
Name __DAT14: #REF!
Name __DAT15: #REF!
Name __DAT16: #REF!
Name __DAT17: #REF!
Name __DAT2: '[7]Raw materials'!#REF!
Name __DAT3: '[7]Raw materials'!#REF!
Name __DAT4: '[7]Raw materials'!#REF!
Name __DAT5: '[7]Raw materials'!#REF!
Name __DAT6: '[7]Raw materials'!#REF!

Sheet 洗碗机成本数据
A1: 分类 | B1: 指标 | C1: / | D1: 1月份 | E1: 2月份 | F1: 3月份 | G1: 4月份 | H1: 5月份 | I1: 6月份 | J1: 7月份 | K1: 8月份 | L1: 9月份 | M1: 10月份 | N1: 11月份 | O1: 12月份 | P1: 年度
A2: 洗碗机定单量 | B2: 洗碗机定单量 | C2: 同期 | D2: 48570 | E2: 46039 | F2: 46330 | G2: 49360 | H2: 53704 | I2: 29664 | J2: 41857 | K2: 31977 | L2: 28268 | M2: 26211 | N2: 34024 | O2: 42093 | P2: 478097
B3: 洗碗机定单量 | C3: 目标 | D3: 50463 | E3: 50450 | F3: 50440 | G3: 48050 | H3: 36788 | I3: 53265 | J3: 42049 | K3: 39150 | L3: 53732 | M3: 48548 | N3: 51408 | O3: 40676 | P3: 565019
B4: 洗碗机定单量 | C4: 26年 | D4: 47360 | E4: 42593 | F4: 23002 | G4: 40893 | H4: 33043 | I4: 53186 | J4: 41500 | K4: 39000.001 | L4: 54085 | M4: 49968 | N4: 51936 | O4: 42190 | P4: 518756
A5: 洗碗机定单量（累计） | B5: 洗碗机定单量（累计） | C5: 同期 | D5: =D2 -> 48570 | E5: =D5+E2 -> 94609 | F5: =E5+F2 -> 140939 | G5: =F5+G2 -> 190299 | H5: =G5+H2 -> 244003 | I5: =H5+I2 -> 273667 | J5: =I5+J2 -> 315524 | K5: =J5+K2 -> 347501 | L5: =K5+L2 -> 375769 | ... O5: =N5+O2 -> 478097 | P5: 19821.23
B6: 洗碗机定单量（累计） | C6: 目标 | D6: =D3 -> 50463 | E6: =D6+E3 -> 100913 | F6: =E6+F3 -> 151353 | G6: =F6+G3 -> 199403 | H6: =G6+H3 -> 236191 | I6: =H6+I3 -> 289456 | J6: =I6+J3 -> 331505 | K6: =J6+K3 -> 370655 | L6: =K6+L3 -> 424387 | ... O6: =N6+O3 -> 565019 | P6: =O6 -> 565019
B7: 洗碗机定单量（累计） | C7: 26年 | D7: =D4 -> 47360 | E7: =D7+E4 -> 89953 | F7: =E7+F4 -> 112955 | G7: =F7+G4 -> 153848 | H7: =G7+H4 -> 186891 | I7: =H7+I4 -> 240077 | J7: =I7+J4 -> 281577 | K7: =J7+K4 -> 320577 | L7: =K7+L4 -> 374662 | ... O7: =N7+O4 -> 518756 | P7: =O7 -> 518756
A8: 洗碗机费用金额 | B8: 洗碗机费用金额 | C8: 同期 | D8: 1702.4888 | E8: 1623.6996 | F8: 1825.8462 | G8: 1591.5968 | H8: 1866.987 | I8: 1737.9 | J8: 1637.4123 | K8: 1533.5455 | L8: 1597.8553 | M8: 1443.0898 | N8: 1758.5061 | O8: 1502.3028 | P8: =SUM(D8:O8) -> 19821.23
B9: 洗碗机费用金额 | C9: 目标 | D9: 1838.2556 | E9: 1852.3924 | F9: 1892.6678 | G9: 1849.6673 | H9: 1928.8688 | I9: 1870.4326 | J9: 1859.2351 | K9: 1842.1673 | L9: 1948.6868 | M9: 1894.9246 | N9: 1861.9628 | O9: 1947.1505 | P9: =SUM(D9:O9) -> 22586.412
B10: 洗碗机费用金额 | C10: 26年 | D10: 1778.218 | E10: 1749.5522 | F10: 1713 | G10: 900.77836 | H10: 1826 | I10: 1438.5835 | J10: 1663.9548 | K10: 1652.6359 | L10: 1816.2017 | M10: 1764.1942 | N10: 1739.899 | O10: 1797.8953 | P10: =SUM(D10:O10) -> 19840.913
A11: 洗碗机费用金额（累计） | B11: 洗碗机费用金额（累计） | C11: 同期 | D11: =D8 -> 1702.4888 | E11: =D11+E8 -> 3326.1883 | F11: =E11+F8 -> 5152.0345 | G11: =F11+G8 -> 6743.6313 | H11: =G11+H8 -> 8610.6183 | I11: =H11+I8 -> 10348.518 | J11: =I11+J8 -> 11985.931 | K11: =J11+K8 -> 13519.476 | L11: =K11+L8 -> 15117.331 | ... O11: =N11+O8 -> 19821.23 | P11: =O11 -> 19821.23
B12: 洗碗机费用金额（累计） | C12: 目标 | D12: =D9 -> 1838.2556 | E12: =D12+E9 -> 3690.648 | F12: =E12+F9 -> 5583.3158 | G12: =F12+G9 -> 7432.9831 | H12: =G12+H9 -> 9361.8519 | I12: =H12+I9 -> 11232.284 | J12: =I12+J9 -> 13091.52 | K12: =J12+K9 -> 14933.687 | L12: =K12+L9 -> 16882.374 | ... O12: =N12+O9 -> 22586.412 | P12: =O12 -> 22586.412
B13: 洗碗机费用金额（累计） | C13: 26年 | D13: =D10 -> 1778.218 | E13: =D13+E10 -> 3527.7702 | F13: =E13+F10 -> 5240.7702 | G13: =F13+G10 -> 6141.5486 | H13: =G13+H10 -> 7967.5486 | I13: =H13+I10 -> 9406.1321 | J13: =I13+J10 -> 11070.087 | K13: =J13+K10 -> 12722.723 | L13: =K13+L10 -> 14538.924 | ... O13: =N13+O10 -> 19840.913 | P13: =O13 -> 19840.913
A14: 洗碗机单台 | B14: 洗碗机单台 | C14: 同期 | D14: 35.046041 | E14: 35.45 | F14: 39.407954 | G14: 32.242707 | H14: 34.764394 | I14: 58.586165 | J14: 39.119199 | K14: 47.957767 | L14: 56.525234 | M14: 55.056648 | N14: 51.684284 | O14: 35.690087 | P14: 41.458596
B15: 洗碗机单台 | C15: 目标 | D15: 36.427791 | E15: 36.72 | F15: 37.525254 | G15: 38.494637 | H15: 52.432012 | I15: 35.115602 | J15: 44.215917 | K15: 47.054083 | L15: 36.266783 | M15: 39.031981 | N15: 36.219319 | O15: 47.869763 | P15: 39.974605
B16: 洗碗机单台 | C16: 26年 | D16: =D10/D4*1000 -> 37.546833 | E16: =E10/E4*1000 -> 41.076051 | F16: =F10/F4*1000 -> 74.471785 | G16: =G10/G4*1000 -> 22.027691 | H16: =H10/H4*1000 -> 55.261326 | I16: =I10/I4*1000 -> 27.048161 | J16: =J10/J4*1000 -> 40.095297 | K16: =K10/K4*1000 -> 42.375277 | ... P16: =P10/P4*1000 -> 38.247101
B17: 洗碗机单台 | C17: 当月单台目标完成率 | D17: =2-D16/D15 -> 0.96928055 | E17: =2-E16/E15 -> 0.88137117 | F17: =2-F16/F15 -> 0.015422249 | G17: =2-G16/G15 -> 1.4277725 | H17: =2-H16/H15 -> 0.94603841 | I17: =2-I16/I15 -> 1.2297395 | J17: =2-J16/J15 -> 1.0931931 | K17: =2-K16/K15 -> 1.0994346 | ... P17: =2-P16/P15 -> 1.0432151
B18: 洗碗机单台 | C18: 单台同期优化 | D18: =(D14-D16)/D14 -> -0.071357321 | E18: =(E14-E16)/E14 -> -0.15870382 | F18: =(F14-F16)/F14 -> -0.88976532 | G18: =(G14-G16)/G14 -> 0.31681634 | H18: =(H14-H16)/H14 -> -0.58959556 | I18: =(I14-I16)/I14 -> 0.53831829 | J18: =(J14-J16)/J14 -> -0.024951897 | K18: =(K14-K16)/K14 -> 0.1164043 | ... P18: =(P14-P16)/P14 -> 0.0774627
B19: 洗碗机制造费差额 | C19: 差额 | D19: =(D16-D14)*D4 -> 118437.49 | E19: =(E16-E14)*E4 -> 239630.37 | F19: =(F16-F14)*F4 -> 806538.24 | G19: =(G16-G14)*G4 -> -417722.67 | H19: =(H16-H14)*H4 -> 677280.13 | I19: =(I16-I14)*I4 -> -1677380.3 | J19: =(J16-J14)*J4 -> 40508.076 | K19: =(K16-K14)*K4 -> -217717.12 | ... P19: =(P16-P14)*P4 -> -1665982.2
A20: 洗碗机单台（累计） | B20: 洗碗机单台（累计） | C20: 同期 | D20: =D11/D5*1000 -> 35.052271 | E20: =E11/E5*1000 -> 35.157209 | F20: =F11/F5*1000 -> 36.555067 | G20: =G11/G5*1000 -> 35.43703 | H20: =H11/H5*1000 -> 35.288985 | I20: =I11/I5*1000 -> 37.814272 | J20: =J11/J5*1000 -> 37.987382 | K20: =K11/K5*1000 -> 38.904855 | ... P20: =P11/P5*1000 -> 1000
B21: 洗碗机单台（累计） | C21: 目标 | D21: =D12/D6*1000 -> 36.427791 | E21: =E12/E6*1000 -> 36.572572 | F21: =F12/F6*1000 -> 36.889363 | G21: =G12/G6*1000 -> 37.276185 | H21: =H12/H6*1000 -> 39.636785 | I21: =I12/I6*1000 -> 38.804808 | J21: =J12/J6*1000 -> 39.491168 | K21: =K12/K6*1000 -> 40.289992 | ... P21: =P12/P6*1000 -> 39.974605
B22: 洗碗机单台（累计） | C22: 26年 | D22: =D13/D7*1000 -> 37.546833 | E22: =E13/E7*1000 -> 39.217927 | F22: =F13/F7*1000 -> 46.396974 | G22: =G13/G7*1000 -> 39.919587 | H22: =H13/H7*1000 -> 42.632061 | I22: =I13/I7*1000 -> 39.179647 | J22: =J13/J7*1000 -> 39.314599 | K22: =K13/K7*1000 -> 39.686948 | ... P22: =P13/P7*1000 -> 38.247101
B23: 洗碗机单台（累计） | C23: 当月单台目标完成率 | D23: =2-D22/D21 -> 0.96928055 | E23: =2-E22/E21 -> 0.92766833 | F23: =2-F22/F21 -> 0.74226687 | G23: =2-G22/G21 -> 0.92908604 | H23: =2-H22/H21 -> 0.92443191 | I23: =2-I22/I21 -> 0.9903404 | J23: =2-J22/J21 -> 1.0044711 | K23: =2-K22/K21 -> 1.0149676 | ... P23: =2-P22/P21 -> 1.0432151
B24: 洗碗机单台（累计） | C24: 累计单台同期优化 | D24: =(D20-D22)/D20 -> -0.071166926 | E24: =(E20-E22)/E20 -> -0.11550174 | F24: =(F20-F22)/F20 -> -0.26923512 | G24: =(G20-G22)/G20 -> -0.1264936 | H24: =(H20-H22)/H20 -> -0.20808408 | I24: =(I20-I22)/I20 -> -0.036107402 | J24: =(J20-J22)/J20 -> -0.03493838 | K24: =(K20-K22)/K20 -> -0.0201027 | ... P24: =(P20-P22)/P20 -> 0.9617529
B25: 洗碗机制造费累计差额 | C25: 累计差额 | D25: =(D22-D20)*D7 -> 118142.47 | E25: =(E22-E20)*E7 -> 365273.85 | F25: =(F22-F20)*F7 -> 1111692.7 | G25: =(G22-G20)*G7 -> 689632.47 | H25: =(H22-H20)*H7 -> 1372354.8 | I25: =(I22-I20)*I7 -> 327795.16 | J25: =(J22-J20)*J7 -> 373713.94 | K25: =(K22-K20)*K7 -> 250720.91 | ... P25: =(P22-P20)*P7 -> -4.9891509e+08
A26: 洗碗机折旧费用 | B26: 洗碗机折旧费用 | C26: 同期 | D26: 547 | E26: 512 | F26: 562 | G26: 551 | H26: 580 | I26: 564 | J26: 579 | K26: 577 | L26: 565 | M26: 370 | N26: 546 | O26: 562 | P26: =SUM(D26:O26) -> 6515
B27: 洗碗机折旧费用 | C27: 目标 | D27: 577 | E27: 536 | F27: 582 | G27: 568 | H27: 580 | I27: 569 | J27: 599 | K27: 600 | L27: 586 | M27: 601 | N27: 591 | O27: 614 | P27: =SUM(D27:O27) -> 7003
B28: 洗碗机折旧费用 | C28: 26年 | D28: 564 | E28: 557 | F28: 565 | G28: 29.8973 | H28: 433.31502 | I28: 433 | J28: 479.85896 | K28: 480.14766 | L28: 469.5718 | M28: 475.19367 | N28: 475.19367 | O28: 494.2163 | P28: =SUM(D28:O28) -> 5456.3944
A29: 洗碗机折旧费用累计 | B29: 洗碗机折旧费用累计 | C29: 同期 | D29: =D26 -> 547 | E29: =D29+E26 -> 1059 | F29: =E29+F26 -> 1621 | G29: =F29+G26 -> 2172 | H29: =G29+H26 -> 2752 | I29: =H29+I26 -> 3316 | J29: =I29+J26 -> 3895 | K29: =J29+K26 -> 4472 | L29: =K29+L26 -> 5037 | ... O29: =N29+O26 -> 6515 | P29: =O29 -> 6515
B30: 洗碗机折旧费用累计 | C30: 目标 | D30: =D27 -> 577 | E30: =D30+E27 -> 1113 | F30: =E30+F27 -> 1695 | G30: =F30+G27 -> 2263 | H30: =G30+H27 -> 2843 | I30: =H30+I27 -> 3412 | J30: =I30+J27 -> 4011 | K30: =J30+K27 -> 4611 | L30: =K30+L27 -> 5197 | ... O30: =N30+O27 -> 7003 | P30: =O30 -> 7003
B31: 洗碗机折旧费用累计 | C31: 26年 | D31: =D28 -> 564 | E31: =D31+E28 -> 1121 | F31: =E31+F28 -> 1686 | G31: =F31+G28 -> 1715.8973 | H31: =G31+H28 -> 2149.2123 | I31: =H31+I28 -> 2582.2123 | J31: =I31+J28 -> 3062.0713 | K31: =J31+K28 -> 3542.2189 | L31: =K31+L28 -> 4011.7907 | ... O31: =N31+O28 -> 5456.3944 | P31: =O31 -> 5456.3944
A32: 洗碗机折旧单台 | B32: 洗碗机折旧单台 | C32: 同期 | D32: =D26/D2*1000 -> 11.262096 | E32: =E26/E2*1000 -> 11.121006 | F32: =F26/F2*1000 -> 12.130369 | G32: =G26/G2*1000 -> 11.162885 | H32: =H26/H2*1000 -> 10.79994 | I32: =I26/I2*1000 -> 19.012945 | J32: =J26/J2*1000 -> 13.832812 | K32: =K26/K2*1000 -> 18.044219 | ... O32: =O26/O2*1000 -> 13.351389 | P32: =P29/P2*1000 -> 13.626942
B33: 洗碗机折旧单台 | C33: 目标 | D33: =D27/D3*1000 -> 11.43412 | E33: =E27/E3*1000 -> 10.624381 | F33: =F27/F3*1000 -> 11.538462 | G33: =G27/G3*1000 -> 11.82102 | H33: =H27/H3*1000 -> 15.766011 | I33: =I27/I3*1000 -> 10.682437 | J33: =J27/J3*1000 -> 14.245285 | K33: =K27/K3*1000 -> 15.32567 | ... O33: =O27/O3*1000 -> 15.094896 | P33: =P30/P3*1000 -> 12.394273
B34: 洗碗机折旧单台 | C34: 26年 | D34: =D28/D4*1000 -> 11.908784 | E34: =E28/E4*1000 -> 13.077266 | F34: =F28/F4*1000 -> 24.563081 | G34: =G28/G4*1000 -> 0.73111046 | H34: =H28/H4*1000 -> 13.113671 | I34: =I28/I4*1000 -> 8.1412402 | J34: =J28/J4*1000 -> 11.562866 | K34: =K28/K4*1000 -> 12.311478 | ... O34: =O28/O4*1000 -> 11.714063 | P34: =P31/P4*1000 -> 10.518229
B35: 洗碗机折旧差额 | C35: 差额 | D35: =(D33-D32)*D4 -> 8147.0616 | E35: =(E33-E32)*E4 -> -21152.771 | F35: =(F33-F32)*F4 -> -13615.058 | G35: =(G33-G32)*G4 -> 26913.108 | H35: =(H33-H32)*H4 -> 164093.86 | I35: =(I33-I32)*I4 -> -443066.4 | J35: =(J33-J32)*J4 -> 17117.652 | K35: =(K33-K32)*K4 -> -106023.41 | ... P35: =(P33-P32)*P4 -> -639454.1
A36: 洗碗机折旧费用累计 | B36: 洗碗机折旧单台累计 | C36: 同期 | D36: =D29/D5*1000 -> 11.262096 | E36: =E29/E5*1000 -> 11.193438 | F36: =F29/F5*1000 -> 11.50143 | G36: =G29/G5*1000 -> 11.413618 | H36: =H29/H5*1000 -> 11.27855 | I36: =I29/I5*1000 -> 12.116916 | J36: =J29/J5*1000 -> 12.344544 | K36: =K29/K5*1000 -> 12.869028 | ... P36: =P29/P5*1000 -> 328.68797
B37: 洗碗机折旧单台累计 | C37: 目标 | D37: =D30/D6*1000 -> 11.43412 | E37: =E30/E6*1000 -> 11.029302 | F37: =F30/F6*1000 -> 11.198985 | G37: =G30/G6*1000 -> 11.348876 | H37: =H30/H6*1000 -> 12.036868 | I37: =I30/I6*1000 -> 11.787629 | J37: =J30/J6*1000 -> 12.099365 | K37: =K30/K6*1000 -> 12.44014 | ... P37: =P30/P6*1000 -> 12.394273
B38: 洗碗机折旧单台累计 | C38: 26年 | D38: =D31/D7*1000 -> 11.908784 | E38: =E31/E7*1000 -> 12.462064 | F38: =F31/F7*1000 -> 14.926298 | G38: =G31/G7*1000 -> 11.153199 | H38: =H31/H7*1000 -> 11.499817 | I38: =I31/I7*1000 -> 10.755767 | J38: =J31/J7*1000 -> 10.874721 | K38: =K31/K7*1000 -> 11.049511 | ... P38: =P31/P7*1000 -> 10.518229
B39: 洗碗机折旧单台差额 | C39: 差额 | D39: =(D38-D36)*D7 -> 30627.136 | E39: =(E38-E36)*E7 -> 114116.65 | F39: =(F38-F36)*F7 -> 386856.01 | G39: =(G38-G36)*G7 -> -40064.928 | H39: =(H38-H36)*H7 -> 41352.859 | I39: =(I38-I36)*I7 -> -326780.48 | J39: =(J38-J36)*J7 -> -413868.48 | K39: =(K38-K36)*K7 -> -583295.37 | ... P39: =(P38-P36)*P7 -> -1.6505247e+08
A40: 洗碗机变动费用 | B40: 洗碗机变动费用 | C40: 同期 | D40: =D8-D26 -> 1155.4888 | E40: =E8-E26 -> 1111.6996 | F40: =F8-F26 -> 1263.8462 | G40: =G8-G26 -> 1040.5968 | H40: =H8-H26 -> 1286.987 | I40: =I8-I26 -> 1173.9 | J40: =J8-J26 -> 1058.4123 | K40: =K8-K26 -> 956.54553 | ... P40: =P8-P26 -> 13306.23
...

Sheet 26年洗碗机费用指标到月测算汇总表 
B1: 土耳其洗碗机费用指标统计
B2: 一、年度预测： 产量预算：年度预算56.5万台↑14%，实际截至到6月 24万台↓12%（大差） 单台预测：25年单台达成41.5欧，26年目标40欧，预测达成38.25欧，同比↓7.7%；额收益166万欧 三、6月达成： 订单量预测：6月同期2.9万台，预测5.3万台，实际5.3万台，较同期↑79% 单台预测：6月同期58.59欧，实际单台费用27.05欧，较同期下54%；额优化167万欧 6月累计单台：6月同期37.81欧，6月实际39.18欧，累计单台↑3.6欧，额恶化32万欧
A3: 费 | B3: 序号 | C3: / | D3: 1月份 | E3: 2月份 | F3: 3月份 | G3: 4月份 | H3: 5月份 | I3: 6月份 | J3: 7月份 | K3: 8月份 | L3: 9月份 | M3: 10月份 | N3: 11月份 | O3: 12月份 | P3: 年度
B4: 费率 | C4: 销售收入（26年预测） | D4: 11387.793 | E4: 11383.957 | F4: 11384.182 | G4: 10843.261 | H4: 8301.8079 | I4: 12020.11 | J4: 9489.0377 | K4: 8834.8314 | L4: 12125.496 | M4: 10955.642 | N4: 11601.048 | O4: 9179.1981 | P4: 127506.36
C5: 销售收入（25年实际） | D5: 11599.19 | E5: 10318.459 | F5: 10279.816 | G5: 10804.991 | H5: 11868.184 | I5: 6637.8974 | J5: 9550.8211 | K5: 7188.5794 | L5: 5817.7726 | M5: 5854.6235 | N5: 7485.28 | O5: 8923.716 | P5: 106138.64
C6: 单价（同期） | D6: 238.80897 | E6: 224.15352 | F6: 221.84897 | G6: 218.88846 | H6: 220.99255 | I6: 223.76947 | J6: 228.17739 | K6: 224.80468 | L6: 205.80772 | M6: 223.36513 | N6: 220 | O6: 212 | P6: 222
C7: 单价（实际） | D7: 225.66619 | E7: 225.66619 | F7: 225.66619 | G7: 225.66619 | H7: 225.66619 | I7: 225.66619 | J7: 225.66619 | K7: 225.66619 | L7: 225.66619 | M7: 225.66619 | N7: 225.66619 | O7: 225.66619 | P7: 225.66619
C8: 制造费用（26年预测） | D8: 1838.2556 | E8: 1852.3924 | F8: 1893.0365 | G8: 1849.6673 | H8: 1928.8688 | I8: 1870.4326 | J8: 1859.2351 | K8: 1842.1673 | L8: 1948.6868 | M8: 1894.9246 | N8: 1861.9628 | O8: 1947.1505 | P8: 22586.78
C9: 制造费用（25年实际） | D9: 1702.2213 | E9: 1632.2334 | F9: 1827.8999 | G9: 1591.5968 | H9: 1866.987 | I9: 1737.9 | J9: 1637.4123 | K9: 1533.5455 | L9: 1597.8553 | M9: 1443.0898 | N9: 1758.5061 | O9: 1502.3028 | P9: 19831.55
C10: 同期 | D10: 0.14675346 | E10: 0.15818577 | F10: 0.17781446 | G10: 0.147302 | H10: 0.15731025 | I10: 0.26181483 | J10: 0.17144205 | K10: 0.21333082 | L10: 0.2746507 | M10: 0.24648721 | N10: 0.23492856 | O10: 0.16834947 | P10: 0.18684571
C11: 目标 | D11: 0.16142334 | E11: 0.16271955 | F11: 0.16628656 | G11: 0.17058221 | H11: 0.23234323 | I11: 0.15560861 | J11: 0.19593505 | K11: 0.20851188 | L11: 0.16070986 | M11: 0.17296335 | N11: 0.16049954 | O11: 0.21212643 | P11: 0.17714238
C12: 26年 | D12: =D8/D4 -> 0.16142334 | E12: =E8/E4 -> 0.16271955 | F12: =F8/F4 -> 0.16628656 | G12: =G8/G4 -> 0.17058221 | H12: =H8/H4 -> 0.23234323 | I12: =I8/I4 -> 0.15560861 | J12: =J8/J4 -> 0.19593505 | K12: =K8/K4 -> 0.20851188 | ... P12: =P8/P4 -> 0.17714238
B13: 降幅 | D13: =(D10-D12)/D10 -> -0.09996281 | E13: =(E10-E12)/E10 -> -0.028661121 | F13: =(F10-F12)/F10 -> 0.064831052 | G13: =(G10-G12)/G10 -> -0.15804409 | H13: =(H10-H12)/H10 -> -0.47697446 | I13: =(I10-I12)/I10 -> 0.40565396 | J13: =(J10-J12)/J10 -> -0.14286464 | K13: =(K10-K12)/K10 -> 0.022589029 | ... P13: =(P10-P12)/P10 -> 0.051932324
B14: 完成率 | D14: =2-D12/D11 -> 1 | E14: =2-E12/E11 -> 1 | F14: =2-F12/F11 -> 1 | G14: =2-G12/G11 -> 1 | H14: =2-H12/H11 -> 1 | I14: =2-I12/I11 -> 1 | J14: =2-J12/J11 -> 1 | K14: =2-K12/K11 -> 1 | ... O14: =2-O12/O11 -> 1
B15: 费率（累计） | C15: 累计销售收入（26年预测） | D15: =D4 -> 11387.793 | E15: =D15+E4 -> 22771.75 | F15: =E15+F4 -> 34155.932 | G15: =F15+G4 -> 44999.193 | H15: =G15+H4 -> 53301.001 | I15: =H15+I4 -> 65321.11 | J15: =I15+J4 -> 74810.148 | K15: =J15+K4 -> 83644.98 | L15: =K15+L4 -> 95770.476 | ... O15: =N15+O4 -> 127506.36 | P15: =O15 -> 127506.36
C16: 累计销售收入（25年实际） | D16: =D5 -> 11599.19 | E16: =D16+E5 -> 21917.65 | F16: =E16+F5 -> 32197.465 | G16: =F16+G5 -> 43002.456 | H16: =G16+H5 -> 54870.64 | I16: =H16+I5 -> 61508.538 | J16: =I16+J5 -> 71059.359 | K16: =J16+K5 -> 78247.938 | L16: =K16+L5 -> 84065.711 | ... O16: =N16+O5 -> 106329.33 | P16: =O16 -> 106329.33
C17: 累计制造费用（26年预测） | D17: =D8 -> 1838.2556 | E17: =D17+E8 -> 3690.648 | F17: =E17+F8 -> 5583.6845 | G17: =F17+G8 -> 7433.3518 | H17: =G17+H8 -> 9362.2206 | I17: =H17+I8 -> 11232.653 | J17: =I17+J8 -> 13091.888 | K17: =J17+K8 -> 14934.056 | L17: =K17+L8 -> 16882.742 | ... O17: =N17+O8 -> 22586.78 | P17: =O17 -> 22586.78
C18: 累计制造费用（25年实际） | D18: =D9 -> 1702.2213 | E18: =D18+E9 -> 3334.4547 | F18: =E18+F9 -> 5162.3545 | G18: =F18+G9 -> 6753.9513 | H18: =G18+H9 -> 8620.9383 | I18: =H18+I9 -> 10358.838 | J18: =I18+J9 -> 11996.251 | K18: =J18+K9 -> 13529.796 | L18: =K18+L9 -> 15127.651 | ... O18: =N18+O9 -> 19831.55 | P18: =O18 -> 19831.55
C19: 同期 | D19: =D18/D16 -> 0.14675346 | E19: =E18/E16 -> 0.1521356 | F19: =F18/F16 -> 0.16033419 | G19: =G18/G16 -> 0.15705966 | H19: =H18/H16 -> 0.15711386 | I19: =I18/I16 -> 0.16841302 | J19: =J18/J16 -> 0.16882014 | K19: =K18/K16 -> 0.1729093 | ... P19: =P18/P16 -> 0.18651063
C20: 目标 | D20: 0.16142334 | E20: 0.16207134 | F20: 0.16347627 | G20: 0.16518856 | H20: 0.17564812 | I20: 0.17196054 | J20: 0.1750015 | K20: 0.17854097 | L20: 0.17628337 | M20: 0.17594257 | N20: 0.1744285 | O20: 0.17714238 | P20: 0.17714238
C21: 26年 | D21: =D17/D15 -> 0.16142334 | E21: =E17/E15 -> 0.16207134 | F21: =F17/F15 -> 0.16347627 | G21: =G17/G15 -> 0.16518856 | H21: =H17/H15 -> 0.17564812 | I21: =I17/I15 -> 0.17196054 | J21: =J17/J15 -> 0.1750015 | K21: =K17/K15 -> 0.17854097 | ... P21: =P17/P15 -> 0.17714238
B22: 降幅 | D22: =(D19-D21)/D19 -> -0.09996281 | E22: =(E19-E21)/E19 -> -0.065308465 | F22: =(F19-F21)/F19 -> -0.019597081 | G22: =(G19-G21)/G19 -> -0.05175674 | H22: =(H19-H21)/H19 -> -0.11796704 | I22: =(I19-I21)/I19 -> -0.021064411 | J22: =(J19-J21)/J19 -> -0.036615098 | K22: =(K19-K21)/K19 -> -0.032570075 | ... O22: =(O19-O21)/O19 -> 0.050229047
B23: 完成率 | D23: =2-D21/D20 -> 1 | E23: =2-E21/E20 -> 1 | F23: =2-F21/F20 -> 1 | G23: =2-G21/G20 -> 1 | H23: =2-H21/H20 -> 1 | I23: =2-I21/I20 -> 1 | J23: =2-J21/J20 -> 1 | K23: 0.06 | L23: =2-L21/L20 -> 1 | M23: =2-M21/M20 -> 1 | N23: =2-N21/N20 -> 1 | O23: =2-O21/O20 -> 1
B24: 单台 | C24: 同期 | D24: 35.046041 | E24: 35.45 | F24: 39.407954 | G24: 32.242707 | H24: 34.764394 | I24: 58.586165 | J24: 39.119199 | K24: 47.957767 | L24: 56.525234 | M24: 55.056648 | N24: 51.684284 | O24: 35.690087 | P24: =P41/P48*1000 -> 41.458596
C25: 目标 | D25: 36.427791 | E25: 36.72 | F25: 37.525254 | G25: 38.494637 | H25: 52.432012 | I25: 35.115602 | J25: 44.215917 | K25: 47.054083 | L25: 36.266783 | M25: 39.031981 | N25: 36.219319 | O25: 47.869763 | P25: =P42/P49*1000 -> 39.974605 | R25: =P24-P26 -> 3.2114947
C26: 26年 | D26: 37.546833 | E26: 41.11 | F26: 74.476709 | G26: 22.053802 | H26: =H39/H50*1000 -> 55.261326 | I26: =I39/I50*1000 -> 27.048161 | J26: =J39/J50*1000 -> 40.095297 | K26: =K39/K50*1000 -> 42.375277 | L26: =L39/L50*1000 -> 33.580508 | M26: =M39/M50*1000 -> 35.306481 | N26: =N39/N50*1000 -> 33.500829 | O26: =O39/O50*1000 -> 42.614252 | P26: =P43/P50*1000 -> 38.247101 | R26: =R25*P50 -> 1665982.2
B27: 当月单台完成率 | D27: =2-D26/D25 -> 0.96928055 | E27: =2-E26/E25 -> 0.88044662 | F27: =2-F26/F25 -> 0.015291021 | G27: =2-G26/G25 -> 1.4270942 | H27: =2-H26/H25 -> 0.94603841 | I27: =2-I26/I25 -> 1.2297395 | J27: =2-J26/J25 -> 1.0931931 | K27: =2-K26/K25 -> 1.0994346 | ... P27: =2-P26/P25 -> 1.0432151
B28: 目标同期优化率 | D28: =D25/D24-1 -> 0.039426701 | E28: =E25/E24-1 -> 0.035825106 | F28: =F25/F24-1 -> -0.047774611 | G28: =G25/G24-1 -> 0.19390214 | H28: =H25/H24-1 -> 0.50821015 | I28: =I25/I24-1 -> -0.40061614 | J28: =J25/J24-1 -> 0.13028688 | K28: =K25/K24-1 -> -0.018843342 | ... O28: =O25/O24-1 -> 0.34126216
B29: 当月单台同期优化率 | D29: =(D24-D26)/D24 -> -0.071357321 | E29: =(E24-E26)/E24 -> -0.1596615 | F29: =(F24-F26)/F24 -> -0.88989028 | G29: =(G24-G26)/G24 -> 0.3160065 | H29: =(H24-H26)/H24 -> -0.58959556 | I29: =(I24-I26)/I24 -> 0.53831829 | J29: =(J24-J26)/J24 -> -0.024951897 | K29: =(K24-K26)/K24 -> 0.1164043 | ... P29: =(P24-P26)/P24 -> 0.0774627 | R29: =7.9*P50 -> 4098172.4
B30: 当月费用额
B31: 单台（累计） | C31: 同期 | D31: =D41/D48*1000 -> 35.052271 | E31: =E41/E56*1000 -> 35.157209 | F31: =F41/F56*1000 -> 36.555067 | G31: =G41/G56*1000 -> 35.43703 | H31: =H41/H56*1000 -> 35.288985 | I31: =I41/I56*1000 -> 37.814272 | J31: =J41/J56*1000 -> 37.987382 | K31: =K41/K56*1000 -> 38.904855 | L31: =L41/L56*1000 -> 40.230385 | ... O31: =O41/O56*1000 -> 41.458596 | P31: =P41/P48*1000 -> 41.458596
C32: 目标 | D32: =D42/D57*1000 -> 36.427791 | E32: =E42/E57*1000 -> 36.572572 | F32: =F42/F57*1000 -> 36.889363 | G32: =G42/G57*1000 -> 37.276185 | H32: =H42/H57*1000 -> 39.636785 | I32: =I42/I57*1000 -> 38.804808 | J32: =J42/J57*1000 -> 39.491168 | K32: =K42/K57*1000 -> 40.289992 | ... N32: =N42/N57*1000 -> 39.362137 | O32: 39.975046 | P32: =O32 -> 39.975046
C33: 26年 | D33: =D43/D58*1000 -> 37.546833 | E33: =E43/E58*1000 -> 39.217927 | F33: =F43/F58*1000 -> 46.396974 | G33: =G43/G58*1000 -> 39.919587 | H33: =H43/H58*1000 -> 42.632061 | I33: =I43/I58*1000 -> 39.179647 | J33: =J43/J58*1000 -> 39.314599 | K33: =K43/K58*1000 -> 39.686948 | ... P33: =P43/P58*1000 -> 38.247101
B34: 累计单台完成率 | D34: =2-D33/D32 -> 0.96928055 | E34: =2-E33/E32 -> 0.92766833 | F34: =2-F33/F32 -> 0.74226687 | G34: =2-G33/G32 -> 0.92908604 | H34: =2-H33/H32 -> 0.92443191 | I34: =2-I33/I32 -> 0.9903404 | J34: =2-J33/J32 -> 1.0044711 | K34: =2-K33/K32 -> 1.0149676 | ... O34: =2-O33/O32 -> 1.0432256 | P34: =O34 -> 1.0432256
B35: 累计单台同期优化率 | D35: =(D31-D33)/D31 -> -0.071166926 | E35: =(E31-E33)/E31 -> -0.11550174 | F35: =(F31-F33)/F31 -> -0.26923512 | G35: =(G31-G33)/G31 -> -0.1264936 | H35: =(H31-H33)/H31 -> -0.20808408 | I35: =(I31-I33)/I31 -> -0.036107402 | J35: =(J31-J33)/J31 -> -0.03493838 | K35: =(K31-K33)/K31 -> -0.0201027 | ... P35: =(P31-P33)/P31 -> 0.0774627
B36: 累计费用额 | D36: =D43 -> 1778.218 | E36: =E43 -> 3527.7702 | F36: =F43 -> 5240.7702 | G36: =G43 -> 6141.5486 | H36: =H43 -> 7967.5486 | I36: =I43 -> 9406.1321 | J36: =J43 -> 11070.087 | K36: =K43 -> 12722.723 | ... O36: =O43 -> 19840.913
B37: 费用金额 | C37: 同期 | D37: 1702.4888 | E37: 1623.6996 | F37: 1825.8462 | G37: 1591.5968 | H37: 1866.987 | I37: 1737.9 | J37: 1637.4123 | K37: 1533.5455 | L37: 1597.8553 | M37: 1443.0898 | N37: 1758.5061 | O37: 1502.3028 | P37: 19821.23
C38: 目标 | D38: 1838.2556 | E38: 1852.3924 | F38: 1892.6678 | G38: 1849.6673 | H38: 1928.8688 | I38: 1870.4326 | J38: 1859.2351 | K38: 1842.1673 | L38: 1948.6868 | M38: 1894.9246 | N38: 1861.9628 | O38: 1947.1505 | P38: 22586.412
C39: 26年 | D39: 1778.218 | E39: 1749.5522 | F39: 1713 | G39: 900.77836 | H39: 1826 | I39: =洗碗机6月!I237 -> 1438.5835 | J39: 1663.9548 | K39: 1652.6359 | L39: 1816.2017 | M39: 1764.1942 | N39: 1739.899 | O39: 1797.8953 | P39: 21453.77
C40: 自制费用额 | D40: 111.76974 | E40: 111.76974 | F40: 111.76974 | G40: 48.384889 | H40: 48.384889 | I40: 48.384889 | J40: 45.368222 | K40: 45.368222 | L40: 51.743222 | M40: 77.276555 | N40: 77.276555 | O40: 68.92201
...

Sheet 洗碗机1月
A1: 总结：1月洗碗机单台制造费同比恶化2.43欧，同比恶化7%，额恶化12万欧 固定： 折旧单台恶化0.65欧，额差3.16万欧 变动： 6666021502、6666021503、6666021505、6666021506去年发生的总费用为1万欧元，今年发生的费用为8万欧元，单台恶化1.48 工资上涨：白领工资下降1%，蓝领工资上涨7%
A2: 维度 | B2: 指标 | C2: 25年实际 | D2: 26年预算 | E2: 预算差异 | F2: 26年实际 | G2: 实际比同期差异 | H2: 制造费差额 | I2: 差异原因
A4: 单 | B4: 产量 | C4: 48570 | D4: 50463 | E4: =D4-C4 -> 1893 | F4: 47360 | G4: =F4-C4 -> -1210 | I4: =(F4-D4)/D4 -> -0.061490597
A5: 时 | B5: 工作天数 | C5: 22 | D5: 20 | E5: =D5-C5 -> -2 | F5: 20 | G5: =F5-C5 -> -2
A6: 人 | B6: 直接人工 | C6: 218 | D6: 244 | E6: =D6-C6 -> 26 | F6: 237 | G6: =F6-C6 -> 19
B7: 人工工资 | C7: =E47/C6*1000 -> 1662.2265 | D7: =G47/D6*1000 -> 1650.6253 | E7: =D7-C7 -> -11.60119 | F7: =I47/F6*1000 -> 1509.3644 | G7: =F7-C7 -> -152.86208 | H7: =F7/C7-1 -> -0.091962246
B8: 间接人工 | C8: 87 | D8: 85 | E8: =D8-C8 -> -2 | F8: 85 | G8: =F8-C8 -> -2
B9: 间接人工工资 | C9: =E127/C8*1000 -> 1846.7721 | D9: =G127/D8*1000 -> 1841.488 | E9: =D9-C9 -> -5.2840483 | F9: =(I127+I124)/F8*1000 -> 2233.9256 | G9: =F9-C9 -> 387.15358 | H9: =F9/C9-1 -> 0.20963799
B10: 白领人数 | C10: 25 | D10: 27 | E10: =D10-C10 -> 2 | F10: 25 | G10: 0.1
B11: 白领人工工资 | C11: =(E130+E131)/C10*1000 -> 4248.7816 | D11: =(G130/D10*1000) -> 3384.9868 | E11: =D11-C11 -> -863.79476 | F11: =(I130+I131)/F10*1000 -> 3865.3176 | G11: =F11-C11 -> -383.464 | H11: =F11/C11-1 -> -0.090252697
A12: 效 | B12: UPPH | C12: =C4/C6/C5/7.5 -> 1.3502919 | D12: =D4/D6/D5/7.5 -> 1.3787705 | E12: =D12-C12 -> 0.028478582 | F12: =F4/F6/F5/7.5 -> 1.3322082 | G12: =F12-C12 -> -0.018083752
A13: 费 | B13: 单台制造费 | C13: =SUM(C14:C26) -> 35.046041 | D13: =SUM(D14:D26) -> 36.427791 | E13: =SUM(E14:E26) -> 1.3817498 | F13: =SUM(F14:F26) -> 37.48 | G13: =F13-C13 -> 2.4339586 | H13: =G13*$F$4 -> 115272.28
B14: 折旧 | C14: 11.25788 | D14: 11.443639 | E14: =D14-C14 -> 0.1857597 | F14: 11.91 | G14: =F14-C14 -> 0.65212028 | H14: =G14*$F$4 -> 30884.417
B15: 运营费 | C15: 0.97865619 | D15: 1.1529596 | E15: =D15-C15 -> 0.17430338 | F15: 1.26 | G15: =F15-C15 -> 0.28134381 | H15: =G15*$F$4 -> 13324.443
B16: 存货跌价准备 | C16: 0.051794898 | D16: 0.17894222 | E16: =D16-C16 -> 0.12714732 | F16: -0.55 | G16: =F16-C16 -> -0.6017949 | H16: =G16*$F$4 -> -28501.006
B17: 固定能源费 | C17: 0.14524655 | D17: 0.10814454 | E17: =D17-C17 -> -0.037102006 | F17: 0.1 | G17: =F17-C17 -> -0.045246546 | H17: =G17*$F$4 -> -2142.8764
B18: 间接人工成本-辅助人员 | C18: 4.2832239 | D18: 3.8592425 | E18: =D18-C18 -> -0.42398146 | F18: 4.99 | G18: =F18-C18 -> 0.70677606 | H18: =G18*$F$4 -> 33472.914
B19: 固定人工-白领 | C19: 2.7653736 | D19: 2.1120424 | E19: =D19-C19 -> -0.65333118 | F19: 2.43 | G19: =F19-C19 -> -0.33537358 | H19: =G19*$F$4 -> -15883.293
B20: 半固定-班车/工作服 | C20: 2.193911 | D20: 3.6270077 | E20: =D20-C20 -> 1.4330967 | F20: 3.47 | G20: =F20-C20 -> 1.276089 | H20: =G20*$F$4 -> 60435.576 | I20: 维修保养费用4个科目上升1.48
B21: 直接人工 | C21: 9.7168881 | D21: 9.6071653 | E21: =D21-C21 -> -0.1097228 | F21: 9.53 | G21: =F21-C21 -> -0.18688806 | H21: =G21*$F$4 -> -8851.0186
B22: 可回收废料 | C22: 0.47761771 | D22: 0.5438747 | E22: =D22-C22 -> 0.066256982 | F22: 0.38 | G22: =F22-C22 -> -0.097617714 | H22: =G22*$F$4 -> -4623.1749
B23: 生产耗用品 | C23: 0.25141257 | D23: 0.33153003 | E23: =D23-C23 -> 0.080117461 | F23: 0.2 | G23: =F23-C23 -> -0.051412571 | H23: =G23*$F$4 -> -2434.8994
B24: 废品回收 | C24: -1.1989953 | D24: -1.09399 | E24: =D24-C24 -> 0.1050053 | F24: -1.19 | G24: =F24-C24 -> 0.0089952853 | H24: =G24*$F$4 -> 426.01671
B25: 变动能源费 | C25: 0.52219925 | D25: 0.76326767 | E25: =D25-C25 -> 0.24106842 | F25: 0.46 | G25: =F25-C25 -> -0.062199255 | H25: =G25*$F$4 -> -2945.7567
B26: 园区分摊费用 | C26: 3.6008332 | D26: 3.7939652 | E26: =D26-C26 -> 0.19313194 | F26: 4.49 | G26: =F26-C26 -> 0.88916679 | H26: =G26*$F$4 -> 42110.939
B27: IT Expense-Internal Charge Out | C27: 2.0598917 | D27: 1.7973014 | E27: -0.1274777 | G27: =(F27/C27)-1 -> -1 | H27: =G27*$C$4 -> -48570
B28: Association dues | C28: 0.10364806 | D28: 0.12931195 | E28: 0.24760611 | G28: =(F28/C28)-1 -> -1 | H28: =G28*$C$4 -> -48570
B29: G&A | C29: 1.4372934 | D29: 1.8673518 | E29: 0.299214 | G29: =(F29/C29)-1 -> -1 | H29: =G29*$C$4 -> -48570
A30: 类型 | B30: 科目编号 | C30: 科目（英文） | D30: 科目（中文） | E30: K€ | F30: 同期台数 | G30: 46330 | H30: 预算台数 | I30: 50440 | J30: 实际台数 | K30: 42593
E31: 25年实际制造费 | F31: 25年实际单台 | G31: 26年预测制造费 | H31: 26年预测单台 | I31: 26年实际制造费 | J31: 26年实际单台 | K31: 同期与实际单台差 | L31: 26年预算与25年实际单台差 | M31: 26年实际与25年预算单台差 | N31: 与预算差异分析 | O31: 与同期差分析
A32: 折旧 | B32: 6666110101 | C32: 6666110101 Depreciation of buildings | D32: 建筑物折旧 | E32: 29.90899 | F32: 0.61579144 | G32: 32.511068 | H32: 0.64425556 | I32: 32.52614 | J32: 0.68678505 | K32: =J32-F32 -> 0.070993606 | L32: =H32-F32 -> 0.028464117 | M32: =J32-H32 -> 0.04252949
B33: 6666110106 | C33: 6666110106 Depreciation of R&D facilities | D33: 研发设施折旧 | E33: 0 | F33: 0 | G33: 0 | H33: 0 | I33: 0 | J33: 0 | K33: =J33-F33 -> 0 | L33: =H33-F33 -> 0 | M33: =J33-H33 -> 0
B34: 6666110107 | C34: 6666110107 Depreciation of mold | D34: 模具折旧 | E34: 210.86474 | F34: 4.3414606 | G34: 228.97844 | H34: 4.5375511 | I34: 224.42191 | J34: 4.7386383 | K34: =J34-F34 -> 0.39717773 | L34: =H34-F34 -> 0.19609052 | M34: =J34-H34 -> 0.20108721 | P34: 1.17
B35: 6666110110 | C35: 6666110110 Depreciation-Plant & Machinery | D35: 厂房及机械折旧 | E35: 288.50449 | F35: 5.9399731 | G35: 297.92456 | H35: 5.9038218 | I35: 295.75794 | J35: 6.2448889 | K35: =J35-F35 -> 0.30491588 | L35: =H35-F35 -> -0.036151294 | M35: =J35-H35 -> 0.34106718
B36: 6666110112 | C36: 6666110112 Depreciation of Furniture & Fixture | D36: 家具及装置折旧 | E36: 7.3326631 | F36: 0.15097103 | G36: 15.246977 | H36: 0.3021417 | I36: 8.94279 | J36: 0.1888258 | K36: =J36-F36 -> 0.037854769 | L36: =H36-F36 -> 0.15117066 | M36: =J36-H36 -> -0.1133159
B37: 6666110204 | C37: 6666110204 Amortization of license, trademarks and | D37: 许可证、商标及摊销 | E37: 0.058686667 | F37: 0.0012082904 | G37: 0.25252 | H37: 0.0050040624 | I37: 0.17412081 | J37: 0.0036765375 | K37: =J37-F37 -> 0.002468247 | L37: =H37-F37 -> 0.0037957719 | M37: =J37-H37 -> -0.0013275249
B38: 6666110207 | C38: 6666110207 Amortization of Software | D38: 软件摊销 | E38: 8.2948964 | F38: 0.1707823 | G38: 2.5668129 | H38: 0.050865246 | I38: 2.34991 | J38: 0.049618032 | K38: =J38-F38 -> -0.12116427 | L38: =H38-F38 -> -0.11991706 | M38: =J38-H38 -> -0.0012472143
B39: 6666110506 | C39: 6666110506 Amortization-Leasehold Improvement | D39: 租赁改良摊销 | E39: 1.164868 | F39: 0.023983282 | G39: 0 | H39: 0 | I39: 0 | J39: 0 | K39: =J39-F39 -> -0.023983282 | L39: =H39-F39 -> -0.023983282 | M39: =J39-H39 -> 0
B40: 6666110206 | C40: 6666110206 Amortization of Patents | D40: 专利摊销 | F40: 0 | H40: 0 | J40: 0 | K40: =J40-F40 -> 0 | L40: =H40-F40 -> 0 | M40: =J40-H40 -> 0
B41: FIX | C41: * CS_Depreciation | D41: * CS_折旧 | E41: 546.12934 | F41: 11.24417 | G41: 577.48038 | H41: 11.443639 | I41: 564.17281 | J41: 11.912433 | K41: =J41-F41 -> 0.66826268 | L41: =H41-F41 -> 0.19946944 | M41: =J41-H41 -> 0.46879325
...

Sheet 洗碗机2月
A1: 总结：2月洗碗机单台制造费同比恶化5.66欧，同比恶化16%，额恶化24万欧， 含直接人工和间接人工上涨12%（每人241欧总计7.1万欧），管理人员上涨5%（每人161欧总计0.3万欧） 固定：CP预算减少，产量↓8%，单台恶化1.2欧，额差5万欧 变动：恶化三项，单台恶化6.1欧，额差26万欧 集中发放直接员工离职补偿14万欧（同期没有） 集中发放间接员工离职补偿3万欧（同期没有） 集中发放员工福利差异8.5万欧（差异8.5万欧，其中5.1万欧为释放预提，3.4万欧为福利费谈判后上涨）
A2: 维度 | B2: 指标 | C2: 25年实际 | D2: 26年预算 | E2: 预算差异 | F2: 26年实际 | H2: 实际比同期差异 | I2: 制造费差额 | J2: 差异原因
A4: 单 | B4: 产量 | C4: 46039 | D4: 50450 | E4: 4420 | F4: 42593 | H4: -3437
A5: 时 | B5: 工作天数 | C5: 20 | D5: 20 | E5: 0 | F5: 20 | H5: 20
A6: 人 | B6: 直接人工人数 | C6: 218 | D6: 244 | E6: 26 | F6: 215 | H6: -3
B7: 直接人工平均工资 | C7: =E47/C6*1000 -> 1419.1073 | D7: =H47/D6*1000 -> 1788.3896 | E7: 574.15 | F7: =J47/F6*1000 -> 1293.0167 | H7: 555.86 | I7: =F7/C7-1 -> -0.088852053
B8: 间接人工人数 | C8: 85 | D8: 85 | E8: 0 | F8: 82 | H8: -3
B9: 间接人工平均工资 | C9: =E127/C8*1000 -> 1598.5866 | D9: =H127/D8*1000 -> 1970.9097 | E9: 552.94 | F9: =(J127+J124)/F8*1000 -> 1717.5341 | H9: 666.86 | I9: =F9/C9-1 -> 0.074407954
B10: 白领人数 | C10: 23 | D10: 27 | E10: 4 | F10: 22 | H10: -1
B11: 白领人工平均工资 | C11: =(E130+E131)/C10*1000 -> 4798.4057 | D11: =(H130/D10*1000) -> 3592.5642 | E11: -1162.64 | F11: =(J130+J131)/F10*1000 -> 4339.0205 | H11: -302.37 | I11: =F11/C11-1 -> -0.095737049
A12: 效 | B12: UPPH | C12: 1.41 | D12: 1.38 | E12: -0.03 | F12: 1.32 | H12: -0.09 | I12: =H12/C12
A13: 费 | B13: 单台制造费 | C13: 35.45 | D13: 36.72 | E13: 1.26 | F13: 41.11 | H13: 5.66 | I13: =H13*$C$4 -> 260580.74 | J13: 制造费用单台差异5.66
B14: 折旧 | C14: 11.13 | D14: 10.63 | E14: -0.49 | F14: 12.31 | G14: =F14*$F$4 -> 524319.83 | H14: 1.18 | I14: =H14*$F$4 -> 50259.74 | J14: 总额上升1.2万，产量下滑8%
B15: 运营费 | C15: 1.21 | D15: 1.16 | E15: -0.05 | F15: 1.16 | G15: =F15*$F$4 -> 49407.88 | H15: -0.05 | I15: =H15*$F$4 -> -2129.65
B16: 存货跌价准备 | C16: 0.05 | D16: 0.18 | E16: 0.13 | F16: 0.12 | G16: =F16*$F$4 -> 5111.16 | H16: 0.07 | I16: =H16*$F$4 -> 2981.51
B17: 固定能源费 | C17: 0.25 | D17: 0.11 | E17: -0.14 | F17: 0.1 | G17: =F17*$F$4 -> 4259.3 | H17: -0.15 | I17: =H17*$F$4 -> -6388.95
B18: 间接人工成本-辅助人员 | C18: 3.51 | D18: 4.11 | E18: 0.61 | F18: 4.94 | G18: =F18*$F$4 -> 210409.42 | H18: 1.43 | I18: =H18*$F$4 -> 60907.99 | J18: 辅助人员2人离职补偿，共计3万欧元，按同期可下降0.95
B19: 固定人工-白领 | C19: 2.68 | D19: 2.24 | E19: -0.44 | F19: 2.61 | G19: =F19*$F$4 -> 111167.73 | H19: -0.07 | I19: =H19*$F$4 -> -2981.51
B20: 半固定-班车/工作服 | C20: 3.34 | D20: 3.56 | E20: 0.22 | F20: 5.81 | G20: =F20*$F$4 -> 247465.33 | H20: 2.47 | I20: =H20*$F$4 -> 105204.71 | J20: 差异8.5万欧，其中5.1万欧为释放预提，3.4万欧为福利费谈判后上涨
B21: 直接人工 | C21: 7.46 | D21: 10.39 | E21: 2.93 | F21: 10.75 | G21: =F21*$F$4 -> 457874.75 | H21: 3.29 | I21: =H21*$F$4 -> 140130.97 | J21: 离职补偿本月集中发放共计14万欧元
B22: 可回收废料 | C22: 0.49 | D22: 0.54 | E22: 0.05 | F22: 0.34 | G22: =F22*$F$4 -> 14481.62 | H22: -0.15 | I22: =H22*$F$4 -> -6388.95
B23: 生产耗用品 | C23: 0.7 | D23: 0.33 | E23: -0.37 | F23: 0.25 | G23: =F23*$F$4 -> 10648.25 | H23: -0.34 | I23: =H23*$F$4 -> -14481.62
B24: 废品回收 | C24: -1.17 | D24: -1.1 | E24: 0.07 | F24: -1.31 | G24: =F24*$F$4 -> -55796.83 | H24: -0.14 | I24: =H24*$F$4 -> -5963.02
B25: 变动能源费 | C25: 0.51 | D25: 0.75 | E25: 0.24 | F25: 0.1 | G25: =F25*$F$4 -> 4259.3 | H25: -0.25 | I25: =H25*$F$4 -> -10648.25
B26: 园区分摊费用 | C26: 5.3 | D26: 3.8 | E26: -1.49 | F26: 3.67 | G26: =F26*$F$4 -> 156316.31 | H26: -1.63 | I26: =H26*$F$4 -> -69426.59
B27: IT Expense-Internal Charge Out | C27: 2.0598917 | D27: 1.7973014 | E27: -0.1274777 | G27: =F27*$F$4 -> 0 | H27: =(F27/C27)-1 -> -1
B28: Association dues | C28: 0.10364806 | D28: 0.12931195 | E28: 0.24760611 | G28: =F28*$F$4 -> 0 | H28: =(F28/C28)-1 -> -1
B29: G&A | C29: 1.4372934 | D29: 1.8673518 | E29: 0.299214 | G29: =F29*$F$4 -> 0 | H29: =(F29/C29)-1 -> -1
A30: 类型 | B30: 科目编号 | C30: 科目（英文） | D30: 科目（中文） | E30: K€ | F30: 同期台数 | H30: 46330 | I30: 预算台数 | J30: 50440 | K30: 42593
E31: 25年实际制造费 | F31: 25年实际单台 | H31: 26年预测制造费 | I31: 26年预测单台 | J31: 26年实际制造费 | K31: 同期与实际单台差 | L31: 26年预算与25年实际单台差 | M31: 26年实际与25年预算单台差 | N31: 与同期差分析 | O31: Budget-ACT VARIANCE Analysis
A32: 折旧 | B32: 6666110101 | C32: 6666110101 Depreciation of buildings | D32: 建筑物折旧 | E32: 27.05117 | F32: 0.58768564 | H32: 29.463954 | I32: 0.58402288 | J32: 29.47877 | K32: 0.69210363 | L32: 0.10441799 | M32: -0.0036627624
B33: 6666110106 | C33: 6666110106 Depreciation of R&D facilities | D33: 研发设施折旧 | E33: 0 | F33: 0 | H33: 0 | I33: 0 | J33: 0 | K33: 0 | L33: 0 | M33: 0
B34: 6666110107 | C34: 6666110107 Depreciation of mold | D34: 模具折旧 | E34: 208.59611 | F34: 4.5317426 | H34: 220.52585 | I34: 4.3711764 | J34: 216.09226 | K34: 5.0734219 | L34: 0.54167936 | M34: -0.16056618 | N34: 产量下滑8%，产量按同期单台可下降0.41 | P34: 1.17
B35: 6666110110 | C35: 6666110110 Depreciation-Plant & Machinery | D35: 厂房及机械折旧 | E35: 261.00381 | F35: 5.6702978 | H35: 269.49018 | I35: 5.3417281 | J35: 268.26628 | K35: 6.2983655 | L35: 0.62806761 | M35: -0.32856975 | N35: 产量下滑8%，产量按同期单台可下降0.52
B36: 6666110112 | C36: 6666110112 Depreciation of Furniture & Fixture | D36: 家具及装置折旧 | E36: 6.81703 | F36: 0.14809972 | H36: 14.298245 | I36: 0.28341418 | J36: 7.96256 | K36: 0.18694527 | L36: 0.038845555 | M36: 0.13531446
B37: 6666110204 | C37: 6666110204 Amortization of license, trademarks and | D37: 许可证、商标及摊销 | E37: 0.25251 | F37: 0.0054857701 | H37: 0.25251 | I37: 0.0050051536 | J37: 0.25251 | K37: 0.0059284389 | L37: 0.0004426688 | M37: -0.00048061653
B38: 6666110207 | C38: 6666110207 Amortization of Software | D38: 软件摊销 | E38: 7.67016 | F38: 0.16663393 | H38: 2.451265 | I38: 0.048588008 | J38: 2.34867 | K38: 0.05514216 | L38: -0.11149177 | M38: -0.11804593
B39: 6666110506 | C39: 6666110506 Amortization-Leasehold Improvement | D39: 租赁改良摊销 | E39: 0.663272 | F39: 0.014409559 | H39: 0 | I39: 0 | J39: 0 | K39: 0 | L39: -0.014409559 | M39: -0.014409559
B40: 6666110206 | C40: 6666110206 Amortization of Patents | D40: 专利摊销 | F40: 0 | I40: 0 | L40: 0 | M40: 0
B41: FIX | C41: * CS_Depreciation | D41: * CS_折旧 | E41: 512.05406 | F41: 11.124355 | H41: 536.48201 | I41: 10.633935 | J41: =SUM(J32:J40) -> 524.40105 | K41: 12.311907 | L41: 1.1875519 | M41: -0.49042033
...

Sheet 洗碗机3月
A1: 总结：3月实际洗碗机单台恶化35.1欧；额恶化80.64万欧 通胀影响，定单量下降负影响72万，通胀影响9.5万 固定：洗碗机单台↑12.5欧，累计恶化28万 变动：洗碗机单台↑22.7欧，累计恶化52万 恶化原因：CP预算减少，产量↓50%
A2: 维度 | B2: 指标 | C2: 25年实际 | D2: 26年预算 | E2: 预算差异 | F2: 26年实际 | H2: 实际比同期差异 | I2: 制造费差额 | J2: 差异原因
A4: 单 | B4: 产量 | C4: 46330 | D4: 50440 | E4: =D4-C4 -> 4110 | F4: 23002 | H4: =F4-C4 -> -23328 | I4: / | J4: 订单量下滑49%
A5: 时 | B5: 工作天数 | C5: 20 | D5: 20 | E5: =D5-C5 -> 0 | F5: 20 | H5: =F5-C5 -> 0
A6: 人 | B6: 直接人工 | C6: 218 | D6: 244 | E6: =D6-C6 -> 26 | F6: 135 | H6: =F6-C6 -> -83
B7: 人工工资 | C7: =E47/C6*1000 -> 1872.3222 | D7: =H47/D6*1000 -> 1806.4003 | E7: =D7-C7 -> -65.921906 | F7: =J47/F6*1000 -> 0 | H7: =F7-C7 -> -1872.3222
B8: 间接人工 | C8: 94 | D8: 85 | E8: =D8-C8 -> -9 | F8: 85 | H8: =F8-C8 -> -9
B9: 间接人工工资 | C9: =E127/C8*1000 -> 2018.0737 | D9: =H127/D8*1000 -> 2009.2296 | E9: =D9-C9 -> -8.8440953 | F9: =(J127+J124)/F8*1000 -> 0 | H9: =F9-C9 -> -2018.0737
B10: 白领人数 | C10: 22 | D10: 27 | E10: =D10-C10 -> 5 | F10: 27 | H10: =F10-C10 -> 5
B11: 白领人工工资 | C11: =(E130+E131)/C10*1000 -> 1437.7168 | D11: =(H130/D10*1000) -> 3259.9326 | E11: =D11-C11 -> 1822.2157 | F11: =(J130+J131)/F10*1000 -> 0 | H11: =F11-C11 -> -1437.7168
A12: 效 | B12: UPPH | C12: =C4/C6/C5/7.5 -> 1.4168196 | D12: =D4/D6/D5 -> 10.336066 | E12: =D12-C12 -> 8.919246 | F12: =F4/F6/F5/7.5 -> 1.1359012 | H12: =F12-C12 -> -0.28091834
A13: 费 | B13: 单台制造费 | C13: =SUM(C14:C26) -> 39.407954 | D13: =SUM(D14:D26) -> 37.525254 | E13: =D13-C13 -> -1.8826997 | F13: =SUM(F14:F26) -> 0.18215807 | G13: =F13*$F$4 -> 4190 | H13: =F13-C13 -> -39.225796 | I13: =H13*$F$4 -> -902271.76
B14: 折旧 | C14: 12.11794 | D14: 11.534082 | E14: =D14-C14 -> -0.58385812 | F14: =K41 -> 0 | G14: =F14*$F$4 -> 0 | H14: =F14-C14 -> -12.11794 | I14: =H14*$F$4 -> -278736.85 | J14: 订单量下滑49%
B15: 运营费 | C15: 0.94499169 | D15: 1.1446286 | E15: =D15-C15 -> 0.19963686 | F15: =K104 -> 0 | G15: =F15*$F$4 -> 0 | H15: =F15-C15 -> -0.94499169 | I15: =H15*$F$4 -> -21736.699 | J15: 订单量下滑49%
B16: 存货跌价准备 | C16: 0.044960399 | D16: 0.17238607 | E16: =D16-C16 -> 0.12742567 | F16: =K111 -> 0 | G16: =F16*$F$4 -> 0 | H16: =F16-C16 -> -0.044960399 | I16: =H16*$F$4 -> -1034.1791
B17: 固定能源费 | C17: =0.235451367157995-0.04 -> 0.19545137 | D17: 0.10997077 | E17: =D17-C17 -> -0.085480595 | F17: =K117 -> 0 | G17: =F17*$F$4 -> 0 | H17: =F17-C17 -> -0.19545137 | I17: =H17*$F$4 -> -4495.7723
B18: 间接人工成本-辅助人员 | C18: 5.3008343 | D18: 4.2015022 | E18: =D18-C18 -> -1.0993321 | F18: =K128 -> 0 | G18: =F18*$F$4 -> 0 | H18: =F18-C18 -> -5.3008343 | I18: =H18*$F$4 -> -121929.79 | J18: 订单量下滑49%
B19: 固定人工-白领 | C19: 0.75709325 | D19: 2.0346606 | E19: =D19-C19 -> 1.2775674 | F19: =K136 -> 0 | G19: =F19*$F$4 -> 0 | H19: =F19-C19 -> -0.75709325 | I19: =H19*$F$4 -> -17414.659
B20: 半固定-班车/工作服 | C20: 3.4692196 | D20: 3.5026887 | E20: =D20-C20 -> 0.033469062 | F20: =K149 -> 0 | G20: =F20*$F$4 -> 0 | H20: =F20-C20 -> -3.4692196 | I20: =H20*$F$4 -> -79798.99 | L20: =K20/G13 -> 0
B21: 直接人工 | C21: 11.161989 | D21: 10.493562 | E21: =D21-C21 -> -0.66842713 | F21: =K50 -> 0 | G21: =F21*$F$4 -> 0 | H21: =F21-C21 -> -11.161989 | I21: =H21*$F$4 -> -256748.06
B22: 可回收废料 | C22: 0.49416212 | D22: 0.54404719 | E22: =D22-C22 -> 0.049885077 | F22: =K55 -> 0 | G22: =F22*$F$4 -> 0 | H22: =F22-C22 -> -0.49416212 | I22: =H22*$F$4 -> -11366.717
B23: 生产耗用品 | C23: 0.77141097 | D23: 0.33163518 | E23: =D23-C23 -> -0.43977579 | F23: =K109 -> 0 | G23: =F23*$F$4 -> 0 | H23: =F23-C23 -> -0.77141097 | I23: =H23*$F$4 -> -17743.995
B24: 废品回收 | C24: -1.2469823 | D24: -1.1002428 | E24: =D24-C24 -> 0.14673953 | F24: =K113 -> 0 | G24: =F24*$F$4 -> 0 | H24: =F24-C24 -> 1.2469823 | I24: =H24*$F$4 -> 28683.087
B25: 变动能源费 | C25: 0.66386754 | D25: 0.7521668 | E25: =D25-C25 -> 0.088299265 | F25: =K120 -> 0.18215807 | G25: =F25*$F$4 -> 4190 | H25: =F25-C25 -> -0.48170946 | I25: =H25*$F$4 -> -11080.281
B26: 园区分摊费用 | C26: 4.7330166 | D26: 3.8041678 | E26: =D26-C26 -> -0.92884877 | F26: =K221 -> 0 | G26: =F26*$F$4 -> 0 | H26: =F26-C26 -> -4.7330166 | I26: =H26*$F$4 -> -108868.85 | J26: 订单量下滑49%
B27: IT Expense-Internal Charge Out | C27: 2.0598917 | D27: 1.7973014 | E27: -0.1274777 | H27: =(F27/C27)-1 -> -1 | J27: =H27-#REF! -> #REF!
B28: Association dues | C28: 0.10364806 | D28: 0.12931195 | E28: 0.24760611 | H28: =(F28/C28)-1 -> -1 | J28: =H28-#REF! -> #REF!
B29: G&A | C29: 1.4372934 | D29: 1.8673518 | E29: 0.299214 | H29: =(F29/C29)-1 -> -1 | J29: =H29-#REF! -> #REF!
A30: 类型 | C30: 科目（英文） | D30: 科目（中文） | E30: K€ | F30: 同期台数 | H30: 46330 | I30: 预算台数 | J30: 50440 | K30: 实际台数 | L30: 23002
E31: 25年实际制造费 | F31: 25年实际单台 | H31: 26年预测制造费 | I31: 26年预测单台 | J31: 26年实际制造费 | K31: 26年实际单台 | L31: 同期与实际单台差 | M31: 实际与预算的差 | N31: 与同期差分析
A32: 折旧 | B32: 6666110101 | C32: 6666110101 Depreciation of buildings | D32: 建筑物折旧 | E32: 29.88156 | F32: 0.64497216 | H32: 32.511138 | I32: =H32/$J$30*1000 -> 0.64455072 | K32: =J32/$F$4*1000 -> 0 | L32: =K32-F32 -> -0.64497216 | M32: =K32-I32 -> -0.64455072
B33: 6666110106 | C33: 6666110106 Depreciation of R&D facilities | D33: 研发设施折旧 | E33: 0 | F33: 0 | H33: 0 | I33: =H33/$J$30*1000 -> 0 | K33: =J33/$F$4*1000 -> 0 | L33: =K33-F33 -> 0 | M33: =K33-I33 -> 0
B34: 6666110107 | C34: 6666110107 Depreciation of mold | D34: 模具折旧 | E34: 222.76497 | F34: 4.808223 | H34: 229.95889 | I34: =H34/$J$30*1000 -> 4.5590581 | K34: =J34/$F$4*1000 -> 0 | L34: =K34-F34 -> -4.808223 | M34: =K34-I34 -> -4.5590581
B35: 6666110110 | C35: 6666110110 Depreciation-Plant & Machinery | D35: 厂房及机械折旧 | E35: 290.93886 | F35: 6.2797077 | H35: 301.0103 | I35: =H35/$J$30*1000 -> 5.9676903 | K35: =J35/$F$4*1000 -> 0 | L35: =K35-F35 -> -6.2797077 | M35: =K35-I35 -> -5.9676903
B36: 6666110112 | C36: 6666110112 Depreciation of Furniture & Fixture | D36: 家具及装置折旧 | E36: 8.46919 | F36: 0.18280142 | H36: 15.560153 | I36: =H36/$J$30*1000 -> 0.30848837 | K36: =J36/$F$4*1000 -> 0 | L36: =K36-F36 -> -0.18280142 | M36: =K36-I36 -> -0.30848837
B37: 6666110204 | C37: 6666110204 Amortization of license, trademarks and | D37: 许可证、商标及摊销 | E37: 0.25252 | F37: 0.0054504641 | H37: 0.25252 | I37: =H37/$J$30*1000 -> 0.0050063442 | K37: =J37/$F$4*1000 -> 0 | L37: =K37-F37 -> -0.0054504641 | M37: =K37-I37 -> -0.0050063442
B38: 6666110207 | C38: 6666110207 Amortization of Software | D38: 软件摊销 | E38: 8.28781 | F38: 0.17888647 | H38: 2.5668229 | I38: =H38/$J$30*1000 -> 0.050888639 | K38: =J38/$F$4*1000 -> 0 | L38: =K38-F38 -> -0.17888647 | M38: =K38-I38 -> -0.050888639
B39: 6666110506 | C39: 6666110506 Amortization-Leasehold Improvement | D39: 租赁改良摊销 | E39: 0.663272 | F39: 0.014316253 | H39: 0 | I39: =H39/$J$30*1000 -> 0 | K39: =J39/$F$4*1000 -> 0 | L39: =K39-F39 -> -0.014316253 | M39: =K39-I39 -> 0
B40: 6666110206 | C40: 6666110206 Amortization of Patents | D40: 专利摊销 | F40: 0 | I40: =H40/$J$30*1000 -> 0 | K40: =J40/$F$4*1000 -> 0 | L40: =K40-F40 -> 0 | M40: =K40-I40 -> 0
B41: FIX | C41: * CS_Depreciation | D41: * CS_折旧 | E41: =SUM(E32:E40) -> 561.25818 | F41: 12.114357 | H41: =SUM(H32:H40) -> 581.85982 | I41: =H41/$J$30*1000 -> 11.535682 | J41: =SUM(J32:J40) -> 0 | K41: =J41/$F$4*1000 -> 0 | L41: =K41-F41 -> -12.114357 | M41: =SUM(M32:M40) -> -11.535682
...

Sheet 洗碗机4月
B1: 1月费用总结： ①单：1月同期35欧元/台，订单量4.86万台，预测单台费用36.4欧元/台，较同期↑3.9%；实际37.48欧元/台，较同期↑6% 共梳理出8个问题
A2: 总结：4月洗碗机单台下降10.19欧；降费41.6万欧 上涨因素：25万欧（定单量下降恶化15万欧，通胀恶化10万欧），下降因素：降费项目59万欧_x000b_固定：洗碗机4月折旧期限延长降费53万，订单量下降0.9万，负影响10万 变动：恶化4项，优化1项 1.存货跌价准备释放预提（超期库存钢卷加工成本成品）-18万欧 2.固定人工同期释放预提-4.19万欧 3.物耗：10万欧的钢卷制成半成品料废=2.6万 4.生产耗用：①钢卷半成品呆滞-6.6万欧 ② 一次性购买了5.6.7三个月的oil预防战争带来的涨价-4万欧 _x000b_
A3: 维度 | B3: 指标 | C3: 25年实际 | D3: 26年预算 | E3: 预算差异 | F3: 26年实际 | G3: 实际比同期差异 | I3: 制造费差额 | J3: 差异原因
A5: 单 | B5: 产量 | C5: 49360 | D5: 48050 | E5: =D5-C5 -> -1310 | F5: 40893 | G5: =F5-C5 -> -8467 | I5: /
A6: 时 | B6: 工作天数 | C6: 21 | D6: 19 | E6: =D6-C6 -> -2 | F6: 21 | G6: =F6-C6 -> 0
A7: 人 | B7: 直接人工 | C7: 218 | D7: 244 | E7: =D7-C7 -> 26 | F7: 222 | G7: =F7-C7 -> 4
B8: 直接人工工资 | C8: =E51/C7*1000 -> 1571.818 | D8: =G51/D7*1000 -> 1737.4776 | E8: =D8-C8 -> 165.65955 | F8: =J51/F7*1000 -> 0 | G8: =F8-C8 -> -1571.818
B9: 间接人工 | C9: 93 | D9: 85 | E9: =D9-C9 -> -8 | F9: 79 | G9: =F9-C9 -> -14
B10: 间接人工工资 | C10: =E131/C9*1000 -> 1607.3939 | D10: =G131/D9*1000 -> 1935.1706 | E10: =D10-C10 -> 327.77671 | F10: =G131/F9*1000 -> 2082.1456 | G10: =F10-C10 -> 474.75169
B11: 白领人数 | C11: 23 | D11: 27 | E11: =D11-C11 -> 4 | F11: 25 | G11: =F11-C11 -> 2
B12: 白领人工工资 | C12: =E134/C11*1000 -> 3754.4496 | D12: =G134/D11*1000 -> 3320.6683 | E12: =D12-C12 -> -433.78127 | F12: =G134/F11*1000 -> 3586.3218 | G12: =F12-C12 -> -168.1278
B13: 一线加辅助 | C13: =C7+C9 -> 311 | F13: =F7+F9 -> 301
B14: 工资 | C14: =E51+E131 -> 492.14396 | F14: =G51+G131 -> 588.43403
B15: 蓝领工资4月 | C15: =C14/C13*1000 -> 1582.4565 | F15: =F14/F13*1000 -> 1954.9303
A16: 效 | B16: UPPH | C16: =C5/C6/C7/7.5 -> 1.4376001 | D16: =D5/D6/D7/7.5 -> 1.3819385 | E16: =D16-C16 -> -0.055661664 | F16: =F5/F6/F7/7.5 -> 1.169541 | G16: =F16-C16 -> -0.26805915
A17: 费 | B17: 单台制造费 | C17: =SUM(C18:C30) -> 32.242707 | D17: =SUM(D18:D30) -> 38.494637 | E17: =D17-C17 -> 6.2519298 | F17: =SUM(F18:F30) -> 4.7344333 | G17: =F17-C17 -> -27.508274 | I17: =G17*$F$5 -> -1124895.8
B18: 折旧 | C18: 11.15487 | D18: 11.825835 | E18: =D18-C18 -> 0.67096456 | F18: =K45 -> 0 | G18: =F18-C18 -> -11.15487 | H18: =G18*$F$5 -> -456156.1 | I18: =G18*$F$5 -> -456156.1
B19: 运营费 | C19: 0.82253246 | D19: 1.187901 | E19: =D19-C19 -> 0.36536851 | F19: =K108 -> -0.00097816252 | G19: =F19-C19 -> -0.82351063 | H19: =G19*$F$5 -> -33675.82 | I19: =G19*$F$5 -> -33675.82 | J19: 清洁及安保团队月均降费8千欧-去年延续项目
B20: 存货跌价准备 | C20: 0.042204283 | D20: 0.17831098 | E20: =D20-C20 -> 0.1361067 | F20: =K115 -> 0 | G20: =F20-C20 -> -0.042204283 | H20: =G20*$F$5 -> -1725.8597 | I20: =G20*$F$5 -> -1725.8597 | J20: 为了消耗多余钢卷，把钢卷做成了半成品，冲减了3月的计提
B21: 固定能源费 | C21: 0.11169154 | D21: 0.1097176 | E21: =D21-C21 -> -0.0019739369 | F21: =K121 -> 0.09316998 | G21: =F21-C21 -> -0.018521559 | H21: =G21*$F$5 -> -757.40213 | I21: =G21*$F$5 -> -757.40213
B22: 间接人工成本-辅助人员 | C22: 4.2614578 | D22: 4.2601306 | E22: =D22-C22 -> -0.0013272011 | F22: =K132 -> 0 | G22: =F22-C22 -> -4.2614578 | H22: =G22*$F$5 -> -174263.79 | I22: =G22*$F$5 -> -174263.79
B23: 固定人工-白领 | C23: 1.1438671 | D23: 2.1712517 | E23: =D23-C23 -> 1.0273847 | F23: =K140 -> 0 | G23: =F23-C23 -> -1.1438671 | H23: =G23*$F$5 -> -46776.156 | I23: =G23*$F$5 -> -46776.156 | J23: 固定人工同期释放预提4.19万欧
B24: 半固定-班车/工作服 | C24: 2.5605976 | D24: 3.6878066 | E24: =D24-C24 -> 1.127209 | F24: =K153 -> 2.1089184 | G24: =F24-C24 -> -0.45167922 | H24: =G24*$F$5 -> -18470.518 | I24: =G24*$F$5 -> -18470.518
B25: 直接人工 | C25: 9.5030898 | D25: 10.602259 | E25: =D25-C25 -> 1.0991691 | F25: =K54 -> 0 | G25: =F25-C25 -> -9.5030898 | H25: =G25*$F$5 -> -388609.85 | I25: =G25*$F$5 -> -388609.85
B26: 可回收废料 | C26: 0.45784677 | D26: 0.40211803 | E26: =D26-C26 -> -0.055728738 | F26: 1.26 | G26: =F26-C26 -> 0.80215323 | H26: =G26*$F$5 -> 32802.452 | I26: =G26*$F$5 -> 32802.452 | J26: 钢卷制造成半成品产生了26千欧的废料
B27: 生产耗用品 | C27: -0.11774365 | D27: 0.33077003 | E27: =D27-C27 -> 0.44851369 | F27: =K113 -> 0 | G27: =F27-C27 -> 0.11774365 | H27: =G27*$F$5 -> 4814.8912 | I27: =G27*$F$5 -> 4814.8912 | J27: 一次性购买了5.6.7三个月的oil预防战争带来的涨价-4万欧 原材料库存损失此从17万调整至6.6万
B28: 废品回收 | C28: -1.5203565 | D28: -0.99579161 | E28: =D28-C28 -> 0.52456493 | F28: =K117 -> 0 | G28: =F28-C28 -> 1.5203565 | H28: =G28*$F$5 -> 62171.94 | I28: =G28*$F$5 -> 62171.94
B29: 变动能源费 | C29: 0.55576788 | D29: 0.74367454 | E29: =D29-C29 -> 0.18790666 | F29: =K124 -> 0.68642555 | G29: =F29-C29 -> 0.13065767 | H29: =G29*$F$5 -> 5342.984 | I29: =G29*$F$5 -> 5342.984
B30: 园区分摊费用 | C30: 3.2668823 | D30: 3.9906542 | E30: =D30-C30 -> 0.72377188 | F30: =K224 -> 0.58689751 | G30: =F30-C30 -> -2.6799848 | H30: =G30*$F$5 -> -109592.62 | I30: =G30*$F$5 -> -109592.62 | J30: 产量下降17%
B31: IT Expense-Internal Charge Out | C31: 2.0266765 | D31: 0.13958524 | E31: -0.1274777 | G31: =(F31/C31)-1 -> -1 | I31: =#REF!/$C$5 -> #REF!
B32: Association dues | C32: 0.10143468 | D32: 1.9635097 | E32: 0.24760611 | G32: =(F32/C32)-1 -> -1 | I32: =#REF!/$C$5 -> #REF!
B33: G&A | C33: 1.1387711 | D33: 1.8673518 | E33: 0.299214 | G33: =(F33/C33)-1 -> -1 | I33: =#REF!/$C$5 -> #REF!
A34: 类型 | B34: 科目编号 | C34: 科目（英文） | D34: 科目（中文） | E34: K€ | F34: 同期台数 | G34: 46330 | I34: 预算台数 | J34: 23500 | K34: 实际台数 | L34: 40893
E35: 25年实际制造费 | F35: 25年实际单台 | G35: 26年预测制造费 | I35: 26年预测单台 | J35: 26年实际制造费 | K35: 26年实际单台 | L35: 预算与实际单台差 | M35: 与同期差分析
A36: 折旧 | B36: 6666110101 | C36: 6666110101 Depreciation of buildings | D36: 建筑物折旧 | E36: 28.96203 | F36: 0.58675101 | G36: 31.49535 | I36: 0.65547035 | K36: =J36/$L$34*1000 -> 0
B37: 6666110106 | C37: 6666110106 Depreciation of R&D facilities | D37: 研发设施折旧 | E37: 0 | F37: 0 | G37: 0 | I37: 0 | K37: =J37/$L$34*1000 -> 0
B38: 6666110107 | C38: 6666110107 Depreciation of mold | D38: 模具折旧 | E38: 221.08877 | F38: 4.479108 | G38: 226.93983 | I38: 4.7229934 | K38: =J38/$L$34*1000 -> 0 | N38: 1.17
B39: 6666110110 | C39: 6666110110 Depreciation-Plant & Machinery | D39: 厂房及机械折旧 | E39: 284.06253 | F39: 5.7549135 | G39: 291.77164 | I39: 6.0722506 | K39: =J39/$L$34*1000 -> 0
B40: 6666110112 | C40: 6666110112 Depreciation of Furniture & Fixture | D40: 家具及装置折旧 | E40: 8.46194 | F40: 0.17143314 | G40: 15.243714 | I40: 0.31724691 | K40: =J40/$L$34*1000 -> 0
B41: 6666110204 | C41: 6666110204 Amortization of license, trademarks and | D41: 许可证、商标及摊销 | E41: 0.25252 | F41: 0.0051158833 | G41: 0.25252 | I41: 0.005255359 | K41: =J41/$L$34*1000 -> 0
...

Sheet 洗碗机5月
B1: 1月费用总结： ①单：1月同期35欧元/台，订单量4.86万台，预测单台费用36.4欧元/台，较同期↑3.9%；实际37.48欧元/台，较同期↑6% 共梳理出8个问题
A2: 5月费用实际：_x000b_①单台：5月实际55.28欧，5月同期30.17欧。较同期↑20.52欧，恶化68万。_x000b_②主要影响：人工工资上涨及通胀影响约11万欧；_x000b_③扣除影响后：单台↑17.20欧，恶化57万欧 ④固定费用异常：折旧整体降费15万，单台恶化2.33欧，影响7.68万欧，原因：产量下降38%,假期错月，次月补差 ⑤变动费用异常：蓝领直接员工工资与预算差异5.8万欧，原因： 1. 制造费影响：加班费未预测，+15.0。 2. 单价/价格影响：节日福利科目预测时人工录入错误。，+30.0。 3. 单价/价格影响：薪资结构影响，+6.0。 4. 单价/价格影响：还未休年假计提，+5.5。 5. 单价/价格影响：离职补偿金，+1.5。 库存跌价准备-原材料与预算差异3.8万欧，原因： 1.Super-entry 项目转产青岛，相关项目零件库龄风险增加：+65K。 2.其他活跃物料风险下降：-27K。 _x000b_
A3: 预测和实际的差（不考虑产量因素）： 总费用实际与4＋8预测差异13.2万欧 1,折旧费用：差异-2.5万欧 2.变动费用：①直接人工：差异5.8万欧 ②生产耗用：差异1.3万欧-具体哪个科目未知 ③变动能源：差异1.0万欧 ②存货跌价准备：差异3.8万欧 3.园区分摊费用：① 5601050100 非经营费用-其他：差异5.3万欧
A4: 维度 | B4: 指标 | C4: 25年实际 | D4: 26年预算 | E4: 26年实际 | F4: 实际比同期差异 | G4: 制造费差额 | H4: 差异原因
A6: 单 | B6: 产量 | C6: 53704 | D6: 36788 | E6: 33043 | F6: =E6-C6 -> -20661
A7: 时 | B7: 工作天数 | C7: 21 | D7: 14 | E7: 21 | F7: =IF(E7="","",E7-C7) -> 0 | I7: =110000/E6 -> 3.3289956
A8: 人 | B8: 直接人工 | C8: 226 | D8: 247 | E8: 164 | F8: -62
B9: 直接人工工资 | C9: =E46/C8*1000 -> 1638.1892 | D9: =G46/D8*1000 -> 1948.6038 | E9: 2918.5846 | F9: 1280.3954
B10: 间接人工 | C10: 93 | D10: 85 | E10: 75 | F10: -18
B11: 间接人工工资 | C11: =E126/C10*1000 -> 1818.4072 | D11: =G126/D10*1000 -> 2196.4172 | E11: 3303.7415 | F11: 1485.3343
B12: 白领人数 | C12: 23 | D12: 27 | E12: 24.67 | F12: 1.67
B13: 白领人工工资 | C13: =E129/C12*1000 -> 2829.583 | D13: =G129/D12*1000 -> 3529.4159 | E13: 4360.4066 | F13: 1530.8235
A14: 效 | B14: UPPH | C14: =C6/C7/(C8+C10)/7.5 -> 1.0688959 | D14: =D6/D7/(D8+D10)/7.5 -> 1.0553069 | E14: =E6/E7/(E8+E10)/7.5 -> 0.87781098 | F14: =IF(E14="","",E14-C14) -> -0.19108487
A15: 费 | B15: 单台制造费 | C15: =SUM(C16:C28) -> 34.764394 | D15: =SUM(D16:D28) -> 52.432012 | E15: =SUM(E16:E28) -> 55.281223 | F15: =E15-C15 -> 20.516829 | G15: =F15*$E$6 -> 677937.58
B16: 折旧 | C16: 10.791543 | D16: 15.772406 | E16: =$J$40 -> 13.113671 | F16: =E16-C16 -> 2.3221282 | G16: =F16*$E$6 -> 76730.081 | H16: =E16*E6 -> 433315.02 | I16: =H16/C6 -> 8.06858
B17: 运营费 | C17: 0.70691531 | D17: 1.5337617 | E17: =$J$103 -> 1.1906613 | F17: =E17-C17 -> 0.48374595 | G17: =F17*$E$6 -> 15984.417 | H17: =E16-I16 -> 5.0450907 | I17: =H17*E6 -> 166704.93
B18: 存货跌价准备 | C18: 0.038792827 | D18: 0.22945591 | E18: =$J$110 -> 1.3927912 | F18: =E18-C18 -> 1.3539984 | G18: =F18*$E$6 -> 44740.169
B19: 固定能源费 | C19: 0.1248583 | D19: 0.095942022 | E19: =$J$116 -> 0.04419635 | F19: =E19-C19 -> -0.080661947 | G19: =F19*$E$6 -> -2665.3127
B20: 间接人工成本-辅助人员 | C20: 4.4930908 | D20: 6.2108564 | E20: =$J$127 -> 7.4987324 | F20: =E20-C20 -> 3.0056416 | G20: =F20*$E$6 -> 99315.415
B21: 固定人工-白领 | C21: 1.5134612 | D21: 3.0107146 | E21: =$J$135 -> 3.2554922 | F21: =E21-C21 -> 1.742031 | G21: =F21*$E$6 -> 57561.932
B22: 半固定-班车/工作服 | C22: 2.5109569 | D22: 4.2326322 | E22: =$J$148 -> 5.0600651 | F22: =E22-C22 -> 2.5491082 | G22: =F22*$E$6 -> 84230.181
B23: 直接人工 | C23: 10.483577 | D23: 15.731221 | E23: =$J$49 -> 14.485606 | F23: =E23-C23 -> 4.0020287 | G23: =F23*$E$6 -> 132239.03
B24: 可回收废料 | C24: 0.52579249 | D24: 0.3955878 | E24: =$J$54 -> 0.48679599 | F24: =E24-C24 -> -0.038996499 | G24: =F24*$E$6 -> -1288.5613
B25: 生产耗用品 | C25: 0.33064148 | D25: 0.3183375 | E25: =$J$108 -> 0.7296211 | F25: =E25-C25 -> 0.39897962 | G25: =F25*$E$6 -> 13183.484
B26: 废品回收 | C26: -1.163369 | D26: -0.98422491 | E26: =$J$112 -> -1.0926626 | F26: =E26-C26 -> 0.070706432 | G26: =F26*$E$6 -> 2336.3526
B27: 变动能源费 | C27: 0.74202238 | D27: 0.65296291 | E27: =$J$119 -> 0.95746815 | F27: =E27-C27 -> 0.21544577 | G27: =F27*$E$6 -> 7118.9744
B28: 园区分摊费用 | C28: 3.6661115 | D28: 5.2323577 | E28: =$J$219 -> 8.1587852 | F28: =E28-C28 -> 4.4926738 | G28: =F28*$E$6 -> 148451.42
A29: 类型 | B29: 科目编号 | C29: 科目（英文） | D29: 科目（中文） | E29: K€ | F29: 同期台数 | G29: 46330 | H29: 预算台数 | I29: 23500 | J29: 实际台数 | K29: 33043 | N29: 4＋8预测产量 | O29: 36000
E30: 25年实际制造费 | F30: 25年实际单台 | G30: 26年预算制造费 | H30: 26年预算单台 | I30: 26年实际制造费 | J30: 26年实际单台 | K30: 同期与实际单台差 | L30: 预算与实际单台差 | M30: 与同期差分析 | N30: 26年预测制造费 | O30: 26年预测单台 | P30: 26年预测单台 | Q30: 费用差 | R30: 预测与实际单台差
A31: 折旧 | B31: 6666110101 | C31: 6666110101 Depreciation of buildings | D31: 建筑物折旧 | E31: 30.081668 | F31: 0.56018004 | G31: 32.511052 | H31: 0.88393289 | I31: 31.88331 | J31: 0.96490361 | K31: =J31-F31 -> 0.40472357 | L31: 0.08097072 | N31: 449.59836 | O31: =N31*1000/$O$29 -> 12.488843 | P31: =O31 -> 12.488843 | R31: =J31-P31 -> -11.52394
B32: 6666110106 | C32: 6666110106 Depreciation of R&D facilities | D32: 研发设施折旧 | E32: 0 | F32: 0 | G32: 0 | H32: 0 | I32: 0 | J32: 0 | K32: =J32-F32 -> 0 | L32: 0 | N32: 0 | O32: =N32*1000/$O$29 -> 0 | P32: =O32 -> 0 | R32: =J32-P32 -> 0
B33: 6666110107 | C33: 6666110107 Depreciation of mold | D33: 模具折旧 | E33: 230.92979 | F33: 4.3003685 | G33: 230.14195 | H33: 6.2572581 | I33: 163.43183 | J33: 4.9460349 | K33: =J33-F33 -> 0.64566641 | L33: -1.3112232 | M33: =K33*$K$29 -> 21334.755 | N33: 2.22095 | O33: =N33*1000/$O$29 -> 0.061693056 | P33: =O33 -> 0.061693056 | R33: =J33-P33 -> 4.8843418
B34: 6666110110 | C34: 6666110110 Depreciation-Plant & Machinery | D34: 厂房及机械折旧 | E34: 299.32499 | F34: 5.5740222 | G34: 300.83235 | H34: 8.1792374 | I34: 232.99299 | J34: 7.0512057 | K34: =J34-F34 -> 1.4771835 | L34: -1.1280317 | M34: =K34*$K$29 -> 48810.576 | N34: 4.4154389 | O34: =N34*1000/$O$29 -> 0.12265108 | P34: =O34 -> 0.12265108 | R34: =J34-P34 -> 6.9285546
B35: 6666110112 | C35: 6666110112 Depreciation of Furniture & Fixture | D35: 家具及装置折旧 | E35: 11.262015 | F35: 0.20972095 | G35: 13.930613 | H35: 0.37875512 | I35: 3.99885 | J35: 0.12101958 | K35: =J35-F35 -> -0.088701365 | L35: -0.25773554 | N35: 2.3742258 | O35: =N35*1000/$O$29 -> 0.065950717 | P35: =O35 -> 0.065950717 | R35: =J35-P35 -> 0.055068864
B36: 6666110204 | C36: 6666110204 Amortization of license, trademarks and | D36: 许可证、商标及摊销 | E36: 0.25251497 | F36: 0.0047023272 | G36: 0.25251 | H36: 0.006865416 | I36: 0.07576 | J36: 0.00229277 | K36: =J36-F36 -> -0.0024095572 | L36: -0.004572646 | N36: 0 | O36: =N36*1000/$O$29 -> 0 | P36: =O36 -> 0 | R36: =J36-P36 -> 0.00229277
B37: 6666110207 | C37: 6666110207 Amortization of Software | D37: 软件摊销 | E37: 6.7839525 | F37: 0.12633059 | G37: 2.5668029 | H37: 0.069788008 | I37: 0.93228 | J37: 0.028214145 | K37: =J37-F37 -> -0.098116441 | L37: -0.041573863 | N37: 0 | O37: =N37*1000/$O$29 -> 0 | P37: =O37 -> 0 | R37: =J37-P37 -> 0.028214145
B38: 6666110506 | C38: 6666110506 Amortization-Leasehold Improvement | D38: 租赁改良摊销 | E38: 0.68159 | F38: 0.012692551 | G38: 0 | H38: 0 | I38: 0 | J38: 0 | K38: =J38-F38 -> -0.012692551 | L38: 0 | N38: 0 | O38: =N38*1000/$O$29 -> 0 | P38: =O38 -> 0 | R38: =J38-P38 -> 0
B39: 6666110206 | C39: 6666110206 Amortization of Patents | D39: 专利摊销 | F39: 0 | H39: 0 | I39: 0 | J39: 0 | K39: =J39-F39 -> 0 | L39: 0 | N39: 0 | O39: =N39*1000/$O$29 -> 0 | P39: =O39 -> 0 | R39: =J39-P39 -> 0
B40: FIX | C40: * CS_Depreciation | D40: * CS_折旧 | E40: 579.31652 | F40: 10.788017 | G40: 580.23528 | H40: 15.775837 | I40: 433.31502 | J40: 13.113671 | K40: =J40-F40 -> 2.3256536 | L40: -2.6621663 | M40: =K40*$K$29 -> 76846.572 | N40: =SUM(N31:N39) -> 458.60897 | O40: =N40*1000/$O$29 -> 12.739138 | P40: =O40 -> 12.739138 | Q40: =I40-N40 -> -25.293954 | R40: =J40-P40 -> 0.37453252
A41: 直接人工 | B41: 5001010205 | C41: 5001010205 Unemployment Insurance -blue collar-Dire | D41: 失业保险-蓝领-直接 | E41: 9.34405 | F41: 0.17400466 | G41: 10.118543 | H41: 0.27510992 | I41: 7.1399794 | J41: 0.21608145 | K41: =J41-F41 -> 0.042076795 | L41: -0.059028468 | N41: 0 | O41: =N41*1000/$O$29 -> 0 | P41: =O41 -> 0 | R41: =J41-P41 -> 0.21608145
...

Sheet 洗碗机6月
B1: 1月费用总结： ①单：1月同期35欧元/台，订单量4.86万台，预测单台费用36.4欧元/台，较同期↑3.9%；实际37.48欧元/台，较同期↑6% 共梳理出8个问题
A2: 维度 | B2: 指标 | C2: 25年实际 | D2: 26年预算 | E2: 26年实际 | F2: 实际比同期差异 | G2: 制造费差额 | H2: 差异原因
A4: 单 | B4: 产量 | C4: 29664 | D4: 53265 | E4: 53186
A5: 时 | B5: 工作天数 | C5: 21 | D5: 14 | E5: 21
A6: 人 | B6: 直接人工 | C6: 226 | D6: 247 | E6: 261
B7: 直接人工工资 | C7: =E47/C6*1000 -> 1638.1892 | D7: =G47/D6*1000 -> 1948.6038 | E7: =I47/E6*1000 -> 1195.4172
B8: 间接人工 | C8: 93 | D8: 85 | E8: 82
B9: 间接人工工资 | C9: =E130/C8*1000 -> 1818.4072 | D9: =G130/D8*1000 -> 2196.4172 | E9: =I130/E8*1000 -> 2154.8715
B10: 白领人数 | C10: 23 | D10: 27 | E10: 25
B11: 白领人工工资 | C11: =E133/C10*1000 -> 2829.583 | D11: =G133/D10*1000 -> 3529.4159 | E11: =I133/E10*1000 -> 3480.1812
A12: 效 | B12: UPPH | C12: =C4/C5/(C6+C8)/7.5 -> 0.59041648 | D12: =D4/D5/(D6+D8)/7.5 -> 1.527969 | E12: =E4/E5/(E6+E8)/7.5 -> 0.98451571
A13: 费 | B13: 单台制造费 | C13: 58.586165 | D13: 35.115602 | E13: 27.048161 | F13: -31.538004 | G13: -1677380.3 | H13: =E13*$E$4 -> 1438583.5
B14: 折旧 | C14: 10.791543 | D14: 15.772406 | E14: 8.1496992 | F14: -2.6418433 | G14: -140509.08 | H14: =E14*$E$4 -> 433449.9
B15: 运营费 | C15: 0.70691531 | D15: 1.5337617 | E15: 1.0090607 | F15: 0.30214534 | G15: 16069.902 | H15: =E15*$E$4 -> 53667.9
B16: 存货跌价准备 | C16: 0.038792827 | D16: 0.22945591 | E16: -0.57750724 | F16: -0.61630007 | G16: -32778.535 | H16: =E16*$E$4 -> -30715.3
B17: 固定能源费 | C17: 0.1248583 | D17: 0.095942022 | E17: 0.039939082 | F17: -0.084919216 | G17: -4516.5134 | H17: =E17*$E$4 -> 2124.2
B18: 间接人工成本-辅助人员 | C18: 4.4930908 | D18: 6.2108564 | E18: 4.3101681 | F18: -0.18292274 | G18: -9728.9289 | H18: =E18*$E$4 -> 229240.6
B19: 固定人工-白领 | C19: 1.5134612 | D19: 3.0107146 | E19: 2.0983078 | F19: 0.58484663 | G19: 31105.653 | H19: =E19*$E$4 -> 111600.6
B20: 半固定-班车/工作服 | C20: 2.5109569 | D20: 4.2326322 | E20: 2.0936111 | F20: -0.41734581 | G20: -22196.954 | H20: =E20*$E$4 -> 111350.8
B21: 直接人工 | C21: 10.483577 | D21: 15.731221 | E21: 7.3634716 | F21: -3.1201056 | G21: -165945.94 | H21: =E21*$E$4 -> 391633.6
B22: 可回收废料 | C22: 0.52579249 | D22: 0.3955878 | E22: 0.52589779 | F22: 0.00010530047 | G22: 5.6005109 | H22: =E22*$E$4 -> 27970.4
